Workbook

Sheet QDL
A1: Dimensionamento de Cálculos Do luminotécnico
A2: Quadro | B2: Nº do circuito | C2: Área | D2: Tensão (V) | E2: Método de Instalação | F2: Método de Referência | G2: Nº de luminárias | H2: Potência Lum. (VA) | I2: Demanda (VA) | J2: Ip (A) | K2: FP | M2: Método de instalação se escolhe da tabela dos slides de ampacidade, isso seria a norma 5410
A3: QDL0 | B3: L0 | C3: SUBESTAÇÃO | D3: 220 | E3: 33 | F3: B1 | G3: 5 | H3: 500 | I3: =H3*G3 -> 2500 | J3: =I3/D3 -> 11.363636 | K3: 0.95 | M3: Em função da elevada altura de 7,0m, dos ambientes adota o método 13 pois tem: livre circulação e ventilação no topo, manutenção em grande altura. Em altura baixas como 3 m pode adotar o método 7. A subestação pode adotar o método 33 pois: Interligação do Transformador com o QGBT para cabos pelo Piso, acomoda cabos grandes e pesados
A4: QDL1 | B4: L1 | C4: SALA DE CALDEIRAS | D4: 220 | E4: 13 | F4: F | G4: 4 | H4: 440 | I4: =H4*G4 -> 1760 | J4: =I4/D4 -> 8 | K4: 0.85
A5: QDL2 | B5: L2 | C5: COMPRESSOR (BOMBAS E PRENSA) | D5: 220 | E5: 13 | F5: F | G5: 6 | H5: 440 | I5: =H5*G5 -> 2640 | J5: =I5/D5 -> 12 | K5: 0.85
A6: QDL3 | B6: L3 | C6: DEPÓSITO DE CARCAÇAS | D6: 220 | E6: 13 | F6: F | G6: 6 | H6: 440 | I6: =H6*G6 -> 2640 | J6: =I6/D6 -> 12 | K6: 0.85
A7: QDL4 | B7: L4 | C7: RASPA | D7: 220 | E7: 13 | F7: F | G7: 7 | H7: 440 | I7: =H7*G7 -> 3080 | J7: =I7/D7 -> 14 | K7: 0.85
B8: L5 | C8: RASPA | D8: 220 | E8: 13 | F8: F | G8: 7 | H8: 440 | I8: =H8*G8 -> 3080 | J8: =I8/D8 -> 14 | K8: 0.85
B9: L6 | C9: RECAPAGEM | D9: 220 | E9: 13 | F9: F | G9: 10 | H9: 440 | I9: =H9*G9 -> 4400 | J9: =I9/D9 -> 20 | K9: 0.95
B10: L7 | C10: RECAPAGEM | D10: 220 | E10: 13 | F10: F | G10: 10 | H10: 440 | I10: =H10*G10 -> 4400 | J10: =I10/D10 -> 20 | K10: 0.95
B11: L8 | C11: RECAPAGEM | D11: 220 | E11: 13 | F11: F | G11: 10 | H11: 440 | I11: =H11*G11 -> 4400 | J11: =I11/D11 -> 20 | K11: 0.95
B12: L9 | C12: RECAPAGEM | D12: 220 | E12: 13 | F12: F | G12: 10 | H12: 440 | I12: =H12*G12 -> 4400 | J12: =I12/D12 -> 20 | K12: 0.95
B13: L10 | C13: RECAPAGEM | D13: 220 | E13: 13 | F13: F | G13: 10 | H13: 440 | I13: =H13*G13 -> 4400 | J13: =I13/D13 -> 20 | K13: 0.95
B14: L11 | C14: RECAPAGEM | D14: 220 | E14: 13 | F14: F | G14: 10 | H14: 440 | I14: =H14*G14 -> 4400 | J14: =I14/D14 -> 20 | K14: 0.95
B15: L12 | C15: RECAPAGEM | D15: 220 | E15: 13 | F15: F | G15: 10 | H15: 440 | I15: =H15*G15 -> 4400 | J15: =I15/D15 -> 20 | K15: 0.95
B16: L13 | C16: RECAPAGEM | D16: 220 | E16: 13 | F16: F | G16: 10 | H16: 440 | I16: =H16*G16 -> 4400 | J16: =I16/D16 -> 20 | K16: 0.95
B17: L14 | C17: RECAPAGEM | D17: 220 | E17: 13 | F17: F | G17: 10 | H17: 440 | I17: =H17*G17 -> 4400 | J17: =I17/D17 -> 20 | K17: 0.95
B18: L15 | C18: RECAPAGEM | D18: 220 | E18: 13 | F18: F | G18: 10 | H18: 440 | I18: =H18*G18 -> 4400 | J18: =I18/D18 -> 20 | K18: 0.95
B19: L16 | C19: RECAPAGEM | D19: 220 | E19: 13 | F19: F | G19: 10 | H19: 440 | I19: =H19*G19 -> 4400 | J19: =I19/D19 -> 20 | K19: 0.95
B20: L17 | C20: RECAPAGEM | D20: 220 | E20: 13 | F20: F | G20: 6 | H20: 440 | I20: =H20*G20 -> 2640 | J20: =I20/D20 -> 12 | K20: 0.95
A21: QDL5 | B21: L18 | C21: ESCRITÓRIO | D21: 220 | E21: 7 | F21: B1 | G21: 15 | H21: 120 | I21: =H21*G21 -> 1800 | J21: =I21/D21 -> 8.1818182 | K21: 0.9
A22: QDL6 | B22: L19 | C22: SAIDA DE PRODUTOS | D22: 220 | E22: 7 | F22: B1 | G22: 3 | H22: 120 | I22: =H22*G22 -> 360 | J22: =I22/D22 -> 1.6363636 | K22: 0.9
B23: L20 | C23: CONTROLE DE QUALIDADE | D23: 220 | E23: 7 | F23: B1 | G23: 18 | H23: 120 | I23: =H23*G23 -> 2160 | J23: =I23/D23 -> 9.8181818 | K23: 0.9
A24: QDL7 | B24: L21 | C24: BANHEIRO (VESTUÁRIO) | D24: 220 | E24: 7 | F24: B1 | G24: 2 | H24: 120 | I24: =H24*G24 -> 240 | J24: =I24/D24 -> 1.0909091 | K24: 0.9
M33: Método de referencia: Adotar método F(unipolares pois Lançar 3 ou 4 cabos unipolares separados (um para cada fase/neutro) torna a montagem física viável na infraestrutura aérea, cada cabo possui sua própria superfície externa de isolação em contato direto com o ar em circulação
M37: OS CIRCUITO DAS RASPA, RECAPAGEM DEVEM: Dividir os circuitos cuja demanda deeem mais de 4500 VA pois ajuda na distribuição. A NBR 5410 (item 9.5.2) recomenda que circuitos terminais de iluminação industrial não sobrecarreguem o disjuntor de proteção. Em 220V, a corrente total seria de 32 A, exigindo fiação de 6mm ou mais e disjuntores elevados, o que foge do padrão eficiente para linhas de iluminação

Sheet QDL-FATOR CORREÇÃO
A1: Fatores de correção
A2: Quadro | B2: Nº do circuito | C2: Área | D2: Circuitos agrupados | E2: Método de Instalação | F2: Método de Referência | G2: Ref (tabela 9.10) | H2: Cabos multipolares | I2: Fator de agrupamento | J2: Fator de temperatura (45º) | K2: Fator de harmônicos | L2: Isolação | M2: Ip (A) | N2: Ip' (A) | O2: Iz (A) | P2: Iz' | R2: FATOR DE AGRUPAMENTO PEGO POR CABOS MULTIPOLARES: SUBESTAÇÃO usa referencia 1 (é embutido a instalação 33-B1(ve metodo B na coluna da tabela abaixo)). SALA DE CALDEIRAS+ COMPRESSOR DEPOISITO DE CARCAÇAS+RASPA usa referencia 4 (bandeja perfurada é 13-F(ve a coluna F da tabela abaixo))
A3: QDL0 | B3: L0 | C3: SUBESTAÇÃO | D3: 1 | E3: 33 | F3: B1 | G3: 1 | H3: 1 | I3: 1 | J3: =$S69 -> 0.87 | K3: 1 | L3: EPR ou XLPE | M3: =QDL!J3 -> 11.363636 | N3: =((M3)*(K3)/(J3*I3)) -> 13.061651 | O3: 23 | P3: =J3*I3*O3 -> 20.01
A4: QDL1 | B4: L1 | C4: SALA DE CALDEIRAS | D4: 1 | E4: 13 | F4: F | G4: 4 | H4: 1 | I4: 1 | J4: =S69 -> 0.87 | K4: 1 | L4: EPR ou XLPE | M4: =QDL!J4 -> 8 | N4: =((M4)*(K4)/(J4*I4)) -> 9.1954023 | O4: 22 | P4: =J4*I4*O4 -> 19.14
A5: QDL2 | B5: L2 | C5: COMPRESSOR (BOMBAS E PRENSA) | D5: 1 | E5: 13 | F5: F | G5: 4 | H5: 1 | I5: 1 | J5: =S69 -> 0.87 | K5: 1 | L5: EPR ou XLPE | M5: =QDL!J5 -> 12 | N5: =((M5)*(K5)/(J5*I5)) -> 13.793103 | O5: 22 | P5: =J5*I5*O5 -> 19.14
A6: QDL3 | B6: L3 | C6: DEPOSITO DE CARCAÇAS | D6: 1 | E6: 13 | F6: F | G6: 4 | H6: 1 | I6: 1 | J6: =S69 -> 0.87 | K6: 1 | L6: EPR ou XLPE | M6: =QDL!J6 -> 12 | N6: =((M6)*(K6)/(J6*I6)) -> 13.793103 | O6: 22 | P6: =J6*I6*O6 -> 19.14
A7: QDL4 | B7: L4 | C7: RASPA | D7: 2 | E7: 13 | F7: F | G7: 4 | H7: 2 | I7: 0.88 | J7: =S69 -> 0.87 | K7: 1 | L7: EPR ou XLPE | M7: =QDL!J7 -> 14 | N7: =((M7)*(K7)/(J7*I7)) -> 18.286311 | O7: 30 | P7: =J7*I7*O7 -> 22.968
B8: L5 | C8: RASPA | D8: 2 | E8: 13 | F8: F | G8: 4 | H8: 2 | I8: 0.88 | J8: =S69 -> 0.87 | K8: 1 | L8: EPR ou XLPE | M8: =QDL!J8 -> 14 | N8: =((M8)*(K8)/(J8*I8)) -> 18.286311 | O8: 30 | P8: =J8*I8*O8 -> 22.968
B9: L6 | C9: RECAPAGEM | D9: 2 | E9: 13 | F9: F | G9: 4 | H9: 2 | I9: 0.88 | J9: =$S69 -> 0.87 | K9: 1 | L9: EPR ou XLPE | M9: =QDL!J9 -> 20 | N9: =((M9)*(K9)/(J9*I9)) -> 26.123302 | O9: 42 | P9: =J9*I9*O9 -> 32.1552
B10: L7 | C10: RECAPAGEM | D10: 2 | E10: 13 | F10: F | G10: 4 | H10: 2 | I10: 0.88 | J10: =$S69 -> 0.87 | K10: 1 | L10: EPR ou XLPE | M10: =QDL!J10 -> 20 | N10: =((M10)*(K10)/(J10*I10)) -> 26.123302 | O10: 42 | P10: =J10*I10*O10 -> 32.1552
B11: L8 | C11: RECAPAGEM | D11: 2 | E11: 13 | F11: F | G11: 4 | H11: 2 | I11: 0.88 | J11: =$S69 -> 0.87 | K11: 1 | L11: EPR ou XLPE | M11: =QDL!J11 -> 20 | N11: =((M11)*(K11)/(J11*I11)) -> 26.123302 | O11: 42 | P11: =J11*I11*O11 -> 32.1552
B12: L9 | C12: RECAPAGEM | D12: 2 | E12: 13 | F12: F | G12: 4 | H12: 2 | I12: 0.88 | J12: =$S69 -> 0.87 | K12: 1 | L12: EPR ou XLPE | M12: =QDL!J12 -> 20 | N12: =((M12)*(K12)/(J12*I12)) -> 26.123302 | O12: 42 | P12: =J12*I12*O12 -> 32.1552
B13: L10 | C13: RECAPAGEM | D13: 2 | E13: 13 | F13: F | G13: 4 | H13: 2 | I13: 0.88 | J13: =$S69 -> 0.87 | K13: 1 | L13: EPR ou XLPE | M13: =QDL!J13 -> 20 | N13: =((M13)*(K13)/(J13*I13)) -> 26.123302 | O13: 42 | P13: =J13*I13*O13 -> 32.1552
B14: L11 | C14: RECAPAGEM | D14: 2 | E14: 13 | F14: F | G14: 4 | H14: 2 | I14: 0.88 | J14: =$S69 -> 0.87 | K14: 1 | L14: EPR ou XLPE | M14: =QDL!J14 -> 20 | N14: =((M14)*(K14)/(J14*I14)) -> 26.123302 | O14: 42 | P14: =J14*I14*O14 -> 32.1552
B15: L12 | C15: RECAPAGEM | D15: 2 | E15: 13 | F15: F | G15: 4 | H15: 2 | I15: 0.88 | J15: =$S69 -> 0.87 | K15: 1 | L15: EPR ou XLPE | M15: =QDL!J15 -> 20 | N15: =((M15)*(K15)/(J15*I15)) -> 26.123302 | O15: 42 | P15: =J15*I15*O15 -> 32.1552
B16: L13 | C16: RECAPAGEM | D16: 2 | E16: 13 | F16: F | G16: 4 | H16: 2 | I16: 0.88 | J16: =$S69 -> 0.87 | K16: 1 | L16: EPR ou XLPE | M16: =QDL!J16 -> 20 | N16: =((M16)*(K16)/(J16*I16)) -> 26.123302 | O16: 42 | P16: =J16*I16*O16 -> 32.1552
B17: L14 | C17: RECAPAGEM | D17: 2 | E17: 13 | F17: F | G17: 4 | H17: 2 | I17: 0.88 | J17: =$S69 -> 0.87 | K17: 1 | L17: EPR ou XLPE | M17: =QDL!J17 -> 20 | N17: =((M17)*(K17)/(J17*I17)) -> 26.123302 | O17: 42 | P17: =J17*I17*O17 -> 32.1552
B18: L15 | C18: RECAPAGEM | D18: 2 | E18: 13 | F18: F | G18: 4 | H18: 2 | I18: 0.88 | J18: =$S69 -> 0.87 | K18: 1 | L18: EPR ou XLPE | M18: =QDL!J18 -> 20 | N18: =((M18)*(K18)/(J18*I18)) -> 26.123302 | O18: 42 | P18: =J18*I18*O18 -> 32.1552
B19: L16 | C19: RECAPAGEM | D19: 2 | E19: 13 | F19: F | G19: 4 | H19: 2 | I19: 0.88 | J19: =$S69 -> 0.87 | K19: 1 | L19: EPR ou XLPE | M19: =QDL!J19 -> 20 | N19: =((M19)*(K19)/(J19*I19)) -> 26.123302 | O19: 42 | P19: =J19*I19*O19 -> 32.1552
B20: L17 | C20: RECAPAGEM | D20: 2 | E20: 13 | F20: F | G20: 4 | H20: 2 | I20: 0.88 | J20: =$S69 -> 0.87 | K20: 1 | L20: EPR ou XLPE | M20: =QDL!J20 -> 12 | N20: =((M20)*(K20)/(J20*I20)) -> 15.673981 | O20: 30 | P20: =J20*I20*O20 -> 22.968
A21: QDL5 | B21: L18 | C21: ESCRITÓRIO | D21: 1 | E21: 7 | F21: B1 | G21: 1 | H21: 1 | I21: 1 | J21: =R69 -> 0.79 | K21: 1 | L21: PVC | M21: =QDL!J21 -> 8.1818182 | N21: =((M21)*(K21)/(J21*I21)) -> 10.356732 | O21: 17.5 | P21: =J21*I21*O21 -> 13.825
A22: QDL6 | B22: L19 | C22: SAIDA DE PRODUTOS | D22: 1 | E22: 7 | F22: B1 | G22: 1 | H22: 1 | I22: 1 | J22: =R69 -> 0.79 | K22: 1 | L22: PVC | M22: =QDL!J22 -> 1.6363636 | N22: =((M22)*(K22)/(J22*I22)) -> 2.0713464 | O22: 17.5 | P22: =J22*I22*O22 -> 13.825
B23: L20 | C23: CONTROLE DE QUALIDADE | D23: 1 | E23: 7 | F23: B1 | G23: 1 | H23: 1 | I23: 1 | J23: =R69 -> 0.79 | K23: 1 | L23: PVC | M23: =QDL!J23 -> 9.8181818 | N23: =((M23)*(K23)/(J23*I23)) -> 12.428078 | O23: 24 | P23: =J23*I23*O23 -> 18.96
A24: QDL7 | B24: L21 | C24: BANHEIRO (VESTUÁRIO) | D24: 1 | E24: 7 | F24: B1 | G24: 1 | H24: 1 | I24: 1 | J24: =R69 -> 0.79 | K24: 1 | L24: PVC | M24: =QDL!J24 -> 1.0909091 | N24: =((M24)*(K24)/(J24*I24)) -> 1.3808976 | O24: 17.5 | P24: =J24*I24*O24 -> 13.825
C27: Método de Instalação | I27: lampada e tomada não usa harmonico, mas tomada de escritório para computador usa harmonico, usa ali no numerador x1,15
C28: 33
C29: 13
C30: 13
C31: 13
C32: 13
C33: 13
Q67: Fator de Correção - Temperatura
Q68: Temperatura | R68: PVC | S68: EPR ou XLPE
Q69: 45 | R69: 0.79 | S69: 0.87
Q71: Adota cabos EPR OU XLPE para ambientes mais nocivos (quentes, sujos, alta concentração de cabos) como: Sala de Caldeiras, Compressor (Bombas e Prensa), Depósito de Carcaças e Raspa, Recapagem, Subestação. Ambientes comuns como: Sala de Produto, Controle de Qualidade, Banheiro (Vestuário) e Escritório adota cabos PVC
Q77: FATOR HARMONICO: ADOTAR 1,15, O valor 1,15 é utilizado porque se trata de um fator de majoração aplicado quando há presença de 3º harmônico (entre 15% e 35%) em sistemas de iluminação e cargas não lineares (como reatores eletrônicos e lâmpadas LED).
Q99: Ip' (A)
O121: I_I (negocio do denominador) é produtorio no denominador: Ele indica que você deve multiplicar todos os fatores de correção entre si e dividir a corrente de projeto Ip por esse resultado.
Q125: pergunta calculo de Ip'
Q126: PERGUNTA CALCULO DE Iz' existe?
...

Sheet SEÇÃO CONDUTORES
A1: Seção dos condutores (mm²)
A2: Quadro | B2: Nº do circuito | C2: Área | D2: Cabos multipolares | E2: Circuitos agrupados | F2: Condutores carregados CC | G2: Isolação | H2: Método de Instalação | I2: Método de Referência | J2: Fase | K2: Neutro | L2: Terra | Q2: Adota Seções nominais os escolhido la em FATOR CORREÇÃO, as seções nominais
A3: QDL0 | B3: L0 | C3: SUBESTAÇÃO | D3: ='QDL-FATOR CORREÇÃO'!H3 -> 1 | E3: ='QDL-FATOR CORREÇÃO'!D3 -> 1 | F3: 2 | G3: EPR ou XLPE | H3: 33 | I3: B1 | J3: 1.5 | K3: 1.5 | L3: 1.5
A4: QDL1 | B4: L1 | C4: SALA DE CALDEIRAS | D4: ='QDL-FATOR CORREÇÃO'!H4 -> 1 | E4: ='QDL-FATOR CORREÇÃO'!D4 -> 1 | F4: 2 | G4: EPR ou XLPE | H4: 13 | I4: F | J4: 1.5 | K4: 1.5 | L4: 1.5
A5: QDL2 | B5: L2 | C5: COMPRESSOR (BOMBAS E PRENSA) | D5: ='QDL-FATOR CORREÇÃO'!H5 -> 1 | E5: ='QDL-FATOR CORREÇÃO'!D5 -> 1 | F5: 2 | G5: EPR ou XLPE | H5: 13 | I5: F | J5: 1.5 | K5: 1.5 | L5: 1.5
A6: QDL3 | B6: L3 | C6: DEPOSITO DE CARCAÇAS | D6: ='QDL-FATOR CORREÇÃO'!H6 -> 1 | E6: ='QDL-FATOR CORREÇÃO'!D6 -> 1 | F6: 2 | G6: EPR ou XLPE | H6: 13 | I6: F | J6: 1.5 | K6: 1.5 | L6: 1.5
A7: QDL4 | B7: L4 | C7: RASPA | D7: ='QDL-FATOR CORREÇÃO'!H7 -> 2 | E7: ='QDL-FATOR CORREÇÃO'!D7 -> 2 | F7: 2 | G7: EPR ou XLPE | H7: 13 | I7: F | J7: 2.5 | K7: 2.5 | L7: 2.5
B8: L5 | C8: RASPA | D8: ='QDL-FATOR CORREÇÃO'!H8 -> 2 | E8: ='QDL-FATOR CORREÇÃO'!D8 -> 2 | F8: 2 | G8: EPR ou XLPE | H8: 13 | I8: F | J8: 2.5 | K8: 2.5 | L8: 2.5
B9: L6 | C9: RECAPAGEM | D9: ='QDL-FATOR CORREÇÃO'!H9 -> 2 | E9: ='QDL-FATOR CORREÇÃO'!D9 -> 2 | F9: 2 | G9: EPR ou XLPE | H9: 13 | I9: F | J9: 4 | K9: 4 | L9: 4
B10: L7 | C10: RECAPAGEM | D10: ='QDL-FATOR CORREÇÃO'!H10 -> 2 | E10: ='QDL-FATOR CORREÇÃO'!D10 -> 2 | F10: 2 | G10: EPR ou XLPE | H10: 13 | I10: F | J10: 4 | K10: 4 | L10: 4
B11: L8 | C11: RECAPAGEM | D11: ='QDL-FATOR CORREÇÃO'!H11 -> 2 | E11: ='QDL-FATOR CORREÇÃO'!D11 -> 2 | F11: 2 | G11: EPR ou XLPE | H11: 13 | I11: F | J11: 4 | K11: 4 | L11: 4
B12: L9 | C12: RECAPAGEM | D12: ='QDL-FATOR CORREÇÃO'!H12 -> 2 | E12: ='QDL-FATOR CORREÇÃO'!D12 -> 2 | F12: 2 | G12: EPR ou XLPE | H12: 13 | I12: F | J12: 4 | K12: 4 | L12: 4
B13: L10 | C13: RECAPAGEM | D13: ='QDL-FATOR CORREÇÃO'!H13 -> 2 | E13: ='QDL-FATOR CORREÇÃO'!D13 -> 2 | F13: 2 | G13: EPR ou XLPE | H13: 13 | I13: F | J13: 4 | K13: 4 | L13: 4
B14: L11 | C14: RECAPAGEM | D14: ='QDL-FATOR CORREÇÃO'!H14 -> 2 | E14: ='QDL-FATOR CORREÇÃO'!D14 -> 2 | F14: 2 | G14: EPR ou XLPE | H14: 13 | I14: F | J14: 4 | K14: 4 | L14: 4
B15: L12 | C15: RECAPAGEM | D15: ='QDL-FATOR CORREÇÃO'!H15 -> 2 | E15: ='QDL-FATOR CORREÇÃO'!D15 -> 2 | F15: 2 | G15: EPR ou XLPE | H15: 13 | I15: F | J15: 4 | K15: 4 | L15: 4
B16: L13 | C16: RECAPAGEM | D16: ='QDL-FATOR CORREÇÃO'!H16 -> 2 | E16: ='QDL-FATOR CORREÇÃO'!D16 -> 2 | F16: 2 | G16: EPR ou XLPE | H16: 13 | I16: F | J16: 4 | K16: 4 | L16: 4
B17: L14 | C17: RECAPAGEM | D17: ='QDL-FATOR CORREÇÃO'!H17 -> 2 | E17: ='QDL-FATOR CORREÇÃO'!D17 -> 2 | F17: 2 | G17: EPR ou XLPE | H17: 13 | I17: F | J17: 4 | K17: 4 | L17: 4
B18: L15 | C18: RECAPAGEM | D18: ='QDL-FATOR CORREÇÃO'!H18 -> 2 | E18: ='QDL-FATOR CORREÇÃO'!D18 -> 2 | F18: 2 | G18: EPR ou XLPE | H18: 13 | I18: F | J18: 4 | K18: 4 | L18: 4
B19: L16 | C19: RECAPAGEM | D19: ='QDL-FATOR CORREÇÃO'!H19 -> 2 | E19: ='QDL-FATOR CORREÇÃO'!D19 -> 2 | F19: 2 | G19: EPR ou XLPE | H19: 13 | I19: F | J19: 4 | K19: 4 | L19: 4
B20: L17 | C20: RECAPAGEM | D20: ='QDL-FATOR CORREÇÃO'!H20 -> 2 | E20: ='QDL-FATOR CORREÇÃO'!D20 -> 2 | F20: 2 | G20: EPR ou XLPE | H20: 13 | I20: F | J20: 4 | K20: 4 | L20: 4
A21: QDL5 | B21: L18 | C21: ESCRITÓRIO | D21: 1 | E21: 1 | F21: 2 | G21: PVC | H21: 7 | I21: B1 | J21: 1.5 | K21: 1.5 | L21: 1.5
A22: QDL6 | B22: L19 | C22: SAIDA DE PRODUTOS | D22: 1 | E22: 1 | F22: 2 | G22: PVC | H22: 7 | I22: B1 | J22: 1.5 | K22: 1.5 | L22: 1.5
B23: L20 | C23: CONTROLE DE QUALIDADE | D23: 1 | E23: 1 | F23: 2 | G23: PVC | H23: 7 | I23: B1 | J23: 2.5 | K23: 2.5 | L23: 2.5
A24: QDL7 | B24: L21 | C24: BANHEIRO (VESTUÁRIO) | D24: 1 | E24: 1 | F24: 2 | G24: PVC | H24: 7 | I24: B1 | J24: 1.5 | K24: 1.5 | L24: 1.5

Sheet DISJUNTORES
A1: Disjuntor (A) | H1: Mudou disjuntor
A2: Quadro | B2: Nº do circuito | C2: Área | D2: Iz' (A) | E2: In (A) | F2: Ip (A) | G2: Iz'>In>Ip
A3: QDL0 | B3: L0 | C3: SUBESTAÇÃO | D3: ='QDL-FATOR CORREÇÃO'!P3 -> 20.01 | E3: 16 | F3: ='QDL-FATOR CORREÇÃO'!M3 -> 11.363636 | G3: =IF(AND(D3>E3,E3>F3),"OK","MUDAR DISJUNTOR") -> OK | H3: 10 para 16
A4: QDL1 | B4: L1 | C4: SALA DE CALDEIRAS | D4: ='QDL-FATOR CORREÇÃO'!P4 -> 19.14 | E4: 16 | F4: ='QDL-FATOR CORREÇÃO'!M4 -> 8 | G4: =IF(AND(D4>E4,E4>F4),"OK","MUDAR DISJUNTOR") -> OK | J4: A corrente comercial do disjuntor é o In
A5: QDL2 | B5: L2 | C5: COMPRESSOR (BOMBAS E PRENSA) | D5: ='QDL-FATOR CORREÇÃO'!P5 -> 19.14 | E5: 16 | F5: ='QDL-FATOR CORREÇÃO'!M5 -> 12 | G5: =IF(AND(D5>E5,E5>F5),"OK","MUDAR DISJUNTOR") -> OK | H5: 10 para 16
A6: QDL3 | B6: L3 | C6: DEPOSITO DE CARCAÇAS | D6: ='QDL-FATOR CORREÇÃO'!P6 -> 19.14 | E6: 16 | F6: ='QDL-FATOR CORREÇÃO'!M6 -> 12 | G6: =IF(AND(D6>E6,E6>F6),"OK","MUDAR DISJUNTOR") -> OK | H6: 10 para 16
A7: QDL4 | B7: L4 | C7: RASPA | D7: ='QDL-FATOR CORREÇÃO'!P7 -> 22.968 | E7: 20 | F7: ='QDL-FATOR CORREÇÃO'!M7 -> 14 | G7: =IF(AND(D7>E7,E7>F7),"OK","MUDAR DISJUNTOR") -> OK
B8: L5 | C8: RASPA | D8: ='QDL-FATOR CORREÇÃO'!P8 -> 22.968 | E8: 20 | F8: ='QDL-FATOR CORREÇÃO'!M8 -> 14 | G8: =IF(AND(D8>E8,E8>F8),"OK","MUDAR DISJUNTOR") -> OK
B9: L6 | C9: RECAPAGEM | D9: ='QDL-FATOR CORREÇÃO'!P9 -> 32.1552 | E9: 25 | F9: ='QDL-FATOR CORREÇÃO'!M9 -> 20 | G9: =IF(AND(D9>E9,E9>F9),"OK","MUDAR DISJUNTOR") -> OK
B10: L7 | C10: RECAPAGEM | D10: ='QDL-FATOR CORREÇÃO'!P10 -> 32.1552 | E10: 25 | F10: ='QDL-FATOR CORREÇÃO'!M10 -> 20 | G10: =IF(AND(D10>E10,E10>F10),"OK","MUDAR DISJUNTOR") -> OK
B11: L8 | C11: RECAPAGEM | D11: ='QDL-FATOR CORREÇÃO'!P11 -> 32.1552 | E11: 25 | F11: ='QDL-FATOR CORREÇÃO'!M11 -> 20 | G11: =IF(AND(D11>E11,E11>F11),"OK","MUDAR DISJUNTOR") -> OK
B12: L9 | C12: RECAPAGEM | D12: ='QDL-FATOR CORREÇÃO'!P12 -> 32.1552 | E12: 25 | F12: ='QDL-FATOR CORREÇÃO'!M12 -> 20 | G12: =IF(AND(D12>E12,E12>F12),"OK","MUDAR DISJUNTOR") -> OK
B13: L10 | C13: RECAPAGEM | D13: ='QDL-FATOR CORREÇÃO'!P13 -> 32.1552 | E13: 25 | F13: ='QDL-FATOR CORREÇÃO'!M13 -> 20 | G13: =IF(AND(D13>E13,E13>F13),"OK","MUDAR DISJUNTOR") -> OK
B14: L11 | C14: RECAPAGEM | D14: ='QDL-FATOR CORREÇÃO'!P14 -> 32.1552 | E14: 25 | F14: ='QDL-FATOR CORREÇÃO'!M14 -> 20 | G14: =IF(AND(D14>E14,E14>F14),"OK","MUDAR DISJUNTOR") -> OK
B15: L12 | C15: RECAPAGEM | D15: ='QDL-FATOR CORREÇÃO'!P15 -> 32.1552 | E15: 25 | F15: ='QDL-FATOR CORREÇÃO'!M15 -> 20 | G15: =IF(AND(D15>E15,E15>F15),"OK","MUDAR DISJUNTOR") -> OK
B16: L13 | C16: RECAPAGEM | D16: ='QDL-FATOR CORREÇÃO'!P16 -> 32.1552 | E16: 25 | F16: ='QDL-FATOR CORREÇÃO'!M16 -> 20 | G16: =IF(AND(D16>E16,E16>F16),"OK","MUDAR DISJUNTOR") -> OK
B17: L14 | C17: RECAPAGEM | D17: ='QDL-FATOR CORREÇÃO'!P17 -> 32.1552 | E17: 25 | F17: ='QDL-FATOR CORREÇÃO'!M17 -> 20 | G17: =IF(AND(D17>E17,E17>F17),"OK","MUDAR DISJUNTOR") -> OK
B18: L15 | C18: RECAPAGEM | D18: ='QDL-FATOR CORREÇÃO'!P18 -> 32.1552 | E18: 25 | F18: ='QDL-FATOR CORREÇÃO'!M18 -> 20 | G18: =IF(AND(D18>E18,E18>F18),"OK","MUDAR DISJUNTOR") -> OK
B19: L16 | C19: RECAPAGEM | D19: ='QDL-FATOR CORREÇÃO'!P19 -> 32.1552 | E19: 25 | F19: ='QDL-FATOR CORREÇÃO'!M19 -> 20 | G19: =IF(AND(D19>E19,E19>F19),"OK","MUDAR DISJUNTOR") -> OK
B20: L17 | C20: RECAPAGEM | D20: ='QDL-FATOR CORREÇÃO'!P20 -> 22.968 | E20: 16 | F20: ='QDL-FATOR CORREÇÃO'!M20 -> 12 | G20: =IF(AND(D20>E20,E20>F20),"OK","MUDAR DISJUNTOR") -> OK
A21: QDL5 | B21: L18 | C21: ESCRITÓRIO | D21: ='QDL-FATOR CORREÇÃO'!P21 -> 13.825 | E21: 10 | F21: ='QDL-FATOR CORREÇÃO'!M21 -> 8.1818182 | G21: =IF(AND(D21>E21,E21>F21),"OK","MUDAR DISJUNTOR") -> OK
A22: QDL6 | B22: L19 | C22: SAIDA DE PRODUTOS | D22: ='QDL-FATOR CORREÇÃO'!P22 -> 13.825 | E22: 10 | F22: ='QDL-FATOR CORREÇÃO'!M22 -> 1.6363636 | G22: =IF(AND(D22>E22,E22>F22),"OK","MUDAR DISJUNTOR") -> OK
B23: L20 | C23: CONTROLE DE QUALIDADE | D23: ='QDL-FATOR CORREÇÃO'!P23 -> 18.96 | E23: 10 | F23: ='QDL-FATOR CORREÇÃO'!M23 -> 9.8181818 | G23: =IF(AND(D23>E23,E23>F23),"OK","MUDAR DISJUNTOR") -> OK
A24: QDL7 | B24: L21 | C24: BANHEIRO (VESTUÁRIO) | D24: ='QDL-FATOR CORREÇÃO'!P24 -> 13.825 | E24: 10 | F24: ='QDL-FATOR CORREÇÃO'!M24 -> 1.0909091 | G24: =IF(AND(D24>E24,E24>F24),"OK","MUDAR DISJUNTOR") -> OK

Sheet QDL-QUEDA DE TENSÃO
I2: Seção dos condutores (mm²)
I3: Quadro | J3: Nº do circuito | K3: Área | L3: Cabos multipolares | M3: Circuitos agrupados | N3: Condutores carregados CC | O3: Isolação | P3: Método de Instalação | Q3: Método de Referência | R3: Fase | S3: Neutro | T3: Terra
I4: QDL0 | J4: L0 | K4: SUBESTAÇÃO | L4: 1 | M4: 1 | N4: 2 | O4: EPR ou XLPE | P4: 33 | Q4: B1 | R4: 1.5 | S4: 1.5 | T4: 1.5
I5: QDL1 | J5: L1 | K5: SALA DE CALDEIRAS | L5: 1 | M5: 1 | N5: 2 | O5: EPR ou XLPE | P5: 13 | Q5: F | R5: 1.5 | S5: 1.5 | T5: 1.5
I6: QDL2 | J6: L2 | K6: COMPRESSOR (BOMBAS E PRENSA) | L6: 1 | M6: 1 | N6: 2 | O6: EPR ou XLPE | P6: 13 | Q6: F | R6: 1.5 | S6: 1.5 | T6: 1.5
I7: QDL3 | J7: L3 | K7: DEPOSITO DE CARCAÇAS | L7: 1 | M7: 1 | N7: 2 | O7: EPR ou XLPE | P7: 13 | Q7: F | R7: 1.5 | S7: 1.5 | T7: 1.5
I8: QDL4 | J8: L4 | K8: RASPA | L8: 2 | M8: 2 | N8: 3 | O8: EPR ou XLPE | P8: 13 | Q8: F | R8: 2.5 | S8: 2.5 | T8: 2.5
J9: L5 | K9: RASPA | L9: 2 | M9: 2 | N9: 3 | O9: EPR ou XLPE | P9: 13 | Q9: F | R9: 2.5 | S9: 2.5 | T9: 2.5
J10: L6
J11: L7
J12: L8
J13: L9
J14: L10
J15: L11
J16: L12
J17: L13
J18: L14
J19: L15
J20: L16
J21: L17 | K21: ESCRITÓRIO | L21: 1 | M21: 1 | N21: 2 | O21: PVC | P21: 7 | Q21: B1 | R21: 1.5 | S21: 1.5 | T21: 1.5
I22: QDL5 | J22: L18 | K22: SAIDA DE PRODUTOS | L22: 1 | M22: 1 | N22: 2 | O22: PVC | P22: 7 | Q22: B1 | R22: 1.5 | S22: 1.5 | T22: 1.5
I23: QDL6 | J23: L19 | K23: CONTROLE DE QUALIDADE | L23: 1 | M23: 1 | N23: 2 | O23: PVC | P23: 7 | Q23: B1 | R23: 2.5 | S23: 2.5 | T23: 2.5
J24: L20 | K24: BANHEIRO (VESTUÁRIO) | L24: 1 | M24: 1 | N24: 2 | O24: PVC | P24: 7 | Q24: B1 | R24: 1.5 | S24: 1.5 | T24: 1.5
I25: QDL7 | J25: L21
I45: Em subida QDL adotar a altura ou pé direito do local e considerar a bitola para subtrair 1,5 ou 3
A51: Tensão (V) | B51: 220
A52: Potência Unitária (VA) | B52: =QDL!$H$3 -> 500
A53: Qtd Luminárias | B53: =QDL!$G$3 -> 5
A54: QDL0 - Subestação | P54: Tabela de queda tensão adaptada Prysmian
A55: Circuito L0 | B55: Corrente Ip (A) | C55: Distância L (m) | D55: Seção (mm²) | E55: R [Ω/m] | F55: X [Ω/m] | G55: FP | H55: ΔV (V) | I55: ΔV (%) | J55: ΔV(%)* | L55: Comprimento | M55: Curva | N55: Subida QDL | P55: QDL0 - Subestação
A56: QDL1-LU1 | B56: 11.363 | C56: =L56+(M56*1.5)+N56 -> 6.12 | D56: 1.5 | E56: =14.8137*10^-3 -> 0.0148137 | F56: =0.1378*10^-3 -> 0.0001378 | G56: =QDL!K$3 -> 0.95 | H56: =2*B56*C56*(E56*G56+F56*SIN(ACOS(G56))) -> 1.9633033 | I56: =H56/220 -> 0.0089241059 | J56: =I56 -> 0.0089241059 | L56: 2.42 | M56: 1 | N56: 2.2 | P56: Circuito L0 | Q56: Corrente Ip (A) | R56: Distância L (m) | S56: Seção (mm²) | T56: FP | U56: ΔV unitário (V) | V56: ΔV (%) | W56: ΔV(%)*
A57: LU1-LU2* | B57: 2.2727 | C57: =L57+(M57*1.5)+N57 -> 8.75 | D57: 1.5 | E57: =14.8137*10^-3 -> 0.0148137 | F57: =0.1378*10^-3 -> 0.0001378 | G57: =QDL!K$3 -> 0.95 | H57: =2*B57*C57*(E57*G57+F57*SIN(ACOS(G57))) -> 0.56142679 | I57: =H57/220 -> 0.00255194 | J57: =J56+I57 -> 0.011476046 | L57: 5.05 | M57: 1 | N57: 2.2 | P57: QDL1-LU1 | Q57: =B56 -> 11.363 | R57: =C56 -> 6.12 | S57: 1.5 | T57: =G57 -> 0.95 | U57: 23 | V57: =(R57/1000)*Q57*U57*(100/220)/100 -> 0.007270254 | W57: =V57 -> 0.007270254
A58: LU1-LU3 | B58: 6.818 | C58: =L58+(M58*1.5)+N58 -> 7.81 | D58: 1.5 | E58: =14.8137*10^-3 -> 0.0148137 | F58: =0.1378*10^-3 -> 0.0001378 | G58: =QDL!K$3 -> 0.95 | H58: =2*B58*C58*(E58*G58+F58*SIN(ACOS(G58))) -> 1.5033185 | I58: =H58/220 -> 0.0068332659 | J58: =J57+I58 -> 0.018309312 | L58: 4.11 | M58: 1 | N58: 2.2 | P58: LU1-LU2* | Q58: =B57 -> 2.2727 | R58: =C57 -> 8.75 | S58: 1.5 | T58: =G58 -> 0.95 | U58: 23 | V58: =(R58/1000)*Q58*U58*(100/220)/100 -> 0.002079004 | W58: =W57+V58 -> 0.009349258
A59: LU3-LU4 | B59: 4.545 | C59: =L59+(M59*1.5)+N59 -> 6.96 | D59: 1.5 | E59: =14.8137*10^-3 -> 0.0148137 | F59: =0.1378*10^-3 -> 0.0001378 | G59: =QDL!K$3 -> 0.95 | H59: =2*B59*C59*(E59*G59+F59*SIN(ACOS(G59))) -> 0.89307123 | I59: =H59/220 -> 0.0040594147 | J59: =J58+I59 -> 0.022368726 | L59: 3.26 | M59: 1 | N59: 2.2 | P59: LU1-LU3 | Q59: =B58 -> 6.818 | R59: =C58 -> 7.81 | S59: 1.5 | T59: =G59 -> 0.95 | U59: 23 | V59: =(R59/1000)*Q59*U59*(100/220)/100 -> 0.005566897 | W59: =W58+V59 -> 0.014916155
A60: LU4-LU5 | B60: 2.2727 | C60: =L60+(M60*1.5)+N60 -> 8.68 | D60: 1.5 | E60: =14.8137*10^-3 -> 0.0148137 | F60: =0.1378*10^-3 -> 0.0001378 | G60: =QDL!K$3 -> 0.95 | H60: =2*B60*C60*(E60*G60+F60*SIN(ACOS(G60))) -> 0.55693538 | I60: =H60/220 -> 0.0025315244 | J60: =J59+I60 -> 0.024900251 | L60: 4.98 | M60: 1 | N60: 2.2 | P60: LU3-LU4 | Q60: =B59 -> 4.545 | R60: =C59 -> 6.96 | S60: 1.5 | T60: =G60 -> 0.95 | U60: 23 | V60: =(R60/1000)*Q60*U60*(100/220)/100 -> 0.0033071073 | W60: =V60 -> 0.0033071073
P61: LU4-LU5 | Q61: =B60 -> 2.2727 | R61: =C60 -> 8.68 | S61: 1.5 | T61: =G61 | U61: 23 | V61: =(R61/1000)*Q61*U61*(100/220)/100 -> 0.0020623719 | W61: =W60+V61 -> 0.0053694792
A63: Potência Unitária | B63: =QDL!$H$4 -> 440
A64: Qtd Luminárias | B64: =QDL!$G$4 -> 4 | P64: Tabela de queda tensão adaptada Prysmian
A65: QDL1 - Sala de Caldeiras | P65: QDL1 - Sala de Caldeiras
A66: Circuito L1 | B66: Corrente Ip (A) | C66: Distância L (m) | D66: Seção (mm²) | E66: R [Ω/m] | F66: X [Ω/m] | G66: FP | H66: ΔV (V) | I66: ΔV (%) | J66: ΔV(%)* | L66: Comprimento | M66: Curva | N66: Subida QDL | P66: Circuito L1 | Q66: Corrente Ip (A) | R66: Distância L (m) | S66: Seção (mm²) | T66: FP | U66: ΔV unitário (V) | V66: ΔV (%) | W66: ΔV(%)*
...

Sheet QDL-BALANÇO TOTAL
A2: QDL_ILUMINAÇÃO
E3: Balanço de potencias (VA)
A4: Quadro | B4: Nº do circuito | C4: Área | D4: DEMANDA (VA) | E4: R | F4: S | G4: T
A5: QDL0 | B5: L0 | C5: SUBESTAÇÃO | D5: =QDL!I3 -> 2500 | E5: 2500 | F5: - | G5: -
A6: QDL1 | B6: L1 | C6: SALA DE CALDEIRAS | D6: =QDL!I4 -> 1760 | E6: - | F6: 1760 | G6: -
A7: QDL2 | B7: L2 | C7: COMPRESSOR (BOMBAS E PRENSA) | D7: =QDL!I5 -> 2640 | E7: - | F7: - | G7: 2640
A8: QDL3 | B8: L3 | C8: DEPOSITO DE CARCAÇAS | D8: =QDL!I6 -> 2640 | E8: 2640 | F8: - | G8: -
A9: QDL4 | B9: L4 | C9: RASPA | D9: =QDL!I7 -> 3080 | E9: - | F9: 3080 | G9: -
B10: L5 | C10: RASPA | D10: =QDL!I8 -> 3080 | E10: - | F10: - | G10: 3080
B11: L6 | C11: RECAPAGEM | D11: =QDL!I9 -> 4400 | E11: - | F11: - | G11: 4400
B12: L7 | C12: RECAPAGEM | D12: =QDL!I10 -> 4400 | E12: - | F12: 4400 | G12: -
B13: L8 | C13: RECAPAGEM | D13: =QDL!I11 -> 4400 | E13: 4400 | G13: -
B14: L9 | C14: RECAPAGEM | D14: =QDL!I12 -> 4400 | E14: - | F14: 4400 | G14: -
B15: L10 | C15: RECAPAGEM | D15: =QDL!I13 -> 4400 | E15: - | G15: 4400
B16: L11 | C16: RECAPAGEM | D16: =QDL!I14 -> 4400 | E16: 4400 | G16: -
B17: L12 | C17: RECAPAGEM | D17: =QDL!I15 -> 4400 | F17: 4400 | G17: -
B18: L13 | C18: RECAPAGEM | D18: =QDL!I16 -> 4400 | E18: - | F18: - | G18: 4400
B19: L14 | C19: RECAPAGEM | D19: =QDL!I17 -> 4400 | E19: 4400 | G19: -
B20: L15 | C20: RECAPAGEM | D20: =QDL!I18 -> 4400 | F20: 4400 | G20: -
B21: L16 | C21: RECAPAGEM | D21: =QDL!I19 -> 4400 | E21: - | F21: - | G21: 4400
B22: L17 | C22: RECAPAGEM | D22: =QDL!I20 -> 2640 | E22: 2640 | F22: - | G22: -
A23: QDL5 | B23: L18 | C23: ESCRITÓRIO | D23: =QDL!I21 -> 1800 | E23: =QDL!I21 -> 1800 | F23: - | G23: -
A24: QDL6 | B24: L19 | C24: SAIDA DE PRODUTOS | D24: =QDL!I22 -> 360 | E24: - | F24: - | G24: =QDL!I22 -> 360
B25: L20 | C25: CONTROLE DE QUALIDADE | D25: =QDL!I23 -> 2160 | E25: - | F25: =QDL!I23 -> 2160 | G25: -
A26: QDL7 | B26: L21 | C26: BANHEIRO (VESTUÁRIO) | D26: =QDL!I24 -> 240 | E26: - | F26: - | G26: =QDL!I24 -> 240
A28: SOMATÓRIO | E28: =SUM(E3:E27) -> 22780 | F28: =SUM(F3:F27) -> 24600 | G28: =SUM(G3:G27) -> 23920
A29: TOTAL DAS FASES | E29: =SUM(E28:G28) -> 71300
C30: DIVISÃO TOTAL DAS FASES | E30: =E29/3 -> 23766.667
C31: FASE MAIS CARREGADA | E31: =G28/220 -> 108.72727
E33: BARRAMENTO AQUI FAÇO DA FASE MAIS CARREGADA PRO QGL E QDL PARA CIRCUITOS DE FASES DESEQUILIBRADAS (É TUDO MENOS MOTOR)
A35: QDF_TOMADAS

Sheet QDL-BALANÇO POTENCIAS
A1: QDL0 - Subestação
A2: Circuito | B2: Área | C2: Corrente do Disjuntor In (A) | D2: Disjuntor | E2: Capacidade de interrupção do disjuntor (kA) | F2: Balanço de potência (VA)
F3: R | G3: S | H3: T
A4: =QDL!B3 -> L0 | B4: =QDL!C3 -> SUBESTAÇÃO | C4: =DISJUNTORES!E3 -> 16 | D4: MDW-C16 | E4: 5 | F4: ='QDL-BALANÇO TOTAL'!E5 -> 2500
A7: QDL1 - Sala de Caldeiras
A8: Circuito | B8: Área | C8: Corrente do Disjuntor In (A) | D8: Disjuntor | E8: Capacidade de interrupção do disjuntor (kA) | F8: Balanço de potência (VA)
F9: R | G9: S | H9: T
A10: =QDL!B4 -> L1 | B10: =QDL!C4 -> SALA DE CALDEIRAS | C10: =DISJUNTORES!E4 -> 16 | D10: MDW-C16 | E10: 5 | F10: ='QDL-BALANÇO TOTAL'!E6 -> - | G10: ='QDL-BALANÇO TOTAL'!F6 -> 1760 | H10: ='QDL-BALANÇO TOTAL'!G6 -> -
J23: Disjuntor escolhe baseado na In obtida lá em disjuntores
J46: Capacidade de interrupção do disjuntor (kA)
J48: pergunta: Capacidade de interrupção do disjuntor (kA) eu posso colocar 2 kA por ser 220 V certo?
J68: Balanço de potência confiro a distribuição em balanço total
A72: QDL2 - Compressor
A73: Circuito | B73: Área | C73: Corrente do Disjuntor In (A) | D73: Disjuntor | E73: Capacidade de interrupção do disjuntor (kA) | F73: Balanço de potência (VA)
F74: R | G74: S | H74: T
A75: =QDL!B5 -> L2 | B75: =QDL!C5 -> COMPRESSOR (BOMBAS E PRENSA) | C75: =DISJUNTORES!E5 -> 16 | D75: MDW-C16 | E75: 5 | F75: ='QDL-BALANÇO TOTAL'!E7 -> - | G75: ='QDL-BALANÇO TOTAL'!F7 -> - | H75: ='QDL-BALANÇO TOTAL'!G7 -> 2640
J95: Disjuntor escolhe baseado na In obtida lá em disjuntores
J118: Capacidade de interrupção do disjuntor (kA)
J120: pergunta: Capacidade de interrupção do disjuntor (kA) eu posso colocar 2 kA por ser 220 V certo?
J140: Balanço de potência confiro a distribuição em balanço total
A143: QDL3 - Depósito de carcaças
A144: Circuito | B144: Área | C144: Corrente do Disjuntor In (A) | D144: Disjuntor | E144: Capacidade de interrupção do disjuntor (kA) | F144: Balanço de potência (VA)
F145: R | G145: S | H145: T
A146: =QDL!B6 -> L3 | B146: =QDL!C6 -> DEPÓSITO DE CARCAÇAS | C146: =DISJUNTORES!E6 -> 16 | D146: MDW-C16 | E146: 5 | F146: ='QDL-BALANÇO TOTAL'!E8 -> 2640 | G146: ='QDL-BALANÇO TOTAL'!F8 -> - | H146: ='QDL-BALANÇO TOTAL'!G8 -> -
K166: Disjuntor escolhe baseado na In obtida lá em disjuntores
K189: Capacidade de interrupção do disjuntor (kA)
K191: pergunta: Capacidade de interrupção do disjuntor (kA) eu posso colocar 2 kA por ser 220 V certo?
K209: Balanço de potência confiro a distribuição em balanço total
A210: QDL4 - Raspa e Recapagem
A211: Circuito | B211: Área | C211: Corrente do Disjuntor In (A) | D211: Disjuntor | E211: Capacidade de interrupção do disjuntor (kA) | F211: Balanço de potência (VA)
F212: R | G212: S | H212: T
A213: =QDL!B7 -> L4 | B213: =QDL!C7 -> RASPA | C213: =DISJUNTORES!E7 -> 20 | D213: MDW-C20 | E213: 5 | F213: ='QDL-BALANÇO TOTAL'!E9 -> - | G213: ='QDL-BALANÇO TOTAL'!F9 -> 3080 | H213: ='QDL-BALANÇO TOTAL'!G9 -> -
A214: =QDL!B8 -> L5 | B214: =QDL!C8 -> RASPA | C214: =DISJUNTORES!E8 -> 20 | D214: MDW-C20 | E214: 5 | F214: ='QDL-BALANÇO TOTAL'!E10 -> - | G214: ='QDL-BALANÇO TOTAL'!F10 -> - | H214: ='QDL-BALANÇO TOTAL'!G10 -> 3080
A215: =QDL!B9 -> L6 | B215: =QDL!C9 -> RECAPAGEM | C215: =DISJUNTORES!E9 -> 25 | D215: MDW-C25 | E215: 5 | F215: ='QDL-BALANÇO TOTAL'!E11 -> - | G215: ='QDL-BALANÇO TOTAL'!F11 -> - | H215: ='QDL-BALANÇO TOTAL'!G11 -> 4400
A216: =QDL!B10 -> L7 | B216: =QDL!C10 -> RECAPAGEM | C216: =DISJUNTORES!E10 -> 25 | D216: MDW-C25 | E216: 5 | F216: ='QDL-BALANÇO TOTAL'!E12 -> - | G216: ='QDL-BALANÇO TOTAL'!F12 -> 4400 | H216: ='QDL-BALANÇO TOTAL'!G12 -> -
A217: =QDL!B11 -> L8 | B217: =QDL!C11 -> RECAPAGEM | C217: =DISJUNTORES!E11 -> 25 | D217: MDW-C25 | E217: 5 | F217: ='QDL-BALANÇO TOTAL'!E13 -> 4400 | G217: ='QDL-BALANÇO TOTAL'!F13 | H217: ='QDL-BALANÇO TOTAL'!G13 -> -
A218: =QDL!B12 -> L9 | B218: =QDL!C12 -> RECAPAGEM | C218: =DISJUNTORES!E12 -> 25 | D218: MDW-C25 | E218: 5 | F218: ='QDL-BALANÇO TOTAL'!E14 -> - | G218: ='QDL-BALANÇO TOTAL'!F14 -> 4400 | H218: ='QDL-BALANÇO TOTAL'!G14 -> -
A219: =QDL!B13 -> L10 | B219: =QDL!C13 -> RECAPAGEM | C219: =DISJUNTORES!E13 -> 25 | D219: MDW-C25 | E219: 5 | F219: ='QDL-BALANÇO TOTAL'!E15 -> - | G219: ='QDL-BALANÇO TOTAL'!F15 | H219: ='QDL-BALANÇO TOTAL'!G15 -> 4400
A220: =QDL!B14 -> L11 | B220: =QDL!C14 -> RECAPAGEM | C220: =DISJUNTORES!E14 -> 25 | D220: MDW-C25 | E220: 5 | F220: ='QDL-BALANÇO TOTAL'!E16 -> 4400 | G220: ='QDL-BALANÇO TOTAL'!F16 | H220: ='QDL-BALANÇO TOTAL'!G16 -> -
A221: =QDL!B15 -> L12 | B221: =QDL!C15 -> RECAPAGEM | C221: =DISJUNTORES!E15 -> 25 | D221: MDW-C25 | E221: 5 | F221: ='QDL-BALANÇO TOTAL'!E17 | G221: ='QDL-BALANÇO TOTAL'!F17 -> 4400 | H221: ='QDL-BALANÇO TOTAL'!G17 -> -
...

Sheet QDGL
A3: Quadro | B3: Nº do circuito | C3: Área | D3: DEMANDA (VA) | E3: FP
A4: QDL0 | B4: L0 | C4: SUBESTAÇÃO | D4: =QDL!I3 -> 2500 | E4: =QDL!K3 -> 0.95
A5: QDL1 | B5: L1 | C5: SALA DE CALDEIRAS | D5: =QDL!I4 -> 1760 | E5: =QDL!K4 -> 0.85
A6: QDL2 | B6: L2 | C6: COMPRESSOR (BOMBAS E PRENSA) | D6: =QDL!I5 -> 2640 | E6: =QDL!K5 -> 0.85
A7: QDL3 | B7: L3 | C7: DEPOSITO DE CARCAÇAS | D7: =QDL!I6 -> 2640 | E7: =QDL!K6 -> 0.85
A8: QDL4 | B8: L4 | C8: RASPA | D8: =QDL!I7 -> 3080 | E8: =QDL!K7 -> 0.85
B9: L5 | C9: RASPA | D9: =QDL!I8 -> 3080 | E9: =QDL!K8 -> 0.85
B10: L6 | D10: =QDL!I9 -> 4400
B11: L7 | D11: =QDL!I10 -> 4400
B12: L8 | D12: =QDL!I11 -> 4400
B13: L9 | D13: =QDL!I12 -> 4400
B14: L10 | D14: =QDL!I13 -> 4400
B15: L11 | D15: =QDL!I14 -> 4400
B16: L12 | D16: =QDL!I15 -> 4400
B17: L13 | D17: =QDL!I16 -> 4400
B18: L14 | D18: =QDL!I17 -> 4400
B19: L15 | D19: =QDL!I18 -> 4400
B20: L16 | D20: =QDL!I19 -> 4400
B21: L17 | D21: =QDL!I20 -> 2640
A22: QDL5 | B22: L18 | C22: ESCRITÓRIO | D22: =QDL!I21 -> 1800 | E22: =QDL!K21 -> 0.9
A23: QDL6 | B23: L19 | C23: SAIDA DE PRODUTOS | D23: =QDL!I22 -> 360 | E23: =QDL!K22 -> 0.9
B24: L20 | C24: CONTROLE DE QUALIDADE | D24: =QDL!I23 -> 2160 | E24: =QDL!K23 -> 0.9
A25: QDL7 | B25: L21 | C25: BANHEIRO (VESTUÁRIO) | D25: =QDL!I24 -> 240 | E25: =QDL!K24 -> 0.9
A28: Circuito | B28: Disjuntor | C28: Corrente do Disjuntor (A) | D28: Potência aparente (VA)
A30: QDL-0 | B30: ='QDL-BALANÇO POTENCIAS'!D4 -> MDW-C16 | C30: 16 | D30: =D4 -> 2500
A31: QDL-1 | B31: MDW-C16 | C31: 16 | D31: =D5 -> 1760
A32: QDL-2 | B32: MDW-C16 | C32: 16 | D32: =D6 -> 2640 | F32: MDW-C16
A33: QDL-3 | B33: MDW-C16 | C33: 16 | D33: =D7 -> 2640
A34: QDL-4 | B34: ='QDL-BALANÇO POTENCIAS'!D77 | D34: =SUM(D8:D21) -> 57200
A35: QDL-5 | D35: =D22 -> 1800
A36: QDL-6 | D36: =SUM(D23:D24) -> 2520
A37: QDL-7 | D37: =D25 -> 240
A38: Total | D38: =SUM(D30:D37) -> 71300
A39: RQDL-1 | E39: Circuito reserva | F39: Circuito reserva de iluminação, não precisa de potencia
A40: RQDL-2
A41: RQDL-3
A42: Total
A45: Quadro | B45: Tensão (V) | C45: Corrente nominal (A) | D45: Método de instalação | E45: Método de referência
A46: QDL-0 | B46: 220 | C46: =D30/B46 -> 11.363636 | D46: 13 | E46: F
A47: QDL-1 | B47: 220 | C47: =D31/B47 -> 8 | D47: 13 | E47: F
...
