Workbook

Sheet DADOS
A1: LOCAL | B1: ALTURA DE MANUSEIO TRABALHO Hpp (m) | C1: LARGURA L (m) | D1: COMPRIMENTO C (m) | E1: ÁREA (m²) | F1: PERÍMETRO (m) | G1: TETO | H1: PAREDE | I1: PISO | J1: ALTURA TOTAL/PÉ-DIREITO Htp (m)
A2: SALA DE CALDEIRAS | B2: 0.8 | C2: 15.92 | D2: 9.6 | E2: =D2*C2 -> 152.832 | F2: =(2*D2)+(2*C2) -> 51.04 | G2: ZINCO | H2: CLARA | I2: CONCRETO | J2: 7
A3: COMPRESSOR (BOMBAS E PRENSA) | B3: 0.8 | C3: 9.28 | D3: 9.6 | E3: =D3*C3 -> 89.088 | F3: =(2*D3)+(2*C3) -> 37.76 | G3: ZINCO | H3: CLARA | I3: CONCRETO | J3: 7
A4: DEPÓSITO DE CARCAÇAS 1 | B4: 0.8 | C4: 8.12 | D4: 6 | E4: =D4*C4 -> 48.72 | F4: =2*D4+2*C4 -> 28.24 | G4: ZINCO | H4: CLARA | I4: CONCRETO | J4: 7
A5: DEPÓSITO DE CARCAÇAS 2 | B5: 0.8 | C5: 11.18 | D5: 9.6 | E5: =D5*C5 -> 107.328 | F5: =2*D5+2*C5 -> 41.56 | G5: ZINCO | H5: CLARA | I5: CONCRETO | J5: 7
A6: RASPA | B6: 0.8 | C6: 8.12 | D6: 30.92 | E6: =D6*C6 -> 251.0704 | F6: =(2*D6)+(2*C6) -> 78.08 | G6: ZINCO | H6: CLARA | I6: CONCRETO | J6: 7
A7: RECAPAGEM 1 | B7: 0.8 | C7: 5 | D7: 30.9 | E7: =D7*C7 -> 154.5 | F7: =(2*D7)+(2*C7) -> 71.8 | G7: ZINCO | H7: CLARA | I7: CONCRETO | J7: 7
A8: RECAPAGEM 2 | B8: 0.8 | C8: 5.23 | D8: 39.25 | E8: =D8*C8 -> 205.2775 | F8: =(2*D8)+(2*C8) -> 88.96 | G8: ZINCO | H8: CLARA | I8: CONCRETO | J8: 7
A9: RECAPAGEM 3 | B9: 0.8 | C9: 27.95 | D9: 43.37 | E9: =D9*C9 -> 1212.1915 | F9: =(2*D9)+(2*C9) -> 142.64 | G9: ZINCO | H9: CLARA | I9: CONCRETO | J9: 7
A10: SAIDA DE PRODUTOS (SALA DE PRODUTOS) | B10: 0.8 | C10: 5 | D10: 6 | E10: =D10*C10 -> 30 | F10: =(2*D10)+(2*C10) -> 22 | G10: CLARO | H10: CLARA | I10: AZULEJO CINZA | J10: 3
A11: CONTROLE DE QUALIDADE | B11: 0.8 | C11: 5 | D11: 6 | E11: =D11*C11 -> 30 | F11: =(2*D11)+(2*C11) -> 22 | G11: BRANCO | H11: BRANCA | I11: AZULEJO CINZA | J11: 3
A12: BANHEIRO(VESTUARIO) | B12: 0.8 | C12: 5.23 | D12: 3.5 | E12: =D12*C12 -> 18.305 | F12: =(2*D12)+(2*C12) -> 17.46 | G12: CLARO | H12: CLARA | I12: AZULEJO CINZA | J12: 3
A13: ESCRITÓRIO | B13: 0.8 | C13: 8.12 | D13: 6 | E13: =D13*C13 -> 48.72 | F13: =(2*D13)+(2*C13) -> 28.24 | G13: BRANCO | H13: BEGE | I13: AZULEJO CINZA | J13: 3
A14: SUBESTAÇÃO | B14: 0.8 | C14: 9.6 | D14: 9.8 | E14: =C14*D14 -> 94.08 | F14: =(2*C14)+(2*D14) -> 38.8 | G14: BRANCO | H14: BRANCA | I14: CONCRETO | J14: 7

Sheet QDF
A1: Dimensionamento de Cálculos Das Tomadas
A2: Quadro | B2: Nº do circuito | C2: Área | D2: Tipo Tomada | E2: Nº Fases | F2: Tensão (V) | G2: Método de Instalação | H2: Método de Referência | I2: Nº de Tomadas | J2: Potência tomada (VA) | K2: Potência Aparente | L2: Corrente Nominal (A) | M2: FP | R2: Método B1 (Número 3): Usa-se se o eletroduto for aparente (de seção circular sobre a parede, como tubulações de PVC ou metálicas aparentes estilo industrial).
A3: QDF0 | B3: T0 | C3: SUBESTAÇÃO | D3: TUG | E3: 1 | F3: 220 | G3: 13 | H3: F | I3: 2 | J3: 400 | K3: =J3*I3 -> 800 | L3: =K3/F3 -> 3.6363636 | M3: 1
A4: QDF1 | B4: T1 | C4: SALA DE CALDEIRAS | D4: TUG | E4: 1 | F4: 220 | G4: 13 | H4: F | I4: 4 | J4: 200 | K4: =J4*I4 -> 800 | L4: =K4/F4 -> 3.6363636 | M4: 1
B5: T2 | D5: TUE | E5: 3 | F5: 220 | G5: 13 | H5: F | I5: 1 | J5: 1000 | K5: =J5*I5 -> 1000 | L5: =K5/F5 -> 4.5454545 | M5: 1 | R5: Método de instalação se escolhe da tabela dos slides de ampacidade, isso seria a norma 5410. MÉTODO DE INSTALAÇÃO VARIA POIS EM ILUMINAÇÃO SE PODE USAR CALHA, MAS PARA CHEGAR EM TOMADAS OU INTERRUPTOR É ATRAVÉS DE ELETRODUTOS
A6: QDF2 | B6: T3 | C6: COMPRESSOR (BOMBAS E PRENSA) | D6: TUG | E6: 1 | F6: 220 | G6: 13 | H6: F | I6: 2 | J6: 200 | K6: =J6*I6 -> 400 | L6: =K6/F6 -> 1.8181818 | M6: 1
B7: T4 | D7: TUE | E7: 3 | F7: 220 | G7: 13 | H7: F | I7: 1 | J7: 1000 | K7: =J7*I7 -> 1000 | L7: =K7/F7 -> 4.5454545 | M7: 1
A8: QDF3 | B8: T5 | C8: DEPÓSITO DE CARCAÇAS | D8: TUG | E8: 1 | F8: 220 | G8: 13 | H8: F | I8: 4 | J8: 200 | K8: =J8*I8 -> 800 | L8: =K8/F8 -> 3.6363636 | M8: 1 | R8: MÉTODO DE INSTALAÇÃO: ADOTAR O PIOR CASO, ISSO SERIA O QUE TIVER O MENOS VALOR DE CORRENTE, CALHA É 13 E OU F, ELETRODUTO É 3
B9: T6 | D9: TUE | E9: 3 | F9: 220 | G9: 13 | H9: F | I9: 1 | J9: 1000 | K9: =J9*I9 -> 1000 | L9: =K9/F9 -> 4.5454545 | M9: 1
A10: QDF4 | B10: T7 | C10: RASPA | D10: TUG | E10: 1 | F10: 220 | G10: 13 | H10: F | I10: 6 | J10: 200 | K10: =J10*I10 -> 1200 | L10: =K10/F10 -> 5.4545455 | M10: 1
B11: T8 | D11: TUE | E11: 3 | F11: 220 | G11: 13 | H11: F | I11: 1 | J11: 1000 | K11: =J11*I11 -> 1000 | L11: =K11/F11 -> 4.5454545 | M11: 1
B12: T9 | C12: RECAPAGEM | D12: TUG | E12: 1 | F12: 220 | G12: 3 | H12: B1 | I12: 12 | J12: 100 | K12: =J12*I12 -> 1200 | L12: =K12/F12 -> 5.4545455 | M12: 1 | R12: EU DEVIA TER USADO O METODO DO ELETROCLHA POIS DEU 30 E ELETRODUTO 31
B13: T10 | C13: RECAPAGEM | D13: TUE | E13: 3 | F13: 380 | G13: 3 | H13: B1 | I13: 12 | J13: 300 | K13: =J13*I13 -> 3600 | L13: =K13/F13 -> 9.4736842 | M13: 1
A14: QDF5 | B14: T11 | C14: ESCRITÓRIO | D14: TUG | E14: 1 | F14: 220 | G14: 3 | H14: B1 | I14: 6 | J14: 200 | K14: =J14*I14 -> 1200 | L14: =K14/F14 -> 5.4545455 | M14: 1
B15: T12 | C15: ESCRITÓRIO | D15: TUG | E15: 1 | F15: 220 | G15: 3 | H15: B1 | I15: 5 | J15: 200 | K15: =J15*I15 -> 1000 | L15: =K15/F15 -> 4.5454545 | M15: 1
A16: QDF6 | B16: T13 | C16: ESCRITÓRIO | D16: TUE | E16: 1 | F16: 220 | G16: 3 | H16: B1 | I16: 1 | J16: 1500 | K16: =J16*I16 -> 1500 | L16: =K16/F16 -> 6.8181818 | M16: 1
B17: T14 | C17: SAIDA DE PRODUTOS | D17: TUG | E17: 1 | F17: 220 | G17: 3 | H17: B1 | I17: 8 | J17: 200 | K17: =J17*I17 -> 1600 | L17: =K17/F17 -> 7.2727273 | M17: 1
B18: T15 | C18: CONTROLE DE QUALIDADE | D18: TUG | E18: 1 | F18: 220 | G18: 3 | H18: B1 | I18: 8 | J18: 200 | K18: =J18*I18 -> 1600 | L18: =K18/F18 -> 7.2727273 | M18: 1
B19: T16 | C19: SAIDA DE PRODUTOS | D19: TUE | E19: 1 | F19: 220 | G19: 3 | H19: B1 | I19: 1 | J19: 1500 | K19: =J19*I19 -> 1500 | L19: =K19/F19 -> 6.8181818 | M19: 1 | P19: VE QUE O PIOR CASO EM 2,5 mm² PARA B1 É 31, PARA F 30. Bom adotar 3B
A20: QDF7 | B20: T17 | C20: CONTROLE DE QUALIDADE | D20: TUE | E20: 1 | F20: 220 | G20: 3 | H20: B1 | I20: 1 | J20: 1500 | K20: =J20*I20 -> 1500 | L20: =K20/F20 -> 6.8181818 | M20: 1
B21: T18 | C21: BANHEIRO (VESTUARIO) | D21: TUG | E21: 1 | F21: 220 | G21: 3 | H21: B1 | I21: 1 | J21: 600 | K21: =J21*I21 -> 600 | L21: =K21/F21 -> 2.7272727 | M21: 1
B22: T19 | C22: BANHEIRO (VESTUARIO) | D22: TUE | E22: 1 | F22: 220 | G22: 3 | H22: B1 | I22: 1 | J22: 9000 | K22: =J22*I22 -> 9000 | L22: =K22/F22 -> 40.909091 | M22: 1
B23: T20 | C23: RESERVA | I23: 0 | J23: 0
F25: 380
A27: ÁREAS COM TETO ALTO 7M BOM ADOTAR O MÉTODO DA ELETROCALHA QUE É O PIOR CASO QUE SERIA O 13
A28: ÁREAS COM TETO BAIXO DE 3M ADOTAR O MÉTODO DO ELETRODUTO QUE É O 3

Sheet QDF-FATOR CORREÇÃO
A1: Fatores de correção
A2: Quadro | B2: Nº do circuito | C2: Área | D2: Circuitos agrupados | E2: Método de Instalação | F2: Método de Referência | G2: Ref (tabela 9.10) | H2: Cabos multipolares | I2: Fator de agrupamento | J2: Fator de temperatura (45º) | K2: Fator de harmônicos | L2: Isolação | M2: Corrente nominal [A] | N2: Ip' (A) | O2: Iz (A) | P2: Iz' | W2: FATOR DE AGRUPAMENTO POR SER METODO 3 B1 QUE É B, ADOTA REFERENCIA 1
A3: QDF0 | B3: T0 | C3: SUBESTAÇÃO | D3: 1 | E3: =QDF!G3 -> 13 | F3: =QDF!H3 -> F | G3: 4 | H3: 1 | I3: 1 | J3: 0.87 | K3: 1 | L3: EPR ou XLPE | M3: =QDF!L3 -> 3.6363636 | N3: =M3/(I3*J3) -> 4.1797283 | O3: 30 | P3: =O3*I3*J3 -> 26.1
A4: QDF1 | B4: T1 | C4: SALA DE CALDEIRAS | D4: 2 | E4: =QDF!G4 -> 13 | F4: =QDF!H4 -> F | G4: 4 | H4: 2 | I4: 0.88 | J4: 0.87 | K4: 1 | L4: EPR ou XLPE | M4: =QDF!L4 -> 3.6363636 | N4: =M4/(I4*J4) -> 4.7496913 | O4: 30 | P4: =O4*I4*J4 -> 22.968
B5: T2 | D5: 2 | E5: =QDF!G5 -> 13 | F5: =QDF!H5 -> F | G5: 4 | H5: 2 | I5: 0.88 | J5: 0.87 | K5: 1 | L5: EPR ou XLPE | M5: =QDF!L5 -> 4.5454545 | N5: =M5/(I5*J5) -> 5.9371141 | O5: 30 | P5: =O5*I5*J5 -> 22.968
A6: QDF2 | B6: T3 | C6: COMPRESSOR (BOMBAS E PRENSA) | D6: 2 | E6: =QDF!G6 -> 13 | F6: =QDF!H6 -> F | G6: 4 | H6: 2 | I6: 0.88 | J6: 0.87 | K6: 1 | L6: EPR ou XLPE | M6: =QDF!L6 -> 1.8181818 | N6: =M6/(I6*J6) -> 2.3748456 | O6: 30 | P6: =O6*I6*J6 -> 22.968
B7: T4 | D7: 2 | E7: =QDF!G7 -> 13 | F7: =QDF!H7 -> F | G7: 4 | H7: 2 | I7: 0.88 | J7: 0.87 | K7: 1 | L7: EPR ou XLPE | M7: =QDF!L7 -> 4.5454545 | N7: =M7/(I7*J7) -> 5.9371141 | O7: 30 | P7: =O7*I7*J7 -> 22.968
A8: QDF3 | B8: T5 | C8: DEPÓSITO DE CARCAÇAS | D8: 2 | E8: =QDF!G8 -> 13 | F8: =QDF!H8 -> F | G8: 4 | H8: 2 | I8: 0.88 | J8: 0.87 | K8: 1 | L8: EPR ou XLPE | M8: =QDF!L8 -> 3.6363636 | N8: =M8/(I8*J8) -> 4.7496913 | O8: 30 | P8: =O8*I8*J8 -> 22.968
B9: T6 | D9: 2 | E9: =QDF!G9 -> 13 | F9: =QDF!H9 -> F | G9: 4 | H9: 2 | I9: 0.88 | J9: 0.87 | K9: 1 | L9: EPR ou XLPE | M9: =QDF!L9 -> 4.5454545 | N9: =M9/(I9*J9) -> 5.9371141 | O9: 30 | P9: =O9*I9*J9 -> 22.968
A10: QDF4 | B10: T7 | C10: RASPA | D10: 2 | E10: =QDF!G10 -> 13 | F10: =QDF!H10 -> F | G10: 4 | H10: 2 | I10: 0.88 | J10: 0.87 | K10: 1 | L10: EPR ou XLPE | M10: =QDF!L10 -> 5.4545455 | N10: =M10/(I10*J10) -> 7.1245369 | O10: 30 | P10: =O10*I10*J10 -> 22.968
B11: T8 | D11: 2 | E11: =QDF!G11 -> 13 | F11: =QDF!H11 -> F | G11: 4 | H11: 2 | I11: 0.88 | J11: 0.87 | K11: 1 | L11: EPR ou XLPE | M11: =QDF!L11 -> 4.5454545 | N11: =M11/(I11*J11) -> 5.9371141 | O11: 30 | P11: =O11*I11*J11 -> 22.968
B12: T9 | C12: RECAPAGEM | D12: 2 | E12: 3 | F12: B1 | G12: 1 | H12: 2 | I12: 0.8 | J12: 0.79 | K12: 1 | L12: PVC | M12: =QDF!L12 -> 5.4545455 | N12: =M12/(I12*J12) -> 8.6306099 | O12: 30 | P12: =O12*I12*J12 -> 18.96
B13: T10 | C13: RECAPAGEM | D13: 2 | E13: 3 | F13: B1 | G13: 1 | H13: 2 | I13: 0.8 | J13: 0.79 | K13: 1 | L13: PVC | M13: =QDF!L13 -> 9.4736842 | N13: =M13/(I13*J13) -> 14.990007 | O13: 30 | P13: =O13*I13*J13 -> 18.96
A14: QDF5 | B14: T11 | C14: ESCRITÓRIO | D14: 2 | E14: 3 | F14: B1 | G14: 1 | H14: 2 | I14: 0.8 | J14: 0.79 | K14: 1.15 | L14: PVC | M14: =QDF!L14 -> 5.4545455 | N14: =(M14*1.15)/(I14*J14) -> 9.9252014 | O14: 24 | P14: =O14*I14*J14 -> 15.168
B15: T12 | C15: ESCRITÓRIO | D15: 2 | E15: 3 | F15: B1 | G15: 1 | H15: 2 | I15: 0.8 | J15: 0.79 | K15: 1.15 | L15: PVC | M15: =QDF!L15 -> 4.5454545 | N15: =(M15*1.15)/(I15*J15) -> 8.2710012 | O15: 24 | P15: =O15*I15*J15 -> 15.168
A16: QDF6 | B16: T13 | C16: ESCRITÓRIO | D16: 2 | E16: 3 | F16: B1 | G16: 1 | H16: 2 | I16: 0.8 | J16: 0.79 | K16: 1 | L16: PVC | M16: =QDF!L16 -> 6.8181818 | N16: =M16/(I16*J16) -> 10.788262 | O16: 24 | P16: =O16*I16*J16 -> 15.168
B17: T14 | C17: SAIDA DE PRODUTOS | D17: 1 | E17: 3 | F17: B1 | G17: 1 | H17: 1 | I17: 1 | J17: 0.79 | K17: 1.15 | L17: PVC | M17: =QDF!L17 -> 7.2727273 | N17: =(M17*1.15)/(I17*J17) -> 10.586881 | O17: 24 | P17: =O17*I17*J17 -> 18.96
B18: T15 | C18: CONTROLE DE QUALIDADE | D18: 2 | E18: 3 | F18: B1 | G18: 1 | H18: 2 | I18: 0.8 | J18: 0.79 | K18: 1.15 | L18: PVC | M18: =QDF!L18 -> 7.2727273 | N18: =(M18*1.15)/(I18*J18) -> 13.233602 | O18: 24 | P18: =O18*I18*J18 -> 15.168
B19: T16 | C19: SAIDA DE PRODUTOS | D19: 1 | E19: 3 | F19: B1 | G19: 1 | H19: 1 | I19: 1 | J19: 0.79 | K19: 1 | L19: PVC | M19: =QDF!L19 -> 6.8181818 | N19: =M19/(I19*J19) -> 8.6306099 | O19: 24 | P19: =O19*I19*J19 -> 18.96
A20: QDF7 | B20: T17 | C20: CONTROLE DE QUALIDADE | D20: 1 | E20: 3 | F20: B1 | G20: 1 | H20: 1 | I20: 1 | J20: 0.79 | K20: 1 | L20: PVC | M20: =QDF!L20 -> 6.8181818 | N20: =M20/(I20*J20) -> 8.6306099 | O20: 24 | P20: =O20*I20*J20 -> 18.96
B21: T18 | C21: BANHEIRO (VESTUARIO) | D21: 1 | E21: 3 | F21: B1 | G21: 1 | H21: 1 | I21: 1 | J21: 0.79 | K21: 1.15 | L21: PVC | M21: =QDF!L21 -> 2.7272727 | N21: =(M21*1.15)/(I21*J21) -> 3.9700806 | O21: 24 | P21: =O21*I21*J21 -> 18.96
B22: T19 | C22: BANHEIRO (VESTUARIO) | D22: 1 | E22: 3 | F22: B1 | G22: 1 | H22: 1 | I22: 1 | J22: 0.79 | K22: 1 | L22: PVC | M22: =QDF!L22 -> 40.909091 | N22: =M22/(I22*J22) -> 51.783659 | O22: 76 | P22: =O22*I22*J22 -> 60.04
B23: T20 | C23: RESERVA
V67: Fator de Correção - Temperatura
V68: Temperatura | W68: PVC | X68: EPR ou XLPE
V69: 45 | W69: 0.79 | X69: 0.87
V71: Adota cabos EPR OU XLPE para ambientes mais nocivos (quentes, sujos, alta concentração de cabos) como: Sala de Caldeiras, Compressor (Bombas e Prensa), Depósito de Carcaças e Raspa, Recapagem, Subestação. Ambientes comuns como: Sala de Produto, Controle de Qualidade, Banheiro (Vestuário) e Escritório adota cabos PVC
V77: FATOR HARMONICO: ADOTAR 1,15, O valor 1,15 é utilizado porque se trata de um fator de majoração aplicado quando há presença de 3º harmônico (entre 15% e 35%) em sistemas de iluminação e cargas não lineares (como reatores eletrônicos e lâmpadas LED).
V99: Ip' (A)
T121: I_I (negocio do denominador) é produtorio no denominador: Ele indica que você deve multiplicar todos os fatores de correção entre si e dividir a corrente de projeto Ip por esse resultado.
V125: pergunta calculo de Ip'
V126: PERGUNTA CALCULO DE Iz' existe?
V129: Iz são os valores de corrente das tabelas que depende do tipo de isolação e instalação. Também verificar a seção minima na tabela que é 2,5 para tomada. Caso da raspa a corrente Ip' deu 18,03A perto do limite que é 22A por segurança adota o debaixo que é 30, adota tipo uns 10 a 30% de segurança

Sheet SEÇÃO CONDUTORES
A1: Seção dos condutores (mm²)
A2: Quadro | B2: Nº do circuito | C2: Área | D2: Cabos multipolares | E2: Circuitos agrupados | F2: Condutores carregados CC | G2: Isolação | H2: Método de Instalação | I2: Método de Referência | J2: Fase (mm²) | K2: Neutro (mm²) | L2: Terra (mm²) | P2: Adota Seções nominais os escolhido la em FATOR CORREÇÃO, as seções nominais
A3: QDF0 | B3: T0 | C3: SUBESTAÇÃO | D3: ='QDF-FATOR CORREÇÃO'!H3 -> 1 | E3: ='QDF-FATOR CORREÇÃO'!D3 -> 1 | F3: 2 | G3: EPR ou XLPE | H3: ='QDF-FATOR CORREÇÃO'!E3 -> 13 | I3: ='QDF-FATOR CORREÇÃO'!F3 -> F | J3: 2.5 | K3: 2.5 | L3: 2.5
A4: QDF1 | B4: T1 | C4: SALA DE CALDEIRAS | D4: ='QDF-FATOR CORREÇÃO'!H4 -> 2 | E4: ='QDF-FATOR CORREÇÃO'!D4 -> 2 | F4: 2 | G4: EPR ou XLPE | H4: ='QDF-FATOR CORREÇÃO'!E4 -> 13 | I4: ='QDF-FATOR CORREÇÃO'!F4 -> F | J4: 2.5 | K4: 2.5 | L4: 2.5
B5: T2 | D5: ='QDF-FATOR CORREÇÃO'!H5 -> 2 | E5: ='QDF-FATOR CORREÇÃO'!D5 -> 2 | F5: 3 | G5: EPR ou XLPE | H5: ='QDF-FATOR CORREÇÃO'!E5 -> 13 | I5: ='QDF-FATOR CORREÇÃO'!F5 -> F | J5: 2.5 | K5: 2.5 | L5: 2.5
A6: QDF2 | B6: T3 | C6: COMPRESSOR (BOMBAS E PRENSA) | D6: ='QDF-FATOR CORREÇÃO'!H6 -> 2 | E6: ='QDF-FATOR CORREÇÃO'!D6 -> 2 | F6: 2 | G6: EPR ou XLPE | H6: ='QDF-FATOR CORREÇÃO'!E6 -> 13 | I6: ='QDF-FATOR CORREÇÃO'!F6 -> F | J6: 2.5 | K6: 2.5 | L6: 2.5
B7: T4 | D7: ='QDF-FATOR CORREÇÃO'!H7 -> 2 | E7: ='QDF-FATOR CORREÇÃO'!D7 -> 2 | F7: 3 | G7: EPR ou XLPE | H7: ='QDF-FATOR CORREÇÃO'!E7 -> 13 | I7: ='QDF-FATOR CORREÇÃO'!F7 -> F | J7: 2.5 | K7: 2.5 | L7: 2.5
A8: QDF3 | B8: T5 | C8: DEPÓSITO DE CARCAÇAS | D8: ='QDF-FATOR CORREÇÃO'!H8 -> 2 | E8: ='QDF-FATOR CORREÇÃO'!D8 -> 2 | F8: 2 | G8: EPR ou XLPE | H8: ='QDF-FATOR CORREÇÃO'!E8 -> 13 | I8: ='QDF-FATOR CORREÇÃO'!F8 -> F | J8: 2.5 | K8: 2.5 | L8: 2.5
B9: T6 | D9: ='QDF-FATOR CORREÇÃO'!H9 -> 2 | E9: ='QDF-FATOR CORREÇÃO'!D9 -> 2 | F9: 3 | G9: EPR ou XLPE | H9: ='QDF-FATOR CORREÇÃO'!E9 -> 13 | I9: ='QDF-FATOR CORREÇÃO'!F9 -> F | J9: 2.5 | K9: 2.5 | L9: 2.5
A10: QDF4 | B10: T7 | C10: RASPA | D10: ='QDF-FATOR CORREÇÃO'!H10 -> 2 | E10: ='QDF-FATOR CORREÇÃO'!D10 -> 2 | F10: 2 | G10: EPR ou XLPE | H10: ='QDF-FATOR CORREÇÃO'!E10 -> 13 | I10: ='QDF-FATOR CORREÇÃO'!F10 -> F | J10: 2.5 | K10: 2.5 | L10: 2.5
B11: T8 | D11: ='QDF-FATOR CORREÇÃO'!H11 -> 2 | E11: ='QDF-FATOR CORREÇÃO'!D11 -> 2 | F11: 3 | G11: EPR ou XLPE | H11: ='QDF-FATOR CORREÇÃO'!E11 -> 13 | I11: ='QDF-FATOR CORREÇÃO'!F11 -> F | J11: 2.5 | K11: 2.5 | L11: 2.5
B12: T9
B13: T10
A14: QDF5 | B14: T11 | C14: ESCRITÓRIO | D14: ='QDF-FATOR CORREÇÃO'!H14 -> 2 | E14: ='QDF-FATOR CORREÇÃO'!D14 -> 2 | F14: 2 | G14: PVC | H14: ='QDF-FATOR CORREÇÃO'!E14 -> 3 | I14: ='QDF-FATOR CORREÇÃO'!F14 -> B1 | J14: 2.5 | K14: 2.5 | L14: 2.5
B15: T12 | C15: ESCRITÓRIO | D15: ='QDF-FATOR CORREÇÃO'!H15 -> 2 | E15: ='QDF-FATOR CORREÇÃO'!D15 -> 2 | F15: 2 | G15: PVC | H15: ='QDF-FATOR CORREÇÃO'!E15 -> 3 | I15: ='QDF-FATOR CORREÇÃO'!F15 -> B1 | J15: 2.5 | K15: 2.5 | L15: 2.5
A16: QDF6 | B16: T13 | C16: ESCRITÓRIO | D16: ='QDF-FATOR CORREÇÃO'!H16 -> 2 | E16: ='QDF-FATOR CORREÇÃO'!D16 -> 2 | F16: 2 | G16: PVC | H16: ='QDF-FATOR CORREÇÃO'!E16 -> 3 | I16: ='QDF-FATOR CORREÇÃO'!F16 -> B1 | J16: 2.5 | K16: 2.5 | L16: 2.5
B17: T14 | C17: SAIDA DE PRODUTOS | D17: ='QDF-FATOR CORREÇÃO'!H17 -> 1 | E17: ='QDF-FATOR CORREÇÃO'!D17 -> 1 | F17: 2 | G17: PVC | H17: ='QDF-FATOR CORREÇÃO'!E17 -> 3 | I17: ='QDF-FATOR CORREÇÃO'!F17 -> B1 | J17: 2.5 | K17: 2.5 | L17: 2.5
B18: T15 | C18: CONTROLE DE QUALIDADE | D18: ='QDF-FATOR CORREÇÃO'!H18 -> 2 | E18: ='QDF-FATOR CORREÇÃO'!D18 -> 2 | F18: 2 | G18: PVC | H18: ='QDF-FATOR CORREÇÃO'!E18 -> 3 | I18: ='QDF-FATOR CORREÇÃO'!F18 -> B1 | J18: 2.5 | K18: 2.5 | L18: 2.5
B19: T16 | C19: SAIDA DE PRODUTOS | D19: ='QDF-FATOR CORREÇÃO'!H19 -> 1 | E19: ='QDF-FATOR CORREÇÃO'!D19 -> 1 | F19: 2 | G19: PVC | H19: ='QDF-FATOR CORREÇÃO'!E19 -> 3 | I19: ='QDF-FATOR CORREÇÃO'!F19 -> B1 | J19: 2.5 | K19: 2.5 | L19: 2.5
A20: QDF7 | B20: T17 | C20: CONTROLE DE QUALIDADE | D20: ='QDF-FATOR CORREÇÃO'!H20 -> 1 | E20: ='QDF-FATOR CORREÇÃO'!D20 -> 1 | F20: 2 | G20: PVC | H20: ='QDF-FATOR CORREÇÃO'!E20 -> 3 | I20: ='QDF-FATOR CORREÇÃO'!F20 -> B1 | J20: 2.5 | K20: 2.5 | L20: 2.5
B21: T18 | C21: BANHEIRO (VESTUARIO) | D21: ='QDF-FATOR CORREÇÃO'!H21 -> 1 | E21: ='QDF-FATOR CORREÇÃO'!D21 -> 1 | F21: 2 | G21: PVC | H21: ='QDF-FATOR CORREÇÃO'!E21 -> 3 | I21: ='QDF-FATOR CORREÇÃO'!F21 -> B1 | J21: 2.5 | K21: 2.5 | L21: 2.5
B22: T19 | C22: BANHEIRO (VESTUARIO) | D22: ='QDF-FATOR CORREÇÃO'!H22 -> 1 | E22: ='QDF-FATOR CORREÇÃO'!D22 -> 1 | F22: 2 | G22: PVC | H22: ='QDF-FATOR CORREÇÃO'!E22 -> 3 | I22: ='QDF-FATOR CORREÇÃO'!F22 -> B1 | J22: 16 | K22: 16 | L22: 16
B23: T20 | C23: RESERVA

Sheet DISJUNTORES
A1: Disjuntor (A) | H1: Mudou disjuntor
A2: Quadro | B2: Nº do circuito | C2: Área | D2: Iz' (A) | E2: In (A) | F2: Ip (A) | G2: Iz'>In>Ip | L2: A corrente comercial do disjuntor é o In
A3: QDF0 | B3: T0 | C3: SUBESTAÇÃO | D3: ='QDF-FATOR CORREÇÃO'!P3 -> 26.1 | E3: 16 | F3: =QDF!L3 -> 3.6363636 | G3: =IF(AND(D3>E3,E3>F3),"OK","MUDAR DISJUNTOR") -> OK
A4: QDF1 | B4: T1 | C4: SALA DE CALDEIRAS | D4: ='QDF-FATOR CORREÇÃO'!P4 -> 22.968 | E4: 10 | F4: =QDF!L4 -> 3.6363636 | G4: =IF(AND(D4>E4,E4>F4),"OK","MUDAR DISJUNTOR") -> OK
B5: T2 | D5: ='QDF-FATOR CORREÇÃO'!P5 -> 22.968 | E5: 10 | F5: =QDF!L5 -> 4.5454545 | G5: =IF(AND(D5>E5,E5>F5),"OK","MUDAR DISJUNTOR") -> OK
A6: QDF2 | B6: T3 | C6: COMPRESSOR (BOMBAS E PRENSA) | D6: ='QDF-FATOR CORREÇÃO'!P6 -> 22.968 | E6: 6 | F6: =QDF!L6 -> 1.8181818 | G6: =IF(AND(D6>E6,E6>F6),"OK","MUDAR DISJUNTOR") -> OK
B7: T4 | D7: ='QDF-FATOR CORREÇÃO'!P7 -> 22.968 | E7: 10 | F7: =QDF!L7 -> 4.5454545 | G7: =IF(AND(D7>E7,E7>F7),"OK","MUDAR DISJUNTOR") -> OK
A8: QDF3 | B8: T5 | C8: DEPÓSITO DE CARCAÇAS | D8: ='QDF-FATOR CORREÇÃO'!P8 -> 22.968 | E8: 10 | F8: =QDF!L8 -> 3.6363636 | G8: =IF(AND(D8>E8,E8>F8),"OK","MUDAR DISJUNTOR") -> OK
B9: T6 | D9: ='QDF-FATOR CORREÇÃO'!P9 -> 22.968 | E9: 10 | F9: =QDF!L9 -> 4.5454545 | G9: =IF(AND(D9>E9,E9>F9),"OK","MUDAR DISJUNTOR") -> OK
A10: QDF4 | B10: T7 | C10: RASPA | D10: ='QDF-FATOR CORREÇÃO'!P10 -> 22.968 | E10: 10 | F10: =QDF!L10 -> 5.4545455 | G10: =IF(AND(D10>E10,E10>F10),"OK","MUDAR DISJUNTOR") -> OK
B11: T8 | D11: ='QDF-FATOR CORREÇÃO'!P11 -> 22.968 | E11: 10 | F11: =QDF!L11 -> 4.5454545 | G11: =IF(AND(D11>E11,E11>F11),"OK","MUDAR DISJUNTOR") -> OK
B12: T9
B13: T10
A14: QDF5 | B14: T11 | C14: ESCRITÓRIO | D14: ='QDF-FATOR CORREÇÃO'!P14 -> 15.168 | E14: 10 | F14: =QDF!L14 -> 5.4545455 | G14: =IF(AND(D14>E14,E14>F14),"OK","MUDAR DISJUNTOR") -> OK
B15: T12 | C15: ESCRITÓRIO | D15: ='QDF-FATOR CORREÇÃO'!P15 -> 15.168 | E15: 10 | F15: =QDF!L15 -> 4.5454545 | G15: =IF(AND(D15>E15,E15>F15),"OK","MUDAR DISJUNTOR") -> OK
A16: QDF6 | B16: T13 | C16: ESCRITÓRIO | D16: ='QDF-FATOR CORREÇÃO'!P16 -> 15.168 | E16: 10 | F16: =QDF!L16 -> 6.8181818 | G16: =IF(AND(D16>E16,E16>F16),"OK","MUDAR DISJUNTOR") -> OK
B17: T14 | C17: SAIDA DE PRODUTOS | D17: ='QDF-FATOR CORREÇÃO'!P17 -> 18.96 | E17: 10 | F17: =QDF!L17 -> 7.2727273 | G17: =IF(AND(D17>E17,E17>F17),"OK","MUDAR DISJUNTOR") -> OK
B18: T15 | C18: CONTROLE DE QUALIDADE | D18: ='QDF-FATOR CORREÇÃO'!P18 -> 15.168 | E18: 10 | F18: =QDF!L18 -> 7.2727273 | G18: =IF(AND(D18>E18,E18>F18),"OK","MUDAR DISJUNTOR") -> OK
B19: T16 | C19: SAIDA DE PRODUTOS | D19: ='QDF-FATOR CORREÇÃO'!P19 -> 18.96 | E19: 10 | F19: =QDF!L19 -> 6.8181818 | G19: =IF(AND(D19>E19,E19>F19),"OK","MUDAR DISJUNTOR") -> OK
A20: QDF7 | B20: T17 | C20: CONTROLE DE QUALIDADE | D20: ='QDF-FATOR CORREÇÃO'!P20 -> 18.96 | E20: 10 | F20: =QDF!L20 -> 6.8181818 | G20: =IF(AND(D20>E20,E20>F20),"OK","MUDAR DISJUNTOR") -> OK
B21: T18 | C21: BANHEIRO (VESTUARIO) | D21: ='QDF-FATOR CORREÇÃO'!P21 -> 18.96 | E21: 10 | F21: =QDF!L21 -> 2.7272727 | G21: =IF(AND(D21>E21,E21>F21),"OK","MUDAR DISJUNTOR") -> OK
B22: T19 | C22: BANHEIRO (VESTUARIO) | D22: ='QDF-FATOR CORREÇÃO'!P22 -> 60.04 | E22: 50 | F22: =QDF!L22 -> 40.909091 | G22: =IF(AND(D22>E22,E22>F22),"OK","MUDAR DISJUNTOR") -> OK
B23: T20 | C23: RESERVA

Sheet QDF-QUEDA DE TENSÃO
A21: Em subida QDL adotar a altura ou pé direito do local e considerar a bitola para subtrair 1,5 ou 3
A25: Tensão (V) | B25: 220
A26: Potência Unitária (VA) | B26: =QDF!J3 -> 400
A27: Qtd Tomadas | B27: =QDF!I3 -> 2
A28: QDF0 - Subestação | P28: Tabela de queda tensão adaptada Prysmian
A29: Circuito L0 | B29: Corrente Ip (A) | C29: Distância L (m) | D29: Seção (mm²) | E29: R [Ω/m] | F29: X [Ω/m] | G29: FP | H29: ΔV (V) | I29: ΔV (%) | J29: ΔV(%)* | L29: Comprimento | M29: Curva | N29: Subida QDL | P29: QDL0 - Subestação
A30: QDF1-TOM1 | B30: =($B$36*4)/$B$25 -> 3.6363636 | C30: =L30+(M30*1.5)+N30 -> 3.49 | D30: 2.5 | E30: =8.8882*10^-3 -> 0.0088882 | F30: =0.1345*10^-3 -> 0.0001345 | G30: 1 | H30: =2*B30*C30*(E30*G30+F30*SIN(ACOS(G30))) -> 0.22559868 | I30: =H30/220 -> 0.0010254485 | J30: =I30 -> 0.0010254485 | L30: 1.69 | M30: 1 | N30: 0.3 | P30: Circuito L0 | Q30: Corrente Ip (A) | R30: Distância L (m) | S30: Seção (mm²) | T30: FP | U30: ΔV unitário (V) | V30: ΔV (%) | W30: ΔV(%)*
A31: QDF1-TOM2 | B31: =($B$36*3)/$B$25 -> 2.7272727 | C31: =L31+(M31*1.5)+N31 -> 11.94 | D31: 2.5 | E31: =8.8882*10^-3 -> 0.0088882 | F31: =0.1345*10^-3 -> 0.0001345 | G31: 1 | H31: =2*B31*C31*(E31*G31+F31*SIN(ACOS(G31))) -> 0.57886423 | I31: =H31/220 -> 0.002631201 | J31: =J30+I31 -> 0.0036566496 | L31: 10.14 | M31: 1 | N31: 0.3 | P31: =A30 -> QDF1-TOM1 | Q31: =B30 -> 3.6363636 | R31: =C30 -> 3.49 | S31: 2.5 | T31: =G31 -> 1 | U31: 16.8 | V31: =(R31/1000)*Q31*U31*(100/220)/100 -> 0.00096912397 | W31: =V31 -> 0.00096912397
P32: =A31 -> QDF1-TOM2 | Q32: =B31 -> 2.7272727 | R32: =C31 -> 11.94 | S32: 2.5 | T32: 1 | U32: 16.8 | V32: =(R32/1000)*Q32*U32*(100/220)/100 -> 0.0024866777 | W32: =W31+V32 -> 0.0034558017
P33: =A32 | Q33: =B32 | R33: =C32
P34: =A33 | Q34: =B33 | R34: =C33
A36: Potência Unitária TUG | B36: =QDF!J4 -> 200 | C36: Potência Unitária TUE | D36: =QDF!J5 -> 1000
A37: Qtd Tomadas | B37: =QDF!I4 -> 4 | C37: Qtd Tomadas | D37: =QDF!I5 -> 1 | P37: Tabela de queda tensão adaptada Prysmian
A38: QDF1 - Sala de Caldeiras | P38: QDF1 - Sala de Caldeiras
A39: Circuito T1 | B39: Corrente Ip (A) | C39: Distância L (m) | D39: Seção (mm²) | E39: R [Ω/m] | F39: X [Ω/m] | G39: FP | H39: ΔV (V) | I39: ΔV (%) | J39: ΔV(%)* | L39: Comprimento | M39: Curva | N39: Subida QDL | P39: Circuito T1 | Q39: Corrente Ip (A) | R39: Distância L (m) | S39: Seção (mm²) | T39: FP | U39: ΔV unitário (V) | V39: ΔV (%) | W39: ΔV(%)*
A40: QDF1-TOM1 | B40: =($B$36*4)/$B$25 -> 3.6363636 | C40: =L40+(M40*1.5)+N40 -> 18.66 | D40: 2.5 | E40: =8.8882*10^-3 -> 0.0088882 | F40: =0.1345*10^-3 -> 0.0001345 | G40: 1 | H40: =2*B40*C40*(E40*G40+F40*SIN(ACOS(G40))) -> 1.2062095 | I40: =H40/220 -> 0.0054827706 | J40: =I40 -> 0.0054827706 | L40: =1.86+3.1+(7-0.3) -> 11.66 | M40: 1 | N40: =7-1.5 -> 5.5 | P40: =A40 -> QDF1-TOM1 | Q40: =B40 -> 3.6363636 | R40: =C40 -> 18.66 | S40: 2.5 | T40: =G40 -> 1 | U40: 16.8 | V40: =(R40/1000)*Q40*U40*(100/220)/100 -> 0.0051816198 | W40: =V40 -> 0.0051816198
A41: QDF1-TOM2 | B41: =($B$36*3)/$B$25 -> 2.7272727 | C41: =L41+(M41*1.5)+N41 -> 19.42 | D41: 2.5 | E41: =8.8882*10^-3 -> 0.0088882 | F41: =0.1345*10^-3 -> 0.0001345 | G41: 1 | H41: =2*B41*C41*(E41*G41+F41*SIN(ACOS(G41))) -> 0.94150279 | I41: =H41/220 -> 0.0042795581 | J41: =J40+I41 -> 0.0097623288 | L41: =3.22+6.5+(7-0.3) -> 16.42 | M41: 2 | N41: 0 | P41: =A41 -> QDF1-TOM2 | Q41: =B41 -> 2.7272727 | R41: =C41 -> 19.42 | S41: 2.5 | T41: =G41 -> 1 | U41: 16.8 | V41: =(R41/1000)*Q41*U41*(100/220)/100 -> 0.0040444959 | W41: =W40+V41 -> 0.0092261157
A42: QDF1-TOM3 | B42: =($B$36*2)/$B$25 -> 1.8181818 | C42: =L42+(M42*1.5)+N42 -> 19.89 | D42: 2.5 | E42: =8.8882*10^-3 -> 0.0088882 | F42: =0.1345*10^-3 -> 0.0001345 | G42: 1 | H42: =2*B42*C42*(E42*G42+F42*SIN(ACOS(G42))) -> 0.64285927 | I42: =H42/220 -> 0.0029220876 | J42: =J41+I42 -> 0.012684416 | L42: =7.09+3.1+(7-0.3) -> 16.89 | M42: 2 | N42: 0 | P42: =A42 -> QDF1-TOM3 | Q42: =B42 -> 1.8181818 | R42: =C42 -> 19.89 | S42: 2.5 | T42: =G42 -> 1 | U42: 16.8 | V42: =(R42/1000)*Q42*U42*(100/220)/100 -> 0.0027615868 | W42: =W41+V42 -> 0.011987702
A43: QDF1-TOM4 | B43: =($B$36*1)/$B$25 -> 0.90909091 | C43: =L43+(M43*1.5)+N43 -> 30.77 | D43: 2.5 | E43: =8.8882*10^-3 -> 0.0088882 | F43: =0.1345*10^-3 -> 0.0001345 | G43: 1 | H43: =2*B43*C43*(E43*G43+F43*SIN(ACOS(G43))) -> 0.49725439 | I43: =H43/220 -> 0.0022602472 | J43: =J42+I43 -> 0.014944664 | L43: =14.57+6.5+(7-0.3) -> 27.77 | M43: 2 | N43: 0 | P43: =A43 -> QDF1-TOM4 | Q43: =B43 -> 0.90909091 | R43: =C43 -> 30.77 | S43: 2.5 | T43: =G43 -> 1 | U43: 16.8 | V43: =(R43/1000)*Q43*U43*(100/220)/100 -> 0.0021360992 | W43: =W42+V43 -> 0.014123802
A44: Circuito T2 | B44: Corrente Ip (A) | C44: Distância L (m) | D44: Seção (mm²) | E44: R [Ω/m] | F44: X [Ω/m] | G44: FP | H44: ΔV (V) | I44: ΔV (%) | J44: ΔV(%)* | L44: Comprimento | M44: Curva | N44: Subida QDL | P44: Circuito T2 | Q44: Corrente Ip (A) | R44: Distância L (m) | S44: Seção (mm²) | T44: FP | U44: ΔV unitário (V) | V44: ΔV (%) | W44: ΔV(%)*
A45: QDF1-TUE | B45: =($D$36*1)/$B$25 -> 4.5454545 | C45: =L45+(M45*1.5)+N45 -> 28.52 | D45: 2.5 | E45: =8.8882*10^-3 -> 0.0088882 | F45: =0.1345*10^-3 -> 0.0001345 | G45: 1 | H45: =2*B45*C45*(E45*G45+F45*SIN(ACOS(G45))) -> 2.3044679 | I45: =H45/220 -> 0.010474854 | J45: =I45 -> 0.010474854 | L45: =3.22+6.5+0.6+(7-0.3) -> 17.02 | M45: 4 | N45: =7-1.5 -> 5.5 | P45: =A45 -> QDF1-TUE | Q45: =B45 -> 4.5454545 | R45: =C45 -> 28.52 | S45: =D45 -> 2.5 | T45: 1 | U45: 16.8 | V45: =(R45/1000)*Q45*U45*(100/220)/100 -> 0.0098995041 | W45: =V45 -> 0.0098995041
A47: PRECISA BOTAR TRECHO A, A até tomada 1 e por ae vai | L47: 2 curvas verticais (uma na subida do quadro e uma na descida para a tomada)
A52: A corrente faz a potencia unitaria vezes o numero de lampadas de cada trecho, dividido pela tensão, cada trecho p/ baixo reduz o numero de luminarias
P53: ΔV unitário pega no catalogo
A54: A distancia se soma os comprimentos dos eletrodutos de cada trecho, no trecho com QDL faz comprimento+curva*1,5 ou 3+subida
A55: A distancia se soma os comprimentos dos eletrodutos de cada trecho
A57: A impedancia Z separada em R (resistencia) e X (reatancia) adotar o valor da tabela de Impedancia de Sequencia Postiva considerando a seção
A78: Calcular o ΔV faz a formula
A98: Calcular o ΔV% faz a formula, no denominador usa Ncp é Número de Condutores de Fase (ou número de fases do circuito).
A101: ΔV(%)* calcula segue a tabela primera, ve que o primeiro trecho é apenas o ΔV, segundo trecho é a soma do ΔV% trecho anterior+ΔV do trecho atual | N101: ΔV(%)* calcula segue a tabela primera, ve que o primeiro trecho é apenas o ΔV, segundo trecho é a soma do ΔV% trecho anterior+ΔV do trecho atual
A128: Potência Unitária TUG | B128: =QDF!J6 -> 200 | C128: Potência Unitária TUE | D128: =QDF!J7 -> 1000
A129: Qtd Tomadas | B129: =QDF!I6 -> 2 | C129: Qtd Tomadas | D129: =QDF!I7 -> 1 | P129: Tabela de queda tensão adaptada Prysmian
A130: QDF2 - Compressor (Bombas e prensa) | P130: QDF2 - Compressor (Bombas e prensa)
A131: Circuito T3 | B131: Corrente Ip (A) | C131: Distância L (m) | D131: Seção (mm²) | E131: R [Ω/m] | F131: X [Ω/m] | G131: FP | H131: ΔV (V) | I131: ΔV (%) | J131: ΔV(%)* | L131: Comprimento | M131: Curva | N131: Subida QDL | P131: Circuito T3 | Q131: Corrente Ip (A) | R131: Distância L (m) | S131: Seção (mm²) | T131: FP | U131: ΔV unitário (V) | V131: ΔV (%) | W131: ΔV(%)*
A132: QDF2-TOM1 | B132: =($B$128*2)/$B$25 -> 1.8181818 | C132: =L132+(M132*1.5)+N132 -> 19.12 | D132: 2.5 | E132: =8.8882*10^-3 -> 0.0088882 | F132: =0.1345*10^-3 -> 0.0001345 | G132: 1 | H132: =2*B132*C132*(E132*G132+F132*SIN(ACOS(G132))) -> 0.61797231 | I132: =H132/220 -> 0.002808965 | J132: =I132 -> 0.002808965 | L132: =2.33+3.09+(7-0.3) -> 12.12 | M132: 1 | N132: =7-1.5 -> 5.5 | P132: =A132 -> QDF2-TOM1 | Q132: =B132 -> 1.8181818 | R132: =C132 -> 19.12 | S132: 2.5 | T132: =G132 -> 1 | U132: 16.8 | V132: =(R132/1000)*Q132*U132*(100/220)/100 -> 0.0026546777 | W132: =V132 -> 0.0026546777
A133: QDF2-TOM2 | B133: =($B$128*1)/$B$25 -> 0.90909091 | C133: =L133+(M133*1.5)+N133 -> 19.67 | D133: 2.5 | E133: =8.8882*10^-3 -> 0.0088882 | F133: =0.1345*10^-3 -> 0.0001345 | G133: 1 | H133: =2*B133*C133*(E133*G133+F133*SIN(ACOS(G133))) -> 0.31787435 | I133: =H133/220 -> 0.0014448834 | J133: =J132+I133 -> 0.0042538484 | L133: =8.65+1.32+(7-0.3) -> 16.67 | M133: 2 | N133: 0 | P133: =A133 -> QDF2-TOM2 | Q133: =B133 -> 0.90909091 | R133: =C133 -> 19.67 | S133: 2.5 | T133: =G133 -> 1 | U133: 16.8 | V133: =(R133/1000)*Q133*U133*(100/220)/100 -> 0.0013655207 | W133: =W132+V133 -> 0.0040201983
P134: =A134 | Q134: =B134 | R134: =C134
P135: =A135 | Q135: =B135 | R135: =C135
A136: Circuito T4 | B136: Corrente Ip (A) | C136: Distância L (m) | D136: Seção (mm²) | E136: R [Ω/m] | F136: X [Ω/m] | G136: FP | H136: ΔV (V) | I136: ΔV (%) | J136: ΔV(%)* | L136: Comprimento | M136: Curva | N136: Subida QDL | P136: Circuito T4 | Q136: Corrente Ip (A) | R136: Distância L (m) | S136: Seção (mm²) | T136: FP | U136: ΔV unitário (V) | V136: ΔV (%) | W136: ΔV(%)*
A137: QDF2-TUE | B137: =($D$128*1)/$B$25 -> 4.5454545 | C137: =L137+(M137*1.5)+N137 -> 28.77 | D137: 2.5 | E137: =8.8882*10^-3 -> 0.0088882 | F137: =0.1345*10^-3 -> 0.0001345 | G137: 1 | H137: =2*B137*C137*(E137*G137+F137*SIN(ACOS(G137))) -> 2.3246683 | I137: =H137/220 -> 0.010566674 | J137: =I137 -> 0.010566674 | L137: =8.65+1.32+0.6+(7-0.3) -> 17.27 | M137: 4 | N137: =7-1.5 -> 5.5 | P137: =A137 -> QDF2-TUE | Q137: =B137 -> 4.5454545 | R137: =C137 -> 28.77 | S137: =D137 -> 2.5 | T137: 1 | U137: 16.8 | V137: =(R137/1000)*Q137*U137*(100/220)/100 -> 0.009986281 | W137: =V137 -> 0.009986281
...

Sheet QDF-BALANÇO TOTAL
A1: QDF_ILUMINAÇÃO
E2: Balanço de potencias (VA)
A3: Quadro | B3: Nº do circuito | C3: Área | D3: DEMANDA (VA) | E3: R | F3: S | G3: T
A4: QDF0 | B4: T0 | C4: SUBESTAÇÃO | D4: =QDF!K3 -> 800 | E4: 800 | F4: - | G4: -
A5: QDF1 | B5: T1 | C5: SALA DE CALDEIRAS | D5: =QDF!K4 -> 800 | E5: - | F5: - | G5: 800
B6: T2 | D6: =QDF!K5 -> 1000 | E6: =D6/3 -> 333.33333 | F6: =D6/3 -> 333.33333 | G6: =D6/3 -> 333.33333 | H6: Circuitos trifásicos se deve dividi-los por 3 para equilibrar entre as fases, é isso mesmo
A7: QDF2 | B7: T3 | C7: COMPRESSOR (BOMBAS E PRENSA) | D7: =QDF!K6 -> 400 | E7: - | F7: 400 | G7: -
B8: T4 | D8: =QDF!K7 -> 1000 | E8: =D8/3 -> 333.33333 | F8: =D8/3 -> 333.33333 | G8: =D8/3 -> 333.33333 | H8: Circuitos trifásicos se deve dividi-los por 3 para equilibrar entre as fases
A9: QDF3 | B9: T5 | C9: DEPÓSITO DE CARCAÇAS | D9: =QDF!K8 -> 800 | E9: - | F9: 800 | G9: -
B10: T6 | D10: =QDF!K9 -> 1000 | E10: =D10/3 -> 333.33333 | F10: =D10/3 -> 333.33333 | G10: =D10/3 -> 333.33333 | H10: Circuitos trifásicos se deve dividi-los por 3 para equilibrar entre as fases
A11: QDF4 | B11: T7 | C11: RASPA | D11: =QDF!K10 -> 1200 | E11: 1200 | F11: - | G11: -
B12: T8 | D12: =QDF!K11 -> 1000 | E12: =D12/3 -> 333.33333 | F12: =D12/3 -> 333.33333 | G12: =D12/3 -> 333.33333 | H12: Circuitos trifásicos se deve dividi-los por 3 para equilibrar entre as fases
B13: T9
B14: T10
A15: QDF5 | B15: T11 | C15: ESCRITÓRIO | D15: =QDF!K14 -> 1200 | E15: =QDF!K14 -> 1200 | F15: - | G15: -
B16: T12 | C16: ESCRITÓRIO | D16: =QDF!K15 -> 1000 | E16: - | F16: =QDF!K15 -> 1000 | G16: -
A17: QDF6 | B17: T13 | C17: SAIDA DE PRODUTOS | D17: =QDF!K16 -> 1500 | E17: =QDF!K16 -> 1500 | F17: - | G17: -
B18: T14 | C18: SAIDA DE PRODUTOS | D18: =QDF!K17 -> 1600 | E18: =QDF!K17 -> 1600 | F18: - | G18: -
B19: T15 | C19: CONTROLE DE QUALIDADE | D19: =QDF!K18 -> 1600 | E19: - | F19: =QDF!K18 -> 1600 | G19: -
B20: T16 | C20: CONTROLE DE QUALIDADE | D20: =QDF!K19 -> 1500 | E20: - | F20: =QDF!K19 -> 1500 | G20: -
A21: QDF7 | B21: T17 | C21: BANHEIRO (VESTUARIO) | D21: =QDF!K20 -> 1500 | E21: - | F21: =QDF!K20 -> 1500 | G21: -
B22: T18 | C22: BANHEIRO (VESTUARIO) | D22: =QDF!K21 -> 600 | E22: =QDF!K21 -> 600 | F22: - | G22: -
B23: T19 | C23: BANHEIRO (VESTUARIO) | D23: =QDF!K22 -> 9000 | E23: - | F23: - | G23: =QDF!K22 -> 9000
B24: T20 | C24: BANHEIRO (VESTUARIO) | D24: =QDF!K23 | E24: - | F24: =QDF!K23 | G24: -
A27: SOMATÓRIO | E27: =SUM(E2:E26) -> 8233.3333 | F27: =SUM(F2:F26) -> 8133.3333 | G27: =SUM(G2:G26) -> 11133.333
A28: TOTAL DAS FASES | E28: =SUM(E27:G27) -> 27500
C29: DIVISÃO TOTAL DAS FASES | E29: =E28/3 -> 9166.6667
C30: FASE MAIS CARREGADA | E30: =G27/220 -> 50.606061
C35: BARRAMENTO AQUI FAÇO DA FASE MAIS CARREGADA PRO QGL E QDL PARA CIRCUITOS DE FASES DESEQUILIBRADAS (É TUDO MENOS MOTOR)

Sheet QDF- BALANÇO POTENCIAS
A1: QDF0 - Subestação
A2: Circuito | B2: Área | C2: Corrente do Disjuntor In (A) | D2: Disjuntor | E2: Capacidade de interrupção do disjuntor (kA) | F2: Balanço de potência (VA)
F3: R | G3: S | H3: T
A4: =QDF!B3 -> T0 | B4: =QDF!C3 -> SUBESTAÇÃO | C4: =DISJUNTORES!E3 -> 16 | D4: MDW-C16 | E4: 5 | F4: ='QDF-BALANÇO TOTAL'!E4 -> 800
A7: QDF1 - Sala de Caldeiras
A8: Circuito | B8: Área | C8: Corrente do Disjuntor In (A) | D8: Disjuntor | E8: Capacidade de interrupção do disjuntor (kA) | F8: Balanço de potência (VA) | K8: TOMADA VAI CIRCUITO RESERVA, O VALOR DE POTENCIA DELE É A MÉDIA DAS FASES
F9: R | G9: S | H9: T
A10: =QDF!B4 -> T1 | B10: =QDF!C4 -> SALA DE CALDEIRAS | C10: =DISJUNTORES!E4 -> 10 | D10: MDW-C10 | E10: 5 | F10: ='QDF-BALANÇO TOTAL'!E5 -> - | G10: ='QDF-BALANÇO TOTAL'!F5 -> - | H10: ='QDF-BALANÇO TOTAL'!G5 -> 800
A11: =QDF!B5 -> T2 | C11: =DISJUNTORES!E5 -> 10 | D11: MDW-C10 | E11: 5 | F11: ='QDF-BALANÇO TOTAL'!E6 -> 333.33333 | G11: ='QDF-BALANÇO TOTAL'!F6 -> 333.33333 | H11: ='QDF-BALANÇO TOTAL'!G6 -> 333.33333
K26: Disjuntor escolhe baseado na In obtida lá em disjuntores
J46: Capacidade de interrupção do disjuntor (kA)
J48: pergunta: Capacidade de interrupção do disjuntor (kA) eu posso colocar 2 kA por ser 220 V certo?
J68: Balanço de potência confiro a distribuição em balanço total
A73: QDF2 - Compressor (bombas e prensa)
A74: Circuito | B74: Área | C74: Corrente do Disjuntor In (A) | D74: Disjuntor | E74: Capacidade de interrupção do disjuntor (kA) | F74: Balanço de potência (VA)
F75: R | G75: S | H75: T
A76: =QDF!B6 -> T3 | B76: =QDF!C6 -> COMPRESSOR (BOMBAS E PRENSA) | C76: =DISJUNTORES!E6 -> 6 | D76: MDW-C6 | E76: 5 | F76: ='QDF-BALANÇO TOTAL'!E7 -> - | G76: ='QDF-BALANÇO TOTAL'!F7 -> 400 | H76: ='QDF-BALANÇO TOTAL'!G7 -> -
A77: =QDF!B7 -> T4 | C77: =DISJUNTORES!E7 -> 10 | D77: MDW-C10 | E77: 5 | F77: ='QDF-BALANÇO TOTAL'!E8 -> 333.33333 | G77: ='QDF-BALANÇO TOTAL'!F8 -> 333.33333 | H77: ='QDF-BALANÇO TOTAL'!G8 -> 333.33333
K94: Disjuntor escolhe baseado na In obtida lá em disjuntores
J114: Capacidade de interrupção do disjuntor (kA)
J116: pergunta: Capacidade de interrupção do disjuntor (kA) eu posso colocar 2 kA por ser 220 V certo?
J136: Balanço de potência confiro a distribuição em balanço total
A139: QDF3- Depósito de carcaças
A140: Circuito | B140: Área | C140: Corrente do Disjuntor In (A) | D140: Disjuntor | E140: Capacidade de interrupção do disjuntor (kA) | F140: Balanço de potência (VA)
F141: R | G141: S | H141: T
A142: =QDF!B8 -> T5 | B142: =QDF!C8 -> DEPÓSITO DE CARCAÇAS | C142: =DISJUNTORES!E8 -> 10 | D142: MDW-C10 | E142: 5 | F142: ='QDF-BALANÇO TOTAL'!E9 -> - | G142: ='QDF-BALANÇO TOTAL'!F9 -> 800 | H142: ='QDF-BALANÇO TOTAL'!G9 -> -
A143: =QDF!B9 -> T6 | C143: =DISJUNTORES!E9 -> 10 | D143: MDW-C10 | E143: 5 | F143: ='QDF-BALANÇO TOTAL'!E10 -> 333.33333 | G143: ='QDF-BALANÇO TOTAL'!F10 -> 333.33333 | H143: ='QDF-BALANÇO TOTAL'!G10 -> 333.33333
L161: Disjuntor escolhe baseado na In obtida lá em disjuntores
K181: Capacidade de interrupção do disjuntor (kA)
K183: pergunta: Capacidade de interrupção do disjuntor (kA) eu posso colocar 2 kA por ser 220 V certo?
K203: Balanço de potência confiro a distribuição em balanço total
A206: QDF4- Raspa e Recapagem
A207: Circuito | B207: Área | C207: Corrente do Disjuntor In (A) | D207: Disjuntor | E207: Capacidade de interrupção do disjuntor (kA) | F207: Balanço de potência (VA)
F208: R | G208: S | H208: T
A209: =QDF!B10 -> T7 | B209: =QDF!C10 -> RASPA | C209: =DISJUNTORES!E10 -> 10 | D209: MDW-C10 | E209: 5 | F209: ='QDF-BALANÇO TOTAL'!E11 -> 1200 | G209: ='QDF-BALANÇO TOTAL'!F11 -> - | H209: ='QDF-BALANÇO TOTAL'!G11 -> -
A210: =QDF!B11 -> T8 | C210: =DISJUNTORES!E11 -> 10 | D210: MDW-C10 | E210: 5 | F210: ='QDF-BALANÇO TOTAL'!E12 -> 333.33333 | G210: ='QDF-BALANÇO TOTAL'!F12 -> 333.33333 | H210: ='QDF-BALANÇO TOTAL'!G12 -> 333.33333
A214: QDF5 - Escritório
A215: Circuito | B215: Nº do circuito | C215: Corrente do Disjuntor In (A) | D215: Disjuntor | E215: Capacidade de interrupção do disjuntor (kA) | F215: Balanço de potência (VA)
F216: R | G216: S | H216: T
A217: =QDF!B15 -> T12 | B217: =QDF!C15 -> ESCRITÓRIO | C217: =DISJUNTORES!E15 -> 10 | D217: MDW-C10 | E217: 5 | F217: ='QDF-BALANÇO TOTAL'!E16 -> - | G217: ='QDF-BALANÇO TOTAL'!F16 -> 1000 | H217: ='QDF-BALANÇO TOTAL'!G16 -> -
...

Sheet QDFG
A2: Quadro | B2: Nº do circuito | C2: Área | D2: DEMANDA (VA)
A3: QDF0 | B3: T0 | C3: SUBESTAÇÃO | D3: =QDF!K3 -> 800
A4: QDF1 | B4: T1 | C4: SALA DE CALDEIRAS | D4: =QDF!K4 -> 800
B5: T2 | D5: =QDF!K5 -> 1000
A6: QDF2 | B6: T3 | C6: COMPRESSOR (BOMBAS E PRENSA) | D6: =QDF!K6 -> 400
B7: T4 | D7: =QDF!K7 -> 1000
A8: QDF3 | B8: T5 | C8: DEPÓSITO DE CARCAÇAS | D8: =QDF!K8 -> 800
B9: T6 | D9: =QDF!K9 -> 1000
A10: QDF4 | B10: T7 | C10: RASPA | D10: =QDF!K10 -> 1200
B11: T8 | D11: =QDF!K11 -> 1000
B12: T9 | D12: 0
B13: T10 | D13: 0
A14: QDF5 | B14: T11 | C14: ESCRITÓRIO | D14: =QDF!K14 -> 1200
B15: T12 | C15: ESCRITÓRIO | D15: =QDF!K15 -> 1000
B16: T13 | C16: ESCRITÓRIO | D16: =QDF!K16 -> 1500
B17: T14 | C17: SAIDA DE PRODUTOS | D17: =QDF!K17 -> 1600
A18: QDF6 | B18: T15 | C18: CONTROLE DE QUALIDADE | D18: =QDF!K18 -> 1600
B19: T16 | C19: SAIDA DE PRODUTOS | D19: =QDF!K19 -> 1500
B20: T17 | C20: CONTROLE DE QUALIDADE | D20: =QDF!K20 -> 1500
B21: T18 | C21: BANHEIRO (VESTUARIO) | D21: =QDF!K21 -> 600
A22: QDF7 | B22: T19 | C22: BANHEIRO (VESTUARIO) | D22: =QDF!K22 -> 9000
B23: T20 | C23: RESERVA | D23: 0
A26: Circuito | B26: Disjuntor | C26: Corrente do Disjuntor (A) | D26: Potência aparente (VA)
A28: QDF-0 | B28: MDW-C16 | C28: 16 | D28: =QDF!K3 -> 800
A29: QDF-1 | B29: MDW-C10 | C29: 10 | D29: =SUM(D4:D5) -> 1800
A30: QDF-2 | B30: MDW-C10 | C30: 10 | D30: =SUM(D6:D7) -> 1400 | F30: MDW-C16
A31: QDF-3 | B31: MDW-C16 | C31: 16 | D31: =SUM(D8:D9) -> 1800
A32: QDF-4 | B32: -
A33: QDF-5 | B33: MDW-C16/2 | C33: 16 | D33: 2700
A34: QDF-6 | B34: MDW-C16/2 | C34: 16 | D34: 3100
A35: QDF-7 | B35: MDW-C50/2 | C35: 50 | D35: 9000
A36: Total | D36: =SUM(D28:D35) -> 20600
A37: RQDL-1 | D37: ='QDF-BALANÇO TOTAL'!E29 -> 9166.6667 | E37: Circuito reserva em tomada precisa de potencia
A38: RQDL-2 | D38: =D37 -> 9166.6667
A39: RQDL-3 | D39: =D37 -> 9166.6667
A40: Total | D40: =SUM(D36:D39) -> 48100
A43: Quadro | B43: Tensão (V) | C43: Corrente nominal (A) | D43: Método de instalação | E43: Método de referência
A44: QDF-0 | B44: 380 | C44: =D28/B44 -> 2.1052632 | D44: 13 | E44: B1
A45: QDF-1 | B45: 380 | C45: =D29/B45 -> 4.7368421 | D45: 13 | E45: B1
A46: QDF-2 | B46: 380 | C46: =D30/B46 -> 3.6842105 | D46: 13 | E46: B1
...
