Workbook

Sheet DADOS
A2: RESPONSÁVEL | B2: LOCAL | C2: ALTURA DE MANUSEIO TRABALHO Hpp (m) | D2: LARGURA L (m) | E2: COMPRIMENTO C (m) | F2: ÁREA (m²) | G2: PERÍMETRO (m) | H2: TETO | I2: PAREDE | J2: PISO | K2: ALTURA TOTAL/PÉ-DIREITO Htp (m)
A3: DANTE | B3: SALA DE CALDEIRAS | C3: 0.8 | D3: 15.92 | E3: 9.6 | F3: =E3*D3 | G3: =(2*E3)+(2*D3) | H3: ZINCO | I3: CLARA | J3: CONCRETO | K3: 7
A4: DANTE | B4: COMPRESSOR (BOMBAS E PRENSA) | C4: 0.8 | D4: 9.28 | E4: 9.6 | F4: =E4*D4 | G4: =(2*E4)+(2*D4) | H4: ZINCO | I4: CLARA | J4: CONCRETO | K4: 7
A5: DANTE | B5: DEPÓSITO DE CARCAÇAS 1 | C5: 0.8 | D5: 8.12 | E5: 6 | F5: =E5*D5 | G5: =2*E5+2*D5 | H5: ZINCO | I5: CLARA | J5: CONCRETO | K5: 7
A6: DANTE | B6: DEPÓSITO DE CARCAÇAS 2 | C6: 0.8 | D6: 11.18 | E6: 9.6 | F6: =E6*D6 | G6: =2*E6+2*D6 | H6: ZINCO | I6: CLARA | J6: CONCRETO | K6: 7
A7: DANTE | B7: RASPA | C7: 0.8 | D7: 8.12 | E7: 30.92 | F7: =E7*D7 | G7: =(2*E7)+(2*D7) | H7: ZINCO | I7: CLARA | J7: CONCRETO | K7: 7
A8: PIETRO | B8: RECAPAGEM 1 | C8: 0.8 | D8: 5 | E8: 30.9 | F8: =E8*D8 | G8: =(2*E8)+(2*D8) | H8: ZINCO | I8: CLARA | J8: CONCRETO | K8: 7
A9: PIETRO | B9: RECAPAGEM 2 | C9: 0.8 | D9: 5.23 | E9: 39.25 | F9: =E9*D9 | G9: =(2*E9)+(2*D9) | H9: ZINCO | I9: CLARA | J9: CONCRETO | K9: 7
A10: PIETRO | B10: RECAPAGEM 3 | C10: 0.8 | D10: 27.95 | E10: 43.37 | F10: =E10*D10 | G10: =(2*E10)+(2*D10) | H10: ZINCO | I10: CLARA | J10: CONCRETO | K10: 7
A11: LUCAS | B11: SAIDA DE PRODUTOS (SALA DE PRODUTOS) | C11: 0.8 | D11: 5 | E11: 6 | F11: =E11*D11 | G11: =(2*E11)+(2*D11) | H11: CLARO | I11: CLARA | J11: AZULEJO CINZA | K11: 3
A12: LUCAS | B12: CONTROLE DE QUALIDADE | C12: 0.8 | D12: 5 | E12: 6 | F12: =E12*D12 | G12: =(2*E12)+(2*D12) | H12: BRANCO | I12: BRANCA | J12: AZULEJO CINZA | K12: 3
A13: LUCAS | B13: BANHEIRO(VESTUARIO) | C13: 0.8 | D13: 5.23 | E13: 3.5 | F13: =E13*D13 | G13: =(2*E13)+(2*D13) | H13: CLARO | I13: CLARA | J13: AZULEJO CINZA | K13: 3
A14: LUCAS | B14: ESCRITÓRIO | C14: 0.8 | D14: 8.12 | E14: 6 | F14: =E14*D14 | G14: =(2*E14)+(2*D14) | H14: BRANCO | I14: BEGE | J14: AZULEJO CINZA | K14: 3
A15: JOÃO | B15: SUBESTAÇÃO | C15: 0.8 | D15: 9.6 | E15: 9.8 | F15: =D15*E15 | G15: =(2*D15)+(2*E15) | H15: BRANCO | I15: BRANCA | J15: CONCRETO | K15: 7

Sheet LUM-SALA CALD
A1: DADOS DO LOCAL
A2: LOCAL | B2: LARGURA L (m) | C2: COMPRIMENTO C (m) | D2: ALTURA DE MANUSEIO TRABALHO Hpp (m) | E2: ALTURA TOTAL/PÉ-DIREITO Htp (m) | F2: ALTURA UTIL/ ALTURA DE TRABALHO Hlp (m) | G2: TETO | H2: PAREDE | I2: PISO | J2: LAMPADA UTILIZADA
A3: SALA DE CALDEIRA | B3: =DADOS!D3 | C3: =DADOS!E3 | D3: =DADOS!C3 | E3: =DADOS!K3 | F3: =E3-D3 | G3: =DADOS!H3 | H3: =DADOS!I3 | I3: =DADOS!J3 | J3: VAPOR DE METAL
A6: MÉTODO LUMENS
A10: ILUMINAMENTO
A13: CARACTERÍSTICAS DA TAREFA E DO OBSERVADOR ADOTADOS
A14: PESO | B14: 0
A15: IDADE | B15: 41
A16: VELOCIDADE E PRECISÃO | B16: IMPORTANTE
A17: REFLETANCIA NO FUNDO DA TAREFA | B17: 0.4
A21: FAIXAS, ILUMINANCIAS E TIPO DE ATIVIDADE ADOTADOS
A22: ADOTADA A FAIXA B | B22: TAREFAS COM REQUISITOS VISUAIS LIMITADOS...
A23: ILUMINÂNCIAS (LUX) | B23: 300
A26: ILUMINÂNCIA MINIMA EM LUX, POR TIPO DE ATIVIDADE ADOTADO
A27: TIPO DE AMBIENTE | B27: LUX
A28: INDÚSTRIA QUIMICA
A29: FORNOS, SECADORES | B29: 200
A31: ADOTADO NO FINAL O MAIOR VALOR QUE É 300 lx
A33: ILUMINÂNCIAS (LUX) | B33: 300
A71: LUMINÁRIA ADOTADA
A73: SALA DE CALDEIRAS POSSUEM ELEVADO PÉ-DIREITO, LUMINÁRIA ADEQUADA PARA ESSE AMBIENTE SÃO TIPO REFLETOR INDUSTRIAL ESTILO CUPULA
A75: DADOS LUMINÁRIA
A76: MODELO | B76: HDK 472
A77: FABRICANTE | B77: Philips
A88: LAMPADA E REATOR ADOTADOS
A89: Podendo ser adotados lampadas de até 400 W, conforme a luminária adotada
A91: DADOS DA LAMPADA
A92: MODELO | B92: MASTER HPI-T Plus 400W/645 E40 1SL/12
A93: FABRICANTE | B93: Philips
A94: TIPO DE LAMPADA | B94: VAPOR METALICO
A95: POTÊNCIA (W) | B95: 400
A96: FLUXO LUMINOSO (lumens) | B96: 33200
A97: NUMERO DE LAMPADAS POR LUMINARIA | B97: 1
A100: DADOS DO REATOR
A101: MODELO | B101: BHLE 400L 200TS
A102: FABRICANTE | B102: Philips
A103: PERDAS (W) | B103: 27.5
A104: FATOR DE POTENCIA | B104: 0.85
A106: De forma a calcular o fluxo luminoso se deve calcular o FATOR DE UTILIZAÇÃO e FATOR DE DEPRECIAÇÃO
A108: FATOR DE UTILIZAÇÃO Fu
...

Sheet RECAPAGEM
A1: DADOS DO LOCAL
B3: LOCAL | C3: LARGURA L (m) | D3: COMPRIMENTO C (m) | E3: ÁREA (m²) | F3: PERÍMETRO (m) | G3: ALTURA DE MANUSEIO TRABALHO Hpp (m) | H3: TETO | I3: PAREDE | J3: PISO | K3: ALTURA TOTAL/PÉ-DIREITO Htp (m) | L3: VELOCIDADE E PRECISÃO | M3: REFLETANCIA DO FUNDO DA TAREFA | N3: IDADE MÉDIA DOS TRABALHADORES | O3: ALTURA MÍNIIMA | P3: TIRANTE
B4: RECAPAGEM 1 | C4: 5 | D4: 30.9 | E4: =D4*C4 | F4: =(2*D4)+(2*C4) | G4: 0.8 | H4: ZINCO | I4: CLARA | J4: CONCRETO | K4: 7 | L4: IMPORTANTE | M4: 0.4 | N4: 41 ANOS | O4: 4 | P4: 1
B5: RECAPAGEM 2 | C5: 5.23 | D5: 39.25 | E5: =D5*C5 | F5: =(2*D5)+(2*C5)
B6: RECAPAGEM 3 | C6: 27.95 | D6: 43.37 | E6: =D6*C6 | F6: =(2*D6)+(2*C6)
A35: LUMINÁRIA
J43: MODELO | K43: HDK 472
J44: FABRICANTE | K44: PHILLIPS
A54: LÂMPADA+REATOR
D57: MODELO | G57: MODELO
D58: FABRICANTE | G58: FABRICANTE
A68: CAVIDADES
I70: refletâncias | L70: Refletâncias Efetivas tab 2.11 – Mamede
B71: relação de cavidade | F71: recinto | G71: teto | H71: piso | I71: teto | J71: piso | K71: parede | M71: 0.1
B72: K | C72: Hlp | D72: Htl | E72: Hpp | F72: Rcr | G72: Rct | H72: Rcp | I72: ρte | J72: ρpi | K72: ρpa | L72: ρcp | M72: ρct(1) | N72: para teto de 50% | O72: para teto de 70%
B73: =(5*(D4+C4))/(D4*C4) | C73: =K4-P4-G4 | D73: =P4 | E73: =G4 | F73: =B73*C73 | G73: =B73*D73 | H73: =B73*E73 | I73: 0.1 | J73: 0.1 | K73: 0.5 | L73: 11 | M73: 11 | N73: 43 | O73: 59
B74: =(5*(D5+C5))/(D5*C5) | C74: =K4-P4-G4 | D74: =P4 | E74: =G4 | F74: =B74*C74 | G74: =B74*D74 | H74: =B74*E74 | L74: 11 | M74: 11 | N74: 43 | O74: 59
B75: =(5*(D6+C6))/(D6*C6) | C75: =K4-P4-G4 | D75: =P4 | E75: =G4 | F75: =B75*C75 | G75: =B75*D75 | H75: =B75*E75 | L75: 10 | M75: 10 | N75: 48 | O75: 67
A95: FATOR DE UTILIZAÇÃO
H96: tab 2.12 – Mamede
A98: Dados de Entrada | B98: RECAPAGEM 1 | E98: RECAPAGEM 2 | H98: RECAPAGEM 3
B99: Rcr=6 | C99: Rcr=7 | D99: =F73 | E99: Rcr=5 | F99: Rcr=6 | G99: =F74 | H99: Rcr=1 | I99: Rcr=2 | J99: =F75
A100: k 1 | B100: 10 | C100: 10 | D100: 7 | E100: 10 | F100: 10 | G100: 6 | H100: 10 | I100: 10 | J100: 2
A101: k 2 | B101: 50 | C101: 50 | D101: 6 | E101: 50 | F101: 50 | G101: 5 | H101: 50 | I101: 50 | J101: 1
A102: Fu 1 | B102: 0.44 | C102: 0.41 | D102: =B108 | E102: 0.47 | F102: 0.44 | G102: =E108 | H102: 0.67 | I102: 0.61 | J102: =H108
A103: Fu 2 | B103: 0.46 | C103: 0.43 | D103: =C108 | E103: 0.5 | F103: 0.46 | G103: =F108 | H103: 0.72 | I103: 0.65 | J103: =I108
A104: k encontrado | B104: =M73 | C104: =B104 | D104: =D99 | E104: =M74 | F104: =E104 | G104: =G99 | H104: =M73 | I104: =H104 | J104: =J99
A105: denominador 1 | B105: =B101-B100 | C105: =C101-C100 | D105: =D101-D100 | E105: =E101-E100 | F105: =F101-F100 | G105: =G101-G100 | H105: =H101-H100 | I105: =I101-I100 | J105: =J101-J100
A106: denominador 2 | B106: =B104-B100 | C106: =C104-C100 | D106: =D101-D104 | E106: =E101-E104 | F106: =F101-F104 | G106: =G101-G104 | H106: =H101-H104 | I106: =I101-I104 | J106: =J101-J104
A107: numerador 1 | B107: =B103-B102 | C107: =C103-C102 | D107: =D102-D103 | E107: =E103-E102 | F107: =F103-F102 | G107: =G102-G103 | H107: =H103-H102 | I107: =I103-I102 | J107: =J102-J103
A108: FU calculado | B108: =((B103*B105)-(B107*B106))/(B105) | C108: =((C103*C105)-(C107*C106))/(C105) | D108: =((D103*D105)-(D107*D106))/(D105) | E108: =((E103*E105)-(E107*E106))/(E105) | F108: =((F103*F105)-(F107*F106))/(F105) | G108: =((G103*G105)-(G107*G106))/(G105) | H108: =((H103*H105)-(H107*H106))/(H105) | I108: =((I103*I105)-(I107*I106))/(I105) | J108: =((J103*J105)-(J107*J106))/(J105)

Sheet SUBESTAÇÃO
A1: DADOS DO LOCAL
A3: LOCAL | B3: ALTURA DE MANUSEIO TRABALHO Hpp (m) | C3: LARGURA L (m) | D3: COMPRIMENTO C (m) | E3: ÁREA (m²) | F3: PERÍMETRO (m) | G3: TETO | H3: PAREDE | I3: PISO | J3: ALTURA TOTAL/PÉ-DIREITO Htp (m) | K3: ALTURA DE INSTALAÇÃO | L3: ALTURA ÚTIL | M3: VELOCIDADE E PRECISÃO | N3: REFLETANCIA DO FUNDO DA TAREFA | O3: IDADE MÉDIA DOS TRABALHADORES | P3: IDADE MÉDIA DOS TRABALHADORES
A4: Subestação | B4: 0.8 | C4: 9.6 | D4: 9.8 | E4: =C4*D4 | F4: =(2*D4)+(2*C4) | G4: BRANCO | H4: BRANCA | I4: CONCRETO | J4: 7 | K4: 6 | L4: =K4-B4 | M4: IMPORTANTE | N4: 0.4 | O4: 41 ANOS | P4: 41 ANOS
A6: ILUMINÂNCIA(Lux) | B6: Fluxo Luminária | C6: Fator de utilização (u) | D6: Fator de depreciação (d) | G6: Refletância do teto | H6: Refletância da parede | I6: Refletância do piso
A7: 150 | G7: 80 | H7: 80 | I7: 45
A9: Cálculo do ìndice do recinto (K) | D9: Cálculo do fluxo luminoso total | F9: Nº de luminárias
A10: K | B10: =D4*C4/(L4*(D4+C4)) | D10: Fluxo | E10: =(A7*E4)/(C7*D7) | F10: =E10/B7
A13: Luminária utilizada
A14: https://comercialex.com.br/produtos/iluminacao/luminaria-convencional/luminaria-a-prova-de-explosao-arandela/

Sheet LUM-LUCAS
A1: T1 - LUMINOTECNICO | MEMORIAL DE CALCULO - LUCAS
A2: Metodo dos Lumens | Areas vinculadas a DADOS!11:14 | Luminaria principal: TMS 426 fluorescente
A3: As dimensoes e o pe-direito sao lidos da aba DADOS. Os valores amarelos sao premissas editaveis; os verdes sao resultados calculados.
A5: PARAMETROS DA LUMINARIA | H5: CRITERIOS ADOTADOS
A6: Luminaria principal | D6: TMS 426 - 2 lampadas fluorescentes de 40 W | H6: Plano de trabalho | J6: 0,80 m acima do piso
A7: Lampadas por luminaria | D7: 2 | H7: Altura util Hlp | J7: Pe-direito - plano de trabalho
A8: Fluxo por lampada [lm] | D8: 3000 | H8: Metodo | J8: Metodo dos Lumens
A9: Potencia por lampada [W] | D9: 40 | H9: Teto claro/branco | J9: 70% na tabela 2.9 (limite tabelado)
A10: Perdas do reator por luminaria [W] | D10: 24.1 | H10: Parede clara/branca | J10: 50% na tabela 2.9
A11: Fator de potencia | D11: 0.9 | H11: Parede bege | J11: 45%, interpolacao entre 50% e 30%
A12: Fator de depreciacao Fdl | D12: 0.75 | H12: Piso azulejo cinza | J12: Tabela 2.9 fornecida usa piso de 10%
A13: Tensao de alimentacao [V] | D13: 220 | H13: Circuitos | J13: QDL5, QDL6 e QDL7 conforme a area
A15: CALCULO INDIVIDUAL - METODO DOS LUMENS
A16: Ambiente | B16: Largura [m] | C16: Comprimento [m] | D16: Area [m2] | E16: Perimetro [m] | F16: Plano trab. [m] | G16: Pe-direito [m] | H16: Hlp [m] | I16: K [-] | J16: Teto [%] | K16: Parede [%] | L16: Piso [%] | M16: E requerida [lux] | N16: Fu [-] | O16: Fdl [-] | P16: Fluxo total [lm] | Q16: Fluxo/lamp. [lm] | R16: Lamp./lum. [-] | S16: NLU teorico [-] | T16: NLU instalado [-] | U16: P lamp. [W] | V16: Perdas [W/lum.] | W16: P total [W] | X16: FP [-] | Y16: S total [VA] | Z16: I em 220 V [A] | AA16: E obtida [lux] | AB16: Verificacao | AC16: QDL
A17: =DADOS!B11 | B17: =DADOS!D11 | C17: =DADOS!E11 | D17: =DADOS!F11 | E17: =DADOS!G11 | F17: =DADOS!C11 | G17: =DADOS!K11 | H17: =G17-F17 | I17: =D17/(H17*(B17+C17)) | J17: =IF(OR(DADOS!H11="BRANCO",DADOS!H11="CLARO"),70,70) | K17: =IF(OR(DADOS!I11="CLARA",DADOS!I11="BRANCA"),50,IF(DADOS!I11="BEGE",45,50)) | L17: =10 | M17: =200 | N17: =IF(K17>=50,AF17,IF(K17<=30,AG17,AG17+(K17-30)*(AF17-AG17)/20)) | O17: =$D$12 | P17: =(M17*D17)/(N17*O17) | Q17: =$D$8 | R17: =$D$7 | S17: =P17/(Q17*R17) | T17: =ROUNDUP(S17,0) | U17: =$D$9 | V17: =$D$10 | W17: =T17*(R17*U17+V17) | X17: =$D$11 | Y17: =W17/X17 | Z17: =Y17/$D$13 | AA17: =(T17*R17*Q17*N17*O17)/D17 | AB17: =IF(AA17>=M17,"OK","REVISAR") | AC17: ="QDL6" | AF17: =IF(I17<=$A$31,$B$31,IF(I17>=$A$40,$B$40,INDEX($B$31:$B$40,MATCH(I17,$A$31:$A$40,1))+(I17-INDEX($A$31:$A$40,MATCH(I17,$A$31:$A$40,1)))*(INDEX($B$31:$B$40,MATCH(I17,$A$31:$A$40,1)+1)-INDEX($B$31:$B$40,MATCH(I17,$A$31:$A$40,1)))/(INDEX($A$31:$A$40,MATCH(I17,$A$31:$A$40,1)+1)-INDEX($A$31:$A$40,MATCH(I17,$A$31:$A$40,1))))) | AG17: =IF(I17<=$A$31,$C$31,IF(I17>=$A$40,$C$40,INDEX($C$31:$C$40,MATCH(I17,$A$31:$A$40,1))+(I17-INDEX($A$31:$A$40,MATCH(I17,$A$31:$A$40,1)))*(INDEX($C$31:$C$40,MATCH(I17,$A$31:$A$40,1)+1)-INDEX($C$31:$C$40,MATCH(I17,$A$31:$A$40,1)))/(INDEX($A$31:$A$40,MATCH(I17,$A$31:$A$40,1)+1)-INDEX($A$31:$A$40,MATCH(I17,$A$31:$A$40,1))))) | AH17: =MATCH(I17,$A$31:$A$40,1)
A18: =DADOS!B12 | B18: =DADOS!D12 | C18: =DADOS!E12 | D18: =DADOS!F12 | E18: =DADOS!G12 | F18: =DADOS!C12 | G18: =DADOS!K12 | H18: =G18-F18 | I18: =D18/(H18*(B18+C18)) | J18: =IF(OR(DADOS!H12="BRANCO",DADOS!H12="CLARO"),70,70) | K18: =IF(OR(DADOS!I12="CLARA",DADOS!I12="BRANCA"),50,IF(DADOS!I12="BEGE",45,50)) | L18: =10 | M18: =500 | N18: =IF(K18>=50,AF18,IF(K18<=30,AG18,AG18+(K18-30)*(AF18-AG18)/20)) | O18: =$D$12 | P18: =(M18*D18)/(N18*O18) | Q18: =$D$8 | R18: =$D$7 | S18: =P18/(Q18*R18) | T18: =ROUNDUP(S18,0) | U18: =$D$9 | V18: =$D$10 | W18: =T18*(R18*U18+V18) | X18: =$D$11 | Y18: =W18/X18 | Z18: =Y18/$D$13 | AA18: =(T18*R18*Q18*N18*O18)/D18 | AB18: =IF(AA18>=M18,"OK","REVISAR") | AC18: ="QDL6" | AF18: =IF(I18<=$A$31,$B$31,IF(I18>=$A$40,$B$40,INDEX($B$31:$B$40,MATCH(I18,$A$31:$A$40,1))+(I18-INDEX($A$31:$A$40,MATCH(I18,$A$31:$A$40,1)))*(INDEX($B$31:$B$40,MATCH(I18,$A$31:$A$40,1)+1)-INDEX($B$31:$B$40,MATCH(I18,$A$31:$A$40,1)))/(INDEX($A$31:$A$40,MATCH(I18,$A$31:$A$40,1)+1)-INDEX($A$31:$A$40,MATCH(I18,$A$31:$A$40,1))))) | AG18: =IF(I18<=$A$31,$C$31,IF(I18>=$A$40,$C$40,INDEX($C$31:$C$40,MATCH(I18,$A$31:$A$40,1))+(I18-INDEX($A$31:$A$40,MATCH(I18,$A$31:$A$40,1)))*(INDEX($C$31:$C$40,MATCH(I18,$A$31:$A$40,1)+1)-INDEX($C$31:$C$40,MATCH(I18,$A$31:$A$40,1)))/(INDEX($A$31:$A$40,MATCH(I18,$A$31:$A$40,1)+1)-INDEX($A$31:$A$40,MATCH(I18,$A$31:$A$40,1))))) | AH18: =MATCH(I18,$A$31:$A$40,1)
A19: =DADOS!B13 | B19: =DADOS!D13 | C19: =DADOS!E13 | D19: =DADOS!F13 | E19: =DADOS!G13 | F19: =DADOS!C13 | G19: =DADOS!K13 | H19: =G19-F19 | I19: =D19/(H19*(B19+C19)) | J19: =IF(OR(DADOS!H13="BRANCO",DADOS!H13="CLARO"),70,70) | K19: =IF(OR(DADOS!I13="CLARA",DADOS!I13="BRANCA"),50,IF(DADOS!I13="BEGE",45,50)) | L19: =10 | M19: =200 | N19: =IF(K19>=50,AF19,IF(K19<=30,AG19,AG19+(K19-30)*(AF19-AG19)/20)) | O19: =$D$12 | P19: =(M19*D19)/(N19*O19) | Q19: =$D$8 | R19: =$D$7 | S19: =P19/(Q19*R19) | T19: =ROUNDUP(S19,0) | U19: =$D$9 | V19: =$D$10 | W19: =T19*(R19*U19+V19) | X19: =$D$11 | Y19: =W19/X19 | Z19: =Y19/$D$13 | AA19: =(T19*R19*Q19*N19*O19)/D19 | AB19: =IF(AA19>=M19,"OK","REVISAR") | AC19: ="QDL7" | AF19: =IF(I19<=$A$31,$B$31,IF(I19>=$A$40,$B$40,INDEX($B$31:$B$40,MATCH(I19,$A$31:$A$40,1))+(I19-INDEX($A$31:$A$40,MATCH(I19,$A$31:$A$40,1)))*(INDEX($B$31:$B$40,MATCH(I19,$A$31:$A$40,1)+1)-INDEX($B$31:$B$40,MATCH(I19,$A$31:$A$40,1)))/(INDEX($A$31:$A$40,MATCH(I19,$A$31:$A$40,1)+1)-INDEX($A$31:$A$40,MATCH(I19,$A$31:$A$40,1))))) | AG19: =IF(I19<=$A$31,$C$31,IF(I19>=$A$40,$C$40,INDEX($C$31:$C$40,MATCH(I19,$A$31:$A$40,1))+(I19-INDEX($A$31:$A$40,MATCH(I19,$A$31:$A$40,1)))*(INDEX($C$31:$C$40,MATCH(I19,$A$31:$A$40,1)+1)-INDEX($C$31:$C$40,MATCH(I19,$A$31:$A$40,1)))/(INDEX($A$31:$A$40,MATCH(I19,$A$31:$A$40,1)+1)-INDEX($A$31:$A$40,MATCH(I19,$A$31:$A$40,1))))) | AH19: =MATCH(I19,$A$31:$A$40,1)
A20: =DADOS!B14 | B20: =DADOS!D14 | C20: =DADOS!E14 | D20: =DADOS!F14 | E20: =DADOS!G14 | F20: =DADOS!C14 | G20: =DADOS!K14 | H20: =G20-F20 | I20: =D20/(H20*(B20+C20)) | J20: =IF(OR(DADOS!H14="BRANCO",DADOS!H14="CLARO"),70,70) | K20: =IF(OR(DADOS!I14="CLARA",DADOS!I14="BRANCA"),50,IF(DADOS!I14="BEGE",45,50)) | L20: =10 | M20: =250 | N20: =IF(K20>=50,AF20,IF(K20<=30,AG20,AG20+(K20-30)*(AF20-AG20)/20)) | O20: =$D$12 | P20: =(M20*D20)/(N20*O20) | Q20: =$D$8 | R20: =$D$7 | S20: =P20/(Q20*R20) | T20: =ROUNDUP(S20,0) | U20: =$D$9 | V20: =$D$10 | W20: =T20*(R20*U20+V20) | X20: =$D$11 | Y20: =W20/X20 | Z20: =Y20/$D$13 | AA20: =(T20*R20*Q20*N20*O20)/D20 | AB20: =IF(AA20>=M20,"OK","REVISAR") | AC20: ="QDL5" | AF20: =IF(I20<=$A$31,$B$31,IF(I20>=$A$40,$B$40,INDEX($B$31:$B$40,MATCH(I20,$A$31:$A$40,1))+(I20-INDEX($A$31:$A$40,MATCH(I20,$A$31:$A$40,1)))*(INDEX($B$31:$B$40,MATCH(I20,$A$31:$A$40,1)+1)-INDEX($B$31:$B$40,MATCH(I20,$A$31:$A$40,1)))/(INDEX($A$31:$A$40,MATCH(I20,$A$31:$A$40,1)+1)-INDEX($A$31:$A$40,MATCH(I20,$A$31:$A$40,1))))) | AG20: =IF(I20<=$A$31,$C$31,IF(I20>=$A$40,$C$40,INDEX($C$31:$C$40,MATCH(I20,$A$31:$A$40,1))+(I20-INDEX($A$31:$A$40,MATCH(I20,$A$31:$A$40,1)))*(INDEX($C$31:$C$40,MATCH(I20,$A$31:$A$40,1)+1)-INDEX($C$31:$C$40,MATCH(I20,$A$31:$A$40,1)))/(INDEX($A$31:$A$40,MATCH(I20,$A$31:$A$40,1)+1)-INDEX($A$31:$A$40,MATCH(I20,$A$31:$A$40,1))))) | AH20: =MATCH(I20,$A$31:$A$40,1)
A29: TABELA 2.9 - TMS 426 | FATOR DE UTILIZACAO Fu
A30: K | B30: Fu teto 70% / parede 50% | C30: Fu teto 70% / parede 30% | AF30: Fu 70/50 inferior | AG30: Fu 70/30 inferior | AH30: Indice tabela
A31: 0.6 | B31: 0.35 | C31: 0.28
A32: 0.8 | B32: 0.43 | C32: 0.36
A33: 1 | B33: 0.5 | C33: 0.42
A34: 1.25 | B34: 0.56 | C34: 0.49
A35: 1.5 | B35: 0.61 | C35: 0.54
A36: 2 | B36: 0.68 | C36: 0.61
A37: 2.5 | B37: 0.72 | C37: 0.67
A38: 3 | B38: 0.76 | C38: 0.71
A39: 4 | B39: 0.8 | C39: 0.76
A40: 5 | B40: 0.83 | C40: 0.8
A43: RESUMO DE CARGAS DE ILUMINACAO
A44: QDL | B44: Ambientes | C44: Luminarias | D44: Potencia total [W] | E44: Potencia aparente [VA] | F44: Corrente [A] | G44: Area total [m2]
A45: ="QDL5" | B45: ="Escritorio" | C45: =SUMIF($AC$17:$AC$20,A45,$T$17:$T$20) | D45: =SUMIF($AC$17:$AC$20,A45,$W$17:$W$20) | E45: =SUMIF($AC$17:$AC$20,A45,$Y$17:$Y$20) | F45: =SUMIF($AC$17:$AC$20,A45,$Z$17:$Z$20) | G45: =SUMIF($AC$17:$AC$20,A45,$D$17:$D$20)
A46: ="QDL6" | B46: ="Sala de Produtos + Controle de Qualidade" | C46: =SUMIF($AC$17:$AC$20,A46,$T$17:$T$20) | D46: =SUMIF($AC$17:$AC$20,A46,$W$17:$W$20) | E46: =SUMIF($AC$17:$AC$20,A46,$Y$17:$Y$20) | F46: =SUMIF($AC$17:$AC$20,A46,$Z$17:$Z$20) | G46: =SUMIF($AC$17:$AC$20,A46,$D$17:$D$20)
A47: ="QDL7" | B47: ="Banheiro / Vestiario" | C47: =SUMIF($AC$17:$AC$20,A47,$T$17:$T$20) | D47: =SUMIF($AC$17:$AC$20,A47,$W$17:$W$20) | E47: =SUMIF($AC$17:$AC$20,A47,$Y$17:$Y$20) | F47: =SUMIF($AC$17:$AC$20,A47,$Z$17:$Z$20) | G47: =SUMIF($AC$17:$AC$20,A47,$D$17:$D$20)
A48: TOTAL | C48: =SUM(C45:C47) | D48: =SUM(D45:D47) | E48: =SUM(E45:E47) | F48: =SUM(F45:F47) | G48: =SUM(G45:G47)
