Workbook

Sheet DADOS
A2: RESPONSÁVEL | B2: LOCAL | C2: ALTURA DE MANUSEIO TRABALHO Hpp (m) | D2: LARGURA L (m) | E2: COMPRIMENTO C (m) | F2: ÁREA (m²) | G2: PERÍMETRO (m) | H2: TETO | I2: PAREDE | J2: PISO | K2: ALTURA TOTAL/PÉ-DIREITO Htp (m)
A3: DANTE | B3: SALA DE CALDEIRAS | C3: 0.8 | D3: 15.92 | E3: 9.6 | F3: =E3*D3 -> 152.832 | G3: =(2*E3)+(2*D3) -> 51.04 | H3: ZINCO | I3: CLARA | J3: CONCRETO | K3: 7
A4: DANTE | B4: COMPRESSOR (BOMBAS E PRENSA) | C4: 0.8 | D4: 9.28 | E4: 9.6 | F4: =E4*D4 -> 89.088 | G4: =(2*E4)+(2*D4) -> 37.76 | H4: ZINCO | I4: CLARA | J4: CONCRETO | K4: 7
A5: DANTE | B5: DEPÓSITO DE CARCAÇAS 1 | C5: 0.8 | D5: 8.12 | E5: 6 | F5: =E5*D5 -> 48.72 | G5: =2*E5+2*D5 -> 28.24 | H5: ZINCO | I5: CLARA | J5: CONCRETO | K5: 7
A6: DANTE | B6: DEPÓSITO DE CARCAÇAS 2 | C6: 0.8 | D6: 11.18 | E6: 9.6 | F6: =E6*D6 -> 107.328 | G6: =2*E6+2*D6 -> 41.56 | H6: ZINCO | I6: CLARA | J6: CONCRETO | K6: 7
A7: DANTE | B7: RASPA | C7: 0.8 | D7: 8.12 | E7: 30.92 | F7: =E7*D7 -> 251.0704 | G7: =(2*E7)+(2*D7) -> 78.08 | H7: ZINCO | I7: CLARA | J7: CONCRETO | K7: 7
A8: PIETRO | B8: RECAPAGEM 1 | C8: 0.8 | D8: 5 | E8: 30.9 | F8: =E8*D8 -> 154.5 | G8: =(2*E8)+(2*D8) -> 71.8 | H8: ZINCO | I8: CLARA | J8: CONCRETO | K8: 7
A9: PIETRO | B9: RECAPAGEM 2 | C9: 0.8 | D9: 5.23 | E9: 39.25 | F9: =E9*D9 -> 205.2775 | G9: =(2*E9)+(2*D9) -> 88.96 | H9: ZINCO | I9: CLARA | J9: CONCRETO | K9: 7
A10: PIETRO | B10: RECAPAGEM 3 | C10: 0.8 | D10: 27.95 | E10: 43.37 | F10: =E10*D10 -> 1212.1915 | G10: =(2*E10)+(2*D10) -> 142.64 | H10: ZINCO | I10: CLARA | J10: CONCRETO | K10: 7
A11: LUCAS | B11: SAIDA DE PRODUTOS (SALA DE PRODUTOS) | C11: 0.8 | D11: 5 | E11: 6 | F11: =E11*D11 -> 30 | G11: =(2*E11)+(2*D11) -> 22 | H11: CLARO | I11: CLARA | J11: AZULEJO CINZA | K11: 3
A12: LUCAS | B12: CONTROLE DE QUALIDADE | C12: 0.8 | D12: 5 | E12: 6 | F12: =E12*D12 -> 30 | G12: =(2*E12)+(2*D12) -> 22 | H12: BRANCO | I12: BRANCA | J12: AZULEJO CINZA | K12: 3
A13: LUCAS | B13: BANHEIRO(VESTUARIO) | C13: 0.8 | D13: 5.23 | E13: 3.5 | F13: =E13*D13 -> 18.305 | G13: =(2*E13)+(2*D13) -> 17.46 | H13: CLARO | I13: CLARA | J13: AZULEJO CINZA | K13: 3
A14: LUCAS | B14: ESCRITÓRIO | C14: 0.8 | D14: 8.12 | E14: 6 | F14: =E14*D14 -> 48.72 | G14: =(2*E14)+(2*D14) -> 28.24 | H14: BRANCO | I14: BEGE | J14: AZULEJO CINZA | K14: 3
A15: JOÃO | B15: SUBESTAÇÃO | C15: 0.8 | D15: 9.6 | E15: 9.8 | F15: =D15*E15 -> 94.08 | G15: =(2*D15)+(2*E15) -> 38.8 | H15: BRANCO | I15: BRANCA | J15: CONCRETO | K15: 7

Sheet LUM-LUCAS
A1: T1 - LUMINOTECNICO | MEMORIAL DE CALCULO - LUCAS
A2: Metodo dos Lumens | Areas vinculadas a DADOS!11:14 | Luminaria principal: TMS 426 fluorescente
A3: As dimensoes e o pe-direito sao lidos da aba DADOS. Os valores amarelos sao premissas editaveis; os verdes sao resultados calculados.
A5: PARAMETROS DA LUMINARIA | H5: CRITERIOS ADOTADOS
A6: Luminaria principal | D6: TMS 426 - 2 lampadas fluorescentes de 40 W | H6: Plano de trabalho | J6: 0,80 m acima do piso
A7: Lampadas por luminaria | D7: 2 | H7: Altura util Hlp | J7: Pe-direito - plano de trabalho
A8: Fluxo por lampada [lm] | D8: 3000 | H8: Metodo | J8: Metodo dos Lumens
A9: Potencia por lampada [W] | D9: 40 | H9: Teto claro/branco | J9: 70% na tabela 2.9 (limite tabelado)
A10: Perdas do reator por luminaria [W] | D10: 24.1 | H10: Parede clara/branca | J10: 50% na tabela 2.9
A11: Fator de potencia | D11: 0.9 | H11: Parede bege | J11: 45%, interpolacao entre 50% e 30%
A12: Fator de depreciacao Fdl | D12: 0.75 | H12: Piso azulejo cinza | J12: Tabela 2.9 fornecida usa piso de 10%
A13: Tensao de alimentacao [V] | D13: 220 | H13: Circuitos | J13: QDL5, QDL6 e QDL7 conforme a area
A15: CALCULO INDIVIDUAL - METODO DOS LUMENS
A16: Ambiente | B16: Largura [m] | C16: Comprimento [m] | D16: Area [m2] | E16: Perimetro [m] | F16: Plano trab. [m] | G16: Pe-direito [m] | H16: Hlp [m] | I16: K [-] | J16: Teto [%] | K16: Parede [%] | L16: Piso [%] | M16: E requerida [lux] | N16: Fu [-] | O16: Fdl [-] | P16: Fluxo total [lm] | Q16: Fluxo/lamp. [lm] | R16: Lamp./lum. [-] | S16: NLU teorico [-] | T16: NLU instalado [-] | U16: P lamp. [W] | V16: Perdas [W/lum.] | W16: P total [W] | X16: FP [-] | Y16: S total [VA] | Z16: I em 220 V [A] | AA16: E obtida [lux] | AB16: Verificacao | AC16: QDL
A17: =DADOS!B11 -> SAIDA DE PRODUTOS (SALA DE PRODUTOS) | B17: =DADOS!D11 -> 5 | C17: =DADOS!E11 -> 6 | D17: =DADOS!F11 -> 30 | E17: =DADOS!G11 -> 22 | F17: =DADOS!C11 -> 0.8 | G17: =DADOS!K11 -> 3 | H17: =G17-F17 -> 2.2 | I17: =D17/(H17*(B17+C17)) -> 1.2396694 | J17: =IF(OR(DADOS!H11="BRANCO",DADOS!H11="CLARO"),70,70) -> 70 | K17: =IF(OR(DADOS!I11="CLARA",DADOS!I11="BRANCA"),50,IF(DADOS!I11="BEGE",45,50)) -> 50 | L17: =10 -> 10 | M17: =200 -> 200 | N17: =IF(K17>=50,AF17,IF(K17<=30,AG17,AG17+(K17-30)*(AF17-AG17)/20)) -> 0.55752066 | O17: =$D$12 -> 0.75 | P17: =(M17*D17)/(N17*O17) -> 14349.244 | Q17: =$D$8 -> 3000 | R17: =$D$7 -> 2 | S17: =P17/(Q17*R17) -> 2.3915407 | T17: =ROUNDUP(S17,0) -> 3 | U17: =$D$9 -> 40 | V17: =$D$10 -> 24.1 | W17: =T17*(R17*U17+V17) -> 312.3 | X17: =$D$11 -> 0.9 | Y17: =W17/X17 -> 347 | Z17: =Y17/$D$13 -> 1.5772727 | AA17: =(T17*R17*Q17*N17*O17)/D17 -> 250.8843 | AB17: =IF(AA17>=M17,"OK","REVISAR") -> OK | AC17: ="QDL6" -> QDL6 | AF17: =IF(I17<=$A$25,$B$25,IF(I17>=$A$34,$B$34,INDEX($B$25:$B$34,MATCH(I17,$A$25:$A$34,1))+(I17-INDEX($A$25:$A$34,MATCH(I17,$A$25:$A$34,1)))*(INDEX($B$25:$B$34,MATCH(I17,$A$25:$A$34,1)+1)-INDEX($B$25:$B$34,MATCH(I17,$A$25:$A$34,1)))/(INDEX($A$25:$A$34,MATCH(I17,$A$25:$A$34,1)+1)-INDEX($A$25:$A$34,MATCH(I17,$A$25:$A$34,1))))) -> 0.55752066 | AG17: =IF(I17<=$A$25,$C$25,IF(I17>=$A$34,$C$34,INDEX($C$25:$C$34,MATCH(I17,$A$25:$A$34,1))+(I17-INDEX($A$25:$A$34,MATCH(I17,$A$25:$A$34,1)))*(INDEX($C$25:$C$34,MATCH(I17,$A$25:$A$34,1)+1)-INDEX($C$25:$C$34,MATCH(I17,$A$25:$A$34,1)))/(INDEX($A$25:$A$34,MATCH(I17,$A$25:$A$34,1)+1)-INDEX($A$25:$A$34,MATCH(I17,$A$25:$A$34,1))))) -> 0.48710744 | AH17: =MATCH(I17,$A$25:$A$34,1) -> 3
A18: =DADOS!B12 -> CONTROLE DE QUALIDADE | B18: =DADOS!D12 -> 5 | C18: =DADOS!E12 -> 6 | D18: =DADOS!F12 -> 30 | E18: =DADOS!G12 -> 22 | F18: =DADOS!C12 -> 0.8 | G18: =DADOS!K12 -> 3 | H18: =G18-F18 -> 2.2 | I18: =D18/(H18*(B18+C18)) -> 1.2396694 | J18: =IF(OR(DADOS!H12="BRANCO",DADOS!H12="CLARO"),70,70) -> 70 | K18: =IF(OR(DADOS!I12="CLARA",DADOS!I12="BRANCA"),50,IF(DADOS!I12="BEGE",45,50)) -> 50 | L18: =10 -> 10 | M18: =500 -> 500 | N18: =IF(K18>=50,AF18,IF(K18<=30,AG18,AG18+(K18-30)*(AF18-AG18)/20)) -> 0.55752066 | O18: =$D$12 -> 0.75 | P18: =(M18*D18)/(N18*O18) -> 35873.11 | Q18: =$D$8 -> 3000 | R18: =$D$7 -> 2 | S18: =P18/(Q18*R18) -> 5.9788517 | T18: =ROUNDUP(S18,0) -> 6 | U18: =$D$9 -> 40 | V18: =$D$10 -> 24.1 | W18: =T18*(R18*U18+V18) -> 624.6 | X18: =$D$11 -> 0.9 | Y18: =W18/X18 -> 694 | Z18: =Y18/$D$13 -> 3.1545455 | AA18: =(T18*R18*Q18*N18*O18)/D18 -> 501.7686 | AB18: =IF(AA18>=M18,"OK","REVISAR") -> OK | AC18: ="QDL6" -> QDL6 | AF18: =IF(I18<=$A$25,$B$25,IF(I18>=$A$34,$B$34,INDEX($B$25:$B$34,MATCH(I18,$A$25:$A$34,1))+(I18-INDEX($A$25:$A$34,MATCH(I18,$A$25:$A$34,1)))*(INDEX($B$25:$B$34,MATCH(I18,$A$25:$A$34,1)+1)-INDEX($B$25:$B$34,MATCH(I18,$A$25:$A$34,1)))/(INDEX($A$25:$A$34,MATCH(I18,$A$25:$A$34,1)+1)-INDEX($A$25:$A$34,MATCH(I18,$A$25:$A$34,1))))) -> 0.55752066 | AG18: =IF(I18<=$A$25,$C$25,IF(I18>=$A$34,$C$34,INDEX($C$25:$C$34,MATCH(I18,$A$25:$A$34,1))+(I18-INDEX($A$25:$A$34,MATCH(I18,$A$25:$A$34,1)))*(INDEX($C$25:$C$34,MATCH(I18,$A$25:$A$34,1)+1)-INDEX($C$25:$C$34,MATCH(I18,$A$25:$A$34,1)))/(INDEX($A$25:$A$34,MATCH(I18,$A$25:$A$34,1)+1)-INDEX($A$25:$A$34,MATCH(I18,$A$25:$A$34,1))))) -> 0.48710744 | AH18: =MATCH(I18,$A$25:$A$34,1) -> 3
A19: =DADOS!B13 -> BANHEIRO(VESTUARIO) | B19: =DADOS!D13 -> 5.23 | C19: =DADOS!E13 -> 3.5 | D19: =DADOS!F13 -> 18.305 | E19: =DADOS!G13 -> 17.46 | F19: =DADOS!C13 -> 0.8 | G19: =DADOS!K13 -> 3 | H19: =G19-F19 -> 2.2 | I19: =D19/(H19*(B19+C19)) -> 0.95308758 | J19: =IF(OR(DADOS!H13="BRANCO",DADOS!H13="CLARO"),70,70) -> 70 | K19: =IF(OR(DADOS!I13="CLARA",DADOS!I13="BRANCA"),50,IF(DADOS!I13="BEGE",45,50)) -> 50 | L19: =10 -> 10 | M19: =200 -> 200 | N19: =IF(K19>=50,AF19,IF(K19<=30,AG19,AG19+(K19-30)*(AF19-AG19)/20)) -> 0.48358065 | O19: =$D$12 -> 0.75 | P19: =(M19*D19)/(N19*O19) -> 10094.145 | Q19: =$D$8 -> 3000 | R19: =$D$7 -> 2 | S19: =P19/(Q19*R19) -> 1.6823575 | T19: =ROUNDUP(S19,0) -> 2 | U19: =$D$9 -> 40 | V19: =$D$10 -> 24.1 | W19: =T19*(R19*U19+V19) -> 208.2 | X19: =$D$11 -> 0.9 | Y19: =W19/X19 -> 231.33333 | Z19: =Y19/$D$13 -> 1.0515152 | AA19: =(T19*R19*Q19*N19*O19)/D19 -> 237.76159 | AB19: =IF(AA19>=M19,"OK","REVISAR") -> OK | AC19: ="QDL7" -> QDL7 | AF19: =IF(I19<=$A$25,$B$25,IF(I19>=$A$34,$B$34,INDEX($B$25:$B$34,MATCH(I19,$A$25:$A$34,1))+(I19-INDEX($A$25:$A$34,MATCH(I19,$A$25:$A$34,1)))*(INDEX($B$25:$B$34,MATCH(I19,$A$25:$A$34,1)+1)-INDEX($B$25:$B$34,MATCH(I19,$A$25:$A$34,1)))/(INDEX($A$25:$A$34,MATCH(I19,$A$25:$A$34,1)+1)-INDEX($A$25:$A$34,MATCH(I19,$A$25:$A$34,1))))) -> 0.48358065 | AG19: =IF(I19<=$A$25,$C$25,IF(I19>=$A$34,$C$34,INDEX($C$25:$C$34,MATCH(I19,$A$25:$A$34,1))+(I19-INDEX($A$25:$A$34,MATCH(I19,$A$25:$A$34,1)))*(INDEX($C$25:$C$34,MATCH(I19,$A$25:$A$34,1)+1)-INDEX($C$25:$C$34,MATCH(I19,$A$25:$A$34,1)))/(INDEX($A$25:$A$34,MATCH(I19,$A$25:$A$34,1)+1)-INDEX($A$25:$A$34,MATCH(I19,$A$25:$A$34,1))))) -> 0.40592627 | AH19: =MATCH(I19,$A$25:$A$34,1) -> 2
A20: =DADOS!B14 -> ESCRITÓRIO | B20: =DADOS!D14 -> 8.12 | C20: =DADOS!E14 -> 6 | D20: =DADOS!F14 -> 48.72 | E20: =DADOS!G14 -> 28.24 | F20: =DADOS!C14 -> 0.8 | G20: =DADOS!K14 -> 3 | H20: =G20-F20 -> 2.2 | I20: =D20/(H20*(B20+C20)) -> 1.568375 | J20: =IF(OR(DADOS!H14="BRANCO",DADOS!H14="CLARO"),70,70) -> 70 | K20: =IF(OR(DADOS!I14="CLARA",DADOS!I14="BRANCA"),50,IF(DADOS!I14="BEGE",45,50)) -> 45 | L20: =10 -> 10 | M20: =250 -> 250 | N20: =IF(K20>=50,AF20,IF(K20<=30,AG20,AG20+(K20-30)*(AF20-AG20)/20)) -> 0.6020725 | O20: =$D$12 -> 0.75 | P20: =(M20*D20)/(N20*O20) -> 26973.496 | Q20: =$D$8 -> 3000 | R20: =$D$7 -> 2 | S20: =P20/(Q20*R20) -> 4.4955827 | T20: =ROUNDUP(S20,0) -> 5 | U20: =$D$9 -> 40 | V20: =$D$10 -> 24.1 | W20: =T20*(R20*U20+V20) -> 520.5 | X20: =$D$11 -> 0.9 | Y20: =W20/X20 -> 578.33333 | Z20: =Y20/$D$13 -> 2.6287879 | AA20: =(T20*R20*Q20*N20*O20)/D20 -> 278.05072 | AB20: =IF(AA20>=M20,"OK","REVISAR") -> OK | AC20: ="QDL5" -> QDL5 | AF20: =IF(I20<=$A$25,$B$25,IF(I20>=$A$34,$B$34,INDEX($B$25:$B$34,MATCH(I20,$A$25:$A$34,1))+(I20-INDEX($A$25:$A$34,MATCH(I20,$A$25:$A$34,1)))*(INDEX($B$25:$B$34,MATCH(I20,$A$25:$A$34,1)+1)-INDEX($B$25:$B$34,MATCH(I20,$A$25:$A$34,1)))/(INDEX($A$25:$A$34,MATCH(I20,$A$25:$A$34,1)+1)-INDEX($A$25:$A$34,MATCH(I20,$A$25:$A$34,1))))) -> 0.6195725 | AG20: =IF(I20<=$A$25,$C$25,IF(I20>=$A$34,$C$34,INDEX($C$25:$C$34,MATCH(I20,$A$25:$A$34,1))+(I20-INDEX($A$25:$A$34,MATCH(I20,$A$25:$A$34,1)))*(INDEX($C$25:$C$34,MATCH(I20,$A$25:$A$34,1)+1)-INDEX($C$25:$C$34,MATCH(I20,$A$25:$A$34,1)))/(INDEX($A$25:$A$34,MATCH(I20,$A$25:$A$34,1)+1)-INDEX($A$25:$A$34,MATCH(I20,$A$25:$A$34,1))))) -> 0.5495725 | AH20: =MATCH(I20,$A$25:$A$34,1) -> 5
A23: TABELA 2.9 - TMS 426 | FATOR DE UTILIZACAO Fu
A24: K | B24: Fu teto 70% / parede 50% | C24: Fu teto 70% / parede 30% | AF24: Fu 70/50 inferior | AG24: Fu 70/30 inferior | AH24: Indice tabela
A25: 0.6 | B25: 0.35 | C25: 0.28
A26: 0.8 | B26: 0.43 | C26: 0.36
A27: 1 | B27: 0.5 | C27: 0.42
A28: 1.25 | B28: 0.56 | C28: 0.49
A29: 1.5 | B29: 0.61 | C29: 0.54
A30: 2 | B30: 0.68 | C30: 0.61
A31: 2.5 | B31: 0.72 | C31: 0.67
A32: 3 | B32: 0.76 | C32: 0.71
A33: 4 | B33: 0.8 | C33: 0.76
A34: 5 | B34: 0.83 | C34: 0.8
A37: RESUMO DE CARGAS DE ILUMINACAO
A38: QDL | B38: Ambientes | C38: Luminarias | D38: Potencia total [W] | E38: Potencia aparente [VA] | F38: Corrente [A] | G38: Area total [m2]
A39: ="QDL5" -> QDL5 | B39: ="Escritorio" -> Escritorio | C39: =SUMIF($AC$17:$AC$20,A39,$T$17:$T$20) -> 5 | D39: =SUMIF($AC$17:$AC$20,A39,$W$17:$W$20) -> 520.5 | E39: =SUMIF($AC$17:$AC$20,A39,$Y$17:$Y$20) -> 578.33333 | F39: =SUMIF($AC$17:$AC$20,A39,$Z$17:$Z$20) -> 2.6287879 | G39: =SUMIF($AC$17:$AC$20,A39,$D$17:$D$20) -> 48.72
A40: ="QDL6" -> QDL6 | B40: ="Sala de Produtos + Controle de Qualidade" -> Sala de Produtos + Controle de Qualidade | C40: =SUMIF($AC$17:$AC$20,A40,$T$17:$T$20) -> 9 | D40: =SUMIF($AC$17:$AC$20,A40,$W$17:$W$20) -> 936.9 | E40: =SUMIF($AC$17:$AC$20,A40,$Y$17:$Y$20) -> 1041 | F40: =SUMIF($AC$17:$AC$20,A40,$Z$17:$Z$20) -> 4.7318182 | G40: =SUMIF($AC$17:$AC$20,A40,$D$17:$D$20) -> 60
A41: ="QDL7" -> QDL7 | B41: ="Banheiro / Vestiario" -> Banheiro / Vestiario | C41: =SUMIF($AC$17:$AC$20,A41,$T$17:$T$20) -> 2 | D41: =SUMIF($AC$17:$AC$20,A41,$W$17:$W$20) -> 208.2 | E41: =SUMIF($AC$17:$AC$20,A41,$Y$17:$Y$20) -> 231.33333 | F41: =SUMIF($AC$17:$AC$20,A41,$Z$17:$Z$20) -> 1.0515152 | G41: =SUMIF($AC$17:$AC$20,A41,$D$17:$D$20) -> 18.305
A42: TOTAL | C42: =SUM(C39:C41) -> 16 | D42: =SUM(D39:D41) -> 1665.6 | E42: =SUM(E39:E41) -> 1850.6667 | F42: =SUM(F39:F41) -> 8.4121212 | G42: =SUM(G39:G41) -> 127.025

Sheet LUM-SALA CALD
A1: DADOS DO LOCAL
A2: LOCAL | B2: LARGURA L (m) | C2: COMPRIMENTO C (m) | D2: ALTURA DE MANUSEIO TRABALHO Hpp (m) | E2: ALTURA TOTAL/PÉ-DIREITO Htp (m) | F2: ALTURA UTIL/ ALTURA DE TRABALHO Hlp (m) | G2: TETO | H2: PAREDE | I2: PISO | J2: LAMPADA UTILIZADA
A3: SALA DE CALDEIRA | B3: =DADOS!D3 -> 15.92 | C3: =DADOS!E3 -> 9.6 | D3: =DADOS!C3 -> 0.8 | E3: =DADOS!K3 -> 7 | F3: =E3-D3 -> 6.2 | G3: =DADOS!H3 -> ZINCO | H3: =DADOS!I3 -> CLARA | I3: =DADOS!J3 -> CONCRETO | J3: VAPOR DE METAL
A6: MÉTODO LUMENS
A10: ILUMINAMENTO
A13: CARACTERÍSTICAS DA TAREFA E DO OBSERVADOR ADOTADOS
A14: IDADE | B14: 41
A15: VELOCIDADE E PRECISÃO | B15: IMPORTANTE
A16: REFLETANCIA NO FUNDO DA TAREFA | B16: 0.4
A17: CALCULO DE PESO | B17: 0
A21: FAIXAS, ILUMINANCIAS E TIPO DE ATIVIDADE ADOTADOS
A22: ADOTADA A FAIXA B | B22: TAREFAS COM REQUISITOS VISUAIS LIMITADOS...
A23: ILUMINÂNCIAS (LUX) | B23: 300
A26: ILUMINÂNCIA MINIMA EM LUX, POR TIPO DE ATIVIDADE ADOTADO
A27: TIPO DE AMBIENTE | B27: LUX
A28: INDÚSTRIA QUIMICA
A29: FORNOS, SECADORES | B29: 200
A31: ADOTADO NO FINAL O MAIOR VALOR QUE É 300 lx
A33: ILUMINÂNCIAS (LUX) | B33: 300
A71: LUMINÁRIA ADOTADA
A73: SALA DE CALDEIRAS POSSUEM ELEVADO PÉ-DIREITO, LUMINÁRIA ADEQUADA PARA ESSE AMBIENTE SÃO TIPO REFLETOR INDUSTRIAL ESTILO CUPULA
A75: DADOS LUMINÁRIA
A76: MODELO | B76: HDK 472+GDK 474 PG
A77: FABRICANTE | B77: Philips
A88: LAMPADA E REATOR ADOTADOS
A89: Podendo ser adotados lampadas de até 400 W, conforme a luminária adotada
A91: DADOS DA LAMPADA
A92: MODELO | B92: MASTER HPI-T Plus 400W/645 E40 1SL/12
A93: FABRICANTE | B93: Philips
A94: TIPO DE LAMPADA | B94: VAPOR METALICO
A95: POTÊNCIA (W) | B95: 400
A96: FLUXO LUMINOSO (lumens) | B96: 33200
A97: NUMERO DE LAMPADAS POR LUMINARIA | B97: 1
A100: DADOS DO REATOR
A101: MODELO | B101: BHLE 400L 200TS
A102: FABRICANTE | B102: Philips
A103: PERDAS (W) | B103: 27.5
A104: FATOR DE POTENCIA | B104: 0.85
A106: De forma a calcular o fluxo luminoso se deve calcular o FATOR DE UTILIZAÇÃO e FATOR DE DEPRECIAÇÃO
A108: FATOR DE UTILIZAÇÃO Fu
...

Sheet LUM-COM(B,P)
A1: DADOS DO LOCAL
A2: LOCAL | B2: LARGURA L (m) | C2: COMPRIMENTO C (m) | D2: ALTURA DE MANUSEIO TRABALHO Hpp (m) | E2: ALTURA TOTAL/PÉ-DIREITO Htp (m) | F2: ALTURA UTIL/ ALTURA DE TRABALHO Hlp (m) | G2: TETO | H2: PAREDE | I2: PISO | J2: LAMPADA UTILIZADA
A3: COMPRESSOR (BOMBAS E PRENSA) | B3: =DADOS!D4 -> 9.28 | C3: =DADOS!E4 -> 9.6 | D3: =DADOS!C4 -> 0.8 | E3: =DADOS!K4 -> 7 | F3: =E3-D3 -> 6.2 | G3: =DADOS!H4 -> ZINCO | H3: =DADOS!I4 -> CLARA | I3: =DADOS!J4 -> CONCRETO | J3: VAPOR DE METAL
A6: MÉTODO LUMENS
A10: ILUMINAMENTO
A13: CARACTERÍSTICAS DA TAREFA E DO OBSERVADOR ADOTADOS
A14: IDADE | B14: 41
A15: VELOCIDADE E PRECISÃO | B15: IMPORTANTE
A16: REFLETANCIA NO FUNDO DA TAREFA | B16: 0.4
A17: CALCULO DE PESO | B17: 0
A21: FAIXAS, ILUMINANCIAS E TIPO DE ATIVIDADE ADOTADOS
A22: ADOTADA A FAIXA B | B22: TAREFAS COM REQUISITOS VISUAIS NORMAIS...
A23: ILUMINÂNCIAS (LUX) | B23: 750
A71: LUMINÁRIA ADOTADA
A73: COMPRESSOR(B,P) POSSUEM ELEVADO PÉ-DIREITO, LUMINÁRIA ADEQUADA PARA ESSE AMBIENTE SÃO TIPO REFLETOR INDUSTRIAL ESTILO CUPULA
A75: DADOS LUMINÁRIA
A76: MODELO | B76: HDK 472+GDK 474 PG
A77: FABRICANTE | B77: Philips
A88: LAMPADA E REATOR ADOTADOS
A89: Podendo ser adotados lampadas de até 400 W, conforme a luminária adotada
A91: DADOS DA LAMPADA
A92: MODELO | B92: MASTER HPI-T Plus 400W/645 E40 1SL/12
A93: FABRICANTE | B93: Philips
A94: TIPO DE LAMPADA | B94: VAPOR METALICO
A95: POTÊNCIA (W) | B95: 400
A96: FLUXO LUMINOSO (lumens) | B96: 33200
A97: NUMERO DE LAMPADAS POR LUMINARIA | B97: 1
A100: DADOS DO REATOR
A101: MODELO | B101: BHLE 400L 200TS
A102: FABRICANTE | B102: Philips
A103: PERDAS (W) | B103: 27.5
A104: FATOR DE POTENCIA | B104: 0.85
A106: De forma a calcular o fluxo luminoso se deve calcular o FATOR DE UTILIZAÇÃO e FATOR DE DEPRECIAÇÃO
A108: FATOR DE UTILIZAÇÃO Fu
A109: DEVE-SE SEGUIR A FORMULA ABAIXO
A112: K | B112: =(C3*B3)/(F3*(C3+B3)) -> 0.76107162
A115: VERIFICA NO LIVRO DO MAMEDE AS REFLETANCIAS
A117: POR MEIO DO VALOR DE K, USA A TABELA PARA ACHAR CONHECENDO AS REFLENTACIAS MÉDIAS DO TETO Pte, DAs PAREDES Ppa, do PISO Ppi, VAI NA TABELA E PEGA OS VALORES
A119: TETO | B119: =G3 -> ZINCO
A120: PAREDE | B120: =H3 -> CLARA
...

Sheet LUM-DEP CAR1
A1: DADOS DO LOCAL
A2: LOCAL | B2: LARGURA L (m) | C2: COMPRIMENTO C (m) | D2: ALTURA DE MANUSEIO TRABALHO Hpp (m) | E2: ALTURA TOTAL/PÉ-DIREITO Htp (m) | F2: ALTURA UTIL/ ALTURA DE TRABALHO Hlp (m) | G2: TETO | H2: PAREDE | I2: PISO | J2: LAMPADA UTILIZADA
A3: DEPÓSITO DE CARCAÇAS 1 | B3: =DADOS!D5 -> 8.12 | C3: =DADOS!E5 -> 6 | D3: =DADOS!C5 -> 0.8 | E3: =DADOS!K5 -> 7 | F3: =E3-D3 -> 6.2 | G3: =DADOS!H5 -> ZINCO | H3: =DADOS!I5 -> CLARA | I3: =DADOS!J5 -> CONCRETO | J3: VAPOR DE METAL
A6: MÉTODO LUMENS
A10: ILUMINAMENTO
A13: CARACTERÍSTICAS DA TAREFA E DO OBSERVADOR ADOTADOS
A15: IDADE | B15: 41
A16: VELOCIDADE E PRECISÃO | B16: IMPORTANTE
A17: REFLETANCIA NO FUNDO DA TAREFA | B17: 0.4
A18: CALCULO DE PESO | B18: 0
A21: FAIXAS, ILUMINANCIAS E TIPO DE ATIVIDADE ADOTADOS
A22: ADOTADA A FAIXA B | B22: TAREFAS COM REQUISITOS VISUAIS LIMITADOS...
A23: ILUMINÂNCIAS (LUX) | B23: 300
A26: ILUMINÂNCIA MINIMA EM LUX, POR TIPO DE ATIVIDADE ADOTADO
A27: TIPO DE AMBIENTE | B27: LUX
A28: LOCAIS DE ARMAZENAMENTO
A29: GRANDES VOLUMES | B29: 200
A31: ADOTADO NO FINAL O MAIOR VALOR QUE É 300 lx
A33: ILUMINÂNCIAS (LUX) | B33: 300
A71: LUMINÁRIA ADOTADA
A73: COMPRESSOR(B,P) POSSUEM ELEVADO PÉ-DIREITO, LUMINÁRIA ADEQUADA PARA ESSE AMBIENTE SÃO TIPO REFLETOR INDUSTRIAL ESTILO CUPULA
A75: DADOS LUMINÁRIA
A76: MODELO | B76: HDK 472+GDK 474 PG
A77: FABRICANTE | B77: Philips
A88: LAMPADA E REATOR ADOTADOS
A89: Podendo ser adotados lampadas de até 400 W, conforme a luminária adotada
A91: DADOS DA LAMPADA
A92: MODELO | B92: MASTER HPI-T Plus 400W/645 E40 1SL/12
A93: FABRICANTE | B93: Philips
A94: TIPO DE LAMPADA | B94: VAPOR METALICO
A95: POTÊNCIA (W) | B95: 400
A96: FLUXO LUMINOSO (lumens) | B96: 33200
A97: NUMERO DE LAMPADAS POR LUMINARIA | B97: 1
A100: DADOS DO REATOR
A101: MODELO | B101: BHLE 400L 200TS
A102: FABRICANTE | B102: Philips
A103: PERDAS (W) | B103: 27.5
A104: FATOR DE POTENCIA | B104: 0.85
A106: De forma a calcular o fluxo luminoso se deve calcular o FATOR DE UTILIZAÇÃO e FATOR DE DEPRECIAÇÃO
A108: FATOR DE UTILIZAÇÃO Fu
...

Sheet LUM-DEP CAR2
A1: DADOS DO LOCAL
A2: LOCAL | B2: LARGURA L (m) | C2: COMPRIMENTO C (m) | D2: ALTURA DE MANUSEIO TRABALHO Hpp (m) | E2: ALTURA TOTAL/PÉ-DIREITO Htp (m) | F2: ALTURA UTIL/ ALTURA DE TRABALHO Hlp (m) | G2: TETO | H2: PAREDE | I2: PISO | J2: LAMPADA UTILIZADA
A3: DEPÓSITO DE CARCAÇAS 2 | B3: =DADOS!D6 -> 11.18 | C3: =DADOS!E6 -> 9.6 | D3: =DADOS!C6 -> 0.8 | E3: =DADOS!K6 -> 7 | F3: =E3-D3 -> 6.2 | G3: =DADOS!H6 -> ZINCO | H3: =DADOS!I6 -> CLARA | I3: =DADOS!J6 -> CONCRETO | J3: VAPOR DE METAL
A6: MÉTODO LUMENS
A10: ILUMINAMENTO
A13: CARACTERÍSTICAS DA TAREFA E DO OBSERVADOR ADOTADOS
A15: IDADE | B15: 41
A16: VELOCIDADE E PRECISÃO | B16: IMPORTANTE
A17: REFLETANCIA NO FUNDO DA TAREFA | B17: 0.4
A18: CALCULO DE PESO | B18: 0
A21: FAIXAS, ILUMINANCIAS E TIPO DE ATIVIDADE ADOTADOS
A22: ADOTADA A FAIXA B | B22: TAREFAS COM REQUISITOS VISUAIS LIMITADOS...
A23: ILUMINÂNCIAS (LUX) | B23: 300
A26: ILUMINÂNCIA MINIMA EM LUX, POR TIPO DE ATIVIDADE ADOTADO
A27: TIPO DE AMBIENTE | B27: LUX
A28: LOCAIS DE ARMAZENAMENTO
A29: GRANDES VOLUMES | B29: 200
A31: ADOTADO NO FINAL O MAIOR VALOR QUE É 300 lx
A33: ILUMINÂNCIAS (LUX) | B33: 300
A71: LUMINÁRIA ADOTADA
A73: COMPRESSOR(B,P) POSSUEM ELEVADO PÉ-DIREITO, LUMINÁRIA ADEQUADA PARA ESSE AMBIENTE SÃO TIPO REFLETOR INDUSTRIAL ESTILO CUPULA
A75: DADOS LUMINÁRIA
A76: MODELO | B76: HDK 472+GDK 474 PG
A77: FABRICANTE | B77: Philips
A88: LAMPADA E REATOR ADOTADOS
A89: Podendo ser adotados lampadas de até 400 W, conforme a luminária adotada
A91: DADOS DA LAMPADA
A92: MODELO | B92: MASTER HPI-T Plus 400W/645 E40 1SL/12
A93: FABRICANTE | B93: Philips
A94: TIPO DE LAMPADA | B94: VAPOR METALICO
A95: POTÊNCIA (W) | B95: 400
A96: FLUXO LUMINOSO (lumens) | B96: 33200
A97: NUMERO DE LAMPADAS POR LUMINARIA | B97: 1
A100: DADOS DO REATOR
A101: MODELO | B101: BHLE 400L 200TS
A102: FABRICANTE | B102: Philips
A103: PERDAS (W) | B103: 27.5
A104: FATOR DE POTENCIA | B104: 0.85
A106: De forma a calcular o fluxo luminoso se deve calcular o FATOR DE UTILIZAÇÃO e FATOR DE DEPRECIAÇÃO
A108: FATOR DE UTILIZAÇÃO Fu
...

Sheet LUM-RASPA
A1: DADOS DO LOCAL
A2: LOCAL | B2: LARGURA L (m) | C2: COMPRIMENTO C (m) | D2: ALTURA DE MANUSEIO TRABALHO Hpp (m) | E2: ALTURA TOTAL/PÉ-DIREITO Htp (m) | F2: ALTURA UTIL/ ALTURA DE TRABALHO Hlp (m) | G2: TETO | H2: PAREDE | I2: PISO | J2: LAMPADA UTILIZADA
A3: RASPA | B3: =DADOS!D7 -> 8.12 | C3: =DADOS!E7 -> 30.92 | D3: =DADOS!C7 -> 0.8 | E3: =DADOS!K7 -> 7 | F3: =E3-D3 -> 6.2 | G3: =DADOS!H7 -> ZINCO | H3: =DADOS!I7 -> CLARA | I3: =DADOS!J7 -> CONCRETO | J3: VAPOR DE METAL
A6: MÉTODO LUMENS
A10: ILUMINAMENTO
A13: CARACTERÍSTICAS DA TAREFA E DO OBSERVADOR ADOTADOS
A14: IDADE | B14: 41
A15: VELOCIDADE E PRECISÃO | B15: IMPORTANTE
A16: REFLETANCIA NO FUNDO DA TAREFA | B16: 0.4
A17: CALCULO DE PESO | B17: 0
A21: FAIXAS, ILUMINANCIAS E TIPO DE ATIVIDADE ADOTADOS
A22: ADOTADA A FAIXA B | B22: TAREFAS COM REQUISITOS VISUAIS NORMAIS...
A23: ILUMINÂNCIAS (LUX) | B23: 750
A33: ILUMINÂNCIAS (LUX) | B33: 750
A71: LUMINÁRIA ADOTADA
A73: SALA DE CALDEIRAS POSSUEM ELEVADO PÉ-DIREITO, LUMINÁRIA ADEQUADA PARA ESSE AMBIENTE SÃO TIPO REFLETOR INDUSTRIAL ESTILO CUPULA
A75: DADOS LUMINÁRIA
A76: MODELO | B76: HDK 472+GDK 474 PG
A77: FABRICANTE | B77: Philips
A88: LAMPADA E REATOR ADOTADOS
A89: Podendo ser adotados lampadas de até 400 W, conforme a luminária adotada
A91: DADOS DA LAMPADA
A92: MODELO | B92: MASTER HPI-T Plus 400W/645 E40 1SL/12
A93: FABRICANTE | B93: Philips
A94: TIPO DE LAMPADA | B94: VAPOR METALICO
A95: POTÊNCIA (W) | B95: 400
A96: FLUXO LUMINOSO (lumens) | B96: 33200
A97: NUMERO DE LAMPADAS POR LUMINARIA | B97: 1
A100: DADOS DO REATOR
A101: MODELO | B101: BHLE 400L 200TS
A102: FABRICANTE | B102: Philips
A103: PERDAS (W) | B103: 27.5
A104: FATOR DE POTENCIA | B104: 0.85
A106: De forma a calcular o fluxo luminoso se deve calcular o FATOR DE UTILIZAÇÃO e FATOR DE DEPRECIAÇÃO
A108: FATOR DE UTILIZAÇÃO Fu
A109: DEVE-SE SEGUIR A FORMULA ABAIXO
A112: K | B112: =(C3*B3)/(F3*(C3+B3)) -> 1.0372753
A115: VERIFICA NO LIVRO DO MAMEDE AS REFLETANCIAS
A117: POR MEIO DO VALOR DE K, USA A TABELA PARA ACHAR CONHECENDO AS REFLENTACIAS MÉDIAS DO TETO Pte, DAs PAREDES Ppa, do PISO Ppi, VAI NA TABELA E PEGA OS VALORES
A119: TETO | B119: =G3 -> ZINCO
...

Sheet RECAPAGEM
A1: DADOS DO LOCAL
B3: LOCAL | C3: LARGURA L (m) | D3: COMPRIMENTO C (m) | E3: ÁREA (m²) | F3: PERÍMETRO (m) | G3: ALTURA DE MANUSEIO TRABALHO Hpp (m) | H3: TETO | I3: PAREDE | J3: PISO | K3: ALTURA TOTAL/PÉ-DIREITO Htp (m) | L3: VELOCIDADE E PRECISÃO | M3: REFLETANCIA DO FUNDO DA TAREFA | N3: IDADE MÉDIA DOS TRABALHADORES | O3: ALTURA MÍNIIMA | P3: TIRANTE
B4: RECAPAGEM 1 | C4: 5 | D4: 30.9 | E4: =D4*C4 -> 154.5 | F4: =(2*D4)+(2*C4) -> 71.8 | G4: 0.8 | H4: ZINCO | I4: CLARA | J4: CONCRETO | K4: 7 | L4: IMPORTANTE | M4: 0.4 | N4: 41 ANOS | O4: 4 | P4: 1
B5: RECAPAGEM 2 | C5: 5.23 | D5: 39.25 | E5: =D5*C5 -> 205.2775 | F5: =(2*D5)+(2*C5) -> 88.96
B6: RECAPAGEM 3 | C6: 27.95 | D6: 43.37 | E6: =D6*C6 -> 1212.1915 | F6: =(2*D6)+(2*C6) -> 142.64
A35: LUMINÁRIA
J43: MODELO | K43: HDK 472
J44: FABRICANTE | K44: PHILLIPS
A54: LÂMPADA+REATOR
D57: MODELO | G57: MODELO
D58: FABRICANTE | G58: FABRICANTE
A68: CAVIDADES
I70: refletâncias | L70: Refletâncias Efetivas tab 2.11 – Mamede
B71: relação de cavidade | F71: recinto | G71: teto | H71: piso | I71: teto | J71: piso | K71: parede | M71: 0.1
B72: K | C72: Hlp | D72: Htl | E72: Hpp | F72: Rcr | G72: Rct | H72: Rcp | I72: ρte | J72: ρpi | K72: ρpa | L72: ρcp | M72: ρct(1) | N72: para teto de 50% | O72: para teto de 70%
B73: =(5*(D4+C4))/(D4*C4) -> 1.1618123 | C73: =K4-P4-G4 -> 5.2 | D73: =P4 -> 1 | E73: =G4 -> 0.8 | F73: =B73*C73 -> 6.0414239 | G73: =B73*D73 -> 1.1618123 | H73: =B73*E73 -> 0.92944984 | I73: 0.1 | J73: 0.1 | K73: 0.5 | L73: 11 | M73: 11 | N73: 43 | O73: 59
B74: =(5*(D5+C5))/(D5*C5) -> 1.0834115 | C74: =K4-P4-G4 -> 5.2 | D74: =P4 -> 1 | E74: =G4 -> 0.8 | F74: =B74*C74 -> 5.6337397 | G74: =B74*D74 -> 1.0834115 | H74: =B74*E74 -> 0.86672918 | L74: 11 | M74: 11 | N74: 43 | O74: 59
B75: =(5*(D6+C6))/(D6*C6) -> 0.29417794 | C75: =K4-P4-G4 -> 5.2 | D75: =P4 -> 1 | E75: =G4 -> 0.8 | F75: =B75*C75 -> 1.5297253 | G75: =B75*D75 -> 0.29417794 | H75: =B75*E75 -> 0.23534235 | L75: 10 | M75: 10 | N75: 48 | O75: 67
A95: FATOR DE UTILIZAÇÃO
H96: tab 2.12 – Mamede
A98: Dados de Entrada | B98: RECAPAGEM 1 | E98: RECAPAGEM 2 | H98: RECAPAGEM 3
B99: Rcr=6 | C99: Rcr=7 | D99: =F73 -> 6.0414239 | E99: Rcr=5 | F99: Rcr=6 | G99: =F74 -> 5.6337397 | H99: Rcr=1 | I99: Rcr=2 | J99: =F75 -> 1.5297253
A100: k 1 | B100: 10 | C100: 10 | D100: 7 | E100: 10 | F100: 10 | G100: 6 | H100: 10 | I100: 10 | J100: 2
A101: k 2 | B101: 50 | C101: 50 | D101: 6 | E101: 50 | F101: 50 | G101: 5 | H101: 50 | I101: 50 | J101: 1
A102: Fu 1 | B102: 0.44 | C102: 0.41 | D102: =B108 -> 0.4595 | E102: 0.47 | F102: 0.44 | G102: =E108 -> 0.47075 | H102: 0.67 | I102: 0.61 | J102: =H108 -> 0.67125
A103: Fu 2 | B103: 0.46 | C103: 0.43 | D103: =C108 -> 0.4295 | E103: 0.5 | F103: 0.46 | G103: =F108 -> 0.4405 | H103: 0.72 | I103: 0.65 | J103: =I108 -> 0.611
A104: k encontrado | B104: =M73 -> 11 | C104: =B104 -> 11 | D104: =D99 -> 6.0414239 | E104: =M74 -> 11 | F104: =E104 -> 11 | G104: =G99 -> 5.6337397 | H104: =M73 -> 11 | I104: =H104 -> 11 | J104: =J99 -> 1.5297253
A105: denominador 1 | B105: =B101-B100 -> 40 | C105: =C101-C100 -> 40 | D105: =D101-D100 -> -1 | E105: =E101-E100 -> 40 | F105: =F101-F100 -> 40 | G105: =G101-G100 -> -1 | H105: =H101-H100 -> 40 | I105: =I101-I100 -> 40 | J105: =J101-J100 -> -1
A106: denominador 2 | B106: =B104-B100 -> 1 | C106: =C104-C100 -> 1 | D106: =D101-D104 -> -0.041423948 | E106: =E101-E104 -> 39 | F106: =F101-F104 -> 39 | G106: =G101-G104 -> -0.63373969 | H106: =H101-H104 -> 39 | I106: =I101-I104 -> 39 | J106: =J101-J104 -> -0.5297253
A107: numerador 1 | B107: =B103-B102 -> 0.02 | C107: =C103-C102 -> 0.02 | D107: =D102-D103 -> 0.03 | E107: =E103-E102 -> 0.03 | F107: =F103-F102 -> 0.02 | G107: =G102-G103 -> 0.03025 | H107: =H103-H102 -> 0.05 | I107: =I103-I102 -> 0.04 | J107: =J102-J103 -> 0.06025
A108: FU calculado | B108: =((B103*B105)-(B107*B106))/(B105) -> 0.4595 | C108: =((C103*C105)-(C107*C106))/(C105) -> 0.4295 | D108: =((D103*D105)-(D107*D106))/(D105) -> 0.42825728 | E108: =((E103*E105)-(E107*E106))/(E105) -> 0.47075 | F108: =((F103*F105)-(F107*F106))/(F105) -> 0.4405 | G108: =((G103*G105)-(G107*G106))/(G105) -> 0.42132937 | H108: =((H103*H105)-(H107*H106))/(H105) -> 0.67125 | I108: =((I103*I105)-(I107*I106))/(I105) -> 0.611 | J108: =((J103*J105)-(J107*J106))/(J105) -> 0.57908405

Sheet SUBESTAÇÃO
A1: DADOS DO LOCAL
A2: LOCAL | B2: LARGURA L (m) | C2: COMPRIMENTO C (m) | D2: ALTURA DE MANUSEIO TRABALHO Hpp (m) | E2: ALTURA TOTAL/PÉ-DIREITO Htp (m) | F2: ALTURA UTIL/ ALTURA DE TRABALHO Hlp (m) | G2: TETO | H2: PAREDE | I2: PISO | J2: LAMPADA UTILIZADA
A3: SUBESTAÇÃO | B3: =DADOS!D15 -> 9.6 | C3: =DADOS!E15 -> 9.8 | D3: =DADOS!C15 -> 0.8 | E3: =DADOS!K15 -> 7 | F3: =E3-D3 -> 6.2 | G3: =DADOS!H15 -> BRANCO | H3: =DADOS!I15 -> BRANCA | I3: =DADOS!J15 -> CONCRETO | J3: MISTA
A6: MÉTODO LUMENS
A8: ILUMINAMENTO
A11: CARACTERÍSTICAS DA TAREFA E DO OBSERVADOR ADOTADOS
A12: IDADE | B12: 41
A13: VELOCIDADE E PRECISÃO | B13: IMPORTANTE
A14: REFLETANCIA NO FUNDO DA TAREFA | B14: 0.4
A15: CALCULO DE PESO | B15: 0
A17: FAIXAS, ILUMINANCIAS E TIPO DE ATIVIDADE ADOTADOS
A18: ADOTADA A FAIXA B | B18: TAREFAS COM REQUISITOS VISUAIS LIMITADOS
A19: ILUMINÂNCIAS (LUX) | B19: 200
A51: LUMINÁRIA ADOTADA
A53: SUBESTAÇÃO NÃO PODE TER LUMINÁRIAS NO TETO, APENAS NAS PAREDES E FORA DAS CABINES DE TRANSFORMADORES - NECESSÁRIO QUE FOSSE ARANDELA ANTI-EXPLOSÃO
A55: DADOS LUMINÁRIA
A56: MODELO | B56: FLW 17/3-MI5500
A57: FABRICANTE | B57: Comercial EX
A68: LAMPADA E REATOR ADOTADOS
A69: Podendo ser adotados lampadas de até 400 W, conforme a luminária adotada
A71: DADOS DA LAMPADA
A72: MODELO | B72: PEGO DOS PDFs disponibilizados
A73: FABRICANTE
A74: TIPO DE LAMPADA | B74: MISTA | E74: https://www.eletricasantaefigenia.com.br/lampada-mista-500w-/prod-10645297/
A75: POTÊNCIA (W) | B75: 500
A76: FLUXO LUMINOSO (lumens) | B76: 32000
A77: NUMERO DE LAMPADAS POR LUMINARIA | B77: 1
A80: DADOS DO REATOR (não possui reator)
A81: MODELO
A82: FABRICANTE
A83: PERDAS (W)
A84: FATOR DE POTENCIA
A86: De forma a calcular o fluxo luminoso se deve calcular o FATOR DE UTILIZAÇÃO e FATOR DE DEPRECIAÇÃO
A88: FATOR DE UTILIZAÇÃO Fu
A89: DEVE-SE SEGUIR A FORMULA ABAIXO
A92: K | B92: =(C3*B3)/(F3*(C3+B3)) -> 0.78217493
A95: VERIFICA NO LIVRO DO MAMEDE AS REFLETANCIAS
A97: POR MEIO DO VALOR DE K, USA A TABELA PARA ACHAR CONHECENDO AS REFLENTACIAS MÉDIAS DO TETO Pte, DAs PAREDES Ppa, do PISO Ppi, VAI NA TABELA E PEGA OS VALORES
A99: TETO | B99: =G3 -> BRANCO
A100: PAREDE | B100: =H3 -> BRANCA
...
