Workbook

Sheet DADOS
A2: RESPONSÁVEL | B2: LOCAL | C2: ALTURA DE MANUSEIO TRABALHO Hpp (m) | D2: LARGURA L (m) | E2: COMPRIMENTO C (m) | F2: ÁREA (m²) | G2: PERÍMETRO (m) | H2: TETO | I2: PAREDE | J2: PISO | K2: ALTURA TOTAL/PÉ-DIREITO Htp (m)
A3: DANTE | B3: SALA DE CALDEIRAS | C3: 0.8 | D3: 15.92 | E3: 9.6 | F3: =E3*D3 -> 152.832 | G3: =(2*E3)+(2*D3) -> 51.04 | H3: ZINCO | I3: CLARA | J3: CONCRETO | K3: 7
A4: DANTE | B4: COMPRESSOR (BOMBAS E PRENSA) | C4: 0.8 | D4: 9.28 | E4: 9.6 | F4: =E4*D4 -> 89.088 | G4: =(2*E4)+(2*D4) -> 37.76 | H4: ZINCO | I4: CLARA | J4: CONCRETO | K4: 7
A5: DANTE | B5: DEPÓSITO DE CARCAÇAS 1 | C5: 0.8 | D5: 8.12 | E5: 6 | F5: =E5*D5 -> 48.72 | G5: =2*E5+2*D5 -> 28.24 | H5: ZINCO | I5: CLARA | J5: CONCRETO | K5: 7
A6: DANTE | B6: DEPÓSITO DE CARCAÇAS 2 | C6: 0.8 | D6: 11.18 | E6: 9.6 | F6: =E6*D6 -> 107.328 | G6: =2*E6+2*D6 -> 41.56 | H6: ZINCO | I6: CLARA | J6: CONCRETO | K6: 7
A7: DANTE | B7: RASPA | C7: 0.8 | D7: 8.12 | E7: 30.92 | F7: =E7*D7 -> 251.0704 | G7: =(2*E7)+(2*D7) -> 78.08 | H7: ZINCO | I7: CLARA | J7: CONCRETO | K7: 7
A8: PIETRO | B8: RECAPAGEM 1 | C8: 0.8 | D8: 5 | E8: 30.9 | F8: =E8*D8 -> 154.5 | G8: =(2*E8)+(2*D8) -> 71.8 | H8: ZINCO | I8: CLARA | J8: CONCRETO | K8: 7
A9: PIETRO | B9: RECAPAGEM 2 | C9: 0.8 | D9: 5.23 | E9: 39.25 | F9: =E9*D9 -> 205.2775 | G9: =(2*E9)+(2*D9) -> 88.96 | H9: ZINCO | I9: CLARA | J9: CONCRETO | K9: 7
A10: PIETRO | B10: RECAPAGEM 3 | C10: 0.8 | D10: 27.95 | E10: 43.37 | F10: =E10*D10 -> 1212.1915 | G10: =(2*E10)+(2*D10) -> 142.64 | H10: ZINCO | I10: CLARA | J10: CONCRETO | K10: 7
A11: LUCAS | B11: SAIDA DE PRODUTOS (SALA DE PRODUTOS) | C11: 0.8 | D11: 5 | E11: 6 | F11: =E11*D11 -> 30 | G11: =(2*E11)+(2*D11) -> 22 | H11: CLARO | I11: CLARA | J11: AZULEJO CINZA | K11: 3
A12: LUCAS | B12: CONTROLE DE QUALIDADE | C12: 0.8 | D12: 5 | E12: 6 | F12: =E12*D12 -> 30 | G12: =(2*E12)+(2*D12) -> 22 | H12: BRANCO | I12: BRANCA | J12: AZULEJO CINZA | K12: 3
A13: LUCAS | B13: BANHEIRO(VESTUARIO) | C13: 0.8 | D13: 5.23 | E13: 3.5 | F13: =E13*D13 -> 18.305 | G13: =(2*E13)+(2*D13) -> 17.46 | H13: CLARO | I13: CLARA | J13: AZULEJO CINZA | K13: 3
A14: LUCAS | B14: ESCRITÓRIO | C14: 0.8 | D14: 8.12 | E14: 6 | F14: =E14*D14 -> 48.72 | G14: =(2*E14)+(2*D14) -> 28.24 | H14: BRANCO | I14: BEGE | J14: AZULEJO CINZA | K14: 3
A15: JOÃO | B15: SUBESTAÇÃO | C15: 0.8 | D15: 9.6 | E15: 9.8 | F15: =D15*E15 -> 94.08 | G15: =(2*D15)+(2*E15) -> 38.8 | H15: BRANCO | I15: BRANCA | J15: CONCRETO | K15: 7

Sheet LUM-SALA CALD
A1: DADOS DO LOCAL
A2: LOCAL | B2: LARGURA L (m) | C2: COMPRIMENTO C (m) | D2: ALTURA DE MANUSEIO TRABALHO Hpp (m) | E2: ALTURA TOTAL/PÉ-DIREITO Htp (m) | F2: ALTURA UTIL/ ALTURA DE TRABALHO Hlp (m) | G2: TETO | H2: PAREDE | I2: PISO | J2: LAMPADA UTILIZADA
A3: SALA DE CALDEIRA | B3: =DADOS!D3 -> 15.92 | C3: =DADOS!E3 -> 9.6 | D3: =DADOS!C3 -> 0.8 | E3: =DADOS!K3 -> 7 | F3: =E3-D3 -> 6.2 | G3: =DADOS!H3 -> ZINCO | H3: =DADOS!I3 -> CLARA | I3: =DADOS!J3 -> CONCRETO | J3: VAPOR DE METAL
A6: MÉTODO LUMENS
A10: ILUMINAMENTO
A13: CARACTERÍSTICAS DA TAREFA E DO OBSERVADOR ADOTADOS
A14: IDADE | B14: 41
A15: VELOCIDADE E PRECISÃO | B15: IMPORTANTE
A16: REFLETANCIA NO FUNDO DA TAREFA | B16: 0.4
A17: CALCULO DE PESO | B17: 0
A21: FAIXAS, ILUMINANCIAS E TIPO DE ATIVIDADE ADOTADOS
A22: ADOTADA A FAIXA B | B22: TAREFAS COM REQUISITOS VISUAIS LIMITADOS...
A23: ILUMINÂNCIAS (LUX) | B23: 300
A26: ILUMINÂNCIA MINIMA EM LUX, POR TIPO DE ATIVIDADE ADOTADO
A27: TIPO DE AMBIENTE | B27: LUX
A28: INDÚSTRIA QUIMICA
A29: FORNOS, SECADORES | B29: 200
A31: ADOTADO NO FINAL O MAIOR VALOR QUE É 300 lx
A33: ILUMINÂNCIAS (LUX) | B33: 300
A71: LUMINÁRIA ADOTADA
A73: SALA DE CALDEIRAS POSSUEM ELEVADO PÉ-DIREITO, LUMINÁRIA ADEQUADA PARA ESSE AMBIENTE SÃO TIPO REFLETOR INDUSTRIAL ESTILO CUPULA
A75: DADOS LUMINÁRIA
A76: MODELO | B76: HDK 472+GDK 474 PG
A77: FABRICANTE | B77: Philips
A88: LAMPADA E REATOR ADOTADOS
A89: Podendo ser adotados lampadas de até 400 W, conforme a luminária adotada
A91: DADOS DA LAMPADA
A92: MODELO | B92: MASTER HPI-T Plus 400W/645 E40 1SL/12
A93: FABRICANTE | B93: Philips
A94: TIPO DE LAMPADA | B94: VAPOR METALICO
A95: POTÊNCIA (W) | B95: 400
A96: FLUXO LUMINOSO (lumens) | B96: 33200
A97: NUMERO DE LAMPADAS POR LUMINARIA | B97: 1
A100: DADOS DO REATOR
A101: MODELO | B101: BHLE 400L 200TS
A102: FABRICANTE | B102: Philips
A103: PERDAS (W) | B103: 27.5
A104: FATOR DE POTENCIA | B104: 0.85
A106: De forma a calcular o fluxo luminoso se deve calcular o FATOR DE UTILIZAÇÃO e FATOR DE DEPRECIAÇÃO
A108: FATOR DE UTILIZAÇÃO Fu
...

Sheet LUM-COM(B,P)
A1: DADOS DO LOCAL
A2: LOCAL | B2: LARGURA L (m) | C2: COMPRIMENTO C (m) | D2: ALTURA DE MANUSEIO TRABALHO Hpp (m) | E2: ALTURA TOTAL/PÉ-DIREITO Htp (m) | F2: ALTURA UTIL/ ALTURA DE TRABALHO Hlp (m) | G2: TETO | H2: PAREDE | I2: PISO | J2: LAMPADA UTILIZADA
A3: COMPRESSOR (BOMBAS E PRENSA) | B3: =DADOS!D4 -> 9.28 | C3: =DADOS!E4 -> 9.6 | D3: =DADOS!C4 -> 0.8 | E3: =DADOS!K4 -> 7 | F3: =E3-D3 -> 6.2 | G3: =DADOS!H4 -> ZINCO | H3: =DADOS!I4 -> CLARA | I3: =DADOS!J4 -> CONCRETO | J3: VAPOR DE METAL
A6: MÉTODO LUMENS
A10: ILUMINAMENTO
A13: CARACTERÍSTICAS DA TAREFA E DO OBSERVADOR ADOTADOS
A14: IDADE | B14: 41
A15: VELOCIDADE E PRECISÃO | B15: IMPORTANTE
A16: REFLETANCIA NO FUNDO DA TAREFA | B16: 0.4
A17: CALCULO DE PESO | B17: 0
A21: FAIXAS, ILUMINANCIAS E TIPO DE ATIVIDADE ADOTADOS
A22: ADOTADA A FAIXA B | B22: TAREFAS COM REQUISITOS VISUAIS NORMAIS...
A23: ILUMINÂNCIAS (LUX) | B23: 750
A71: LUMINÁRIA ADOTADA
A73: COMPRESSOR(B,P) POSSUEM ELEVADO PÉ-DIREITO, LUMINÁRIA ADEQUADA PARA ESSE AMBIENTE SÃO TIPO REFLETOR INDUSTRIAL ESTILO CUPULA
A75: DADOS LUMINÁRIA
A76: MODELO | B76: HDK 472+GDK 474 PG
A77: FABRICANTE | B77: Philips
A88: LAMPADA E REATOR ADOTADOS
A89: Podendo ser adotados lampadas de até 400 W, conforme a luminária adotada
A91: DADOS DA LAMPADA
A92: MODELO | B92: MASTER HPI-T Plus 400W/645 E40 1SL/12
A93: FABRICANTE | B93: Philips
A94: TIPO DE LAMPADA | B94: VAPOR METALICO
A95: POTÊNCIA (W) | B95: 400
A96: FLUXO LUMINOSO (lumens) | B96: 33200
A97: NUMERO DE LAMPADAS POR LUMINARIA | B97: 1
A100: DADOS DO REATOR
A101: MODELO | B101: BHLE 400L 200TS
A102: FABRICANTE | B102: Philips
A103: PERDAS (W) | B103: 27.5
A104: FATOR DE POTENCIA | B104: 0.85
A106: De forma a calcular o fluxo luminoso se deve calcular o FATOR DE UTILIZAÇÃO e FATOR DE DEPRECIAÇÃO
A108: FATOR DE UTILIZAÇÃO Fu
A109: DEVE-SE SEGUIR A FORMULA ABAIXO
A112: K | B112: =(C3*B3)/(F3*(C3+B3)) -> 0.76107162
A115: VERIFICA NO LIVRO DO MAMEDE AS REFLETANCIAS
A117: POR MEIO DO VALOR DE K, USA A TABELA PARA ACHAR CONHECENDO AS REFLENTACIAS MÉDIAS DO TETO Pte, DAs PAREDES Ppa, do PISO Ppi, VAI NA TABELA E PEGA OS VALORES
A119: TETO | B119: =G3 -> ZINCO
A120: PAREDE | B120: =H3 -> CLARA
...

Sheet LUM-DEP CAR1
A1: DADOS DO LOCAL
A2: LOCAL | B2: LARGURA L (m) | C2: COMPRIMENTO C (m) | D2: ALTURA DE MANUSEIO TRABALHO Hpp (m) | E2: ALTURA TOTAL/PÉ-DIREITO Htp (m) | F2: ALTURA UTIL/ ALTURA DE TRABALHO Hlp (m) | G2: TETO | H2: PAREDE | I2: PISO | J2: LAMPADA UTILIZADA
A3: DEPÓSITO DE CARCAÇAS 1 | B3: =DADOS!D5 -> 8.12 | C3: =DADOS!E5 -> 6 | D3: =DADOS!C5 -> 0.8 | E3: =DADOS!K5 -> 7 | F3: =E3-D3 -> 6.2 | G3: =DADOS!H5 -> ZINCO | H3: =DADOS!I5 -> CLARA | I3: =DADOS!J5 -> CONCRETO | J3: VAPOR DE METAL
A6: MÉTODO LUMENS
A10: ILUMINAMENTO
A13: CARACTERÍSTICAS DA TAREFA E DO OBSERVADOR ADOTADOS
A15: IDADE | B15: 41
A16: VELOCIDADE E PRECISÃO | B16: IMPORTANTE
A17: REFLETANCIA NO FUNDO DA TAREFA | B17: 0.4
A18: CALCULO DE PESO | B18: 0
A21: FAIXAS, ILUMINANCIAS E TIPO DE ATIVIDADE ADOTADOS
A22: ADOTADA A FAIXA B | B22: TAREFAS COM REQUISITOS VISUAIS LIMITADOS...
A23: ILUMINÂNCIAS (LUX) | B23: 300
A26: ILUMINÂNCIA MINIMA EM LUX, POR TIPO DE ATIVIDADE ADOTADO
A27: TIPO DE AMBIENTE | B27: LUX
A28: LOCAIS DE ARMAZENAMENTO
A29: GRANDES VOLUMES | B29: 200
A31: ADOTADO NO FINAL O MAIOR VALOR QUE É 300 lx
A33: ILUMINÂNCIAS (LUX) | B33: 300
A71: LUMINÁRIA ADOTADA
A73: COMPRESSOR(B,P) POSSUEM ELEVADO PÉ-DIREITO, LUMINÁRIA ADEQUADA PARA ESSE AMBIENTE SÃO TIPO REFLETOR INDUSTRIAL ESTILO CUPULA
A75: DADOS LUMINÁRIA
A76: MODELO | B76: HDK 472+GDK 474 PG
A77: FABRICANTE | B77: Philips
A88: LAMPADA E REATOR ADOTADOS
A89: Podendo ser adotados lampadas de até 400 W, conforme a luminária adotada
A91: DADOS DA LAMPADA
A92: MODELO | B92: MASTER HPI-T Plus 400W/645 E40 1SL/12
A93: FABRICANTE | B93: Philips
A94: TIPO DE LAMPADA | B94: VAPOR METALICO
A95: POTÊNCIA (W) | B95: 400
A96: FLUXO LUMINOSO (lumens) | B96: 33200
A97: NUMERO DE LAMPADAS POR LUMINARIA | B97: 1
A100: DADOS DO REATOR
A101: MODELO | B101: BHLE 400L 200TS
A102: FABRICANTE | B102: Philips
A103: PERDAS (W) | B103: 27.5
A104: FATOR DE POTENCIA | B104: 0.85
A106: De forma a calcular o fluxo luminoso se deve calcular o FATOR DE UTILIZAÇÃO e FATOR DE DEPRECIAÇÃO
A108: FATOR DE UTILIZAÇÃO Fu
...

Sheet LUM-DEP CAR2
A1: DADOS DO LOCAL
A2: LOCAL | B2: LARGURA L (m) | C2: COMPRIMENTO C (m) | D2: ALTURA DE MANUSEIO TRABALHO Hpp (m) | E2: ALTURA TOTAL/PÉ-DIREITO Htp (m) | F2: ALTURA UTIL/ ALTURA DE TRABALHO Hlp (m) | G2: TETO | H2: PAREDE | I2: PISO | J2: LAMPADA UTILIZADA
A3: DEPÓSITO DE CARCAÇAS 2 | B3: =DADOS!D6 -> 11.18 | C3: =DADOS!E6 -> 9.6 | D3: =DADOS!C6 -> 0.8 | E3: =DADOS!K6 -> 7 | F3: =E3-D3 -> 6.2 | G3: =DADOS!H6 -> ZINCO | H3: =DADOS!I6 -> CLARA | I3: =DADOS!J6 -> CONCRETO | J3: VAPOR DE METAL
A6: MÉTODO LUMENS
A10: ILUMINAMENTO
A13: CARACTERÍSTICAS DA TAREFA E DO OBSERVADOR ADOTADOS
A15: IDADE | B15: 41
A16: VELOCIDADE E PRECISÃO | B16: IMPORTANTE
A17: REFLETANCIA NO FUNDO DA TAREFA | B17: 0.4
A18: CALCULO DE PESO | B18: 0
A21: FAIXAS, ILUMINANCIAS E TIPO DE ATIVIDADE ADOTADOS
A22: ADOTADA A FAIXA B | B22: TAREFAS COM REQUISITOS VISUAIS LIMITADOS...
A23: ILUMINÂNCIAS (LUX) | B23: 300
A26: ILUMINÂNCIA MINIMA EM LUX, POR TIPO DE ATIVIDADE ADOTADO
A27: TIPO DE AMBIENTE | B27: LUX
A28: LOCAIS DE ARMAZENAMENTO
A29: GRANDES VOLUMES | B29: 200
A31: ADOTADO NO FINAL O MAIOR VALOR QUE É 300 lx
A33: ILUMINÂNCIAS (LUX) | B33: 300
A71: LUMINÁRIA ADOTADA
A73: COMPRESSOR(B,P) POSSUEM ELEVADO PÉ-DIREITO, LUMINÁRIA ADEQUADA PARA ESSE AMBIENTE SÃO TIPO REFLETOR INDUSTRIAL ESTILO CUPULA
A75: DADOS LUMINÁRIA
A76: MODELO | B76: HDK 472+GDK 474 PG
A77: FABRICANTE | B77: Philips
A88: LAMPADA E REATOR ADOTADOS
A89: Podendo ser adotados lampadas de até 400 W, conforme a luminária adotada
A91: DADOS DA LAMPADA
A92: MODELO | B92: MASTER HPI-T Plus 400W/645 E40 1SL/12
A93: FABRICANTE | B93: Philips
A94: TIPO DE LAMPADA | B94: VAPOR METALICO
A95: POTÊNCIA (W) | B95: 400
A96: FLUXO LUMINOSO (lumens) | B96: 33200
A97: NUMERO DE LAMPADAS POR LUMINARIA | B97: 1
A100: DADOS DO REATOR
A101: MODELO | B101: BHLE 400L 200TS
A102: FABRICANTE | B102: Philips
A103: PERDAS (W) | B103: 27.5
A104: FATOR DE POTENCIA | B104: 0.85
A106: De forma a calcular o fluxo luminoso se deve calcular o FATOR DE UTILIZAÇÃO e FATOR DE DEPRECIAÇÃO
A108: FATOR DE UTILIZAÇÃO Fu
...

Sheet LUM-RASPA
A1: DADOS DO LOCAL
A2: LOCAL | B2: LARGURA L (m) | C2: COMPRIMENTO C (m) | D2: ALTURA DE MANUSEIO TRABALHO Hpp (m) | E2: ALTURA TOTAL/PÉ-DIREITO Htp (m) | F2: ALTURA UTIL/ ALTURA DE TRABALHO Hlp (m) | G2: TETO | H2: PAREDE | I2: PISO | J2: LAMPADA UTILIZADA
A3: RASPA | B3: =DADOS!D7 -> 8.12 | C3: =DADOS!E7 -> 30.92 | D3: =DADOS!C7 -> 0.8 | E3: =DADOS!K7 -> 7 | F3: =E3-D3 -> 6.2 | G3: =DADOS!H7 -> ZINCO | H3: =DADOS!I7 -> CLARA | I3: =DADOS!J7 -> CONCRETO | J3: VAPOR DE METAL
A6: MÉTODO LUMENS
A10: ILUMINAMENTO
A13: CARACTERÍSTICAS DA TAREFA E DO OBSERVADOR ADOTADOS
A14: IDADE | B14: 41
A15: VELOCIDADE E PRECISÃO | B15: IMPORTANTE
A16: REFLETANCIA NO FUNDO DA TAREFA | B16: 0.4
A17: CALCULO DE PESO | B17: 0
A21: FAIXAS, ILUMINANCIAS E TIPO DE ATIVIDADE ADOTADOS
A22: ADOTADA A FAIXA B | B22: TAREFAS COM REQUISITOS VISUAIS NORMAIS...
A23: ILUMINÂNCIAS (LUX) | B23: 750
A33: ILUMINÂNCIAS (LUX) | B33: 750
A71: LUMINÁRIA ADOTADA
A73: SALA DE CALDEIRAS POSSUEM ELEVADO PÉ-DIREITO, LUMINÁRIA ADEQUADA PARA ESSE AMBIENTE SÃO TIPO REFLETOR INDUSTRIAL ESTILO CUPULA
A75: DADOS LUMINÁRIA
A76: MODELO | B76: HDK 472+GDK 474 PG
A77: FABRICANTE | B77: Philips
A88: LAMPADA E REATOR ADOTADOS
A89: Podendo ser adotados lampadas de até 400 W, conforme a luminária adotada
A91: DADOS DA LAMPADA
A92: MODELO | B92: MASTER HPI-T Plus 400W/645 E40 1SL/12
A93: FABRICANTE | B93: Philips
A94: TIPO DE LAMPADA | B94: VAPOR METALICO
A95: POTÊNCIA (W) | B95: 400
A96: FLUXO LUMINOSO (lumens) | B96: 33200
A97: NUMERO DE LAMPADAS POR LUMINARIA | B97: 1
A100: DADOS DO REATOR
A101: MODELO | B101: BHLE 400L 200TS
A102: FABRICANTE | B102: Philips
A103: PERDAS (W) | B103: 27.5
A104: FATOR DE POTENCIA | B104: 0.85
A106: De forma a calcular o fluxo luminoso se deve calcular o FATOR DE UTILIZAÇÃO e FATOR DE DEPRECIAÇÃO
A108: FATOR DE UTILIZAÇÃO Fu
A109: DEVE-SE SEGUIR A FORMULA ABAIXO
A112: K | B112: =(C3*B3)/(F3*(C3+B3)) -> 1.0372753
A115: VERIFICA NO LIVRO DO MAMEDE AS REFLETANCIAS
A117: POR MEIO DO VALOR DE K, USA A TABELA PARA ACHAR CONHECENDO AS REFLENTACIAS MÉDIAS DO TETO Pte, DAs PAREDES Ppa, do PISO Ppi, VAI NA TABELA E PEGA OS VALORES
A119: TETO | B119: =G3 -> ZINCO
...

Sheet RECAPAGEM
A1: DADOS DO LOCAL
B3: LOCAL | C3: LARGURA L (m) | D3: COMPRIMENTO C (m) | E3: ÁREA (m²) | F3: PERÍMETRO (m) | G3: ALTURA DE MANUSEIO TRABALHO Hpp (m) | H3: TETO | I3: PAREDE | J3: PISO | K3: ALTURA TOTAL/PÉ-DIREITO Htp (m) | L3: VELOCIDADE E PRECISÃO | M3: REFLETANCIA DO FUNDO DA TAREFA | N3: IDADE MÉDIA DOS TRABALHADORES | O3: ALTURA MÍNIIMA | P3: TIRANTE | Q3: K | R3: Hlp | S3: Htl | T3: Hpp
B4: RECAPAGEM 1 | C4: 5 | D4: 30.9 | E4: =D4*C4 -> 154.5 | F4: =(2*D4)+(2*C4) -> 71.8 | G4: 0.8 | H4: ZINCO | I4: CLARA | J4: CONCRETO | K4: 7 | L4: IMPORTANTE | M4: 0.4 | N4: 41 ANOS | O4: 4 | P4: 1 | Q4: =(5*(D4+C4))/(D4*C4) -> 1.1618123 | R4: =K4-P4-G4 -> 5.2 | S4: =P4 -> 1 | T4: =G4 -> 0.8
B5: RECAPAGEM 2 | C5: 5.23 | D5: 39.25 | E5: =D5*C5 -> 205.2775 | F5: =(2*D5)+(2*C5) -> 88.96 | Q5: =(5*(D5+C5))/(D5*C5) -> 1.0834115 | R5: =K4-P4-G4 -> 5.2 | S5: =P4 -> 1 | T5: =G4 -> 0.8
B6: RECAPAGEM 3 | C6: 27.95 | D6: 43.37 | E6: =D6*C6 -> 1212.1915 | F6: =(2*D6)+(2*C6) -> 142.64 | Q6: =(5*(D6+C6))/(D6*C6) -> 0.29417794 | R6: =K4-P4-G4 -> 5.2 | S6: =P4 -> 1 | T6: =G4 -> 0.8
A35: LUMINÁRIA
J43: MODELO | K43: HDK 472
J44: FABRICANTE | K44: PHILLIPS
A54: LÂMPADA+REATOR
D57: MODELO | G57: MODELO
D58: FABRICANTE | G58: FABRICANTE
A68: CAVIDADES
E70: refletâncias | H70: Refletâncias Efetivas tab 2.11 – Mamede
C71: recinto | D71: teto | E71: piso | F71: parede clara | G71: teto claro (zinco) | H71: piso escuro
B72: LOCAL | C72: Rcr | D72: Rct | E72: Rcp | F72: ρpa | G72: ρte | H72: ρpi | I72: ρct(1) | J72: ρcp | O72: para teto de 50% | P72: para teto de 70%
B73: RECAPAGEM 1 | C73: =Q4*R4 -> 6.0414239 | D73: =Q4*S4 -> 1.1618123 | E73: =Q4*T4 -> 0.92944984 | F73: 0.5 | G73: 0.5 | H73: 0.1 | I73: 43 | J73: 11 | O73: 43 | P73: 59
B74: RECAPAGEM 2 | C74: =Q5*R5 -> 5.6337397 | D74: =Q5*S5 -> 1.0834115 | E74: =Q5*T5 -> 0.86672918 | I74: 43 | J74: 11 | O74: 43 | P74: 59
B75: RECAPAGEM 3 | C75: =Q6*R6 -> 1.5297253 | D75: =Q6*S6 -> 0.29417794 | E75: =Q6*T6 -> 0.23534235 | I75: 47 | J75: 10 | O75: 48 | P75: 67
A95: FATOR DE UTILIZAÇÃO
H96: tab 2.12 – Mamede
B98: LOCAL | C98: Rcr | D98: k1 | E98: k2 | F98: fu1 | G98: fu2 | H98: k | I98: a | J98: b | K98: c | L98: fu
B99: RECAPAGEM 1 | C99: 6 | D99: 10 | E99: 50 | F99: 0.44 | G99: 0.46 | H99: =I73 -> 43 | I99: =E99-D99 -> 40 | J99: =H99-D99 -> 33 | K99: =G99-F99 -> 0.02 | L99: =((G99*I99)-(K99*J99))/$I$99 -> 0.4435
C100: 7 | D100: 10 | E100: 50 | F100: 0.41 | G100: 0.43 | H100: =I73 -> 43 | I100: =E100-D100 -> 40 | J100: =H100-D100 -> 33 | K100: =G100-F100 -> 0.02 | L100: =((G100*I100)-(K100*J100))/I100 -> 0.4135
C101: =C73 -> 6.0414239 | D101: 7 | E101: 6 | F101: =L99 -> 0.4435 | G101: =L100 -> 0.4135 | H101: =C101 -> 6.0414239 | I101: =E101-D101 -> -1 | J101: =E101-H101 -> -0.041423948 | K101: =F101-G101 -> 0.03 | L101: =((G101*I101)-(K101*J101))/I101 -> 0.41225728
B102: RECAPAGEM 2 | C102: 5 | D102: 10 | E102: 50 | F102: 0.47 | G102: 0.5 | H102: =I74 -> 43 | I102: =E102-D102 -> 40 | J102: =H102-D102 -> 33 | K102: =G102-F102 -> 0.03 | L102: =((G102*I102)-(K102*J102))/$I$99 -> 0.47525
C103: 6 | D103: 10 | E103: 50 | F103: 0.44 | G103: 0.46 | H103: =I74 -> 43 | I103: =E103-D103 -> 40 | J103: =H103-D103 -> 33 | K103: =G103-F103 -> 0.02 | L103: =((G103*I103)-(K103*J103))/I103 -> 0.4435
C104: =C74 -> 5.6337397 | D104: 6 | E104: 5 | F104: =L102 -> 0.47525 | G104: =L103 -> 0.4435 | H104: =C104 -> 5.6337397 | I104: =E104-D104 -> -1 | J104: =E104-H104 -> -0.63373969 | K104: =G104-F104 -> -0.03175 | L104: =((G104*I104)-(K104*J104))/I104 -> 0.46362124
B105: RECAPAGEM 3 | C105: 1 | D105: 10 | E105: 50 | F105: 0.67 | G105: 0.72 | H105: =I75 -> 47 | I105: =E105-D105 -> 40 | J105: =H105-D105 -> 37 | K105: =G105-F105 -> 0.05 | L105: =((G105*I105)-(K105*J105))/$I$99 -> 0.67375
C106: 2 | D106: 10 | E106: 50 | F106: 0.61 | G106: 0.65 | H106: =I75 -> 47 | I106: =E106-D106 -> 40 | J106: =H106-D106 -> 37 | K106: =G106-F106 -> 0.04 | L106: =((G106*I106)-(K106*J106))/I106 -> 0.613
C107: =C75 -> 1.5297253 | D107: 2 | E107: 1 | F107: =L105 -> 0.67375 | G107: =L106 -> 0.613 | H107: =C107 -> 1.5297253 | I107: =E107-D107 -> -1 | J107: =E107-H107 -> -0.5297253 | K107: =G107-F107 -> -0.06075 | L107: =((G107*I107)-(K107*J107))/I107 -> 0.64518081
A111: CORREÇÃO FATOR DE UTILIZAÇÃO
B114: LOCAL | C114: ρcp | D114: fu | E114: fcu | F114: fu'
B115: RECAPAGEM 1 | C115: =J73 -> 11 | D115: =L101 -> 0.41225728 | E115: 1.02 | F115: =D115/E115 -> 0.40417381
B116: RECAPAGEM 2 | C116: =J74 -> 11 | D116: =L104 -> 0.46362124 | E116: 1.02 | F116: =D116/E116 -> 0.45453062
B117: RECAPAGEM 3 | C117: =J75 -> 10 | D117: =L107 -> 0.64518081 | E117: 1.04 | F117: =D117/E117 -> 0.62036617
A126: FATOR DE DEPRECIAÇÃO
B130: LOCAL | C130: vida util | D130: tempo de manutenção | E130: tempo de uso
B131: RECAPAGEM 1
B132: RECAPAGEM 2
B133: RECAPAGEM 3

Sheet SUBESTAÇÃO
A1: DADOS DO LOCAL
A2: LOCAL | B2: LARGURA L (m) | C2: COMPRIMENTO C (m) | D2: ALTURA DE MANUSEIO TRABALHO Hpp (m) | E2: ALTURA TOTAL/PÉ-DIREITO Htp (m) | F2: ALTURA UTIL/ ALTURA DE TRABALHO Hlp (m) | G2: TETO | H2: PAREDE | I2: PISO | J2: LAMPADA UTILIZADA
A3: SUBESTAÇÃO | B3: =DADOS!D15 -> 9.6 | C3: =DADOS!E15 -> 9.8 | D3: =DADOS!C15 -> 0.8 | E3: =DADOS!K15 -> 7 | F3: =E3-D3 -> 6.2 | G3: =DADOS!H15 -> BRANCO | H3: =DADOS!I15 -> BRANCA | I3: =DADOS!J15 -> CONCRETO | J3: MISTA
A6: MÉTODO LUMENS
A8: ILUMINAMENTO
A11: CARACTERÍSTICAS DA TAREFA E DO OBSERVADOR ADOTADOS
A12: IDADE | B12: 41
A13: VELOCIDADE E PRECISÃO | B13: IMPORTANTE
A14: REFLETANCIA NO FUNDO DA TAREFA | B14: 0.4
A15: CALCULO DE PESO | B15: 0
A17: FAIXAS, ILUMINANCIAS E TIPO DE ATIVIDADE ADOTADOS
A18: ADOTADA A FAIXA B | B18: TAREFAS COM REQUISITOS VISUAIS LIMITADOS
A19: ILUMINÂNCIAS (LUX) | B19: 200
A51: LUMINÁRIA ADOTADA
A53: SUBESTAÇÃO NÃO PODE TER LUMINÁRIAS NO TETO, APENAS NAS PAREDES E FORA DAS CABINES DE TRANSFORMADORES - NECESSÁRIO QUE FOSSE ARANDELA ANTI-EXPLOSÃO
A55: DADOS LUMINÁRIA
A56: MODELO | B56: FLW 17/3-MI5500
A57: FABRICANTE | B57: Comercial EX
A60: https://comercialex.com.br/produtos/iluminacao/luminaria-convencional/luminaria-a-prova-de-explosao-arandela/
A68: LAMPADA E REATOR ADOTADOS
A69: Podendo ser adotados lampadas de até 400 W, conforme a luminária adotada
A71: DADOS DA LAMPADA
A72: MODELO | B72: PEGO DOS PDFs disponibilizados
A73: FABRICANTE
A74: TIPO DE LAMPADA | B74: MISTA | E74: https://www.eletricasantaefigenia.com.br/lampada-mista-500w-/prod-10645297/
A75: POTÊNCIA (W) | B75: 500
A76: FLUXO LUMINOSO (lumens) | B76: 32000
A77: NUMERO DE LAMPADAS POR LUMINARIA | B77: 1
A80: DADOS DO REATOR (não possui reator)
A81: MODELO
A82: FABRICANTE
A83: PERDAS (W)
A84: FATOR DE POTENCIA
A86: De forma a calcular o fluxo luminoso se deve calcular o FATOR DE UTILIZAÇÃO e FATOR DE DEPRECIAÇÃO
A88: FATOR DE UTILIZAÇÃO Fu
A89: DEVE-SE SEGUIR A FORMULA ABAIXO
A92: K | B92: =(C3*B3)/(F3*(C3+B3)) -> 0.78217493
A95: VERIFICA NO LIVRO DO MAMEDE AS REFLETANCIAS
A97: POR MEIO DO VALOR DE K, USA A TABELA PARA ACHAR CONHECENDO AS REFLENTACIAS MÉDIAS DO TETO Pte, DAs PAREDES Ppa, do PISO Ppi, VAI NA TABELA E PEGA OS VALORES
A99: TETO | B99: =G3 -> BRANCO
...

Sheet LUM-SP-CQ-B-E
A1: DADOS DO LOCAL
A2: LOCAL | B2: LARGURA L (m) | C2: COMPRIMENTO C (m) | D2: ALTURA DE MANUSEIO TRABALHO Hpp (m) | E2: ALTURA TOTAL/PÉ-DIREITO Htp (m) | F2: ALTURA ÚTIL / ALTURA DE TRABALHO Hlp (m) | G2: TETO | H2: PAREDE | I2: PISO | J2: LÂMPADA UTILIZADA
A3: SAÍDA DE PRODUTOS (SALA DE PRODUTOS) | B3: 5 | C3: 6 | D3: 0.8 | E3: 3 | F3: =E3-D3 -> 2.2 | G3: CLARO | H3: CLARA | I3: AZULEJO CINZA | J3: FLUORESCENTE
A4: CONTROLE DE QUALIDADE | B4: 5 | C4: 6 | D4: 0.8 | E4: 3 | F4: =E4-D4 -> 2.2 | G4: BRANCO | H4: BRANCA | I4: AZULEJO CINZA | J4: FLUORESCENTE
A5: BANHEIRO (VESTUÁRIO) | B5: 5.23 | C5: 3.5 | D5: 0.8 | E5: 3 | F5: =E5-D5 -> 2.2 | G5: CLARO | H5: CLARA | I5: AZULEJO CINZA | J5: FLUORESCENTE
A6: ESCRITÓRIO | B6: 8.12 | C6: 6 | D6: 0.8 | E6: 3 | F6: =E6-D6 -> 2.2 | G6: BRANCO | H6: BEGE | I6: AZULEJO CINZA | J6: FLUORESCENTE
A8: MÉTODO LUMENS
A9: As quatro áreas são dimensionadas pelo Método dos Lumens. A revisão segue o padrão das demais páginas, corrigindo refletâncias e incorporando as faixas de iluminância usadas no restante do trabalho.
A11: ILUMINAMENTO
A13: CARACTERÍSTICAS DA TAREFA E DO OBSERVADOR ADOTADAS
A14: IDADE | B14: 41
A15: VELOCIDADE E PRECISÃO | B15: IMPORTANTE
A16: REFLETÂNCIA NO FUNDO DA TAREFA | B16: 0.4
A17: CÁLCULO DE PESO | B17: 0
A20: FAIXAS, ILUMINÂNCIAS E TIPO DE ATIVIDADE ADOTADOS
A21: AMBIENTE | B21: FAIXA | C21: TIPO DE ATIVIDADE | D21: LUX INFERIOR | E21: LUX MÉDIO | F21: LUX SUPERIOR | G21: PESO | H21: E PELA FAIXA [lux] | I21: E ESPECÍFICA [lux] | J21: E ADOTADA [lux]
A22: =A3 -> SAÍDA DE PRODUTOS (SALA DE PRODUTOS) | B22: A | C22: Recintos não usados para trabalho contínuo, depósitos | D22: 100 | E22: 150 | F22: 200 | G22: =$B$17 -> 0 | H22: =IF(G22<=-2,D22,IF(G22>=2,F22,E22)) -> 150 | I22: 200 | J22: =MAX(H22,I22) -> 200
A23: =A4 -> CONTROLE DE QUALIDADE | B23: B | C23: Tarefas com requisitos especiais: inspeção | D23: 1000 | E23: 1500 | F23: 2000 | G23: =$B$17 -> 0 | H23: =IF(G23<=-2,D23,IF(G23>=2,F23,E23)) -> 1500 | I23: 500 | J23: =MAX(H23,I23) -> 1500
A24: =A5 -> BANHEIRO (VESTUÁRIO) | B24: A | C24: Orientação simples para permanência curta | D24: 50 | E24: 75 | F24: 100 | G24: =$B$17 -> 0 | H24: =IF(G24<=-2,D24,IF(G24>=2,F24,E24)) -> 75 | I24: 200 | J24: =MAX(H24,I24) -> 200
A25: =A6 -> ESCRITÓRIO | B25: B | C25: Tarefas com requisitos visuais normais: escritórios | D25: 500 | E25: 750 | F25: 1000 | G25: =$B$17 -> 0 | H25: =IF(G25<=-2,D25,IF(G25>=2,F25,E25)) -> 750 | I25: 250 | J25: =MAX(H25,I25) -> 750
A47: ILUMINÂNCIA FINAL ADOTADA
A48: AMBIENTE | B48: TIPO ESPECÍFICO | C48: E PELA FAIXA [lux] | D48: E MÍNIMA ESPECÍFICA [lux] | E48: E FINAL ADOTADA [lux]
A49: =A22 -> SAÍDA DE PRODUTOS (SALA DE PRODUTOS) | B49: LOCAIS DE ARMAZENAMENTO - GRANDES VOLUMES | C49: =H22 -> 150 | D49: =I22 -> 200 | E49: =J22 -> 200
A50: =A23 -> CONTROLE DE QUALIDADE | B50: INSPEÇÃO / CONTROLE DE QUALIDADE | C50: =H23 -> 1500 | D50: =I23 -> 500 | E50: =J23 -> 1500
A51: =A24 -> BANHEIRO (VESTUÁRIO) | B51: BANHEIROS / VESTIÁRIOS | C51: =H24 -> 75 | D51: =I24 -> 200 | E51: =J24 -> 200
A52: =A25 -> ESCRITÓRIO | B52: ESCRITÓRIOS - SALA DE TRABALHO | C52: =H25 -> 750 | D52: =I25 -> 250 | E52: =J25 -> 750
A54: Critério final: maior valor entre a faixa e a iluminância específica. Sala de Produtos = 200 lux; Controle de Qualidade = 1500 lux; Banheiro/Vestiário = 200 lux; Escritório = 750 lux.
A56: LUMINÁRIA, LÂMPADA E REATOR ADOTADOS
A58: DADOS DA LUMINÁRIA
A59: MODELO | B59: TMS 426 - 2 x 40 W
A60: FABRICANTE | B60: Philips
A61: APLICAÇÃO | B61: Ambientes internos de baixo pé-direito
A63: DADOS DA LÂMPADA
A64: MODELO | B64: FLUORESCENTE COMUM
A65: TIPO | B65: FLUORESCENTE
A66: POTÊNCIA [W] | B66: 40
A67: FLUXO LUMINOSO [lm] | B67: 3000
A68: LÂMPADAS POR LUMINÁRIA | B68: 2
A70: DADOS DO REATOR
A71: CONFIGURAÇÃO | B71: DUPLO 2 x 40 W
...
