Workbook

Sheet QDL
A1: Dimensionamento de Cálculos Do luminotécnico
A2: Quadro | B2: Nº do circuito | C2: Área | D2: Tensão (V) | E2: Método de Instalação | F2: Método de Referência | G2: Nº de luminárias | H2: Potência Lum. (VA) | I2: Demanda (VA) | J2: Ip (A) | K2: FP | M2: Método de instalação se escolhe da tabela dos slides de ampacidade, isso seria a norma 5410
A3: QDL0 | B3: L0 | C3: SUBESTAÇÃO | D3: 220 | E3: 33 | F3: B1 | G3: 5 | H3: 500 | I3: =H3*G3 -> 2500 | J3: =I3/D3 -> 11.363636 | K3: 0.95 | M3: Em função da elevada altura de 7,0m, dos ambientes adota o método 13 pois tem: livre circulação e ventilação no topo, manutenção em grande altura. Em altura baixas como 3 m pode adotar o método 7. A subestação pode adotar o método 33 pois: Interligação do Transformador com o QGBT para cabos pelo Piso, acomoda cabos grandes e pesados
A4: QDL1 | B4: L1 | C4: SALA DE CALDEIRAS | D4: 220 | E4: 13 | F4: F | G4: 4 | H4: 440 | I4: =H4*G4 -> 1760 | J4: =I4/D4 -> 8 | K4: 0.85
A5: QDL2 | B5: L2 | C5: COMPRESSOR (BOMBAS E PRENSA) | D5: 220 | E5: 13 | F5: F | G5: 6 | H5: 440 | I5: =H5*G5 -> 2640 | J5: =I5/D5 -> 12 | K5: 0.85
A6: QDL3 | B6: L3 | C6: DEPÓSITO DE CARCAÇAS | D6: 220 | E6: 13 | F6: F | G6: 6 | H6: 440 | I6: =H6*G6 -> 2640 | J6: =I6/D6 -> 12 | K6: 0.85
A7: QDL4 | B7: L4 | C7: RASPA | D7: 220 | E7: 13 | F7: F | G7: 6 | H7: 440 | I7: =H7*G7 -> 2640 | J7: =I7/D7 -> 12 | K7: 0.85
B8: L5 | C8: RASPA | D8: 220 | E8: 13 | F8: F | G8: 6 | H8: 440 | I8: =H8*G8 -> 2640 | J8: =I8/D8 -> 12 | K8: 0.85
B9: L6
B10: L7
B11: L8
B12: L9
B13: L10
B14: L11
B15: L12
B16: L13
B17: L14
B18: L15
B19: L16
B20: L17
A21: QDL5 | B21: L18
A22: QDL6 | B22: L19
B23: L20
A24: QDL7 | B24: L21
M33: Método de referencia: Adotar método F(unipolares pois Lançar 3 ou 4 cabos unipolares separados (um para cada fase/neutro) torna a montagem física viável na infraestrutura aérea, cada cabo possui sua própria superfície externa de isolação em contato direto com o ar em circulação
M37: OS CIRCUITO DAS RASPA, RECAPAGEM DEVEM: Dividir os circuitos cuja demanda deeem mais de 4500 VA pois ajuda na distribuição. A NBR 5410 (item 9.5.2) recomenda que circuitos terminais de iluminação industrial não sobrecarreguem o disjuntor de proteção. Em 220V, a corrente total seria de 32 A, exigindo fiação de 6mm ou mais e disjuntores elevados, o que foge do padrão eficiente para linhas de iluminação

Sheet QDL-FATOR CORREÇÃO
A1: Fatores de correção
A2: Quadro | B2: Nº do circuito | C2: Área | D2: Circuitos agrupados | E2: Método de Instalação | F2: Método de Referência | G2: Ref (tabela 9.10) | H2: Cabos multipolares | I2: Fator de agrupamento | J2: Fator de temperatura (45º) | K2: Fator de harmônicos | L2: Isolação | M2: Ip (A) | N2: Ip' (A) | O2: Iz (A) | P2: Iz' | R2: FATOR DE AGRUPAMENTO PEGO POR CABOS MULTIPOLARES: SUBESTAÇÃO usa referencia 1 (é embutido a instalação 33). SALA DE CALDEIRAS+ COMPRESSOR DEPOISITO DE CARCAÇAS+RASPA usa referencia 4 (bandeja perfurada é 13)
A3: QDL0 | B3: L0 | C3: SUBESTAÇÃO | D3: 1 | E3: 33 | F3: B1 | G3: 1 | H3: 1 | I3: 1 | J3: =S69 -> 0.87 | K3: 1.15 | L3: EPR ou XLPE | M3: =QDL!J3 -> 11.363636 | N3: =((M3*K3)/(J3*I3)) -> 15.020899 | O3: 23 | P3: =J3*I3*O3 -> 20.01
A4: QDL1 | B4: L1 | C4: SALA DE CALDEIRAS | D4: 1 | E4: 13 | F4: F | G4: 4 | H4: 1 | I4: 1 | J4: =S69 -> 0.87 | K4: 1.15 | L4: EPR ou XLPE | M4: =QDL!J4 -> 8 | N4: =((M4*K4)/(J4*I4)) -> 10.574713 | O4: 22 | P4: =J4*I4*O4 -> 19.14
A5: QDL2 | B5: L2 | C5: COMPRESSOR (BOMBAS E PRENSA) | D5: 1 | E5: 13 | F5: F | G5: 4 | H5: 1 | I5: 1 | J5: =S69 -> 0.87 | K5: 1.15 | L5: EPR ou XLPE | M5: =QDL!J5 -> 12 | N5: =((M5*K5)/(J5*I5)) -> 15.862069 | O5: 22 | P5: =J5*I5*O5 -> 19.14
A6: QDL3 | B6: L3 | C6: DEPOSITO DE CARCAÇAS | D6: 1 | E6: 13 | F6: F | G6: 4 | H6: 1 | I6: 1 | J6: =S69 -> 0.87 | K6: 1.15 | L6: EPR ou XLPE | M6: =QDL!J6 -> 12 | N6: =((M6*K6)/(J6*I6)) -> 15.862069 | O6: 22 | P6: =J6*I6*O6 -> 19.14
A7: QDL4 | B7: L4 | C7: RASPA | D7: 2 | E7: 13 | F7: F | G7: 4 | H7: 2 | I7: 0.88 | J7: =S69 -> 0.87 | K7: 1.15 | L7: EPR ou XLPE | M7: =QDL!J7 -> 12 | N7: =((M7*K7)/(J7*I7)) -> 18.025078 | O7: 30 | P7: =J7*I7*O7 -> 22.968
B8: L5 | C8: RASPA | D8: 2 | E8: 13 | F8: F | G8: 4 | H8: 2 | I8: 0.88 | J8: =S69 -> 0.87 | K8: 1.15 | L8: EPR ou XLPE | M8: =QDL!J8 -> 12 | N8: =((M8*K8)/(J8*I8)) -> 18.025078 | O8: 30 | P8: =J8*I8*O8 -> 22.968
B9: L6
B10: L7
B11: L8
B12: L9
B13: L10
B14: L11
B15: L12
B16: L13
B17: L14
B18: L15
B19: L16
B20: L17
A21: QDL5 | B21: L18
A22: QDL6 | B22: L19
B23: L20
A24: QDL7 | B24: L21
C27: Método de Instalação
C28: 33
C29: 13
C30: 13
C31: 13
C32: 13
C33: 13
Q67: Fator de Correção - Temperatura
Q68: Temperatura | R68: PVC | S68: EPR ou XLPE
Q69: 45 | R69: 0.79 | S69: 0.87
Q71: Adota cabos EPR OU XLPE para ambientes mais nocivos (quentes, sujos, alta concentração de cabos) como: Sala de Caldeiras, Compressor (Bombas e Prensa), Depósito de Carcaças e Raspa, Recapagem, Subestação. Ambientes comuns como: Sala de Produto, Controle de Qualidade, Banheiro (Vestuário) e Escritório adota cabos PVC
Q77: FATOR HARMONICO: ADOTAR 1,15, O valor 1,15 é utilizado porque se trata de um fator de majoração aplicado quando há presença de 3º harmônico (entre 15% e 35%) em sistemas de iluminação e cargas não lineares (como reatores eletrônicos e lâmpadas LED).
Q99: Ip' (A)
O121: I_I (negocio do denominador) é produtorio no denominador: Ele indica que você deve multiplicar todos os fatores de correção entre si e dividir a corrente de projeto Ip por esse resultado.
Q125: pergunta calculo de Ip'
Q126: PERGUNTA CALCULO DE Iz' existe?
...

Sheet SEÇÃO CONDUTORES
A1: Seção dos condutores (mm²)
A2: Quadro | B2: Nº do circuito | C2: Área | D2: Cabos multipolares | E2: Circuitos agrupados | F2: Condutores carregados CC | G2: Isolação | H2: Método de Instalação | I2: Método de Referência | J2: Fase | K2: Neutro | L2: Terra | Q2: Adota Seções nominais os escolhido la em FATOR CORREÇÃO, as seções nominais
A3: QDL0 | B3: L0 | C3: SUBESTAÇÃO | D3: 1 | E3: 1 | F3: 2 | G3: EPR ou XLPE | H3: 33 | I3: B1 | J3: 1.5 | K3: 1.5 | L3: 1.5
A4: QDL1 | B4: L1 | C4: SALA DE CALDEIRAS | D4: 1 | E4: 1 | F4: 2 | G4: EPR ou XLPE | H4: 13 | I4: F | J4: 1.5 | K4: 1.5 | L4: 1.5
A5: QDL2 | B5: L2 | C5: COMPRESSOR (BOMBAS E PRENSA) | D5: 1 | E5: 1 | F5: 2 | G5: EPR ou XLPE | H5: 13 | I5: F | J5: 1.5 | K5: 1.5 | L5: 1.5
A6: QDL3 | B6: L3 | C6: DEPOSITO DE CARCAÇAS | D6: 1 | E6: 1 | F6: 2 | G6: EPR ou XLPE | H6: 13 | I6: F | J6: 1.5 | K6: 1.5 | L6: 1.5
A7: QDL4 | B7: L4 | C7: RASPA | D7: 2 | E7: 2 | F7: 3 | G7: EPR ou XLPE | H7: 13 | I7: F | J7: 2.5 | K7: 2.5 | L7: 2.5
B8: L5 | C8: RASPA | D8: 2 | E8: 2 | F8: 3 | G8: EPR ou XLPE | H8: 13 | I8: F | J8: 2.5 | K8: 2.5 | L8: 2.5
B9: L6
B10: L7
B11: L8
B12: L9
B13: L10
B14: L11
B15: L12
B16: L13
B17: L14
B18: L15
B19: L16
B20: L17
A21: QDL-5 | B21: L18
A22: QDL-6 | B22: L19
B23: L20
A24: QDL-7 | B24: L21

Sheet DISJUNTORES
A1: Disjuntor (A) | H1: Mudou disjuntor
A2: Quadro | B2: Nº do circuito | C2: Área | D2: Iz' (A) | E2: In (A) | F2: Ip (A) | G2: Iz'>In>Ip
A3: QDL0 | B3: L0 | C3: SUBESTAÇÃO | D3: ='QDL-FATOR CORREÇÃO'!P3 -> 20.01 | E3: 16 | F3: ='QDL-FATOR CORREÇÃO'!M3 -> 11.363636 | G3: =IF(AND(D3>E3,E3>F3),"OK","MUDAR DISJUNTOR") -> OK | H3: 10 para 16
A4: QDL1 | B4: L1 | C4: SALA DE CALDEIRAS | D4: ='QDL-FATOR CORREÇÃO'!P4 -> 19.14 | E4: 10 | F4: ='QDL-FATOR CORREÇÃO'!M4 -> 8 | G4: =IF(AND(D4>E4,E4>F4),"OK","MUDAR DISJUNTOR") -> OK | J4: A corrente comercial do disjuntor é o In
A5: QDL2 | B5: L2 | C5: COMPRESSOR (BOMBAS E PRENSA) | D5: ='QDL-FATOR CORREÇÃO'!P5 -> 19.14 | E5: 16 | F5: ='QDL-FATOR CORREÇÃO'!M5 -> 12 | G5: =IF(AND(D5>E5,E5>F5),"OK","MUDAR DISJUNTOR") -> OK | H5: 10 para 16
A6: QDL3 | B6: L3 | C6: DEPOSITO DE CARCAÇAS | D6: ='QDL-FATOR CORREÇÃO'!P6 -> 19.14 | E6: 16 | F6: ='QDL-FATOR CORREÇÃO'!M6 -> 12 | G6: =IF(AND(D6>E6,E6>F6),"OK","MUDAR DISJUNTOR") -> OK | H6: 10 para 16
A7: QDL4 | B7: L4 | C7: RASPA | D7: ='QDL-FATOR CORREÇÃO'!P7 -> 22.968 | E7: 16 | F7: ='QDL-FATOR CORREÇÃO'!M7 -> 12 | G7: =IF(AND(D7>E7,E7>F7),"OK","MUDAR DISJUNTOR") -> OK
B8: L5 | C8: RASPA | D8: ='QDL-FATOR CORREÇÃO'!P8 -> 22.968 | E8: 16 | F8: ='QDL-FATOR CORREÇÃO'!M8 -> 12 | G8: =IF(AND(D8>E8,E8>F8),"OK","MUDAR DISJUNTOR") -> OK
B9: L6
B10: L7
B11: L8
B12: L9
B13: L10
B14: L11
B15: L12
B16: L13
B17: L14
B18: L15
B19: L16
B20: L17
A21: QDL5 | B21: L18
A22: QDL6 | B22: L19
B23: L20
A24: QDL7 | B24: L21

Sheet QDL-QUEDA DE TENSÃO
I2: Seção dos condutores (mm²)
I3: Quadro | J3: Nº do circuito | K3: Área | L3: Cabos multipolares | M3: Circuitos agrupados | N3: Condutores carregados CC | O3: Isolação | P3: Método de Instalação | Q3: Método de Referência | R3: Fase | S3: Neutro | T3: Terra
I4: QDL0 | J4: L0 | K4: SUBESTAÇÃO | L4: 1 | M4: 1 | N4: 2 | O4: EPR ou XLPE | P4: 33 | Q4: B1 | R4: 1.5 | S4: 1.5 | T4: 1.5
I5: QDL1 | J5: L1 | K5: SALA DE CALDEIRAS | L5: 1 | M5: 1 | N5: 2 | O5: EPR ou XLPE | P5: 13 | Q5: F | R5: 1.5 | S5: 1.5 | T5: 1.5
I6: QDL2 | J6: L2 | K6: COMPRESSOR (BOMBAS E PRENSA) | L6: 1 | M6: 1 | N6: 2 | O6: EPR ou XLPE | P6: 13 | Q6: F | R6: 1.5 | S6: 1.5 | T6: 1.5
I7: QDL3 | J7: L3 | K7: DEPOSITO DE CARCAÇAS | L7: 1 | M7: 1 | N7: 2 | O7: EPR ou XLPE | P7: 13 | Q7: F | R7: 1.5 | S7: 1.5 | T7: 1.5
I8: QDL4 | J8: L4 | K8: RASPA | L8: 2 | M8: 2 | N8: 3 | O8: EPR ou XLPE | P8: 13 | Q8: F | R8: 2.5 | S8: 2.5 | T8: 2.5
J9: L5 | K9: RASPA | L9: 2 | M9: 2 | N9: 3 | O9: EPR ou XLPE | P9: 13 | Q9: F | R9: 2.5 | S9: 2.5 | T9: 2.5
J10: L6
J11: L7
J12: L8
J13: L9
J14: L10
J15: L11
J16: L12
J17: L13
J18: L14
J19: L15
J20: L16
J21: L17
I22: QDL5 | J22: L18
I23: QDL6 | J23: L19
J24: L20
I25: QDL7 | J25: L21
I45: Em subida QDL adotar a altura ou pé direito do local e considerar a bitola para subtrair 1,5 ou 3
A51: Tensão (V) | B51: 220
A52: Potência Unitária (VA) | B52: =QDL!$H$3 -> 500
A53: Qtd Luminárias | B53: =QDL!$G$3 -> 5
A54: QDL0 - Subestação | P54: Tabela de queda tensão adaptada Prysmian
A55: Circuito L0 | B55: Corrente Ip (A) | C55: Distância L (m) | D55: Seção (mm²) | E55: R [Ω/m] | F55: X [Ω/m] | G55: FP | H55: ΔV (V) | I55: ΔV (%) | J55: ΔV(%)* | L55: Comprimento | M55: Curva | N55: Subida QDL | P55: QDL0 - Subestação
P56: Circuito L0 | Q56: Corrente Ip (A) | R56: Distância L (m) | S56: Seção (mm²) | T56: FP | U56: ΔV unitário (V) | V56: ΔV (%) | W56: ΔV(%)*
P57: =A56 | Q57: =B56 | R57: =C56
P58: =A57 | Q58: =B57 | R58: =C57
P59: =A58 | Q59: =B58 | R59: =C58
P60: =A59 | Q60: =B59 | R60: =C59
A62: Potência Unitária | B62: =QDL!$H$4 -> 440
A63: Qtd Luminárias | B63: =QDL!$G$4 -> 4 | P63: Tabela de queda tensão adaptada Prysmian
A64: QDL1 - Sala de Caldeiras | P64: QDL1 - Sala de Caldeiras
A65: Circuito L1 | B65: Corrente Ip (A) | C65: Distância L (m) | D65: Seção (mm²) | E65: R [Ω/m] | F65: X [Ω/m] | G65: FP | H65: ΔV (V) | I65: ΔV (%) | J65: ΔV(%)* | L65: Comprimento | M65: Curva | N65: Subida QDL | P65: Circuito L1 | Q65: Corrente Ip (A) | R65: Distância L (m) | S65: Seção (mm²) | T65: FP | U65: ΔV unitário (V) | V65: ΔV (%) | W65: ΔV(%)*
A66: QDL1-LU1 | B66: =($B$62*4)/$B$51 -> 8 | C66: =L66+(M66*1.5)+N66 -> 11.42 | D66: 1.5 | E66: =14.8137*10^-3 -> 0.0148137 | F66: =0.1378*10^-3 -> 0.0001378 | G66: =QDL!K$4 -> 0.85 | H66: =2*B66*C66*(E66*G66+F66*SIN(ACOS(G66))) -> 2.3140091 | I66: =H66/220 -> 0.010518223 | J66: =I66 -> 0.010518223 | L66: =1.5+1.42 -> 2.92 | M66: 2 | N66: =7-1.5 -> 5.5 | P66: =A66 -> QDL1-LU1 | Q66: =B66 -> 8 | R66: =C66 -> 11.42 | S66: 1.5 | T66: =G66 -> 0.85 | U66: 23 | V66: =(R66/1000)*Q66*U66*(100/220)/100 -> 0.0095512727 | W66: =V66 -> 0.0095512727
...

Sheet QDL-BALANÇO TOTAL
A2: QDL_ILUMINAÇÃO
E3: Balanço de potencias (VA)
A4: Quadro | B4: Nº do circuito | C4: Área | D4: DEMANDA (VA) | E4: R | F4: S | G4: T
A5: QDL0 | B5: L0 | C5: SUBESTAÇÃO | D5: =QDL!I3 -> 2500 | E5: 2500 | F5: - | G5: -
A6: QDL1 | B6: L1 | C6: SALA DE CALDEIRAS | D6: =QDL!I4 -> 1760 | E6: - | F6: 1760 | G6: -
A7: QDL2 | B7: L2 | C7: COMPRESSOR (BOMBAS E PRENSA) | D7: =QDL!I5 -> 2640 | E7: - | F7: - | G7: 2640
A8: QDL3 | B8: L3 | C8: DEPOSITO DE CARCAÇAS | D8: =QDL!I6 -> 2640 | E8: 2640 | F8: - | G8: -
A9: QDL4 | B9: L4 | C9: RASPA | D9: =QDL!I7 -> 2640 | E9: - | F9: 2640 | G9: -
B10: L5 | C10: RASPA | D10: =QDL!I8 -> 2640 | E10: - | F10: - | G10: 2640
B11: L6
B12: L7
B13: L8
B14: L9
B15: L10
B16: L11
B17: L12
B18: L13
B19: L14
B20: L15
B21: L16
B22: L17
A23: QDL5 | B23: L18
A24: QDL6 | B24: L19
B25: L20
A26: QDL7 | B26: L21
A28: SOMATÓRIO | E28: =SUM(E3:E27) -> 5140 | F28: =SUM(F3:F27) -> 4400 | G28: =SUM(G3:G27) -> 5280
A29: TOTAL DAS FASES | E29: =SUM(E28:G28) -> 14820
C30: DIVISÃO TOTAL DAS FASES | E30: =E29/3 -> 4940
C31: FASE MAIS CARREGADA | E31: =G28/220 -> 24
A35: QDF_TOMADAS

Sheet QDL-BALANÇO POTENCIAS
A1: QDL0 - Subestação
A2: Circuito | B2: Área | C2: Corrente do Disjuntor In (A) | D2: Disjuntor | E2: Capacidade de interrupção do disjuntor (kA) | F2: Balanço de potência (VA)
F3: R | G3: S | H3: T
A7: QDL1 - Sala de Caldeiras
A8: Circuito | B8: Área | C8: Corrente do Disjuntor In (A) | D8: Disjuntor | E8: Capacidade de interrupção do disjuntor (kA) | F8: Balanço de potência (VA)
F9: R | G9: S | H9: T
A10: =QDL!B4 -> L1 | B10: =QDL!C4 -> SALA DE CALDEIRAS | C10: =DISJUNTORES!E4 -> 10 | D10: MDW-C10 | E10: 5 | F10: ='QDL-BALANÇO TOTAL'!E6 -> - | G10: ='QDL-BALANÇO TOTAL'!F6 -> 1760 | H10: ='QDL-BALANÇO TOTAL'!G6 -> -
J23: Disjuntor escolhe baseado na In obtida lá em disjuntores
J46: Capacidade de interrupção do disjuntor (kA)
J48: pergunta: Capacidade de interrupção do disjuntor (kA) eu posso colocar 2 kA por ser 220 V certo?
J68: Balanço de potência confiro a distribuição em balanço total
A72: QDL2 - Compressor
A73: Circuito | B73: Área | C73: Corrente do Disjuntor In (A) | D73: Disjuntor | E73: Capacidade de interrupção do disjuntor (kA) | F73: Balanço de potência (VA)
F74: R | G74: S | H74: T
A75: =QDL!B5 -> L2 | B75: =QDL!C5 -> COMPRESSOR (BOMBAS E PRENSA) | C75: =DISJUNTORES!E5 -> 16 | D75: MDW-C16 | E75: 5 | F75: ='QDL-BALANÇO TOTAL'!E7 -> - | G75: ='QDL-BALANÇO TOTAL'!F7 -> - | H75: ='QDL-BALANÇO TOTAL'!G7 -> 2640
J95: Disjuntor escolhe baseado na In obtida lá em disjuntores
J118: Capacidade de interrupção do disjuntor (kA)
J120: pergunta: Capacidade de interrupção do disjuntor (kA) eu posso colocar 2 kA por ser 220 V certo?
J140: Balanço de potência confiro a distribuição em balanço total
A143: QDL3 - Depósito de carcaças
A144: Circuito | B144: Área | C144: Corrente do Disjuntor In (A) | D144: Disjuntor | E144: Capacidade de interrupção do disjuntor (kA) | F144: Balanço de potência (VA)
F145: R | G145: S | H145: T
A146: =QDL!B6 -> L3 | B146: =QDL!C6 -> DEPÓSITO DE CARCAÇAS | C146: =DISJUNTORES!E6 -> 16 | D146: MDW-C16 | E146: 5 | F146: ='QDL-BALANÇO TOTAL'!E8 -> 2640 | G146: ='QDL-BALANÇO TOTAL'!F8 -> - | H146: ='QDL-BALANÇO TOTAL'!G8 -> -
K166: Disjuntor escolhe baseado na In obtida lá em disjuntores
K189: Capacidade de interrupção do disjuntor (kA)
K191: pergunta: Capacidade de interrupção do disjuntor (kA) eu posso colocar 2 kA por ser 220 V certo?
K209: Balanço de potência confiro a distribuição em balanço total
A210: QDL4 - Raspa e Recapagem
A211: Circuito | B211: Área | C211: Corrente do Disjuntor In (A) | D211: Disjuntor | E211: Capacidade de interrupção do disjuntor (kA) | F211: Balanço de potência (VA)
F212: R | G212: S | H212: T
A213: =QDL!B7 -> L4 | B213: =QDL!C7 -> RASPA | C213: =DISJUNTORES!E7 -> 16 | D213: MDW-C16 | E213: 5 | F213: ='QDL-BALANÇO TOTAL'!E9 -> - | G213: ='QDL-BALANÇO TOTAL'!F9 -> 2640 | H213: ='QDL-BALANÇO TOTAL'!G9 -> -
A214: =QDL!B8 -> L5 | B214: =QDL!C8 -> RASPA | C214: =DISJUNTORES!E8 -> 16 | D214: MDW-C16 | E214: 5 | F214: ='QDL-BALANÇO TOTAL'!E10 -> - | G214: ='QDL-BALANÇO TOTAL'!F10 -> - | H214: ='QDL-BALANÇO TOTAL'!G10 -> 2640
A215: =QDL!B9 -> L6 | C215: =DISJUNTORES!E9 | D215: =QDL!D205
A216: =QDL!B10 -> L7 | C216: =DISJUNTORES!E10 | D216: =QDL!D206
A217: =QDL!B11 -> L8 | C217: =DISJUNTORES!E11 | D217: =QDL!D207
A218: =QDL!B12 -> L9 | C218: =DISJUNTORES!E12 | D218: =QDL!D208
A219: =QDL!B13 -> L10 | C219: =DISJUNTORES!E13 | D219: =QDL!D209
A220: =QDL!B14 -> L11 | C220: =DISJUNTORES!E14 | D220: =QDL!D210
A221: =QDL!B15 -> L12 | C221: =DISJUNTORES!E15 | D221: =QDL!D211
A222: =QDL!B16 -> L13 | C222: =DISJUNTORES!E16 | D222: =QDL!D212
...

Sheet QDGL
A3: Quadro | B3: Nº do circuito | C3: Área | D3: DEMANDA (VA) | E3: FP
A4: QDL0 | B4: L0 | C4: SUBESTAÇÃO | D4: =QDL!I3 -> 2500 | E4: =QDL!K3 -> 0.95
A5: QDL1 | B5: L1 | C5: SALA DE CALDEIRAS | D5: =QDL!I4 -> 1760 | E5: =QDL!K4 -> 0.85
A6: QDL2 | B6: L2 | C6: COMPRESSOR (BOMBAS E PRENSA) | D6: =QDL!I5 -> 2640 | E6: =QDL!K5 -> 0.85
A7: QDL3 | B7: L3 | C7: DEPOSITO DE CARCAÇAS | D7: =QDL!I6 -> 2640 | E7: =QDL!K6 -> 0.85
A8: QDL4 | B8: L4 | C8: RASPA | D8: =QDL!I7 -> 2640 | E8: =QDL!K7 -> 0.85
B9: L5 | C9: RASPA | D9: =QDL!I8 -> 2640 | E9: =QDL!K8 -> 0.85
B10: L6 | D10: =QDL!I9
B11: L7 | D11: =QDL!I10
B12: L8 | D12: =QDL!I11
B13: L9 | D13: =QDL!I12
B14: L10 | D14: =QDL!I13
B15: L11 | D15: =QDL!I14
B16: L12 | D16: =QDL!I15
B17: L13 | D17: =QDL!I16
B18: L14 | D18: =QDL!I17
B19: L15 | D19: =QDL!I18
B20: L16 | D20: =QDL!I19
B21: L17 | D21: =QDL!I20
A22: QDL5 | B22: L18
A23: QDL6 | B23: L19
B24: L20
A25: QDL7 | B25: L21
A28: Circuito | B28: Disjuntor | C28: Corrente do Disjuntor (A) | D28: Potência aparente (VA)
A30: QDL-0 | B30: MDWH-C10 | C30: 10 | D30: =D4 -> 2500
A31: QDL-1 | B31: MDWH-C10 | C31: 10 | D31: =D5 -> 1760
A32: QDL-2 | B32: MDWH-C10 | C32: 10 | D32: =D6 -> 2640
A33: QDL-3 | B33: MDWH-C10 | C33: 10 | D33: =D7 -> 2640
A34: QDL-4 | B34: MDWH-C100 | C34: 100 | D34: =SUM(D8:D21) -> 5280
A35: QDL-5 | B35: MDWH-C10 | C35: 10 | D35: =D22
A36: QDL-6 | B36: MDWH-C10-3 | C36: 10 | D36: =SUM(D23:D24) -> 0
A37: QDL-7 | B37: MDWH-C10 | C37: 10 | D37: =D25
A38: Total | D38: =SUM(D30:D37) -> 14820
A39: RQDL-1 | D39: ='QDL-BALANÇO TOTAL'!E30 -> 4940
A40: RQDL-2 | D40: =D39 -> 4940
A41: RQDL-3 | D41: =D39 -> 4940
A42: Total | D42: =SUM(D38:D41) -> 29640
A45: Quadro | B45: Tensão [V] | C45: Corrente nominal [A] | D45: Método de instalação | E45: Método de referência
A46: QDL-0 | B46: 220 | C46: =D30/B46 -> 11.363636 | D46: 13 | E46: F
A47: QDL-1 | B47: 220 | C47: =D31/B47 -> 8 | D47: 13 | E47: F
...
