Workbook

Sheet Controle
C2: SETOR | D2: ALTURA (m) | E2: ALTURA DE TRABALHO (m) | F2: LARGURA (m) | G2: COMPRIMENTO (m) | H2: PERÍMETRO (m) | I2: ÁREA (m²) | J2: TETO | K2: PAREDE | L2: PISO
C3: SUBESTAÇÃO | D3: 7 | E3: 0.8 | F3: 9.6 | G3: 9.8 | H3: =(2*F3)+(2*G3) -> 38.8 | I3: =F3*G3 -> 94.08 | J3: BRANCO | K3: BRANCA | L3: CONCRETO
C4: ESCRITÓRIO | D4: 3 | E4: 0.8 | F4: 6 | G4: 8.12 | H4: =(2*F4)+(2*G4) -> 28.24 | I4: =F4*G4 -> 48.72 | J4: BRANCO | K4: BEGE | L4: AZULEJO CINZA
C5: CONTROLE DE QUALIDADE | D5: 3 | E5: 0.8 | F5: 6 | G5: 5 | H5: =(2*F5)+(2*G5) -> 22 | I5: =F5*G5 -> 30 | J5: BRANCO | K5: BRANCA | L5: AZULEJO CINZA
C6: SAIDA DE PRODUTOS | D6: 3 | E6: 0.8 | F6: 6 | G6: 5 | H6: =(2*F6)+(2*G6) -> 22 | I6: =F6*G6 -> 30 | J6: CLARO | K6: CLARA | L6: AZULEJO CINZA
C7: BANHEIRO | D7: 3 | E7: 0.8 | F7: 3.5 | G7: 5.23 | H7: =(2*F7)+(2*G7) -> 17.46 | I7: =F7*G7 -> 18.305 | J7: CLARO | K7: CLARA | L7: AZULEJO CINZA
C8: DEPÓSITO DE CARCAÇAS 01 | D8: 7 | E8: 0.8 | F8: 6 | G8: 8.12 | H8: 56.96 | I8: 157.69 | J8: ZINCO | K8: CLARA | L8: CONCRETO
C9: DEPÓSITO DE CARCAÇAS 02 | D9: 7 | E9: 0.8 | F9: 9.6 | G9: 11.18 | H9: 56.96 | I9: 157.69 | J9: ZINCO | K9: CLARA | L9: CONCRETO
C10: SALA DE CALDEIRA | D10: 7 | E10: 0.8 | F10: 9.6 | G10: 15.92 | H10: =(2*F10)+(2*G10) -> 51.04 | I10: =F10*G10 -> 152.832 | J10: ZINCO | K10: CLARA | L10: CONCRETO
C11: RASPA | D11: 7 | E11: 0.8 | F11: 30.92 | G11: 8.12 | H11: =(2*F11)+(2*G11) -> 78.08 | I11: =F11*G11 -> 251.0704 | J11: ZINCO | K11: CLARA | L11: CONCRETO
C12: COMPRESSOR | D12: 7 | E12: 0.8 | F12: 9.6 | G12: 9.28 | H12: =(2*F12)+(2*G12) -> 37.76 | I12: =F12*G12 -> 89.088 | J12: ZINCO | K12: CLARA | L12: CONCRETO
C13: RECAPAGEM | D13: 7 | E13: 0.8 | F13: - | G13: - | H13: 163.77 | I13: 1585.67 | J13: ZINCO | K13: CLARA | L13: CONCRETO
B15: T1
B16: RESPONSÁVEL | C16: SETOR | D16: MÉTODO | E16: ALTURA DE TRABALHO (m) | F16: TIRANTE (m) | G16: ALTURA MÍNIMA (m) | H16: PÉ DIREITO (m) | I16: TETO | J16: PAREDE | K16: PISO | L16: STATUS
B17: GABRIEL | C17: SUBESTAÇÃO | D17: LUMENS | E17: 0.8 | F17: 0 | G17: 4 | H17: 7 | I17: BRANCO | J17: BRANCA | K17: CONCRETO | L17: FEITO
B18: GABRIEL | C18: ESCRITÓRIO | D18: LUMENS | E18: 0.8 | F18: - | G18: - | H18: 3 | I18: BRANCO | J18: BEGE | K18: AZULEJO CINZA | L18: FEITO
B19: GABRIEL | C19: CONTROLE DE QUALIDADE | D19: LUMENS | E19: 0.8 | F19: - | G19: - | H19: 3 | I19: BRANCO | J19: BRANCA | K19: AZULEJO CINZA | L19: FEITO
B20: GABRIEL | C20: SAIDA DE PRODUTOS | D20: LUMENS | E20: 0.8 | F20: - | G20: - | H20: 3 | I20: CLARO | J20: CLARA | K20: AZULEJO CINZA | L20: FEITO
B21: GABRIEL | C21: BANHEIRO | D21: LUMENS | E21: 0.8 | F21: - | G21: - | H21: 3 | I21: CLARO | J21: CLARA | K21: AZULEJO CINZA | L21: FEITO
B22: GABRIEL | C22: DEPÓSITO DE CARCAÇAS 01 | D22: LUMENS | E22: 0.8 | F22: 1 | G22: 4 | H22: 7 | I22: ZINCO | J22: CLARA | K22: CONCRETO | L22: FEITO
B23: GABRIEL | C23: DEPÓSITO DE CARCAÇAS 02 | D23: LUMENS | E23: 0.8 | F23: 1 | G23: 4 | H23: 7 | I23: ZINCO | J23: CLARA | K23: CONCRETO | L23: FEITO
B24: GABRIEL | C24: SALA DE CALDEIRA | D24: LUMENS | E24: 0.8 | F24: 1 | G24: 4 | H24: 7 | I24: ZINCO | J24: CLARA | K24: CONCRETO | L24: FEITO
B25: GABRIEL | C25: RASPA | D25: LUMENS | E25: 0.8 | F25: 1 | G25: 4 | H25: 7 | I25: ZINCO | J25: CLARA | K25: CONCRETO | L25: FEITO
B26: GABRIEL | C26: COMPRESSOR | D26: LUMENS | E26: 0.8 | F26: 1 | G26: 4 | H26: 7 | I26: ZINCO | J26: CLARA | K26: CONCRETO | L26: FEITO
B27: GABRIEL | C27: RECAPAGEM | D27: CAVIDADES | E27: 0.8 | F27: 1 | G27: 4 | H27: 7 | I27: ZINCO | J27: CLARA | K27: CONCRETO | L27: FEITO
C29: SETOR | D29: LUMINÁRIA | F29: LÂMPADAS | K29: REATOR | O29: DADOS DE PROJETO
D30: MODELO | E30: FABRICANTE | F30: MODELO | G30: FABRICANTE | H30: POTÊNCIA (W) | I30: FLUXO LUMINOSO | J30: NÚMERO DE LUMINÁRIAS | K30: MODELO | L30: FABRICANTE | M30: POTÊNCIA REATOR | N30: F.P | O30: TENSÃO (V) | P30: QUANTIDADE DE LUMINÁRIA | Q30: POTÊNCIA POR PONTO (VA) | R30: POTÊNCIA FINAL (VA) | S30: CORRENTE (A)
C31: SUBESTAÇÃO | D31: ='Subestação'!$B$9 -> NE250CN3H25 | E31: ='Subestação'!B$10 -> Nutsteel | F31: ='Subestação'!B$21 -> HQI-T 250 W/D PRO | G31: ='Subestação'!B$22 -> OSRAM | H31: ='Subestação'!B$23 -> 250 | I31: ='Subestação'!B$24 -> 19100 | J31: ='Subestação'!B$25 -> 1 | K31: ='Subestação'!E$21 -> PTo 250/220…240 3DIM | L31: ='Subestação'!E$22 -> OSRAM | M31: ='Subestação'!E$23 -> 12.5 | N31: ='Subestação'!E$24 -> 0.95 | O31: ='Subestação'!B$148 -> 220 | P31: ='Subestação'!B$123 -> 5 | Q31: ='Subestação'!B$150 -> 270 | R31: =Q31*P31 -> 1350 | S31: =R31/O31 -> 6.1363636
C32: ESCRITÓRIO | D32: ='Escritório'!$B$9 -> TSM 426 - 2 lampadas de 40W | E32: ='Escritório'!B$10 -> Phillips | F32: ='Escritório'!B$21 -> Luminária TMS 426 | G32: ='Escritório'!B$22 -> Phillips | H32: ='Escritório'!B$23 -> 40 | I32: ='Escritório'!B$24 -> 3000 | J32: ='Escritório'!B$25 -> 2 | K32: ='Escritório'!E$21 -> POUP-AFP-6F | L32: ='Escritório'!E$22 -> Intral | M32: ='Escritório'!E$23 -> 4 | N32: ='Escritório'!E$24 -> 0.97 | O32: ='Escritório'!B$148 -> 220 | P32: ='Escritório'!B$123 -> 4 | Q32: ='Escritório'!B$150 -> 90 | R32: =Q32*P32 -> 360 | S32: =R32/O32 -> 1.6363636
C33: CONTROLE DE QUALIDADE | D33: ='Controle de Qualidade'!B$9 -> TSM 426 - 2 lampadas de 40W | E33: ='Controle de Qualidade'!B$10 -> Phillips | F33: ='Controle de Qualidade'!B$21 -> Luminária TMS 426 | G33: ='Controle de Qualidade'!B$22 -> Phillips | H33: ='Controle de Qualidade'!B$23 -> 40 | I33: ='Controle de Qualidade'!B$24 -> 3000 | J33: ='Controle de Qualidade'!B$25 -> 2 | K33: ='Controle de Qualidade'!E$21 -> POUP-AFP-6F | L33: ='Controle de Qualidade'!E$22 -> Intral | M33: ='Controle de Qualidade'!E$23 -> 4 | N33: ='Controle de Qualidade'!E$24 -> 0.97 | O33: ='Controle de Qualidade'!B$148 -> 220 | P33: ='Controle de Qualidade'!B$123 -> 16 | Q33: ='Controle de Qualidade'!B$150 -> 90 | R33: =Q33*P33 -> 1440 | S33: =R33/O33 -> 6.5454545
C34: SAIDA DE PRODUTOS | D34: ='Saida de produto'!B$9 -> TSM 426 - 2 lampadas de 40W | E34: ='Saida de produto'!B$10 -> Phillips | F34: ='Saida de produto'!B$21 -> Luminária TMS 426 | G34: ='Saida de produto'!B$22 -> Phillips | H34: ='Saida de produto'!B$23 -> 40 | I34: ='Saida de produto'!B$24 -> 3000 | J34: ='Saida de produto'!B$25 -> 2 | K34: ='Saida de produto'!E$21 -> POUP-AFP-6F | L34: ='Saida de produto'!E$22 -> Intral | M34: ='Saida de produto'!E$23 -> 4 | N34: ='Saida de produto'!E$24 -> 0.97 | O34: ='Saida de produto'!B$148 -> 220 | P34: ='Saida de produto'!B$123 -> 6 | Q34: ='Saida de produto'!B$150 -> 90 | R34: =Q34*P34 -> 540 | S34: =R34/O34 -> 2.4545455
C35: BANHEIRO | D35: =Banheiro!B$9 -> TSM 426 - 2 lampadas de 40W | E35: =Banheiro!B$10 -> Phillips | F35: =Banheiro!B$21 -> Luminária TMS 426 | G35: =Banheiro!B$22 -> Phillips | H35: =Banheiro!B$23 -> 40 | I35: =Banheiro!B$24 -> 3000 | J35: =Banheiro!B$25 -> 2 | K35: =Banheiro!E$21 -> POUP-AFP-6F | L35: =Banheiro!E$22 -> Intral | M35: =Banheiro!E$23 -> 4 | N35: =Banheiro!E$24 -> 0.97 | O35: =Banheiro!B$148 -> 220 | P35: =Banheiro!B$123 -> 2 | Q35: =Banheiro!B$150 -> 90 | R35: =Q35*P35 -> 180 | S35: =R35/O35 -> 0.81818182
C36: DEPÓSITO DE CARCAÇAS 01 | D36: ='Dep. Carcaça 01'!$B$9 -> HDK 474 + GDK 472 PG | E36: ='Dep. Carcaça 01'!B$10 -> Phillips | F36: ='Dep. Carcaça 01'!B$21 -> SON 250W E E40 CO 1SL | G36: ='Dep. Carcaça 01'!B$22 -> Phillips | H36: ='Dep. Carcaça 01'!B$23 -> 250 | I36: ='Dep. Carcaça 01'!B$24 -> 26000 | J36: ='Dep. Carcaça 01'!B$25 -> 1 | K36: ='Dep. Carcaça 01'!E$21 -> VSTI250A26IGOS | L36: ='Dep. Carcaça 01'!E$22 -> Phillips | M36: ='Dep. Carcaça 01'!E$23 -> 30 | N36: ='Dep. Carcaça 01'!E$24 -> 0.95 | O36: ='Dep. Carcaça 01'!B$148 -> 220 | P36: ='Dep. Carcaça 01'!B$123 -> 2 | Q36: ='Dep. Carcaça 01'!B$150 -> 290 | R36: =Q36*P36 -> 580 | S36: =R36/O36 -> 2.6363636
C37: DEPÓSITO DE CARCAÇAS 02 | D37: ='Dep. Carcaça 02'!$B$9 -> HDK 474 + GDK 472 PG | E37: ='Dep. Carcaça 02'!B$10 -> Phillips | F37: ='Dep. Carcaça 02'!B$21 -> SON 250W E E40 CO 1SL | G37: ='Dep. Carcaça 02'!B$22 -> Phillips | H37: ='Dep. Carcaça 02'!B$23 -> 250 | I37: ='Dep. Carcaça 02'!B$24 -> 26000 | J37: ='Dep. Carcaça 02'!B$25 -> 1 | K37: ='Dep. Carcaça 02'!E$21 -> VSTI250A26IGOS | L37: ='Dep. Carcaça 02'!E$22 -> Phillips | M37: ='Dep. Carcaça 02'!E$23 -> 30 | N37: ='Dep. Carcaça 02'!E$24 -> 0.95 | O37: ='Dep. Carcaça 02'!B$148 -> 220 | P37: ='Dep. Carcaça 02'!B$123 -> 4 | Q37: ='Dep. Carcaça 02'!B$150 -> 290 | R37: =Q37*P37 -> 1160 | S37: =R37/O37 -> 5.2727273
C38: SALA DE CALDEIRA | D38: ='Sala de Caldeira'!B$9 -> HDK 474 + GDK 472 PG | E38: ='Sala de Caldeira'!B$10 -> Phillips | F38: ='Sala de Caldeira'!B$21 -> SON 250W E E40 CO 1SL | G38: ='Sala de Caldeira'!B$22 -> Phillips | H38: ='Sala de Caldeira'!B$23 -> 250 | I38: ='Sala de Caldeira'!B$24 -> 26000 | J38: ='Sala de Caldeira'!B$25 -> 1 | K38: ='Sala de Caldeira'!E$21 -> VSTI250A26IGOS | L38: ='Sala de Caldeira'!E$22 -> Phillips | M38: ='Sala de Caldeira'!E$23 -> 30 | N38: ='Sala de Caldeira'!E$24 -> 0.95 | O38: ='Sala de Caldeira'!B$148 -> 220 | P38: ='Sala de Caldeira'!B$123 -> 4 | Q38: ='Sala de Caldeira'!B$150 -> 290 | R38: =Q38*P38 -> 1160 | S38: =R38/O38 -> 5.2727273
C39: RASPA | D39: =Raspa!B$9 -> HDK 474 + GDK 472 PG | E39: =Raspa!B$10 -> Phillips | F39: =Raspa!B$21 -> SON 250W E E40 CO 1SL | G39: =Raspa!B$22 -> Phillips | H39: =Raspa!B$23 -> 250 | I39: =Raspa!B$24 -> 26000 | J39: =Raspa!B$25 -> 1 | K39: =Raspa!E$21 -> VSTI250A26IGOS | L39: =Raspa!E$22 -> Phillips | M39: =Raspa!E$23 -> 30 | N39: =Raspa!E$24 -> 0.95 | O39: =Raspa!B$148 -> 220 | P39: =Raspa!B$123 -> 16 | Q39: =Raspa!B$150 -> 290 | R39: =Q39*P39 -> 4640 | S39: =R39/O39 -> 21.090909
C40: COMPRESSOR | D40: =Compressor!B$9 -> HDK 474 + GDK 472 PG | E40: =Compressor!B$10 -> Phillips | F40: =Compressor!B$21 -> SON 250W E E40 CO 1SL | G40: =Compressor!B$22 -> Phillips | H40: =Compressor!B$23 -> 250 | I40: =Compressor!B$24 -> 26000 | J40: =Compressor!B$25 -> 1 | K40: =Compressor!E$21 -> VSTI250A26IGOS | L40: =Compressor!E$22 -> Phillips | M40: =Compressor!E$23 -> 30 | N40: =Compressor!E$24 -> 0.95 | O40: =Compressor!B$148 -> 220 | P40: =Compressor!B$123 -> 6 | Q40: =Compressor!B$150 -> 290 | R40: =Q40*P40 -> 1740 | S40: =R40/O40 -> 7.9090909
C41: RECAPAGEM | D41: ='Recapagem - Cavidades'!B24 -> HDK 474 + GDK 472 PG | E41: ='Recapagem - Cavidades'!B25 -> Phillips | F41: ='Recapagem - Cavidades'!B36 -> SON 400W E E40 CO 1SL | G41: ='Recapagem - Cavidades'!B37 -> Phillips | H41: ='Recapagem - Cavidades'!B38 -> 400 | I41: ='Recapagem - Cavidades'!B39 -> 48800 | J41: ='Recapagem - Cavidades'!B40 -> 1 | K41: ='Recapagem - Cavidades'!E36 -> VTE400A26HQI E | L41: ='Recapagem - Cavidades'!E37 -> Phillips | M41: ='Recapagem - Cavidades'!E38 -> 30 | N41: ='Recapagem - Cavidades'!E39 -> 0.95 | O41: 220 | P41: =SUM('Recapagem - Cavidades'!B119:D119) -> 113 | Q41: ='Recapagem - Cavidades'!B125 -> 440 | R41: =Q41*P41 -> 49720 | S41: =R41/O41 -> 226
C45: SETOR | D45: DADOS DE PROJETO
D46: TENSÃO (V) | E46: QUANTIDADE DE LUMINÁRIA | F46: POTÊNCIA POR PONTO (W) | G46: POTÊNCIA FINAL (W) | H46: CORRENTE (A)
...

Sheet Template
A1: CARACTERISTICAS DO AMBIENTE
A3: SETOR | B3: LARGURA (m) | C3: COMPRIMENTO (m) | D3: ALTURA (m) | E3: ALTURA DE TRABALHO (m) | F3: Hlp (m) | G3: TETO | H3: PAREDE | I3: PISO | J3: TIPO DE LÂMPADA
A4: CONTROLE DE QUALIDADE | B4: {=_xlfn.XLOOKUP($A4,Controle!$C:$C,Controle!F:F)} -> 6 | C4: {=_xlfn.XLOOKUP($A4,Controle!$C:$C,Controle!G:G)} -> 5 | D4: {=_xlfn.XLOOKUP($A4,Controle!$C:$C,Controle!D:D)} -> 3 | E4: {=_xlfn.XLOOKUP($A4,Controle!$C:$C,Controle!E:E)} -> 0.8 | F4: =D4-E4 -> 2.2 | G4: {=_xlfn.XLOOKUP($A4,Controle!$C:$C,Controle!J:J)} -> BRANCO | H4: {=_xlfn.XLOOKUP($A4,Controle!$C:$C,Controle!K:K)} -> BRANCA | I4: {=_xlfn.XLOOKUP($A4,Controle!$C:$C,Controle!L:L)} -> AZULEJO CINZA | J4: FLUORESCENTE
A6: LUMINÁRIA SELECIONADA
A8: CARACTERISTICAS LUMINÁRIA
A9: MODELO | B9: TSM 426 - 2 lampadas de 40W
A10: FABRICANTE | B10: Phillips
A18: LÂMPADA E RETOR SELECIONADOS
A20: CARACTERISTICAS LÂMPADA | D20: CARACTERISTICAS REATOR
A21: MODELO | B21: Luminária TMS 426 | D21: MODELO | E21: POUP-AFP-6F
A22: FABRICANTE | B22: Phillips | D22: FABRICANTE | E22: Intral
A23: POTÊNCIA (W) | B23: 40 | D23: POTÊNCIA REATOR | E23: =(B23*B25)*5/100 -> 4
A24: FLUXO LUMINOSO | B24: 3000 | D24: F.P | E24: 0.97
A25: NÚMERO DE LUMINÁRIAS | B25: 2
A27: DETERMINAÇÃO DO FATOR DE DEPRECIAÇÃO (Fdl)
A29: Categoria da Luminaria | B29: IV
A30: Vida útil da lampada (tabela 2.1 mamede) (h) | B30: 10000
A31: Tempo de manutenção (meses) | B31: =(B30/2)/(14*30) -> 11.904762
A32: Categoria do local | B32: LIMPO
A45: FATOR DE DEPRECIAÇÃO | B45: 0.88
A47: DETERMINAÇÃO DO FATOR DE UTILIZAÇÃO (Fu)
A52: K | B52: =(C4*B4)/(F4*(C4+B4)) -> 1.2396694
A56: tera que fazer interpolação pois 1,52 nao existe na tabela 2.9 do mamede
A62: TETO | B62: =G4 -> BRANCO
A63: PAREDE | B63: =H4 -> BRANCA
A64: PISO | B64: =I4 -> AZULEJO CINZA
A65: pte | B65: 0.7
A66: ppa | B66: 0.5
A67: pp | B67: 0.45
A68: Fu | B68: 0.56
A76: DETERMINAÇÃO DE ILUMINAMENTO (E)
A78: IDADE | B78: 41 anos
A79: VELOCIDADE E PRECISÃO | B79: Importante
A80: REFLETÂNCIA NO FUNDO DA TAREFA | B80: 0.4
A81: PESO FINAL | B81: 0
A93: CATEGORIA B - INSPEÇÃO
A94: ILUMINAMENTO (Lux) | B94: 1500
A108: DETERMINAÇÃO DE FLUXO TOTAL (Wt)
A113: Wt (lm) | B113: =(B94*(B4*C4))/(B45*B68) -> 91314.935
A119: DETERMINAÇÃO DE NÚMERO DE LUMINÁRIAS (Nlu)
...

Sheet Subestação
A1: CARACTERISTICAS DO AMBIENTE
A3: SETOR | B3: LARGURA (m) | C3: COMPRIMENTO (m) | D3: ALTURA (m) | E3: ALTURA DE TRABALHO (m) | F3: Hlp (m) | G3: TETO | H3: PAREDE | I3: PISO | J3: TIPO DE LÂMPADA
A4: SUBESTAÇÃO | B4: {=_xlfn.XLOOKUP($A4,Controle!$C:$C,Controle!F:F)} -> 9.6 | C4: {=_xlfn.XLOOKUP($A4,Controle!$C:$C,Controle!G:G)} -> 9.8 | D4: {=_xlfn.XLOOKUP($A4,Controle!$C:$C,Controle!D:D)} -> 7 | E4: {=_xlfn.XLOOKUP($A4,Controle!$C:$C,Controle!E:E)} -> 0.8 | F4: =D4-E4 -> 6.2 | G4: {=_xlfn.XLOOKUP($A4,Controle!$C:$C,Controle!J:J)} -> BRANCO | H4: {=_xlfn.XLOOKUP($A4,Controle!$C:$C,Controle!K:K)} -> BRANCA | I4: {=_xlfn.XLOOKUP($A4,Controle!$C:$C,Controle!L:L)} -> CONCRETO | J4: VAPOR DE SÓDIO
A6: LUMINÁRIA SELECIONADA
A8: CARACTERISTICAS LUMINÁRIA
A9: MODELO | B9: NE250CN3H25
A10: FABRICANTE | B10: Nutsteel
A18: LÂMPADA E RETOR SELECIONADOS
A20: CARACTERISTICAS LÂMPADA | D20: CARACTERISTICAS REATOR
A21: MODELO | B21: HQI-T 250 W/D PRO | D21: MODELO | E21: PTo 250/220…240 3DIM
A22: FABRICANTE | B22: OSRAM | D22: FABRICANTE | E22: OSRAM
A23: POTÊNCIA (W) | B23: 250 | D23: POTÊNCIA REATOR | E23: =(B23*B25)*5/100 -> 12.5
A24: FLUXO LUMINOSO | B24: 19100 | D24: F.P | E24: 0.95
A25: NÚMERO DE LUMINÁRIAS | B25: 1
A27: DETERMINAÇÃO DO FATOR DE DEPRECIAÇÃO (Fdl)
A29: Categoria da Luminaria | B29: V
A30: Vida útil da lampada (tabela 2.1 mamede) (h) | B30: 16000
A31: Tempo de manutenção (meses) | B31: =(B30/2)/(14*30) -> 19.047619
A32: Categoria do local | B32: LIMPO
A45: FATOR DE DEPRECIAÇÃO | B45: 0.82
A47: DETERMINAÇÃO DO FATOR DE UTILIZAÇÃO (Fu)
A52: K | B52: =(C4*B4)/(F4*(C4+B4)) -> 0.78217493
A56: tera que fazer interpolação pois 1,52 nao existe na tabela 2.9 do mamede
A62: TETO | B62: =G4 -> BRANCO
A63: PAREDE | B63: =H4 -> BRANCA
A64: PISO | B64: =I4 -> CONCRETO
A65: pte | B65: 0.7
A66: ppa | B66: 0.7
A67: pp | B67: 0.1
A68: Fu | B68: 0.26
A76: DETERMINAÇÃO DE ILUMINAMENTO (E)
A78: IDADE | B78: 41 anos
A79: VELOCIDADE E PRECISÃO | B79: Importante
A80: REFLETÂNCIA NO FUNDO DA TAREFA | B80: 0.4
A81: PESO FINAL | B81: 0
A93: CATEGORIA B - REQUISITOS VISUAIS LIMITADOS
A94: ILUMINAMENTO (Lux) | B94: 200
A108: DETERMINAÇÃO DE FLUXO TOTAL (Wt)
A113: Wt (lm) | B113: =(B94*(B4*C4))/(B45*B68) -> 88255.159
A119: DETERMINAÇÃO DE NÚMERO DE LUMINÁRIAS (Nlu)
...

Sheet Sala de Caldeira
A1: CARACTERISTICAS DO AMBIENTE
A3: SETOR | B3: LARGURA (m) | C3: COMPRIMENTO (m) | D3: ALTURA (m) | E3: ALTURA DE TRABALHO (m) | F3: Hlp (m) | G3: TETO | H3: PAREDE | I3: PISO | J3: TIPO DE LÂMPADA
A4: SALA DE CALDEIRA | B4: {=_xlfn.XLOOKUP($A4,Controle!$C:$C,Controle!F:F)} -> 9.6 | C4: {=_xlfn.XLOOKUP($A4,Controle!$C:$C,Controle!G:G)} -> 15.92 | D4: {=_xlfn.XLOOKUP($A4,Controle!$C:$C,Controle!D:D)} -> 7 | E4: {=_xlfn.XLOOKUP($A4,Controle!$C:$C,Controle!E:E)} -> 0.8 | F4: =D4-E4 -> 6.2 | G4: {=_xlfn.XLOOKUP($A4,Controle!$C:$C,Controle!J:J)} -> ZINCO | H4: {=_xlfn.XLOOKUP($A4,Controle!$C:$C,Controle!K:K)} -> CLARA | I4: {=_xlfn.XLOOKUP($A4,Controle!$C:$C,Controle!L:L)} -> CONCRETO | J4: VAPOR DE SÓDIO
A6: LUMINÁRIA SELECIONADA
A8: CARACTERISTICAS LUMINÁRIA
A9: MODELO | B9: HDK 474 + GDK 472 PG
A10: FABRICANTE | B10: Phillips
A18: LÂMPADA E RETOR SELECIONADOS
A20: CARACTERISTICAS LÂMPADA | D20: CARACTERISTICAS REATOR
A21: MODELO | B21: SON 250W E E40 CO 1SL | D21: MODELO | E21: VSTI250A26IGOS
A22: FABRICANTE | B22: Phillips | D22: FABRICANTE | E22: Phillips
A23: POTÊNCIA (W) | B23: 250 | D23: PERDA (W) | E23: 30
A24: FLUXO LUMINOSO | B24: 26000 | D24: F.P | E24: 0.95
A25: NÚMERO DE LAMPADAS POR LUMINARIA | B25: 1
A27: DETERMINAÇÃO DO FATOR DE DEPRECIAÇÃO (Fdl)
A29: Categoria da Luminaria | B29: I
A30: Vida útil da lampada (tabela 2.1 mamede) (h) | B30: 18000
A31: Tempo de manutenção (meses) | B31: =(B30/2)/(14*30) -> 21.428571
A32: Categoria do local | B32: SUJO
A45: FATOR DE DEPRECIAÇÃO | B45: 0.78
A47: DETERMINAÇÃO DO FATOR DE UTILIZAÇÃO (Fu)
A52: K | B52: =(C4*B4)/(F4*(C4+B4)) -> 0.96592173
A62: TETO | B62: =G4 -> ZINCO
A63: PAREDE | B63: =H4 -> CLARA
A64: PISO | B64: =I4 -> CONCRETO
A65: pte | B65: 0.5
A66: ppa | B66: 0.5
A67: pp | B67: 0.1
A68: Fu | B68: 0.62
A76: DETERMINAÇÃO DE ILUMINAMENTO (E)
A78: IDADE | B78: 41 anos
A79: VELOCIDADE E PRECISÃO | B79: Importante
A80: REFLETÂNCIA NO FUNDO DA TAREFA | B80: 0.4
A81: PESO FINAL | B81: 0
A93: CATEGORIA B - TRABALHO BRUTO DE MAQUINARIA
A94: ILUMINAMENTO (Lux) | B94: 300
A108: DETERMINAÇÃO DE FLUXO TOTAL (Wt)
A113: Wt (lm) | B113: =(B94*(B4*C4))/(B45*B68) -> 94808.933
A119: DETERMINAÇÃO DE NÚMERO DE LUMINÁRIAS (Nlu)
A122: Nlu | B122: =(B113/(B25*B24)) -> 3.6464974
...

Sheet Compressor
A1: CARACTERISTICAS DO AMBIENTE
A3: SETOR | B3: LARGURA (m) | C3: COMPRIMENTO (m) | D3: ALTURA (m) | E3: ALTURA DE TRABALHO (m) | F3: Hlp (m) | G3: TETO | H3: PAREDE | I3: PISO | J3: TIPO DE LÂMPADA
A4: COMPRESSOR | B4: {=_xlfn.XLOOKUP($A4,Controle!$C:$C,Controle!F:F)} -> 9.6 | C4: {=_xlfn.XLOOKUP($A4,Controle!$C:$C,Controle!G:G)} -> 9.28 | D4: {=_xlfn.XLOOKUP($A4,Controle!$C:$C,Controle!D:D)} -> 7 | E4: {=_xlfn.XLOOKUP($A4,Controle!$C:$C,Controle!E:E)} -> 0.8 | F4: =D4-E4 -> 6.2 | G4: {=_xlfn.XLOOKUP($A4,Controle!$C:$C,Controle!J:J)} -> ZINCO | H4: {=_xlfn.XLOOKUP($A4,Controle!$C:$C,Controle!K:K)} -> CLARA | I4: {=_xlfn.XLOOKUP($A4,Controle!$C:$C,Controle!L:L)} -> CONCRETO | J4: FLUORESCENTE
A6: LUMINÁRIA SELECIONADA
A8: CARACTERISTICAS LUMINÁRIA
A9: MODELO | B9: HDK 474 + GDK 472 PG
A10: FABRICANTE | B10: Phillips
A18: LÂMPADA E RETOR SELECIONADOS
A20: CARACTERISTICAS LÂMPADA | D20: CARACTERISTICAS REATOR
A21: MODELO | B21: SON 250W E E40 CO 1SL | D21: MODELO | E21: VSTI250A26IGOS
A22: FABRICANTE | B22: Phillips | D22: FABRICANTE | E22: Phillips
A23: POTÊNCIA (W) | B23: 250 | D23: PERDA (W) | E23: 30
A24: FLUXO LUMINOSO | B24: 26000 | D24: F.P | E24: 0.95
A25: NÚMERO DE LUMINÁRIAS | B25: 1
A27: DETERMINAÇÃO DO FATOR DE DEPRECIAÇÃO (Fdl)
A29: Categoria da Luminaria | B29: I
A30: Vida útil da lampada (tabela 2.1 mamede) (h) | B30: 18000
A31: Tempo de manutenção (meses) | B31: =(B30/2)/(14*30) -> 21.428571
A32: Categoria do local | B32: SUJO
A45: FATOR DE DEPRECIAÇÃO | B45: 0.78
A47: DETERMINAÇÃO DO FATOR DE UTILIZAÇÃO (Fu)
A52: K | B52: =(C4*B4)/(F4*(C4+B4)) -> 0.76107162
A56: tera que fazer interpolação pois 1,52 nao existe na tabela 2.9 do mamede
A62: TETO | B62: =G4 -> ZINCO
A63: PAREDE | B63: =H4 -> CLARA
A64: PISO | B64: =I4 -> CONCRETO
A65: pte | B65: 0.5
A66: ppa | B66: 0.5
A67: pp | B67: 0.1
A68: Fu | B68: 0.57
A76: DETERMINAÇÃO DE ILUMINAMENTO (E)
A78: IDADE | B78: 41 anos
A79: VELOCIDADE E PRECISÃO | B79: Importante
A80: REFLETÂNCIA NO FUNDO DA TAREFA | B80: 0.4
A81: PESO FINAL | B81: 0
A93: CATEGORIA B - INSPEÇÃO
A94: ILUMINAMENTO (Lux) | B94: 750
A108: DETERMINAÇÃO DE FLUXO TOTAL (Wt)
A113: Wt (lm) | B113: =(B94*(B4*C4))/(B45*B68) -> 150283.4
A119: DETERMINAÇÃO DE NÚMERO DE LUMINÁRIAS (Nlu)
...

Sheet Dep. Carcaça 02
A1: CARACTERISTICAS DO AMBIENTE
A3: SETOR | B3: LARGURA (m) | C3: COMPRIMENTO (m) | D3: ALTURA (m) | E3: ALTURA DE TRABALHO (m) | F3: Hlp (m) | G3: TETO | H3: PAREDE | I3: PISO | J3: TIPO DE LÂMPADA
A4: DEPÓSITO DE CARCAÇAS 02 | B4: {=_xlfn.XLOOKUP($A4,Controle!$C:$C,Controle!F:F)} -> 9.6 | C4: {=_xlfn.XLOOKUP($A4,Controle!$C:$C,Controle!G:G)} -> 11.18 | D4: {=_xlfn.XLOOKUP($A4,Controle!$C:$C,Controle!D:D)} -> 7 | E4: {=_xlfn.XLOOKUP($A4,Controle!$C:$C,Controle!E:E)} -> 0.8 | F4: =D4-E4 -> 6.2 | G4: {=_xlfn.XLOOKUP($A4,Controle!$C:$C,Controle!J:J)} -> ZINCO | H4: {=_xlfn.XLOOKUP($A4,Controle!$C:$C,Controle!K:K)} -> CLARA | I4: {=_xlfn.XLOOKUP($A4,Controle!$C:$C,Controle!L:L)} -> CONCRETO | J4: FLUORESCENTE
A6: LUMINÁRIA SELECIONADA
A8: CARACTERISTICAS LUMINÁRIA
A9: MODELO | B9: HDK 474 + GDK 472 PG
A10: FABRICANTE | B10: Phillips
A18: LÂMPADA E RETOR SELECIONADOS
A20: CARACTERISTICAS LÂMPADA | D20: CARACTERISTICAS REATOR
A21: MODELO | B21: SON 250W E E40 CO 1SL | D21: MODELO | E21: VSTI250A26IGOS
A22: FABRICANTE | B22: Phillips | D22: FABRICANTE | E22: Phillips
A23: POTÊNCIA (W) | B23: 250 | D23: PERDA (W) | E23: 30
A24: FLUXO LUMINOSO | B24: 26000 | D24: F.P | E24: 0.95
A25: NÚMERO DE LUMINÁRIAS | B25: 1
A27: DETERMINAÇÃO DO FATOR DE DEPRECIAÇÃO (Fdl)
A29: Categoria da Luminaria | B29: I
A30: Vida útil da lampada (tabela 2.1 mamede) (h) | B30: 18000
A31: Tempo de manutenção (meses) | B31: =(B30/2)/(14*30) -> 21.428571
A32: Categoria do local | B32: SUJO
A45: FATOR DE DEPRECIAÇÃO | B45: 0.78
A47: DETERMINAÇÃO DO FATOR DE UTILIZAÇÃO (Fu)
A52: K | B52: =(C4*B4)/(F4*(C4+B4)) -> 0.83305908
A56: tera que fazer interpolação pois 1,52 nao existe na tabela 2.9 do mamede
A62: TETO | B62: =G4 -> ZINCO
A63: PAREDE | B63: =H4 -> CLARA
A64: PISO | B64: =I4 -> CONCRETO
A65: pte | B65: 0.5
A66: ppa | B66: 0.5
A67: pp | B67: 0.1
A68: Fu | B68: 0.57
A76: DETERMINAÇÃO DE ILUMINAMENTO (E)
A78: IDADE | B78: 41 anos
A79: VELOCIDADE E PRECISÃO | B79: Importante
A80: REFLETÂNCIA NO FUNDO DA TAREFA | B80: 0.4
A81: PESO FINAL | B81: 0
A93: CATEGORIA B - INSPEÇÃO
A94: ILUMINAMENTO (Lux) | B94: 300
A108: DETERMINAÇÃO DE FLUXO TOTAL (Wt)
A113: Wt (lm) | B113: =(B94*(B4*C4))/(B45*B68) -> 72421.053
A119: DETERMINAÇÃO DE NÚMERO DE LUMINÁRIAS (Nlu)
...

Sheet Dep. Carcaça 01
A1: CARACTERISTICAS DO AMBIENTE
A3: SETOR | B3: LARGURA (m) | C3: COMPRIMENTO (m) | D3: ALTURA (m) | E3: ALTURA DE TRABALHO (m) | F3: Hlp (m) | G3: TETO | H3: PAREDE | I3: PISO | J3: TIPO DE LÂMPADA
A4: DEPÓSITO DE CARCAÇAS 01 | B4: {=_xlfn.XLOOKUP($A4,Controle!$C:$C,Controle!F:F)} -> 6 | C4: {=_xlfn.XLOOKUP($A4,Controle!$C:$C,Controle!G:G)} -> 8.12 | D4: {=_xlfn.XLOOKUP($A4,Controle!$C:$C,Controle!D:D)} -> 7 | E4: {=_xlfn.XLOOKUP($A4,Controle!$C:$C,Controle!E:E)} -> 0.8 | F4: =D4-E4 -> 6.2 | G4: {=_xlfn.XLOOKUP($A4,Controle!$C:$C,Controle!J:J)} -> ZINCO | H4: {=_xlfn.XLOOKUP($A4,Controle!$C:$C,Controle!K:K)} -> CLARA | I4: {=_xlfn.XLOOKUP($A4,Controle!$C:$C,Controle!L:L)} -> CONCRETO | J4: FLUORESCENTE
A6: LUMINÁRIA SELECIONADA
A8: CARACTERISTICAS LUMINÁRIA
A9: MODELO | B9: HDK 474 + GDK 472 PG
A10: FABRICANTE | B10: Phillips
A18: LÂMPADA E RETOR SELECIONADOS
A20: CARACTERISTICAS LÂMPADA | D20: CARACTERISTICAS REATOR
A21: MODELO | B21: SON 250W E E40 CO 1SL | D21: MODELO | E21: VSTI250A26IGOS
A22: FABRICANTE | B22: Phillips | D22: FABRICANTE | E22: Phillips
A23: POTÊNCIA (W) | B23: 250 | D23: PERDA (W) | E23: 30
A24: FLUXO LUMINOSO | B24: 26000 | D24: F.P | E24: 0.95
A25: NÚMERO DE LUMINÁRIAS | B25: 1
A27: DETERMINAÇÃO DO FATOR DE DEPRECIAÇÃO (Fdl)
A29: Categoria da Luminaria | B29: I
A30: Vida útil da lampada (tabela 2.1 mamede) (h) | B30: 18000
A31: Tempo de manutenção (meses) | B31: =(B30/2)/(14*30) -> 21.428571
A32: Categoria do local | B32: SUJO
A45: FATOR DE DEPRECIAÇÃO | B45: 0.78
A47: DETERMINAÇÃO DO FATOR DE UTILIZAÇÃO (Fu)
A52: K | B52: =(C4*B4)/(F4*(C4+B4)) -> 0.55652015
A56: tera que fazer interpolação pois 1,52 nao existe na tabela 2.9 do mamede
A62: TETO | B62: =G4 -> ZINCO
A63: PAREDE | B63: =H4 -> CLARA
A64: PISO | B64: =I4 -> CONCRETO
A65: pte | B65: 0.5
A66: ppa | B66: 0.5
A67: pp | B67: 0.1
A68: Fu | B68: 0.5
A76: DETERMINAÇÃO DE ILUMINAMENTO (E)
A78: IDADE | B78: 41 anos
A79: VELOCIDADE E PRECISÃO | B79: Importante
A80: REFLETÂNCIA NO FUNDO DA TAREFA | B80: 0.4
A81: PESO FINAL | B81: 0
A93: CATEGORIA B - INSPEÇÃO
A94: ILUMINAMENTO (Lux) | B94: 300
A108: DETERMINAÇÃO DE FLUXO TOTAL (Wt)
A113: Wt (lm) | B113: =(B94*(B4*C4))/(B45*B68) -> 37476.923
A119: DETERMINAÇÃO DE NÚMERO DE LUMINÁRIAS (Nlu)
...

Sheet Raspa
A1: CARACTERISTICAS DO AMBIENTE
A3: SETOR | B3: LARGURA (m) | C3: COMPRIMENTO (m) | D3: ALTURA (m) | E3: ALTURA DE TRABALHO (m) | F3: Hlp (m) | G3: TETO | H3: PAREDE | I3: PISO | J3: TIPO DE LÂMPADA
A4: Raspa | B4: {=_xlfn.XLOOKUP($A4,Controle!$C:$C,Controle!F:F)} -> 30.92 | C4: {=_xlfn.XLOOKUP($A4,Controle!$C:$C,Controle!G:G)} -> 8.12 | D4: {=_xlfn.XLOOKUP($A4,Controle!$C:$C,Controle!D:D)} -> 7 | E4: {=_xlfn.XLOOKUP($A4,Controle!$C:$C,Controle!E:E)} -> 0.8 | F4: =D4-E4 -> 6.2 | G4: {=_xlfn.XLOOKUP($A4,Controle!$C:$C,Controle!J:J)} -> ZINCO | H4: {=_xlfn.XLOOKUP($A4,Controle!$C:$C,Controle!K:K)} -> CLARA | I4: {=_xlfn.XLOOKUP($A4,Controle!$C:$C,Controle!L:L)} -> CONCRETO | J4: VAPOR DE SÓDIO
A6: LUMINÁRIA SELECIONADA
A8: CARACTERISTICAS LUMINÁRIA
A9: MODELO | B9: HDK 474 + GDK 472 PG
A10: FABRICANTE | B10: Phillips
A18: LÂMPADA E RETOR SELECIONADOS
A20: CARACTERISTICAS LÂMPADA | D20: CARACTERISTICAS REATOR
A21: MODELO | B21: SON 250W E E40 CO 1SL | D21: MODELO | E21: VSTI250A26IGOS
A22: FABRICANTE | B22: Phillips | D22: FABRICANTE | E22: Phillips
A23: POTÊNCIA (W) | B23: 250 | D23: PERDA (W) | E23: 30
A24: FLUXO LUMINOSO | B24: 26000 | D24: F.P | E24: 0.95
A25: NÚMERO DE LUMINÁRIAS | B25: 1
A27: DETERMINAÇÃO DO FATOR DE DEPRECIAÇÃO (Fdl)
A29: Categoria da Luminaria | B29: I
A30: Vida útil da lampada (tabela 2.1 mamede) (h) | B30: 18000
A31: Tempo de manutenção (meses) | B31: =(B30/2)/(14*30) -> 21.428571
A32: Categoria do local | B32: SUJO
A45: FATOR DE DEPRECIAÇÃO | B45: 0.78
A47: DETERMINAÇÃO DO FATOR DE UTILIZAÇÃO (Fu)
A52: K | B52: =(C4*B4)/(F4*(C4+B4)) -> 1.0372753
A56: tera que fazer interpolação pois 1,52 nao existe na tabela 2.9 do mamede
A62: TETO | B62: =G4 -> ZINCO
A63: PAREDE | B63: =H4 -> CLARA
A64: PISO | B64: =I4 -> CONCRETO
A65: pte | B65: 0.5
A66: ppa | B66: 0.5
A67: pp | B67: 0.1
A68: Fu | B68: 0.62
A76: DETERMINAÇÃO DE ILUMINAMENTO (E)
A78: IDADE | B78: 41 anos
A79: VELOCIDADE E PRECISÃO | B79: Importante
A80: REFLETÂNCIA NO FUNDO DA TAREFA | B80: 0.4
A81: PESO FINAL | B81: 0
A93: CATEGORIA B - INSPEÇÃO
A94: ILUMINAMENTO (Lux) | B94: 750
A108: DETERMINAÇÃO DE FLUXO TOTAL (Wt)
A113: Wt (lm) | B113: =(B94*(B4*C4))/(B45*B68) -> 389377.17
A119: DETERMINAÇÃO DE NÚMERO DE LUMINÁRIAS (Nlu)
...

Sheet Recapagem - Cavidades
A1: CARACTERISTICAS DO AMBIENTE
A3: Dados de Entrada | B3: Área 1 | C3: Área 2 | D3: Área 3 | E3: Recapagem | F3: 1585.56
A4: Largura (m) | B4: 43.38 | C4: =30.9+6+2.35 -> 39.25 | D4: 30.9 | E4: 43.37 | F4: =F3/G4 -> 36.558912 | G4: 43.37
A5: Comprimento (m) | B5: 27.95 | C5: 5.23 | D5: 5 | E5: 38.18 | G5: =G4/G8 -> #DIV/0! | H5: =G5/2 -> #DIV/0!
A6: Altura (m) | B6: 7 | C6: 7 | D6: 7 | E6: 7 | G6: =E5/H8 -> #DIV/0! | H6: =G6/2 -> #DIV/0!
A7: Altura de trabalho (m) | B7: 0.8 | C7: 0.8 | D7: 0.8 | E7: 0.8
A8: Altura mínima exigida | B8: 4 | C8: 4 | D8: 4 | E8: 4 | G8: =F120 | H8: =G119
A9: Comprimento Tirante (m) | B9: 0 | C9: 0 | D9: 0 | E9: 0
A10: Htl (m) | B10: 1 | C10: 1 | D10: 1 | E10: 1
A11: Hlp (m) | B11: =(B6-B10)-B7 -> 5.2 | C11: =(C6-C10)-C7 -> 5.2 | D11: =(D6-D10)-D7 -> 5.2 | E11: =(E6-E10)-E7 -> 5.2 | F11: =B4*B5 -> 1212.471 | G11: =C4*C5 -> 205.2775 | H11: =D4*D5 -> 154.5
A12: Hpp (m) | B12: =B7 -> 0.8 | C12: =C7 -> 0.8 | D12: =D7 -> 0.8 | E12: =E7 -> 0.8
A13: Tipo de Lâmpada | B13: Vapor de Sódio | C13: Vapor de Sódio | D13: Vapor de Sódio | E13: Vapor de Sódio
A14: Cor Teto | B14: =Controle!J13 -> ZINCO | C14: =Controle!J13 -> ZINCO | D14: =Controle!J13 -> ZINCO | E14: =Controle!J13 -> ZINCO | F14: 0.5 | G14: =E11*1.5 -> 7.8
A15: Cor Parede | B15: =Controle!K13 -> CLARA | C15: =Controle!K13 -> CLARA | D15: =Controle!K13 -> CLARA | E15: =Controle!K13 -> CLARA | F15: 0.5
A16: Cor chão | B16: =Controle!L13 -> CONCRETO | C16: =Controle!L13 -> CONCRETO | D16: =Controle!L13 -> CONCRETO | E16: =Controle!L13 -> CONCRETO | F16: 0.1
A17: Fator de relação de cavidade (k) | B17: =5*(B4+B5)/(B4*B5) -> 0.29415137 | C17: =5*(C4+C5)/(C4*C5) -> 1.0834115 | D17: =5*(D4+D5)/(D4*D5) -> 1.1618123 | E17: =5*(E4+E5)/(E4*E5) -> 0.24624568
A21: LUMINÁRIA SELECIONADA
A23: CARACTERISTICAS LUMINÁRIA
A24: MODELO | B24: HDK 474 + GDK 472 PG
A25: FABRICANTE | B25: Phillips
A33: LÂMPADA E RETOR SELECIONADOS
A35: CARACTERISTICAS LÂMPADA | D35: CARACTERISTICAS REATOR
A36: MODELO | B36: SON 400W E E40 CO 1SL | D36: MODELO | E36: VTE400A26HQI E
A37: FABRICANTE | B37: Phillips | D37: FABRICANTE | E37: Phillips
A38: POTÊNCIA (W) | B38: 400 | D38: PERDA (W) | E38: 30
A39: FLUXO LUMINOSO | B39: 48800 | D39: F.P | E39: 0.95
A40: NÚMERO DE LUMINÁRIAS | B40: 1
A42: DADOS DAS CAVIDADES
A44: Dados de Entrada | J44: Refletancia efetiva da cavidade do piso (ρcp) | M44: Refletancia efetiva da cavidade do teto (ρct)
A45: Relação da Cavidade do Teto (Rct) | B45: =B17*B10 -> 0.29415137 | C45: =C17*C10 -> 1.0834115 | D45: =D17*D10 -> 1.1618123 | E45: =E17*E10 -> 0.24624568 | F45: Calculado | J45: PISO | K45: =B16 -> CONCRETO | M45: TETO | N45: =B14 -> ZINCO
A46: Relação da Cavidado do recinto (Rcr) | B46: =B17*B11 -> 1.5295871 | C46: =C17*C11 -> 5.6337397 | D46: =D17*D11 -> 6.0414239 | E46: =E17*E11 -> 1.2804775 | F46: Calculado | J46: PAREDE | K46: =B15 -> CLARA | M46: PAREDE | N46: =B15 -> CLARA
A47: Relação da Cavidade do piso (Rcp) | B47: =B17*B12 -> 0.23532109 | C47: =C17*C12 -> 0.86672918 | D47: =D17*D12 -> 0.92944984 | E47: =E17*E12 -> 0.19699655 | F47: Calculado | J47: ppi | K47: 0.1 | M47: pte | N47: 0.5
A48: Refletancia efetiva da cavidade do piso (ρcp) | B48: 10 | C48: 11 | D48: 11 | E48: 10 | F48: Valor da tabela | J48: ppa | K48: 0.5 | M48: ppa | N48: 0.5
A49: Refletancia efetiva da cavidade do teto (ρct) | B49: 47 | C49: 41 | D49: 41 | E49: 48 | F49: Valor da tabela | J49: Relação da Cavidade do piso (Rcp) | M49: ppi
M50: Relação da Cavidade do Teto (Rct)
A52: INTERPOLAÇÃO - FATOR DE UTILIZAÇÃO
A53: Dados de Entrada | B53: AREA 1 | E53: AREA 2 | H53: AREA 3
B54: Rcr=1 | C54: Rcr=2 | D54: =B46 -> 1.5295871 | E54: Rcr=5 | F54: Rcr=6 | G54: =C46 -> 5.6337397 | H54: Rcr=6 | I54: Rcr=7 | J54: =D46 -> 6.0414239
A55: k 1 | B55: 10 | C55: 10 | D55: 2 | E55: 10 | F55: 10 | G55: 6 | H55: 10 | I55: 10 | J55: 7
A56: k 2 | B56: 50 | C56: 50 | D56: 1 | E56: 50 | F56: 50 | G56: 5 | H56: 50 | I56: 50 | J56: 6
...

Sheet Escritório
A1: CARACTERISTICAS DO AMBIENTE
A3: SETOR | B3: LARGURA (m) | C3: COMPRIMENTO (m) | D3: ALTURA (m) | E3: ALTURA DE TRABALHO (m) | F3: Hlp (m) | G3: TETO | H3: PAREDE | I3: PISO | J3: TIPO DE LÂMPADA
A4: ESCRITÓRIO | B4: {=_xlfn.XLOOKUP($A4,Controle!$C:$C,Controle!F:F)} -> 6 | C4: {=_xlfn.XLOOKUP($A4,Controle!$C:$C,Controle!G:G)} -> 8.12 | D4: {=_xlfn.XLOOKUP($A4,Controle!$C:$C,Controle!D:D)} -> 3 | E4: {=_xlfn.XLOOKUP($A4,Controle!$C:$C,Controle!E:E)} -> 0.8 | F4: =D4-E4 -> 2.2 | G4: {=_xlfn.XLOOKUP($A4,Controle!$C:$C,Controle!J:J)} -> BRANCO | H4: {=_xlfn.XLOOKUP($A4,Controle!$C:$C,Controle!K:K)} -> BEGE | I4: {=_xlfn.XLOOKUP($A4,Controle!$C:$C,Controle!L:L)} -> AZULEJO CINZA | J4: FLUORESCENTE
A6: LUMINÁRIA SELECIONADA
A8: CARACTERISTICAS LUMINÁRIA
A9: MODELO | B9: TSM 426 - 2 lampadas de 40W
A10: FABRICANTE | B10: Phillips
A18: LÂMPADA E RETOR SELECIONADOS
A20: CARACTERISTICAS LÂMPADA | D20: CARACTERISTICAS REATOR
A21: MODELO | B21: Luminária TMS 426 | D21: MODELO | E21: POUP-AFP-6F
A22: FABRICANTE | B22: Phillips | D22: FABRICANTE | E22: Intral
A23: POTÊNCIA (W) | B23: 40 | D23: POTÊNCIA REATOR | E23: =(B23*B25)*5/100 -> 4
A24: FLUXO LUMINOSO | B24: 3000 | D24: F.P | E24: 0.97
A25: NÚMERO DE LUMINÁRIAS | B25: 2
A27: DETERMINAÇÃO DO FATOR DE DEPRECIAÇÃO (Fdl)
A29: Categoria da Luminaria | B29: IV
A30: Vida útil da lampada (tabela 2.1 mamede) (h) | B30: 10000
A31: Tempo de manutenção (meses) | B31: =(B30/2)/(14*30) -> 11.904762
A32: Categoria do local | B32: LIMPO
A45: FATOR DE DEPRECIAÇÃO | B45: 0.88
A47: DETERMINAÇÃO DO FATOR DE UTILIZAÇÃO (Fu)
A52: K | B52: =(C4*B4)/(F4*(C4+B4)) -> 1.568375
A56: tera que fazer interpolação pois 1,52 nao existe na tabela 2.9 do mamede
A62: TETO | B62: =G4 -> BRANCO
A63: PAREDE | B63: =H4 -> BEGE
A64: PISO | B64: =I4 -> AZULEJO CINZA
A65: pte | B65: 0.7
A66: ppa | B66: 0.5
A67: pp | B67: 0.45
A68: Fu | B68: 0.61
A76: DETERMINAÇÃO DE ILUMINAMENTO (E)
A78: IDADE | B78: 41 anos
A79: VELOCIDADE E PRECISÃO | B79: Importante
A80: REFLETÂNCIA NO FUNDO DA TAREFA | B80: 0.4
A81: PESO FINAL | B81: 0
A93: CATEGORIA B - REQUISITOS VISUAIS LIMITADOS
A94: ILUMINAMENTO (Lux) | B94: 200
A108: DETERMINAÇÃO DE FLUXO TOTAL (Wt)
A113: Wt (lm) | B113: =(B94*(B4*C4))/(B45*B68) -> 18152.012
A119: DETERMINAÇÃO DE NÚMERO DE LUMINÁRIAS (Nlu)
...

Sheet Controle de Qualidade
A1: CARACTERISTICAS DO AMBIENTE
A3: SETOR | B3: LARGURA (m) | C3: COMPRIMENTO (m) | D3: ALTURA (m) | E3: ALTURA DE TRABALHO (m) | F3: Hlp (m) | G3: TETO | H3: PAREDE | I3: PISO | J3: TIPO DE LÂMPADA
A4: CONTROLE DE QUALIDADE | B4: {=_xlfn.XLOOKUP($A4,Controle!$C:$C,Controle!F:F)} -> 6 | C4: {=_xlfn.XLOOKUP($A4,Controle!$C:$C,Controle!G:G)} -> 5 | D4: {=_xlfn.XLOOKUP($A4,Controle!$C:$C,Controle!D:D)} -> 3 | E4: {=_xlfn.XLOOKUP($A4,Controle!$C:$C,Controle!E:E)} -> 0.8 | F4: =D4-E4 -> 2.2 | G4: {=_xlfn.XLOOKUP($A4,Controle!$C:$C,Controle!J:J)} -> BRANCO | H4: {=_xlfn.XLOOKUP($A4,Controle!$C:$C,Controle!K:K)} -> BRANCA | I4: {=_xlfn.XLOOKUP($A4,Controle!$C:$C,Controle!L:L)} -> AZULEJO CINZA | J4: FLUORESCENTE
A6: LUMINÁRIA SELECIONADA
A8: CARACTERISTICAS LUMINÁRIA
A9: MODELO | B9: TSM 426 - 2 lampadas de 40W
A10: FABRICANTE | B10: Phillips
A18: LÂMPADA E RETOR SELECIONADOS
A20: CARACTERISTICAS LÂMPADA | D20: CARACTERISTICAS REATOR
A21: MODELO | B21: Luminária TMS 426 | D21: MODELO | E21: POUP-AFP-6F
A22: FABRICANTE | B22: Phillips | D22: FABRICANTE | E22: Intral
A23: POTÊNCIA (W) | B23: 40 | D23: POTÊNCIA REATOR | E23: =(B23*B25)*5/100 -> 4
A24: FLUXO LUMINOSO | B24: 3000 | D24: F.P | E24: 0.97
A25: NÚMERO DE LUMINÁRIAS | B25: 2
A27: DETERMINAÇÃO DO FATOR DE DEPRECIAÇÃO (Fdl)
A29: Categoria da Luminaria | B29: IV
A30: Vida útil da lampada (tabela 2.1 mamede) (h) | B30: 10000
A31: Tempo de manutenção (meses) | B31: =(B30/2)/(14*30) -> 11.904762
A32: Categoria do local | B32: LIMPO
A45: FATOR DE DEPRECIAÇÃO | B45: 0.88
A47: DETERMINAÇÃO DO FATOR DE UTILIZAÇÃO (Fu)
A52: K | B52: =(C4*B4)/(F4*(C4+B4)) -> 1.2396694
A56: tera que fazer interpolação pois 1,52 nao existe na tabela 2.9 do mamede
A62: TETO | B62: =G4 -> BRANCO
A63: PAREDE | B63: =H4 -> BRANCA
A64: PISO | B64: =I4 -> AZULEJO CINZA
A65: pte | B65: 0.7
A66: ppa | B66: 0.5
A67: pp | B67: 0.45
A68: Fu | B68: 0.56
A76: DETERMINAÇÃO DE ILUMINAMENTO (E)
A78: IDADE | B78: 41 anos
A79: VELOCIDADE E PRECISÃO | B79: Importante
A80: REFLETÂNCIA NO FUNDO DA TAREFA | B80: 0.4
A81: PESO FINAL | B81: 0
A93: CATEGORIA B - INSPEÇÃO
A94: ILUMINAMENTO (Lux) | B94: 1500
A108: DETERMINAÇÃO DE FLUXO TOTAL (Wt)
A113: Wt (lm) | B113: =(B94*(B4*C4))/(B45*B68) -> 91314.935
A119: DETERMINAÇÃO DE NÚMERO DE LUMINÁRIAS (Nlu)
...

Sheet Saida de produto
A1: CARACTERISTICAS DO AMBIENTE
A3: SETOR | B3: LARGURA (m) | C3: COMPRIMENTO (m) | D3: ALTURA (m) | E3: ALTURA DE TRABALHO (m) | F3: Hlp (m) | G3: TETO | H3: PAREDE | I3: PISO | J3: TIPO DE LÂMPADA
A4: SAIDA DE PRODUTOS | B4: {=_xlfn.XLOOKUP($A4,Controle!$C:$C,Controle!F:F)} -> 6 | C4: {=_xlfn.XLOOKUP($A4,Controle!$C:$C,Controle!G:G)} -> 5 | D4: {=_xlfn.XLOOKUP($A4,Controle!$C:$C,Controle!D:D)} -> 3 | E4: {=_xlfn.XLOOKUP($A4,Controle!$C:$C,Controle!E:E)} -> 0.8 | F4: =D4-E4 -> 2.2 | G4: {=_xlfn.XLOOKUP($A4,Controle!$C:$C,Controle!J:J)} -> CLARO | H4: {=_xlfn.XLOOKUP($A4,Controle!$C:$C,Controle!K:K)} -> CLARA | I4: {=_xlfn.XLOOKUP($A4,Controle!$C:$C,Controle!L:L)} -> AZULEJO CINZA | J4: FLUORESCENTE
A6: LUMINÁRIA SELECIONADA
A8: CARACTERISTICAS LUMINÁRIA
A9: MODELO | B9: TSM 426 - 2 lampadas de 40W
A10: FABRICANTE | B10: Phillips
A18: LÂMPADA E RETOR SELECIONADOS
A20: CARACTERISTICAS LÂMPADA | D20: CARACTERISTICAS REATOR
A21: MODELO | B21: Luminária TMS 426 | D21: MODELO | E21: POUP-AFP-6F
A22: FABRICANTE | B22: Phillips | D22: FABRICANTE | E22: Intral
A23: POTÊNCIA (W) | B23: 40 | D23: POTÊNCIA REATOR | E23: =(B23*B25)*5/100 -> 4
A24: FLUXO LUMINOSO | B24: 3000 | D24: F.P | E24: 0.97
A25: NÚMERO DE LÃMPADA POR LUMINÁRIA | B25: 2
A27: DETERMINAÇÃO DO FATOR DE DEPRECIAÇÃO (Fdl)
A29: Categoria da Luminaria | B29: IV
A30: Vida útil da lampada (tabela 2.1 mamede) (h) | B30: 10000
A31: Tempo de manutenção (meses) | B31: =(B30/2)/(14*30) -> 11.904762
A32: Categoria do local | B32: MÉDIO
A45: FATOR DE DEPRECIAÇÃO | B45: 0.82
A47: DETERMINAÇÃO DO FATOR DE UTILIZAÇÃO (Fu)
A52: K | B52: =(C4*B4)/(F4*(C4+B4)) -> 1.2396694
A56: tera que fazer interpolação pois 1,52 nao existe na tabela 2.9 do mamede
A62: TETO | B62: =G4 -> CLARO
A63: PAREDE | B63: =H4 -> CLARA
A64: PISO | B64: =I4 -> AZULEJO CINZA
A65: pte | B65: 0.5
A66: ppa | B66: 0.5
A67: pp | B67: 0.45
A68: Fu | B68: 0.43
A76: DETERMINAÇÃO DE ILUMINAMENTO (E)
A78: IDADE | B78: 41 anos
A79: VELOCIDADE E PRECISÃO | B79: Importante
A80: REFLETÂNCIA NO FUNDO DA TAREFA | B80: 0.4
A81: PESO FINAL | B81: 0
A93: CATEGORIA B - REQUISITOS VISUAIS LIMITADOS
A94: ILUMINAMENTO (Lux) | B94: 300
A108: DETERMINAÇÃO DE FLUXO TOTAL (Wt)
A113: Wt (lm) | B113: =(B94*(B4*C4))/(B45*B68) -> 25524.674
A119: DETERMINAÇÃO DE NÚMERO DE LUMINÁRIAS (Nlu)
...

Sheet Banheiro
A1: CARACTERISTICAS DO AMBIENTE
A3: SETOR | B3: LARGURA (m) | C3: COMPRIMENTO (m) | D3: ALTURA (m) | E3: ALTURA DE TRABALHO (m) | F3: Hlp (m) | G3: TETO | H3: PAREDE | I3: PISO | J3: TIPO DE LÂMPADA
A4: BANHEIRO | B4: {=_xlfn.XLOOKUP($A4,Controle!$C:$C,Controle!F:F)} -> 3.5 | C4: {=_xlfn.XLOOKUP($A4,Controle!$C:$C,Controle!G:G)} -> 5.23 | D4: {=_xlfn.XLOOKUP($A4,Controle!$C:$C,Controle!D:D)} -> 3 | E4: {=_xlfn.XLOOKUP($A4,Controle!$C:$C,Controle!E:E)} -> 0.8 | F4: =D4-E4 -> 2.2 | G4: {=_xlfn.XLOOKUP($A4,Controle!$C:$C,Controle!J:J)} -> CLARO | H4: {=_xlfn.XLOOKUP($A4,Controle!$C:$C,Controle!K:K)} -> CLARA | I4: {=_xlfn.XLOOKUP($A4,Controle!$C:$C,Controle!L:L)} -> AZULEJO CINZA | J4: FLUORESCENTE
A6: LUMINÁRIA SELECIONADA
A8: CARACTERISTICAS LUMINÁRIA
A9: MODELO | B9: TSM 426 - 2 lampadas de 40W
A10: FABRICANTE | B10: Phillips
A18: LÂMPADA E RETOR SELECIONADOS
A20: CARACTERISTICAS LÂMPADA | D20: CARACTERISTICAS REATOR
A21: MODELO | B21: Luminária TMS 426 | D21: MODELO | E21: POUP-AFP-6F
A22: FABRICANTE | B22: Phillips | D22: FABRICANTE | E22: Intral
A23: POTÊNCIA (W) | B23: 40 | D23: POTÊNCIA REATOR | E23: =(B23*B25)*5/100 -> 4
A24: FLUXO LUMINOSO | B24: 3000 | D24: F.P | E24: 0.97
A25: NÚMERO DE LUMINÁRIAS | B25: 2
A27: DETERMINAÇÃO DO FATOR DE DEPRECIAÇÃO (Fdl)
A29: Categoria da Luminaria | B29: IV
A30: Vida útil da lampada (tabela 2.1 mamede) (h) | B30: 10000
A31: Tempo de manutenção (meses) | B31: =(B30/2)/(14*30) -> 11.904762
A32: Categoria do local | B32: MUITO LIMPO
A45: FATOR DE DEPRECIAÇÃO | B45: 0.96
A47: DETERMINAÇÃO DO FATOR DE UTILIZAÇÃO (Fu)
A52: K | B52: =(C4*B4)/(F4*(C4+B4)) -> 0.95308758
A56: tera que fazer interpolação pois 1,52 nao existe na tabela 2.9 do mamede
A62: TETO | B62: =G4 -> CLARO
A63: PAREDE | B63: =H4 -> CLARA
A64: PISO | B64: =I4 -> AZULEJO CINZA
A65: pte | B65: 0.5
A66: ppa | B66: 0.5
A67: pp | B67: 0.45
A68: Fu | B68: 0.36
A76: DETERMINAÇÃO DE ILUMINAMENTO (E)
A78: IDADE | B78: 41 anos
A79: VELOCIDADE E PRECISÃO | B79: Importante
A80: REFLETÂNCIA NO FUNDO DA TAREFA | B80: 0.4
A81: PESO FINAL | B81: 0
A93: CATEGORIA B - INSPEÇÃO
A94: ILUMINAMENTO (Lux) | B94: 200
A108: DETERMINAÇÃO DE FLUXO TOTAL (Wt)
A113: Wt (lm) | B113: =(B94*(B4*C4))/(B45*B68) -> 10593.171
A119: DETERMINAÇÃO DE NÚMERO DE LUMINÁRIAS (Nlu)
...
