Workbook

Sheet Dados de Entrada
A1: Fator de Agrupamento
A2: Ref | B2: 1 | C2: 2 | D2: 3 | E2: 4 | F2: 5 | G2: 6 | H2: 7 | I2: 8 | J2: 9 | K2: 12 | L2: 16 | M2: 20
A3: 1 | B3: 1 | C3: 0.8 | D3: 0.7 | E3: 0.65 | F3: 0.6 | G3: 0.57 | H3: 0.54 | I3: 0.52 | J3: 0.5 | K3: 0.45 | L3: 0.41 | M3: 0.38
A4: 2 | B4: 1 | C4: 0.85 | D4: 0.79 | E4: 0.75 | F4: 0.73 | G4: 0.72 | H4: 0.72 | I4: 0.71 | J4: 0.7 | K4: 0.7 | L4: 0.7 | M4: 0.7
A5: 3 | B5: 0.95 | C5: 0.81 | D5: 0.72 | E5: 0.68 | F5: 0.66 | G5: 0.63 | H5: 0.63 | I5: 0.62 | J5: 0.61 | K5: 0.61 | L5: 0.61 | M5: 0.61
A6: 4 | B6: 1 | C6: 0.88 | D6: 0.82 | E6: 0.77 | F6: 0.75 | G6: 0.73 | H6: 0.73 | I6: 0.72 | J6: 0.72 | K6: 0.72 | L6: 0.72 | M6: 0.72
A7: 5 | B7: 1 | C7: 0.87 | D7: 0.82 | E7: 0.8 | F7: 0.8 | G7: 0.79 | H7: 0.79 | I7: 0.78 | J7: 0.78 | K7: 0.78 | L7: 0.78 | M7: 0.78
A9: Fator de correção - Temperatura
A10: Temperatura | B10: PVC | C10: EPR ou XLPE
A11: 45 | B11: 0.79 | C11: 0.87
A13: Seções nominais mm² | B13: B1 | F13: F
B14: PVC | D14: EPR ou XLPE | F14: Justaposto | G14: Trifólio
B15: 2 | C15: 3 | D15: 2 | E15: 3 | F15: 2 | G15: 3
B16: =B13&B14&B15 -> B1PVC2 | C16: =B13&B14&C15 -> B1PVC3 | D16: =B13&D14&D15 -> B1EPR ou XLPE2 | E16: =B13&D14&E15 -> B1EPR ou XLPE3 | F16: =F13&F14&F15 -> FJustaposto2 | G16: =F13&G14&G15 -> FTrifólio3
A17: 0.5 | B17: 9 | C17: 8 | D17: 12 | E17: 10 | F17: 11 | G17: 8
A18: 0.75 | B18: 11 | C18: 10 | D18: 15 | E18: 13 | F18: 14 | G18: 11
A19: 1 | B19: 14 | C19: 12 | D19: 18 | E19: 16 | F19: 17 | G19: 13
A20: 1.5 | B20: 17.5 | C20: 15.5 | D20: 23 | E20: 20 | F20: 22 | G20: 17
A21: 2.5 | B21: 24 | C21: 21 | D21: 31 | E21: 28 | F21: 31 | G21: 24
A22: 4 | B22: 32 | C22: 28 | D22: 42 | E22: 37 | F22: 41 | G22: 33
A23: 6 | B23: 41 | C23: 36 | D23: 54 | E23: 48 | F23: 53 | G23: 43
A24: 10 | B24: 57 | C24: 50 | D24: 75 | E24: 66 | F24: 73 | G24: 60
A25: 16 | B25: 76 | C25: 68 | D25: 100 | E25: 88 | F25: 99 | G25: 82
A26: 25 | B26: 101 | C26: 89 | D26: 133 | E26: 117 | F26: 131 | G26: 110
A27: 35 | B27: 125 | C27: 110 | D27: 164 | E27: 144 | F27: 162 | G27: 137
A28: 50 | B28: 151 | C28: 134 | D28: 198 | E28: 175 | F28: 196 | G28: 167
... A34: 240 | B34: 415 | C34: 370 | D34: 546 | E34: 481 | F34: 546 | G34: 485
A36: Seções nominais mm² | E36: 0.5 | F36: 0.75 | G36: 1 | H36: 1.5 | I36: 2.5 | J36: 4 | K36: 6 | L36: 10 | M36: 16 | N36: 25 | O36: 35 | P36: 50 | Q36: 70 | R36: 95 | S36: 120 | T36: 150 | U36: 185 | V36: 240
A37: B1 | B37: PVC | C37: 2 | D37: =A37&B37&C37 -> B1PVC2 | E37: 9 | F37: 11 | G37: 14 | H37: 17.5 | I37: 24 | J37: 32 | K37: 41 | L37: 57 | M37: 76 | N37: 101 | O37: 125 | P37: 151 | Q37: 192 | R37: 232 | S37: 269 | T37: 309 | U37: 353 | V37: 415
C38: 3 | D38: =A37&B37&C38 -> B1PVC3 | E38: 8 | F38: 10 | G38: 12 | H38: 15.5 | I38: 21 | J38: 28 | K38: 36 | L38: 50 | M38: 68 | N38: 89 | O38: 110 | P38: 134 | Q38: 141 | R38: 207 | S38: 239 | T38: 275 | U38: 314 | V38: 370
B39: EPR ou XLPE | C39: 2 | D39: =A37&B39&C39 -> B1EPR ou XLPE2 | E39: 12 | F39: 15 | G39: 18 | H39: 23 | I39: 31 | J39: 42 | K39: 54 | L39: 75 | M39: 100 | N39: 133 | O39: 164 | P39: 198 | Q39: 253 | R39: 306 | S39: 354 | T39: 407 | U39: 464 | V39: 546
C40: 3 | D40: =A37&B39&C40 -> B1EPR ou XLPE3 | E40: 10 | F40: 13 | G40: 16 | H40: 20 | I40: 28 | J40: 37 | K40: 48 | L40: 66 | M40: 88 | N40: 117 | O40: 144 | P40: 175 | Q40: 222 | R40: 269 | S40: 312 | T40: 358 | U40: 408 | V40: 481
A41: F | B41: Justaposto | C41: 2 | D41: =A41&B41&C41 -> FJustaposto2 | E41: 11 | F41: 14 | G41: 17 | H41: 22 | I41: 31 | J41: 41 | K41: 53 | L41: 73 | M41: 99 | N41: 131 | O41: 162 | P41: 196 | Q41: 251 | R41: 304 | S41: 352 | T41: 406 | U41: 463 | V41: 546
B42: Trifólio | C42: 3 | D42: =A41&B42&C42 -> FTrifólio3 | E42: 8 | F42: 11 | G42: 13 | H42: 17 | I42: 24 | J42: 33 | K42: 43 | L42: 60 | M42: 82 | N42: 110 | O42: 137 | P42: 167 | Q42: 216 | R42: 264 | S42: 308 | T42: 356 | U42: 409 | V42: 485

Sheet QDL
A1: Dados calculados no luminotécnico | M1: POTENCIA QUADRO | N1: CORRENTE QDL
A2: Quadro | B2: Nº do circuito | C2: Área | D2: Tensão (V) | E2: Método de Instalação | F2: Método de Referência | G2: Nº de luminárias | H2: Potência Lum. (VA) | I2: Demanda (VA) | J2: Ip (A) | K2: F.P | M2: Demanda do quadro (+reservas)
A3: QDL-0 | B3: L0 | C3: Subestação | D3: 220 | E3: 33 | F3: B1 | G3: 5 | H3: 270 | I3: =H3*G3 -> 1350 | J3: =I3/D3 -> 6.1363636 | K3: 0.95 | M3: =I3 -> 1350 | N3: =M3/(SQRT(3)*380) -> 2.0511128
A4: QDL-1 | B4: L1 | C4: Sala de caldeiras | D4: 220 | E4: 13 | F4: F | G4: 4 | H4: 290 | I4: =H4*G4 -> 1160 | J4: =I4/D4 -> 5.2727273 | K4: 0.95 | M4: =I4 -> 1160 | N4: =M4/(SQRT(3)*380) -> 1.7624377
A5: QDL-2 | B5: L2 | C5: Compressor | D5: 220 | E5: 13 | F5: F | G5: 6 | H5: 290 | I5: =H5*G5 -> 1740 | J5: =I5/D5 -> 7.9090909 | K5: 0.95 | M5: =I5 -> 1740 | N5: =M5/(SQRT(3)*380) -> 2.6436565
A6: QDL-3 | B6: L3 | C6: Depósito de carcaças | D6: 220 | E6: 13 | F6: F | G6: 6 | H6: 290 | I6: =H6*G6 -> 1740 | J6: =I6/D6 -> 7.9090909 | K6: 0.95 | M6: =I6 -> 1740 | N6: =M6/(SQRT(3)*380) -> 2.6436565
A7: QDL-4 | B7: L4 | C7: Recapagem | D7: 220 | E7: 13 | F7: F | G7: 10 | H7: 440 | I7: =H7*G7 -> 4400 | J7: =I7/D7 -> 20 | K7: 0.95 | M7: =I7 -> 4400
B8: L5 | C8: Recapagem | D8: 220 | E8: 13 | F8: F | G8: 10 | H8: 440 | I8: =H8*G8 -> 4400 | J8: =I8/D8 -> 20 | K8: 0.95 | M8: =I8 -> 4400
B9: L6 | C9: Recapagem | D9: 220 | E9: 13 | F9: F | G9: 10 | H9: 440 | I9: =H9*G9 -> 4400 | J9: =I9/D9 -> 20 | K9: 0.95 | M9: =I9 -> 4400
B10: L7 | C10: Recapagem | D10: 220 | E10: 13 | F10: F | G10: 10 | H10: 440 | I10: =H10*G10 -> 4400 | J10: =I10/D10 -> 20 | K10: 0.95 | M10: =I10 -> 4400
B11: L8 | C11: Recapagem | D11: 220 | E11: 13 | F11: F | G11: 10 | H11: 440 | I11: =H11*G11 -> 4400 | J11: =I11/D11 -> 20 | K11: 0.95 | M11: =I11 -> 4400
B12: L9 | C12: Recapagem | D12: 220 | E12: 13 | F12: F | G12: 10 | H12: 440 | I12: =H12*G12 -> 4400 | J12: =I12/D12 -> 20 | K12: 0.95 | M12: =I12 -> 4400
B13: L10 | C13: Recapagem | D13: 220 | E13: 13 | F13: F | G13: 10 | H13: 440 | I13: =H13*G13 -> 4400 | J13: =I13/D13 -> 20 | K13: 0.95 | M13: =I13 -> 4400
B14: L11 | C14: Recapagem | D14: 220 | E14: 13 | F14: F | G14: 10 | H14: 440 | I14: =H14*G14 -> 4400 | J14: =I14/D14 -> 20 | K14: 0.95
B15: L12 | C15: Recapagem | D15: 220 | E15: 13 | F15: F | G15: 10 | H15: 440 | I15: =H15*G15 -> 4400 | J15: =I15/D15 -> 20 | K15: 0.95
B16: L13 | C16: Recapagem | D16: 220 | E16: 13 | F16: F | G16: 10 | H16: 440 | I16: =H16*G16 -> 4400 | J16: =I16/D16 -> 20 | K16: 0.95
B17: L14 | C17: Recapagem | D17: 220 | E17: 13 | F17: F | G17: 10 | H17: 440 | I17: =H17*G17 -> 4400 | J17: =I17/D17 -> 20 | K17: 0.95
B18: L15 | C18: Recapagem | D18: 220 | E18: 13 | F18: F | G18: 6 | H18: 440 | I18: =H18*G18 -> 2640 | J18: =I18/D18 -> 12 | K18: 0.95
B19: L16 | C19: Raspa | D19: 220 | E19: 13 | F19: F | G19: 8 | H19: 290 | I19: =H19*G19 -> 2320 | J19: =I19/D19 -> 10.545455 | K19: 0.95 | M19: =I19 -> 2320
B20: L17 | C20: Raspa | D20: 220 | E20: 13 | F20: F | G20: 8 | H20: 290 | I20: =H20*G20 -> 2320 | J20: =I20/D20 -> 10.545455 | K20: 0.95
A21: QDL-5 | B21: L18 | C21: Escritório | D21: 220 | E21: 7 | F21: B1 | G21: 4 | H21: 90 | I21: =H21*G21 -> 360 | J21: =I21/D21 -> 1.6363636 | K21: 0.98 | M21: =I21 -> 360 | N21: =M21/(SQRT(3)*380) -> 0.54696341
A22: QDL-6 | B22: L19 | C22: Saída de produto | D22: 220 | E22: 7 | F22: B1 | G22: 6 | H22: 90 | I22: =H22*G22 -> 540 | J22: =I22/D22 -> 2.4545455 | K22: 0.98 | M22: =I22 -> 540 | O22: =M22+M23 -> 1980
B23: L20 | C23: Controle de qualidade | D23: 220 | E23: 7 | F23: B1 | G23: 16 | H23: 90 | I23: =H23*G23 -> 1440 | J23: =I23/D23 -> 6.5454545 | K23: 0.98 | M23: =I23 -> 1440 | N23: =O22/(SQRT(3)*380) -> 3.0082988
A24: QDL-7 | B24: L21 | C24: Banheiros | D24: 220 | E24: 7 | F24: B1 | G24: 2 | H24: 90 | I24: =H24*G24 -> 180 | J24: =I24/D24 -> 0.81818182 | K24: 0.98 | M24: =I24 -> 180 | N24: =M24/(SQRT(3)*380) -> 0.27348171
A26: Fatores de correção
A27: Quadro | B27: Nº do circuito | C27: Circuitos agrupados | D27: Fator de agrupamento | E27: Fator de temperatura (45ºC) | F27: Fator de harmônicos | G27: Isolação | H27: Ip (A) | I27: Ip' (A) | J27: Iz (A) | K27: Iz'
A28: QDL-0 | B28: L0 | C28: 1 | D28: {=INDEX('Dados de Entrada'!$A$2:$M$7,MATCH(L28,'Dados de Entrada'!$A$2:$A$7,1),MATCH(C28,'Dados de Entrada'!$A$2:$M$2,1))} -> 1 | E28: {=INDEX('Dados de Entrada'!$A$10:$C$11,2,MATCH(G28,'Dados de Entrada'!$A$10:$C$10,0))} -> 0.87 | F28: 1.15 | G28: EPR ou XLPE | H28: =J3 -> 6.1363636 | I28: =((H28*F28)/(E28*D28)) -> 8.1112853 | J28: 23 | K28: =E28*D28*J28 -> 20.01 | L28: =IF(E3=7,1,4) -> 4 | M28: =F3&G28&2 -> B1EPR ou XLPE2
A29: QDL-1 | B29: L1 | C29: 1 | D29: {=INDEX('Dados de Entrada'!$A$2:$M$7,MATCH(L29,'Dados de Entrada'!$A$2:$A$7,1),MATCH(C29,'Dados de Entrada'!$A$2:$M$2,1))} -> 1 | E29: {=INDEX('Dados de Entrada'!$A$10:$C$11,2,MATCH(G29,'Dados de Entrada'!$A$10:$C$10,0))} -> 0.87 | F29: 1.15 | G29: EPR ou XLPE | H29: =J4 -> 5.2727273 | I29: =((H29*F29)/(E29*D29)) -> 6.969697 | J29: 23 | K29: =E29*D29*J29 -> 20.01 | L29: =IF(E4=7,1,4) -> 4 | M29: =F4&G29&2 -> FEPR ou XLPE2
A30: QDL-2 | B30: L2 | C30: 1 | D30: {=INDEX('Dados de Entrada'!$A$2:$M$7,MATCH(L30,'Dados de Entrada'!$A$2:$A$7,1),MATCH(C30,'Dados de Entrada'!$A$2:$M$2,1))} -> 1 | E30: {=INDEX('Dados de Entrada'!$A$10:$C$11,2,MATCH(G30,'Dados de Entrada'!$A$10:$C$10,0))} -> 0.87 | F30: 1.15 | G30: EPR ou XLPE | H30: =J5 -> 7.9090909 | I30: =((H30*F30)/(E30*D30)) -> 10.454545 | J30: 23 | K30: =E30*D30*J30 -> 20.01 | L30: =IF(E5=7,1,4) -> 4 | M30: =F5&G30&2 -> FEPR ou XLPE2
A31: QDL-3 | B31: L3 | C31: 1 | D31: {=INDEX('Dados de Entrada'!$A$2:$M$7,MATCH(L31,'Dados de Entrada'!$A$2:$A$7,1),MATCH(C31,'Dados de Entrada'!$A$2:$M$2,1))} -> 1 | E31: {=INDEX('Dados de Entrada'!$A$10:$C$11,2,MATCH(G31,'Dados de Entrada'!$A$10:$C$10,0))} -> 0.87 | F31: 1.15 | G31: EPR ou XLPE | H31: =J6 -> 7.9090909 | I31: =((H31*F31)/(E31*D31)) -> 10.454545 | J31: 23 | K31: =E31*D31*J31 -> 20.01 | L31: =IF(E6=7,1,4) -> 4 | M31: =F6&G31&2 -> FEPR ou XLPE2
A32: QDL-4 | B32: L4 | C32: 2 | D32: {=INDEX('Dados de Entrada'!$A$2:$M$7,MATCH(L32,'Dados de Entrada'!$A$2:$A$7,1),MATCH(C32,'Dados de Entrada'!$A$2:$M$2,1))} -> 0.88 | E32: {=INDEX('Dados de Entrada'!$A$10:$C$11,2,MATCH(G32,'Dados de Entrada'!$A$10:$C$10,0))} -> 0.87 | F32: 1.15 | G32: EPR ou XLPE | H32: =J7 -> 20 | I32: =((H32*F32)/(E32*D32)) -> 30.041797 | J32: 41 | K32: =E32*D32*J32 -> 31.3896 | L32: =IF(E7=7,1,4) -> 4 | M32: =F7&G32&2 -> FEPR ou XLPE2
B33: L5 | C33: 2 | D33: {=INDEX('Dados de Entrada'!$A$2:$M$7,MATCH(L33,'Dados de Entrada'!$A$2:$A$7,1),MATCH(C33,'Dados de Entrada'!$A$2:$M$2,1))} -> 0.88 | E33: {=INDEX('Dados de Entrada'!$A$10:$C$11,2,MATCH(G33,'Dados de Entrada'!$A$10:$C$10,0))} -> 0.87 | F33: 1.15 | G33: EPR ou XLPE | H33: =J8 -> 20 | I33: =((H33*F33)/(E33*D33)) -> 30.041797 | J33: 41 | K33: =E33*D33*J33 -> 31.3896 | L33: =IF(E8=7,1,4) -> 4 | M33: =F8&G33&2 -> FEPR ou XLPE2
B34: L6 | C34: 2 | D34: {=INDEX('Dados de Entrada'!$A$2:$M$7,MATCH(L34,'Dados de Entrada'!$A$2:$A$7,1),MATCH(C34,'Dados de Entrada'!$A$2:$M$2,1))} -> 0.88 | E34: {=INDEX('Dados de Entrada'!$A$10:$C$11,2,MATCH(G34,'Dados de Entrada'!$A$10:$C$10,0))} -> 0.87 | F34: 1.15 | G34: EPR ou XLPE | H34: =J9 -> 20 | I34: =((H34*F34)/(E34*D34)) -> 30.041797 | J34: 41 | K34: =E34*D34*J34 -> 31.3896 | L34: =IF(E9=7,1,4) -> 4 | M34: =F9&G34&2 -> FEPR ou XLPE2
B35: L7 | C35: 2 | D35: {=INDEX('Dados de Entrada'!$A$2:$M$7,MATCH(L35,'Dados de Entrada'!$A$2:$A$7,1),MATCH(C35,'Dados de Entrada'!$A$2:$M$2,1))} -> 0.88 | E35: {=INDEX('Dados de Entrada'!$A$10:$C$11,2,MATCH(G35,'Dados de Entrada'!$A$10:$C$10,0))} -> 0.87 | F35: 1.15 | G35: EPR ou XLPE | H35: =J10 -> 20 | I35: =((H35*F35)/(E35*D35)) -> 30.041797 | J35: 41 | K35: =E35*D35*J35 -> 31.3896 | L35: =IF(E10=7,1,4) -> 4 | M35: =F10&G35&2 -> FEPR ou XLPE2
B36: L8 | C36: 2 | D36: {=INDEX('Dados de Entrada'!$A$2:$M$7,MATCH(L36,'Dados de Entrada'!$A$2:$A$7,1),MATCH(C36,'Dados de Entrada'!$A$2:$M$2,1))} -> 0.88 | E36: {=INDEX('Dados de Entrada'!$A$10:$C$11,2,MATCH(G36,'Dados de Entrada'!$A$10:$C$10,0))} -> 0.87 | F36: 1.15 | G36: EPR ou XLPE | H36: =J11 -> 20 | I36: =((H36*F36)/(E36*D36)) -> 30.041797 | J36: 41 | K36: =E36*D36*J36 -> 31.3896 | L36: =IF(E11=7,1,4) -> 4 | M36: =F11&G36&2 -> FEPR ou XLPE2
B37: L9 | C37: 2 | D37: {=INDEX('Dados de Entrada'!$A$2:$M$7,MATCH(L37,'Dados de Entrada'!$A$2:$A$7,1),MATCH(C37,'Dados de Entrada'!$A$2:$M$2,1))} -> 0.88 | E37: {=INDEX('Dados de Entrada'!$A$10:$C$11,2,MATCH(G37,'Dados de Entrada'!$A$10:$C$10,0))} -> 0.87 | F37: 1.15 | G37: EPR ou XLPE | H37: =J12 -> 20 | I37: =((H37*F37)/(E37*D37)) -> 30.041797 | J37: 41 | K37: =E37*D37*J37 -> 31.3896 | L37: =IF(E12=7,1,4) -> 4 | M37: =F12&G37&2 -> FEPR ou XLPE2
B38: L10 | C38: 2 | D38: {=INDEX('Dados de Entrada'!$A$2:$M$7,MATCH(L38,'Dados de Entrada'!$A$2:$A$7,1),MATCH(C38,'Dados de Entrada'!$A$2:$M$2,1))} -> 0.88 | E38: {=INDEX('Dados de Entrada'!$A$10:$C$11,2,MATCH(G38,'Dados de Entrada'!$A$10:$C$10,0))} -> 0.87 | F38: 1.15 | G38: EPR ou XLPE | H38: =J13 -> 20 | I38: =((H38*F38)/(E38*D38)) -> 30.041797 | J38: 41 | K38: =E38*D38*J38 -> 31.3896 | L38: =IF(E13=7,1,4) -> 4 | M38: =F13&G38&2 -> FEPR ou XLPE2
B39: L11 | C39: 2 | D39: {=INDEX('Dados de Entrada'!$A$2:$M$7,MATCH(L39,'Dados de Entrada'!$A$2:$A$7,1),MATCH(C39,'Dados de Entrada'!$A$2:$M$2,1))} -> 0.88 | E39: {=INDEX('Dados de Entrada'!$A$10:$C$11,2,MATCH(G39,'Dados de Entrada'!$A$10:$C$10,0))} -> 0.87 | F39: 1.15 | G39: EPR ou XLPE | H39: =J14 -> 20 | I39: =((H39*F39)/(E39*D39)) -> 30.041797 | J39: 41 | K39: =E39*D39*J39 -> 31.3896 | L39: =IF(E14=7,1,4) -> 4 | M39: =F14&G39&2 -> FEPR ou XLPE2
B40: L12 | C40: 2 | D40: {=INDEX('Dados de Entrada'!$A$2:$M$7,MATCH(L40,'Dados de Entrada'!$A$2:$A$7,1),MATCH(C40,'Dados de Entrada'!$A$2:$M$2,1))} -> 0.88 | E40: {=INDEX('Dados de Entrada'!$A$10:$C$11,2,MATCH(G40,'Dados de Entrada'!$A$10:$C$10,0))} -> 0.87 | F40: 1.15 | G40: EPR ou XLPE | H40: =J15 -> 20 | I40: =((H40*F40)/(E40*D40)) -> 30.041797 | J40: 41 | K40: =E40*D40*J40 -> 31.3896 | L40: =IF(E15=7,1,4) -> 4
B41: L13 | C41: 2 | D41: {=INDEX('Dados de Entrada'!$A$2:$M$7,MATCH(L41,'Dados de Entrada'!$A$2:$A$7,1),MATCH(C41,'Dados de Entrada'!$A$2:$M$2,1))} -> 0.88 | E41: {=INDEX('Dados de Entrada'!$A$10:$C$11,2,MATCH(G41,'Dados de Entrada'!$A$10:$C$10,0))} -> 0.87 | F41: 1.15 | G41: EPR ou XLPE | H41: =J16 -> 20 | I41: =((H41*F41)/(E41*D41)) -> 30.041797 | J41: 41 | K41: =E41*D41*J41 -> 31.3896 | L41: =IF(E16=7,1,4) -> 4
...

Sheet Queda de Tensão - QDL
A1: Tensão (V) | B1: 220
A2: Potência Unitária (VA) | B2: =QDL!$H$3 -> 270
A3: Qtd Luminárias | B3: =QDL!$G$3 -> 5 | O3: Utilizando a tabela de tensão unitária Prysmian
A4: QDL0 - Subestação | O4: QDL0 - Subestação
A5: Circuito L0 | B5: Corrente (A) | C5: Distância (m) | D5: R [Ω/m] | E5: X [Ω/m] | F5: FP | G5: ΔV (V) | H5: ΔV (%) | I5: ΔV(%)* | K5: Comprimento | L5: Curva | M5: Subida QDL | O5: Circuito L0 | P5: Ip (A) | Q5: Distância (m) | R5: ΔV unitário (V) | S5: ΔV (%) | T5: ΔV(%)*
A6: QDL0-Lu1 | B6: =($B$2*5)/$B$1 -> 6.1363636 | C6: =K6+(L6*1.5)+M6 -> 8.0577 | D6: =14.8137*10^-3 -> 0.0148137 | E6: =0.1378*10^-3 -> 0.0001378 | F6: =QDL!$K$3 -> 0.95 | G6: =2*B6*C6*(D6*F6+E6*SIN(ACOS(F6))) -> 1.3959349 | H6: =G6/220 -> 0.0063451584 | I6: =H6 -> 0.0063451584 | K6: 3.5577 | L6: 2 | M6: 1.5 | O6: QDL0-Lu1 | P6: =B6 -> 6.1363636 | Q6: =C6 -> 8.0577 | R6: 27.4 | S6: =(Q6/1000)*P6*R6*(100/220)/100 -> 0.0061581472 | T6: =S6 -> 0.0061581472
A7: Lu1-Lu2* | B7: =($B$2*1)/$B$1 -> 1.2272727 | C7: =K7+(L7*1.5)+M7 -> 0.2913 | D7: =14.8137*10^-3 -> 0.0148137 | E7: =0.1378*10^-3 -> 0.0001378 | F7: =QDL!$K$3 -> 0.95 | G7: =2*B7*C7*(D7*F7+E7*SIN(ACOS(F7))) -> 0.010093099 | H7: =G7/220 -> 4.5877723e-05 | I7: =I6+H7 -> 0.0063910362 | K7: 0.2913 | L7: 0 | M7: 0 | O7: Lu1-Lu2 | P7: =B7 -> 1.2272727 | Q7: =C7 -> 0.2913 | R7: 27.4 | S7: =(Q7/1000)*P7*R7*(100/220)/100 -> 4.4525566e-05 | T7: =T6+S7 -> 0.0062026727
A8: Lu1-Lu3 | B8: =($B$2*3)/$B$1 -> 3.6818182 | C8: =K8+(L8*1.5)+M8 -> 11.1627 | D8: =14.8137*10^-3 -> 0.0148137 | E8: =0.1378*10^-3 -> 0.0001378 | F8: =QDL!$K$3 -> 0.95 | G8: =2*B8*C8*(D8*F8+E8*SIN(ACOS(F8))) -> 1.1603114 | H8: =G8/220 -> 0.0052741427 | I8: =I6+H8 -> 0.011619301 | K8: =3+2.1627+3 -> 8.1627 | L8: 2 | M8: 0 | O8: Lu2-Lu3 | P8: =B8 -> 3.6818182 | Q8: =C8 -> 11.1627 | R8: 27.4 | S8: =(Q8/1000)*P8*R8*(100/220)/100 -> 0.0051186976 | T8: =T6+S8 -> 0.011276845
A9: Lu3-Lu4 | B9: =($B$2*2)/$B$1 -> 2.4545455 | C9: =K9+(L9*1.5)+M9 -> 0.2461 | D9: =14.8137*10^-3 -> 0.0148137 | E9: =0.1378*10^-3 -> 0.0001378 | F9: =QDL!$K$3 -> 0.95 | G9: =2*B9*C9*(D9*F9+E9*SIN(ACOS(F9))) -> 0.017053977 | H9: =G9/220 -> 7.7518075e-05 | I9: =I8+H9 -> 0.011696819 | K9: 0.2461 | L9: 0 | M9: 0 | O9: Lu3-Lu4 | P9: =B9 -> 2.4545455 | Q9: =C9 -> 0.2461 | R9: 27.4 | S9: =(Q9/1000)*P9*R9*(100/220)/100 -> 7.523338e-05 | T9: =T8+S9 -> 0.011352078
A10: Lu4-Lu5* | B10: =($B$2*1)/$B$1 -> 1.2272727 | C10: =K10+(L10*1.5)+M10 -> 9.4914 | D10: =14.8137*10^-3 -> 0.0148137 | E10: =0.1378*10^-3 -> 0.0001378 | F10: =QDL!$K$3 -> 0.95 | G10: =2*B10*C10*(D10*F10+E10*SIN(ACOS(F10))) -> 0.32886248 | H10: =G10/220 -> 0.0014948295 | I10: =I9+H10 -> 0.013191649 | K10: =3+0.4914+3 -> 6.4914 | L10: 2 | M10: 0 | O10: Lu4-Lu5 | P10: =B10 -> 1.2272727 | Q10: =C10 -> 9.4914 | R10: 27.4 | S10: =(Q10/1000)*P10*R10*(100/220)/100 -> 0.0014507723 | T10: =T9+S10 -> 0.01280285
A12: Potência Unitária | B12: =QDL!$H$4 -> 290
A13: Qtd Luminárias | B13: =QDL!$G$4 -> 4
A14: QDL1 - Sala de Caldeiras | O14: QDL1 - Sala de Caldeiras
A15: Circuito L1 | B15: Corrente (A) | C15: Distância (m) | D15: R [Ω/m] | E15: X [Ω/m] | F15: FP | G15: ΔV (V) | H15: ΔV (%) | I15: ΔV(%)* | K15: Comprimento | L15: Curva | M15: Subida QDL | O15: Circuito L1 | P15: Ip (A) | Q15: Distância (m) | R15: ΔV unitário (V) | S15: ΔV (%) | T15: ΔV(%)*
A16: QDL1-Lu1 | B16: =($B$12*4)/$B$1 -> 5.2727273 | C16: =K16+(L16*1.5)+M16 -> 13 | D16: =14.8137*10^-3 -> 0.0148137 | E16: =0.1378*10^-3 -> 0.0001378 | F16: =QDL!K$4 -> 0.95 | G16: =2*B16*C16*(D16*F16+E16*SIN(ACOS(F16))) -> 1.9351812 | H16: =G16/220 -> 0.0087962781 | I16: =H16 -> 0.0087962781 | K16: =1.62+2.88 -> 4.5 | L16: 2 | M16: =7-1.5 -> 5.5 | O16: ='Queda de Tensão - QDL'!$A16 -> QDL1-Lu1 | P16: =B16 -> 5.2727273 | Q16: =C16 -> 13 | R16: 27.4 | S16: =(Q16/1000)*P16*R16*(100/220)/100 -> 0.0085370248 | T16: =S16 -> 0.0085370248
A17: Lu1-Lu2 | B17: =($B$12*3)/$B$1 -> 3.9545455 | C17: =K17+(L17*1.5)+M17 -> 3.98 | D17: =14.8137*10^-3 -> 0.0148137 | E17: =0.1378*10^-3 -> 0.0001378 | F17: =QDL!K$4 -> 0.95 | G17: =2*B17*C17*(D17*F17+E17*SIN(ACOS(F17))) -> 0.44434737 | H17: =G17/220 -> 0.0020197608 | I17: =I16+H17 -> 0.010816039 | K17: 3.98 | L17: 0 | M17: 0 | O17: ='Queda de Tensão - QDL'!$A17 -> Lu1-Lu2 | P17: =B17 -> 3.9545455 | Q17: =C17 -> 3.98 | R17: 27.4 | S17: =(Q17/1000)*P17*R17*(100/220)/100 -> 0.0019602322 | T17: =T16+S17 -> 0.010497257
A18: Lu2-Lu3 | B18: =($B$12*2)/$B$1 -> 2.6363636 | C18: =K18+(L18*1.5)+M18 -> 3.98 | D18: =14.8137*10^-3 -> 0.0148137 | E18: =0.1378*10^-3 -> 0.0001378 | F18: =QDL!K$4 -> 0.95 | G18: =2*B18*C18*(D18*F18+E18*SIN(ACOS(F18))) -> 0.29623158 | H18: =G18/220 -> 0.0013465072 | I18: =I17+H18 -> 0.012162546 | K18: 3.98 | L18: 0 | M18: 0 | O18: ='Queda de Tensão - QDL'!$A18 -> Lu2-Lu3 | P18: =B18 -> 2.6363636 | Q18: =C18 -> 3.98 | R18: 27.4 | S18: =(Q18/1000)*P18*R18*(100/220)/100 -> 0.0013068215 | T18: =T17+S18 -> 0.011804079
A19: Lu3-Lu4* | B19: =($B$12*1)/$B$1 -> 1.3181818 | C19: =K19+(L19*1.5)+M19 -> 3.98 | D19: =14.8137*10^-3 -> 0.0148137 | E19: =0.1378*10^-3 -> 0.0001378 | F19: =QDL!K$4 -> 0.95 | G19: =2*B19*C19*(D19*F19+E19*SIN(ACOS(F19))) -> 0.14811579 | H19: =G19/220 -> 0.00067325359 | I19: =I18+H19 -> 0.0128358 | K19: 3.98 | L19: 0 | M19: 0 | O19: {='Queda de Tensão - QDL'!$A$19} -> Lu3-Lu4* | P19: =B19 -> 1.3181818 | Q19: =C19 -> 3.98 | R19: 27.4 | S19: =(Q19/1000)*P19*R19*(100/220)/100 -> 0.00065341074 | T19: =T18+S19 -> 0.012457489
A21: Potência Unitária | B21: =QDL!$H$5 -> 290
A22: Qtd Luminárias | B22: =QDL!$G$5 -> 6
A23: QDL2 - Compressor | O23: QDL2 - Compressor
A24: Circuito L2 | B24: Corrente (A) | C24: Distância (m) | D24: R [Ω/m] | E24: X [Ω/m] | F24: FP | G24: ΔV (V) | H24: ΔV (%) | I24: ΔV(%)* | K24: Comprimento | L24: Curva | M24: Subida QDL | O24: Circuito L2 | P24: Ip (A) | Q24: Distância (m) | R24: ΔV unitário (V) | S24: ΔV (%) | T24: ΔV(%)*
A25: QDL2-Lu1 | B25: =($B$21*6)/$B$1 -> 7.9090909 | C25: =K25+(L25*1.5)+M25 -> 8.11 | D25: =14.8137*10^-3 -> 0.0148137 | E25: =0.1378*10^-3 -> 0.0001378 | F25: =QDL!K$5 -> 0.95 | G25: =2*B25*C25*(D25*F25+E25*SIN(ACOS(F25))) -> 1.810883 | H25: =G25/220 -> 0.0082312864 | I25: =H25 -> 0.0082312864 | K25: 1.11 | L25: 1 | M25: =7-1.5 -> 5.5 | O25: ='Queda de Tensão - QDL'!$A25 -> QDL2-Lu1 | P25: =B25 -> 7.9090909 | Q25: =C25 -> 8.11 | R25: 27.4 | S25: =(Q25/1000)*P25*R25*(100/220)/100 -> 0.0079886851 | T25: =S25 -> 0.0079886851
A26: Lu1-Lu2 | B26: =($B$21*2)/$B$1 -> 2.6363636 | C26: =K26+(L26*1.5)+M26 -> 3.09 | D26: =14.8137*10^-3 -> 0.0148137 | E26: =0.1378*10^-3 -> 0.0001378 | F26: =QDL!K$5 -> 0.95 | G26: =2*B26*C26*(D26*F26+E26*SIN(ACOS(F26))) -> 0.22998884 | H26: =G26/220 -> 0.0010454038 | I26: =I25+H26 -> 0.0092766902 | K26: 3.09 | L26: 0 | M26: 0 | O26: ='Queda de Tensão - QDL'!$A26 -> Lu1-Lu2 | P26: =B26 -> 2.6363636 | Q26: =C26 -> 3.09 | R26: 27.4 | S26: =(Q26/1000)*P26*R26*(100/220)/100 -> 0.0010145926 | T26: =T25+S26 -> 0.0090032777
A27: Lu2-Lu3* | B27: =($B$21*1)/$B$1 -> 1.3181818 | C27: =K27+(L27*1.5)+M27 -> 3.09 | D27: =14.8137*10^-3 -> 0.0148137 | E27: =0.1378*10^-3 -> 0.0001378 | F27: =QDL!K$5 -> 0.95 | G27: =2*B27*C27*(D27*F27+E27*SIN(ACOS(F27))) -> 0.11499442 | H27: =G27/220 -> 0.00052270191 | I27: =I26+H27 -> 0.0097993921 | K27: 3.09 | L27: 0 | M27: 0 | O27: ='Queda de Tensão - QDL'!$A27 -> Lu2-Lu3* | P27: =B27 -> 1.3181818 | Q27: =C27 -> 3.09 | R27: 27.4 | S27: =(Q27/1000)*P27*R27*(100/220)/100 -> 0.00050729628 | T27: =T26+S27 -> 0.009510574
A28: Lu1-Lu4 | B28: =($B$21*3)/$B$1 -> 3.9545455 | C28: =K28+(L28*1.5)+M28 -> 6.3 | D28: =14.8137*10^-3 -> 0.0148137 | E28: =0.1378*10^-3 -> 0.0001378 | F28: =QDL!K$5 -> 0.95 | G28: =2*B28*C28*(D28*F28+E28*SIN(ACOS(F28))) -> 0.70336393 | H28: =G28/220 -> 0.0031971088 | I28: =I25+H28 -> 0.011428395 | K28: 4.8 | L28: 1 | M28: 0 | O28: ='Queda de Tensão - QDL'!$A28 -> Lu1-Lu4 | P28: =B28 -> 3.9545455 | Q28: =C28 -> 6.3 | R28: 27.4 | S28: =(Q28/1000)*P28*R28*(100/220)/100 -> 0.0031028802 | T28: =T25+S28 -> 0.011091565
A29: Lu4-Lu5 | B29: =($B$21*2)/$B$1 -> 2.6363636 | C29: =K29+(L29*1.5)+M29 -> 4.59 | D29: =14.8137*10^-3 -> 0.0148137 | E29: =0.1378*10^-3 -> 0.0001378 | F29: =QDL!K$5 -> 0.95 | G29: =2*B29*C29*(D29*F29+E29*SIN(ACOS(F29))) -> 0.34163391 | H29: =G29/220 -> 0.0015528814 | I29: =I28+H29 -> 0.012981276 | K29: 3.09 | L29: 1 | M29: 0 | O29: ='Queda de Tensão - QDL'!$A29 -> Lu4-Lu5 | P29: =B29 -> 2.6363636 | Q29: =C29 -> 4.59 | R29: 27.4 | S29: =(Q29/1000)*P29*R29*(100/220)/100 -> 0.0015071132 | T29: =T28+S29 -> 0.012598679
A30: Lu5-Lu6* | B30: =($B$21*1)/$B$1 -> 1.3181818 | C30: =K30+(L30*1.5)+M30 -> 3.09 | D30: =14.8137*10^-3 -> 0.0148137 | E30: =0.1378*10^-3 -> 0.0001378 | F30: =QDL!K$5 -> 0.95 | G30: =2*B30*C30*(D30*F30+E30*SIN(ACOS(F30))) -> 0.11499442 | H30: =G30/220 -> 0.00052270191 | I30: =I29+H30 -> 0.013503978 | K30: 3.09 | L30: 0 | M30: 0 | O30: ='Queda de Tensão - QDL'!$A30 -> Lu5-Lu6* | P30: =B30 -> 1.3181818 | Q30: =C30 -> 3.09 | R30: 27.4 | S30: =(Q30/1000)*P30*R30*(100/220)/100 -> 0.00050729628 | T30: =T29+S30 -> 0.013105975
A32: Potência Unitária | B32: =QDL!$H$6 -> 290
A33: Qtd Luminárias | B33: =QDL!$G$6 -> 6
A34: QDL3 - Depósito de Carcaças | O34: QDL3 - Depósito de Carcaça
A35: Circuito L3 | B35: Corrente (A) | C35: Distância (m) | D35: R [Ω/m] | E35: X [Ω/m] | F35: FP | G35: ΔV (V) | H35: ΔV (%) | I35: ΔV(%)* | K35: Comprimento | L35: Curva | M35: Subida QDL | O35: Circuito L3 | P35: Ip (A) | Q35: Distância (m) | R35: ΔV unitário (V) | S35: ΔV (%) | T35: ΔV(%)*
A36: QDL3-Lu1 | B36: =($B$32*6)/$B$1 -> 7.9090909 | C36: =K36+(L36*1.5)+M36 -> 11.92 | D36: =14.8137*10^-3 -> 0.0148137 | E36: =0.1378*10^-3 -> 0.0001378 | F36: =QDL!K$6 -> 0.95 | G36: =2*B36*C36*(D36*F36+E36*SIN(ACOS(F36))) -> 2.6616184 | H36: =G36/220 -> 0.012098266 | I36: =H36 -> 0.012098266 | K36: =2.03+1.39 -> 3.42 | L36: 2 | M36: 5.5 | O36: ='Queda de Tensão - QDL'!$A36 -> QDL3-Lu1 | P36: =B36 -> 7.9090909 | Q36: =C36 -> 11.92 | R36: 27.4 | S36: =(Q36/1000)*P36*R36*(100/220)/100 -> 0.011741693 | T36: =S36 -> 0.011741693
A37: Lu1-Lu2 | B37: =($B$32*2)/$B$1 -> 2.6363636 | C37: =K37+(L37*1.5)+M37 -> 5.59 | D37: =14.8137*10^-3 -> 0.0148137 | E37: =0.1378*10^-3 -> 0.0001378 | F37: =QDL!K$6 -> 0.95 | G37: =2*B37*C37*(D37*F37+E37*SIN(ACOS(F37))) -> 0.41606395 | H37: =G37/220 -> 0.0018911998 | I37: =I36+H37 -> 0.013989465 | K37: 5.59 | L37: 0 | M37: 0 | O37: ='Queda de Tensão - QDL'!$A37 -> Lu1-Lu2 | P37: =B37 -> 2.6363636 | Q37: =C37 -> 5.59 | R37: 27.4 | S37: =(Q37/1000)*P37*R37*(100/220)/100 -> 0.0018354603 | T37: =T36+S37 -> 0.013577153
A38: Lu2-Lu3* | B38: =($B$32*1)/$B$1 -> 1.3181818 | C38: =K38+(L38*1.5)+M38 -> 6.3 | D38: =14.8137*10^-3 -> 0.0148137 | E38: =0.1378*10^-3 -> 0.0001378 | F38: =QDL!K$6 -> 0.95 | G38: =2*B38*C38*(D38*F38+E38*SIN(ACOS(F38))) -> 0.23445464 | H38: =G38/220 -> 0.0010657029 | I38: =I37+H38 -> 0.015055168 | K38: 4.8 | L38: 1 | M38: 0 | O38: ='Queda de Tensão - QDL'!$A38 -> Lu2-Lu3* | P38: =B38 -> 1.3181818 | Q38: =C38 -> 6.3 | R38: 27.4 | S38: =(Q38/1000)*P38*R38*(100/220)/100 -> 0.0010342934 | T38: =T37+S38 -> 0.014611446
A39: Lu1-Lu4 | B39: =($B$32*3)/$B$1 -> 3.9545455 | C39: =K39+(L39*1.5)+M39 -> 4.8 | D39: =14.8137*10^-3 -> 0.0148137 | E39: =0.1378*10^-3 -> 0.0001378 | F39: =QDL!K$6 -> 0.95 | G39: =2*B39*C39*(D39*F39+E39*SIN(ACOS(F39))) -> 0.53589632 | H39: =G39/220 -> 0.0024358924 | I39: =I36+H39 -> 0.014534158 | K39: 4.8 | L39: 0 | M39: 0 | O39: ='Queda de Tensão - QDL'!$A39 -> Lu1-Lu4 | P39: =B39 -> 3.9545455 | Q39: =C39 -> 4.8 | R39: 27.4 | S39: =(Q39/1000)*P39*R39*(100/220)/100 -> 0.0023640992 | T39: =T36+S39 -> 0.014105792
A40: Lu4-Lu5 | B40: =($B$32*2)/$B$1 -> 2.6363636 | C40: =K40+(L40*1.5)+M40 -> 7.1 | D40: =14.8137*10^-3 -> 0.0148137 | E40: =0.1378*10^-3 -> 0.0001378 | F40: =QDL!K$6 -> 0.95 | G40: =2*B40*C40*(D40*F40+E40*SIN(ACOS(F40))) -> 0.52845332 | H40: =G40/220 -> 0.0024020605 | I40: =I39+H40 -> 0.016936218 | K40: 5.6 | L40: 1 | M40: 0 | O40: ='Queda de Tensão - QDL'!$A40 -> Lu4-Lu5 | P40: =B40 -> 2.6363636 | Q40: =C40 -> 7.1 | R40: 27.4 | S40: =(Q40/1000)*P40*R40*(100/220)/100 -> 0.0023312645 | T40: =T39+S40 -> 0.016437056
A41: Lu5-Lu6* | B41: =($B$32*1)/$B$1 -> 1.3181818 | C41: =K41+(L41*1.5)+M41 -> 5.56 | D41: =14.8137*10^-3 -> 0.0148137 | E41: =0.1378*10^-3 -> 0.0001378 | F41: =QDL!K$6 -> 0.95 | G41: =2*B41*C41*(D41*F41+E41*SIN(ACOS(F41))) -> 0.20691553 | H41: =G41/220 -> 0.00094052512 | I41: =I40+H41 -> 0.017876744 | K41: 4.06 | L41: 1 | M41: 0 | O41: ='Queda de Tensão - QDL'!$A41 -> Lu5-Lu6* | P41: =B41 -> 1.3181818 | Q41: =C41 -> 5.56 | R41: 27.4 | S41: =(Q41/1000)*P41*R41*(100/220)/100 -> 0.00091280496 | T41: =T40+S41 -> 0.017349861
A43: Potência Unitária | B43: =QDL!$H$19 -> 290
A44: Qtd Luminárias | B44: 8
...

Sheet BALANÇO DE POTENCIAS QDL
A1: QDL0 - Subestação
A2: Circuito | B2: Disjuntor | C2: Corrente do Disjuntor (A) | D2: Capacidade de interrupção do disjuntor (kA) | E2: Balanço de potência (VA)
E3: R | F3: S | G3: T
A4: =QDL!B3 -> L0 | B4: MDW-C10 | C4: =QDL!D199 -> 10 | D4: 5 | E4: ='BALANÇO TOTAL'!E3 -> 1350 | F4: ='BALANÇO TOTAL'!F3 -> - | G4: ='BALANÇO TOTAL'!G3 -> -
A7: QDL1 - Sala de Caldeiras
A8: Circuito | B8: Disjuntor | C8: Corrente do Disjuntor (A) | D8: Capacidade de interrupção do disjuntor (kA) | E8: Balanço de potência (VA)
E9: R | F9: S | G9: T
A10: =QDL!B4 -> L1 | B10: MDW-C10 | C10: =QDL!D200 -> 10 | D10: 5 | E10: ='BALANÇO TOTAL'!E4 -> - | F10: ='BALANÇO TOTAL'!F4 -> 1160 | G10: ='BALANÇO TOTAL'!G4 -> -
A13: QDL2 - Compressor
A14: Circuito | B14: Disjuntor | C14: Corrente do Disjuntor (A) | D14: Capacidade de interrupção do disjuntor (kA) | E14: Balanço de potência (VA)
E15: R | F15: S | G15: T
A16: =QDL!B5 -> L2 | B16: MDW-C10 | C16: =QDL!D201 -> 10 | D16: 5 | E16: ='BALANÇO TOTAL'!E5 -> - | F16: ='BALANÇO TOTAL'!F5 -> - | G16: ='BALANÇO TOTAL'!G5 -> 1740
A19: QDL3 - Depósito de carcaças
A20: Circuito | B20: Disjuntor | C20: Corrente do Disjuntor (A) | D20: Capacidade de interrupção do disjuntor (kA) | E20: Balanço de potência (VA)
E21: R | F21: S | G21: T
A22: =QDL!B6 -> L3 | B22: MDW-C10 | C22: =QDL!D202 -> 10 | D22: 5 | E22: ='BALANÇO TOTAL'!E6 -> - | F22: ='BALANÇO TOTAL'!F6 -> 1740 | G22: ='BALANÇO TOTAL'!G6 -> -
A25: QDL4 - Recapagem e Raspa
A26: Circuito | B26: Disjuntor | C26: Corrente do Disjuntor (A) | D26: Capacidade de interrupção do disjuntor (kA) | E26: Balanço de potência (VA)
E27: R | F27: S | G27: T
A28: =QDL!B7 -> L4 | B28: MDW-C25 | C28: =QDL!D203 -> 25 | D28: 5 | E28: ='BALANÇO TOTAL'!E7 -> 4400 | F28: ='BALANÇO TOTAL'!F7 -> - | G28: ='BALANÇO TOTAL'!G7 -> -
A29: =QDL!B8 -> L5 | B29: MDW-C25 | C29: =QDL!D204 -> 25 | D29: 5 | E29: ='BALANÇO TOTAL'!E8 -> - | F29: ='BALANÇO TOTAL'!F8 -> - | G29: ='BALANÇO TOTAL'!G8 -> 4400 | I29: fase mais carregada é a R com 19920
A30: =QDL!B9 -> L6 | B30: MDW-C25 | C30: =QDL!D205 -> 25 | D30: 5 | E30: ='BALANÇO TOTAL'!E9 -> - | F30: ='BALANÇO TOTAL'!F9 -> 4400 | G30: ='BALANÇO TOTAL'!G9 -> -
A31: =QDL!B10 -> L7 | B31: MDW-C25 | C31: =QDL!D206 -> 25 | D31: 5 | E31: ='BALANÇO TOTAL'!E10 -> 4400 | F31: ='BALANÇO TOTAL'!F10 -> - | G31: ='BALANÇO TOTAL'!G10 -> - | I31: =SUM(E28:G41) -> 55680
A32: =QDL!B11 -> L8 | B32: MDW-C25 | C32: =QDL!D207 -> 25 | D32: 5 | E32: ='BALANÇO TOTAL'!E11 -> - | F32: ='BALANÇO TOTAL'!F11 -> - | G32: ='BALANÇO TOTAL'!G11 -> 4400 | I32: =I31/3 -> 18560
A33: =QDL!B12 -> L9 | B33: MDW-C25 | C33: =QDL!D208 -> 25 | D33: 5 | E33: ='BALANÇO TOTAL'!E12 -> - | F33: ='BALANÇO TOTAL'!F12 -> 4400 | G33: ='BALANÇO TOTAL'!G12 -> -
A34: =QDL!B13 -> L10 | B34: MDW-C25 | C34: =QDL!D209 -> 25 | D34: 5 | E34: ='BALANÇO TOTAL'!E13 -> 4400 | F34: ='BALANÇO TOTAL'!F13 -> - | G34: ='BALANÇO TOTAL'!G13 -> - | I34: =E42/220 -> 90.545455
A35: =QDL!B14 -> L11 | B35: MDW-C25 | C35: =QDL!D210 -> 25 | D35: 5 | E35: ='BALANÇO TOTAL'!E14 -> - | F35: ='BALANÇO TOTAL'!F14 -> - | G35: ='BALANÇO TOTAL'!G14 -> 4400
A36: =QDL!B15 -> L12 | B36: MDW-C25 | C36: =QDL!D211 -> 25 | D36: 5 | E36: ='BALANÇO TOTAL'!E15 -> - | F36: ='BALANÇO TOTAL'!F15 -> 4400 | G36: ='BALANÇO TOTAL'!G15 -> -
A37: =QDL!B16 -> L13 | B37: MDW-C25 | C37: =QDL!D212 -> 25 | D37: 5 | E37: ='BALANÇO TOTAL'!E16 -> 4400 | F37: ='BALANÇO TOTAL'!F16 -> - | G37: ='BALANÇO TOTAL'!G16 -> -
A38: =QDL!B17 -> L14 | B38: MDW-C25 | C38: =QDL!D213 -> 25 | D38: 5 | E38: ='BALANÇO TOTAL'!E17 -> - | F38: ='BALANÇO TOTAL'!F17 -> - | G38: ='BALANÇO TOTAL'!G17 -> 4400
A39: =QDL!B18 -> L15 | B39: MDW-C16 | C39: =QDL!D214 -> 16 | D39: 5 | E39: ='BALANÇO TOTAL'!E18 -> - | F39: ='BALANÇO TOTAL'!F18 -> 2640 | G39: ='BALANÇO TOTAL'!G18 -> -
A40: =QDL!B19 -> L16 | B40: MDW-C16 | C40: =QDL!D215 -> 16 | D40: 5 | E40: ='BALANÇO TOTAL'!E19 -> - | F40: ='BALANÇO TOTAL'!F19 -> 2320 | G40: ='BALANÇO TOTAL'!G19 -> -
A41: =QDL!B20 -> L17 | B41: MDW-C16 | C41: =QDL!D216 -> 16 | D41: 5 | E41: ='BALANÇO TOTAL'!E20 -> 2320 | F41: ='BALANÇO TOTAL'!F20 -> - | G41: ='BALANÇO TOTAL'!G20 -> -
D42: total | E42: =SUM(E28:E41) -> 19920 | F42: =SUM(F28:F41) -> 18160 | G42: =SUM(G28:G41) -> 17600
A45: QDL5 - Escritório
A46: Circuito | B46: Disjuntor | C46: Corrente do Disjuntor (A) | D46: Capacidade de interrupção do disjuntor (kA) | E46: Balanço de potência (VA)
E47: R | F47: S | G47: T
A48: =QDL!B21 -> L18 | B48: MDW-C6 | C48: =QDL!D217 -> 6 | D48: 5 | E48: ='BALANÇO TOTAL'!E21 -> - | F48: ='BALANÇO TOTAL'!F21 -> - | G48: ='BALANÇO TOTAL'!G21 -> 360
A51: QDL6 - Sala de produto e controle de qualidade
A52: Circuito | B52: Disjuntor | C52: Corrente do Disjuntor (A) | D52: Capacidade de interrupção do disjuntor (kA) | E52: Balanço de potência (VA)
...

Sheet BALANÇO TOTAL
E1: Balanço de potência (VA)
E2: R | F2: S | G2: T
A3: QDL-0 | B3: L0 | C3: Subestação | D3: =QDL!I3 -> 1350 | E3: 1350 | F3: - | G3: -
A4: QDL-1 | B4: L1 | C4: Sala de caldeiras | D4: =QDL!I4 -> 1160 | E4: - | F4: 1160 | G4: -
A5: QDL-2 | B5: L2 | C5: Compressor | D5: =QDL!I5 -> 1740 | E5: - | F5: - | G5: 1740
A6: QDL-3 | B6: L3 | C6: Depósito de carcaças | D6: =QDL!I6 -> 1740 | E6: - | F6: 1740 | G6: -
A7: QDL-4 | B7: L4 | C7: Recapagem | D7: =QDL!I7 -> 4400 | E7: 4400 | F7: - | G7: -
B8: L5 | C8: Recapagem | D8: =QDL!I8 -> 4400 | E8: - | F8: - | G8: 4400
B9: L6 | C9: Recapagem | D9: =QDL!I9 -> 4400 | E9: - | F9: 4400 | G9: -
B10: L7 | C10: Recapagem | D10: =QDL!I10 -> 4400 | E10: 4400 | F10: - | G10: -
B11: L8 | C11: Recapagem | D11: =QDL!I11 -> 4400 | E11: - | F11: - | G11: 4400
B12: L9 | C12: Recapagem | D12: =QDL!I12 -> 4400 | E12: - | F12: 4400 | G12: -
B13: L10 | C13: Recapagem | D13: =QDL!I13 -> 4400 | E13: 4400 | F13: - | G13: -
B14: L11 | C14: Recapagem | D14: =QDL!I14 -> 4400 | E14: - | F14: - | G14: 4400
B15: L12 | C15: Recapagem | D15: =QDL!I15 -> 4400 | E15: - | F15: 4400 | G15: -
B16: L13 | C16: Recapagem | D16: =QDL!I16 -> 4400 | E16: 4400 | F16: - | G16: -
B17: L14 | C17: Recapagem | D17: =QDL!I17 -> 4400 | E17: - | F17: - | G17: 4400
B18: L15 | C18: Recapagem | D18: =QDL!I18 -> 2640 | E18: - | F18: 2640 | G18: -
B19: L16 | C19: Raspa | D19: =QDL!I19 -> 2320 | E19: - | F19: 2320 | G19: -
B20: L17 | C20: Raspa | D20: =QDL!I20 -> 2320 | E20: 2320 | F20: - | G20: -
A21: QDL-5 | B21: L18 | C21: Escritório | D21: =QDL!I21 -> 360 | E21: - | F21: - | G21: 360
A22: QDL-6 | B22: L19 | C22: Saída de produto | D22: =QDL!I22 -> 540 | E22: - | F22: 540 | G22: -
B23: L20 | C23: Controle de qualidade | D23: =QDL!I23 -> 1440 | E23: - | F23: - | G23: 1440
A24: QDL-7 | B24: L21 | C24: Banheiros | D24: =QDL!I24 -> 180 | E24: - | F24: - | G24: 180
E25: =SUM(E3:E24) -> 21270 | F25: =SUM(F3:F24) -> 21600 | G25: =SUM(G3:G24) -> 21320
E26: TOTAL = | F26: =SUM(E25:G25) -> 64190 | G26: =F26/3 -> 21396.667
E27: Balanço de potência (VA)
E28: R | F28: S | G28: T
A29: QDF-1 | B29: T1 | C29: Sala de caldeiras | D29: 800 | E29: 800 | F29: - | G29: -
B30: T2 | D30: 1000 | E30: =1000/3 -> 333.33333 | F30: =1000/3 -> 333.33333 | G30: =1000/3 -> 333.33333
A31: QDF-2 | B31: T3 | C31: Compressor | D31: 1600 | E31: - | F31: 600 | G31: -
B32: T4 | D32: 1000 | E32: =1000/3 -> 333.33333 | F32: =1000/3 -> 333.33333 | G32: =1000/3 -> 333.33333
A33: QDF-3 | B33: T5 | C33: Depósito de carcaças | D33: 800 | E33: - | F33: - | G33: 800
B34: T6 | D34: 1000 | E34: 333.33333 | F34: 333.33333 | G34: 333.33333
A35: QDF-4 | B35: T7 | C35: Recapagem | D35: 1600 | E35: - | F35: 2000 | G35: -
B36: T8 | D36: 4000 | E36: =4000/3 -> 1333.3333 | F36: =4000/3 -> 1333.3333 | G36: =4000/3 -> 1333.3333
B37: T9 | C37: Raspa | D37: 1200 | E37: 1200 | F37: - | G37: -
B38: T10 | D38: 1000 | E38: 333.33333 | F38: 333.33333 | G38: 333.33333
A39: QDF-5 | B39: T11 | C39: Escritório | D39: 600 | E39: - | F39: - | G39: 600
B40: T12 | D40: 1920 | E40: - | F40: - | G40: 1920
...

Sheet QDGL
A1: Quadro | B1: Corrente nominal [A] | C1: Tensão [V] | E1: Método de instalação | F1: Método de referência | I1: Circuito | J1: Disjuntor | K1: Corrente do Disjuntor (A) | L1: Potência aparente (VA)
A2: QDL-0 | B2: =L3/C2 -> 6.1363636 | C2: 220 | D2: -18.19 | E2: 13 | F2: F
A3: QDL-1 | B3: =L4/C3 -> 5.2727273 | C3: 220 | D3: -18.19 | E3: 13 | F3: F | I3: QDL-0 | J3: MDWH-C10 | K3: 10 | L3: =Q3 -> 1350 | N3: QDL-0 | O3: L0 | P3: Subestação | Q3: =QDL!I3 -> 1350 | R3: =QDL!K3 -> 0.95
A4: QDL-2 | B4: =L5/C4 -> 7.9090909 | C4: 220 | D4: -18.19 | E4: 13 | F4: F | I4: QDL-1 | J4: MDWH-C10 | K4: 10 | L4: =Q4 -> 1160 | N4: QDL-1 | O4: L1 | P4: Sala de caldeiras | Q4: =QDL!I4 -> 1160 | R4: =QDL!K4 -> 0.95
A5: QDL-3 | B5: =L6/C5 -> 7.9090909 | C5: 220 | D5: -18.19 | E5: 13 | F5: F | I5: QDL-2 | J5: MDWH-C10 | K5: 10 | L5: =Q5 -> 1740 | N5: QDL-2 | O5: L2 | P5: Compressor | Q5: =QDL!I5 -> 1740 | R5: =QDL!K5 -> 0.95
A6: QDL-4 | B6: =L7/(sqrt(3)*C6) -> 84.597008 | C6: 380 | D6: -18.19 | E6: 13 | F6: F | I6: QDL-3 | J6: MDWH-C10 | K6: 10 | L6: =Q6 -> 1740 | N6: QDL-3 | O6: L3 | P6: Depósito de carcaças | Q6: =QDL!I6 -> 1740 | R6: =QDL!K6 -> 0.95
A7: QDL-5 | B7: =L8/C7 -> 1.6363636 | C7: 220 | D7: -11.48 | E7: 13 | F7: F | I7: QDL-4 | J7: MDWH-C100 | K7: 100 | L7: =SUM(Q7:Q20) -> 55680 | N7: QDL-4 | O7: L4 | P7: Recapagem | Q7: =QDL!I7 -> 4400 | R7: =QDL!K7 -> 0.95
A8: QDL-6 | B8: =L9/C8 -> 9 | C8: 220 | D8: -11.48 | E8: 13 | F8: F | I8: QDL-5 | J8: MDWH-C10 | K8: 10 | L8: =Q21 -> 360 | O8: L5 | P8: Recapagem | Q8: =QDL!I8 -> 4400 | R8: =QDL!K8 -> 0.95
A9: QDL-7 | B9: =L10/C9 -> 0.81818182 | C9: 220 | D9: -11.48 | E9: 13 | F9: F | I9: QDL-6 | J9: MDWH-C10-3 | K9: 10 | L9: =SUM(Q22:Q23) -> 1980 | O9: L6 | P9: Recapagem | Q9: =QDL!I9 -> 4400 | R9: =QDL!K9 -> 0.95
I10: QDL-7 | J10: MDWH-C10 | K10: 10 | L10: =Q24 -> 180 | O10: L7 | P10: Recapagem | Q10: =QDL!I10 -> 4400 | R10: =QDL!K10 -> 0.95
I11: Total | L11: =SUM(L3:L10) -> 64190 | O11: L8 | P11: Recapagem | Q11: =QDL!I11 -> 4400 | R11: =QDL!K11 -> 0.95
I12: RQDL-1 | L12: ='BALANÇO TOTAL'!G26 -> 21396.667 | O12: L9 | P12: Recapagem | Q12: =QDL!I12 -> 4400 | R12: =QDL!K12 -> 0.95
I13: RQDL-2 | L13: =L12 -> 21396.667 | O13: L10 | P13: Recapagem | Q13: =QDL!I13 -> 4400 | R13: =QDL!K13 -> 0.95
I14: RQDL-3 | L14: =L12 -> 21396.667 | O14: L11 | P14: Recapagem | Q14: =QDL!I14 -> 4400 | R14: =QDL!K14 -> 0.95
I15: Total | L15: =SUM(L11:L14) -> 128380 | O15: L12 | P15: Recapagem | Q15: =QDL!I15 -> 4400 | R15: =QDL!K15 -> 0.95
O16: L13 | P16: Recapagem | Q16: =QDL!I16 -> 4400 | R16: =QDL!K16 -> 0.95
O17: L14 | P17: Recapagem | Q17: =QDL!I17 -> 4400 | R17: =QDL!K17 -> 0.95
O18: L15 | P18: Recapagem | Q18: =QDL!I18 -> 2640 | R18: =QDL!K18 -> 0.95
O19: L16 | P19: Raspa | Q19: =QDL!I19 -> 2320 | R19: =QDL!K19 -> 0.95
B20: quadro mais longe? | O20: L17 | P20: Raspa | Q20: =QDL!I20 -> 2320 | R20: =QDL!K20 -> 0.95
B21: Circuito L1 | C21: Corrente (A) | F21: Distância (m) | G21: R [Ω/m] | H21: X [Ω/m] | I21: FP | J21: ΔV [V] | K21: ΔV [%] | L21: ΔV[%]* | N21: QDL-5 | O21: L18 | P21: Escritório | Q21: =QDL!I21 -> 360 | R21: =QDL!K21 -> 0.98
B22: QDGL-QDL5 | C22: =B7 -> 1.6363636 | F22: 127 | G22: =14.8137*10^-3 -> 0.0148137 | H22: =0.1378*10^-3 -> 0.0001378 | I22: 0.92 | J22: =2*C22*F22*(G22*I22+H22*SIN(ACOS(I22))) -> 5.6869904 | K22: =J22/380 -> 0.014965764 | L22: =K22 -> 0.014965764 | N22: QDL-6 | O22: L19 | P22: Saída de produto | Q22: =QDL!I22 -> 540 | R22: =QDL!K22 -> 0.98
O23: L20 | P23: Controle de qualidade | Q23: =QDL!I23 -> 1440 | R23: =QDL!K23 -> 0.98
B24: Quadro | C24: Fator de agrupamento | F24: Fator de temperatura (50ºC) | G24: Fator de harmônicos | H24: Isolação | I24: Corrente nominal [A] | J24: Ip' (A) | K24: Iz (A) | L24: IZ' (A) | N24: QDL-7 | O24: L21 | P24: Banheiros | Q24: =QDL!I24 -> 180 | R24: =QDL!K24 -> 0.98
B25: QGDL | C25: 1 | F25: {=INDEX('Dados de Entrada'!$A$10:$C$11,2,MATCH(H25,'Dados de Entrada'!$A$10:$C$10,0))} -> 0.87 | G25: 1.05 | H25: EPR ou XLPE | I25: =B30 -> 32.817805 | J25: =(I25*G25)/(F25*C25) -> 39.607695 | K25: 144 | L25: =K25*F25*C25 -> 125.28
B28: ='BALANÇO TOTAL'!F25 -> 21600 | C28: POTENCIA FASE MAIS CARREGADA DO QGDL
B29: =380*SQRT(3) -> 658.17931
B30: =B28/B29 -> 32.817805 | G30: usei B1 7

Sheet Dados de entrada - TUGs
A1: Área | B1: Largura | C1: Comprimento | D1: Perimetro | F1: nº de TUGs | G1: Stugs | H1: TUEs
A2: Subestação | B2: 9.6 | C2: 9.8 | D2: =(2*B2)+(C2*2) -> 38.8 | E2: =D2/5 -> 7.76 | F2: =ROUNDUP(D2/5,0) -> 8 | G2: =F2*100 -> 800 | H2: -
A3: Sala de caldeiras | B3: 9.6 | C3: 15.92 | D3: =(2*B3)+(C3*2) -> 51.04 | E3: =D3/5 -> 10.208 | F3: =ROUNDUP(D3/5,0) -> 11 | G3: =F3*100 -> 1100 | H3: analisar planta
A4: Compressor | B4: 9.6 | C4: 9.28 | D4: =(2*B4)+(C4*2) -> 37.76 | E4: =D4/5 -> 7.552 | F4: =ROUNDUP(D4/5,0) -> 8 | G4: =F4*100 -> 800 | H4: analisar planta
A5: Depósito de carcaças | B5: 38.51 | C5: 43.37 | D5: =(2*B5)+(C5*2) -> 163.76 | E5: =D5/5 -> 32.752 | F5: =ROUNDUP(D5/5,0) -> 33 | G5: =F5*100 -> 3300 | H5: analisar planta
A6: Recapagem | B6: 11.18 | C6: 15.8 | D6: =(2*B6)+(C6*2) -> 53.96 | E6: =D6/5 -> 10.792 | F6: =ROUNDUP(D6/5,0) -> 11 | G6: =F6*100 -> 1100 | H6: analisar planta
A7: Raspa | B7: 30.92 | C7: 8.12 | D7: =(2*B7)+(C7*2) -> 78.08 | E7: =D7/5 -> 15.616 | F7: =ROUNDUP(D7/5,0) -> 16 | G7: =F7*100 -> 1600 | H7: analisar planta
A8: Escritório | B8: 6 | C8: 8.12 | D8: =(2*B8)+(C8*2) -> 28.24 | E8: =D8/5 -> 5.648 | F8: =ROUNDUP(D8/5,0) -> 6 | G8: =F8*100 -> 600 | H8: 1 ar condicionado
A9: Saída de produto | B9: 6 | C9: 5 | D9: =(2*B9)+(C9*2) -> 22 | E9: =D9/5 -> 4.4 | F9: =ROUNDUP(D9/5,0) -> 5 | G9: =F9*100 -> 500 | H9: 2 ar condicionado
A10: Controle de qualidade | B10: 6 | C10: 5 | D10: =(2*B10)+(C10*2) -> 22 | E10: =D10/5 -> 4.4 | F10: =ROUNDUP(D10/5,0) -> 5 | G10: =F10*100 -> 500 | H10: 3 ar condicionado
A11: Banheiros | B11: 3.5 | C11: 5.23 | D11: =(2*B11)+(C11*2) -> 17.46 | E11: =D11/5 -> 3.492 | F11: =ROUNDUP(D11/5,0) -> 4 | G11: =F11*100 -> 400 | H11: 3 chuveiros
